24-Oct-2019 15:27:00.450 WARNING [Thread-123] org.apache.catalina.servlets.CGIServlet$CGIRunner.sendToLog stderr line: [Traceback (most recent call last):]
24-Oct-2019 15:27:00.454 WARNING [Thread-123] org.apache.catalina.servlets.CGIServlet$CGIRunner.sendToLog stderr line: [  File "C:\Users\hayde\Desktop\UCI\Fall 2019\EECS 118\MP2\apache-tomcat-9.0.26\webapps\test\WEB-INF\cgi\project_3_gallery1.py", line 93, in <module>]
24-Oct-2019 15:27:00.455 WARNING [Thread-123] org.apache.catalina.servlets.CGIServlet$CGIRunner.sendToLog stderr line: [    display += display_imgs + display_img_title_link + display_detail_button + display_detail_link ]
24-Oct-2019 15:27:00.457 WARNING [Thread-123] org.apache.catalina.servlets.CGIServlet$CGIRunner.sendToLog stderr line: [NameError: name 'display_detail_link' is not defined]
24-Oct-2019 15:27:00.480 WARNING [Thread-123] org.apache.catalina.servlets.CGIServlet$CGIRunner.sendToLog Received [4] lines on stderr
24-Oct-2019 15:42:04.095 WARNING [Thread-130] org.apache.catalina.servlets.CGIServlet$CGIRunner.sendToLog stderr line: [Traceback (most recent call last):]
24-Oct-2019 15:42:04.095 WARNING [Thread-130] org.apache.catalina.servlets.CGIServlet$CGIRunner.sendToLog stderr line: [  File "C:\Users\hayde\Desktop\UCI\Fall 2019\EECS 118\MP2\apache-tomcat-9.0.26\webapps\test\WEB-INF\cgi\project_3.py", line 33, in <module>]
24-Oct-2019 15:42:04.096 WARNING [Thread-130] org.apache.catalina.servlets.CGIServlet$CGIRunner.sendToLog stderr line: [    display_gals += "Name: <a href='/test/cgi-bin/project_3_gallery1.py'>"+gal_1_name[i][0]+"</a><br />"+"Description: "+gal_1_des[i][0]]
24-Oct-2019 15:42:04.098 WARNING [Thread-130] org.apache.catalina.servlets.CGIServlet$CGIRunner.sendToLog stderr line: [NameError: name 'gal_1_name' is not defined]
24-Oct-2019 15:42:04.113 WARNING [Thread-130] org.apache.catalina.servlets.CGIServlet$CGIRunner.sendToLog Received [4] lines on stderr
24-Oct-2019 16:26:17.421 WARNING [Thread-137] org.apache.catalina.servlets.CGIServlet$CGIRunner.sendToLog stderr line: [  File "C:\Users\hayde\Desktop\UCI\Fall 2019\EECS 118\MP2\apache-tomcat-9.0.26\webapps\test\WEB-INF\cgi\project_3.py", line 34]
24-Oct-2019 16:26:17.423 WARNING [Thread-137] org.apache.catalina.servlets.CGIServlet$CGIRunner.sendToLog stderr line: [    display_gals += """<input type='hidden' name='"""+gal_name[i][0]+"""'>""""]
24-Oct-2019 16:26:17.425 WARNING [Thread-137] org.apache.catalina.servlets.CGIServlet$CGIRunner.sendToLog stderr line: [                                                                             ^]
24-Oct-2019 16:26:17.426 WARNING [Thread-137] org.apache.catalina.servlets.CGIServlet$CGIRunner.sendToLog stderr line: [SyntaxError: EOL while scanning string literal]
24-Oct-2019 16:26:17.434 WARNING [Thread-137] org.apache.catalina.servlets.CGIServlet$CGIRunner.sendToLog Received [4] lines on stderr
24-Oct-2019 16:26:39.514 WARNING [Thread-138] org.apache.catalina.servlets.CGIServlet$CGIRunner.sendToLog stderr line: [  File "C:\Users\hayde\Desktop\UCI\Fall 2019\EECS 118\MP2\apache-tomcat-9.0.26\webapps\test\WEB-INF\cgi\project_3.py", line 34]
24-Oct-2019 16:26:39.514 WARNING [Thread-138] org.apache.catalina.servlets.CGIServlet$CGIRunner.sendToLog stderr line: [    display_gals += """<input type='hidden' name="""+gal_name[i][0]+""">""""]
24-Oct-2019 16:26:39.516 WARNING [Thread-138] org.apache.catalina.servlets.CGIServlet$CGIRunner.sendToLog stderr line: [                                                                           ^]
24-Oct-2019 16:26:39.519 WARNING [Thread-138] org.apache.catalina.servlets.CGIServlet$CGIRunner.sendToLog stderr line: [SyntaxError: EOL while scanning string literal]
24-Oct-2019 16:26:39.524 WARNING [Thread-138] org.apache.catalina.servlets.CGIServlet$CGIRunner.sendToLog Received [4] lines on stderr
24-Oct-2019 16:43:28.053 WARNING [Thread-145] org.apache.catalina.servlets.CGIServlet$CGIRunner.sendToLog stderr line: [Traceback (most recent call last):]
24-Oct-2019 16:43:28.053 WARNING [Thread-145] org.apache.catalina.servlets.CGIServlet$CGIRunner.sendToLog stderr line: [  File "C:\Users\hayde\Desktop\UCI\Fall 2019\EECS 118\MP2\apache-tomcat-9.0.26\webapps\test\WEB-INF\cgi\project_3_gallery1.py", line 15, in <module>]
24-Oct-2019 16:43:28.055 WARNING [Thread-145] org.apache.catalina.servlets.CGIServlet$CGIRunner.sendToLog stderr line: [    query = "select link from image where gallery_name ='"+gallery_name+"'"]
24-Oct-2019 16:43:28.056 WARNING [Thread-145] org.apache.catalina.servlets.CGIServlet$CGIRunner.sendToLog stderr line: [TypeError: must be str, not NoneType]
24-Oct-2019 16:43:28.071 WARNING [Thread-145] org.apache.catalina.servlets.CGIServlet$CGIRunner.sendToLog Received [4] lines on stderr
24-Oct-2019 16:43:59.318 WARNING [Thread-147] org.apache.catalina.servlets.CGIServlet$CGIRunner.sendToLog stderr line: [Traceback (most recent call last):]
24-Oct-2019 16:43:59.318 WARNING [Thread-147] org.apache.catalina.servlets.CGIServlet$CGIRunner.sendToLog stderr line: [  File "C:\Users\hayde\Desktop\UCI\Fall 2019\EECS 118\MP2\apache-tomcat-9.0.26\webapps\test\WEB-INF\cgi\project_3_gallery1.py", line 15, in <module>]
24-Oct-2019 16:43:59.320 WARNING [Thread-147] org.apache.catalina.servlets.CGIServlet$CGIRunner.sendToLog stderr line: [    query = "select link from image where gallery_name ='"+gallery_name+"'"]
24-Oct-2019 16:43:59.320 WARNING [Thread-147] org.apache.catalina.servlets.CGIServlet$CGIRunner.sendToLog stderr line: [NameError: name 'gallery_name' is not defined]
24-Oct-2019 16:43:59.338 WARNING [Thread-147] org.apache.catalina.servlets.CGIServlet$CGIRunner.sendToLog Received [4] lines on stderr
24-Oct-2019 16:44:28.145 WARNING [Thread-148] org.apache.catalina.servlets.CGIServlet$CGIRunner.sendToLog stderr line: [  File "C:\Users\hayde\Desktop\UCI\Fall 2019\EECS 118\MP2\apache-tomcat-9.0.26\webapps\test\WEB-INF\cgi\project_3_gallery1.py", line 3]
24-Oct-2019 16:44:28.146 WARNING [Thread-148] org.apache.catalina.servlets.CGIServlet$CGIRunner.sendToLog stderr line: [    import cgi, cgitb, pymysql, cgitb.enable()]
24-Oct-2019 16:44:28.149 WARNING [Thread-148] org.apache.catalina.servlets.CGIServlet$CGIRunner.sendToLog stderr line: [                                            ^]
24-Oct-2019 16:44:28.152 WARNING [Thread-148] org.apache.catalina.servlets.CGIServlet$CGIRunner.sendToLog stderr line: [SyntaxError: invalid syntax]
24-Oct-2019 16:44:28.154 WARNING [Thread-148] org.apache.catalina.servlets.CGIServlet$CGIRunner.sendToLog Received [4] lines on stderr
24-Oct-2019 16:45:04.007 WARNING [Thread-149] org.apache.catalina.servlets.CGIServlet$CGIRunner.sendToLog stderr line: [  File "C:\Users\hayde\Desktop\UCI\Fall 2019\EECS 118\MP2\apache-tomcat-9.0.26\webapps\test\WEB-INF\cgi\project_3_gallery1.py", line 3]
24-Oct-2019 16:45:04.007 WARNING [Thread-149] org.apache.catalina.servlets.CGIServlet$CGIRunner.sendToLog stderr line: [    import cgi, cgitb, pymysql, cgitb.enable()]
24-Oct-2019 16:45:04.013 WARNING [Thread-149] org.apache.catalina.servlets.CGIServlet$CGIRunner.sendToLog stderr line: [                                            ^]
24-Oct-2019 16:45:04.018 WARNING [Thread-149] org.apache.catalina.servlets.CGIServlet$CGIRunner.sendToLog stderr line: [SyntaxError: invalid syntax]
24-Oct-2019 16:45:04.030 WARNING [Thread-149] org.apache.catalina.servlets.CGIServlet$CGIRunner.sendToLog Received [4] lines on stderr
24-Oct-2019 16:45:48.198 WARNING [Thread-150] org.apache.catalina.servlets.CGIServlet$CGIRunner.sendToLog stderr line: [  File "C:\Users\hayde\Desktop\UCI\Fall 2019\EECS 118\MP2\apache-tomcat-9.0.26\webapps\test\WEB-INF\cgi\project_3_gallery1.py", line 3]
24-Oct-2019 16:45:48.199 WARNING [Thread-150] org.apache.catalina.servlets.CGIServlet$CGIRunner.sendToLog stderr line: [    import cgi, cgitb, pymysql, cgitb.enable()]
24-Oct-2019 16:45:48.200 WARNING [Thread-150] org.apache.catalina.servlets.CGIServlet$CGIRunner.sendToLog stderr line: [                                            ^]
24-Oct-2019 16:45:48.201 WARNING [Thread-150] org.apache.catalina.servlets.CGIServlet$CGIRunner.sendToLog stderr line: [SyntaxError: invalid syntax]
24-Oct-2019 16:45:48.206 WARNING [Thread-150] org.apache.catalina.servlets.CGIServlet$CGIRunner.sendToLog Received [4] lines on stderr
24-Oct-2019 16:46:25.815 WARNING [Thread-151] org.apache.catalina.servlets.CGIServlet$CGIRunner.sendToLog stderr line: [  File "C:\Users\hayde\Desktop\UCI\Fall 2019\EECS 118\MP2\apache-tomcat-9.0.26\webapps\test\WEB-INF\cgi\project_3_gallery1.py", line 3]
24-Oct-2019 16:46:25.815 WARNING [Thread-151] org.apache.catalina.servlets.CGIServlet$CGIRunner.sendToLog stderr line: [    import cgi, cgitb, pymysql, cgitb.enable()]
24-Oct-2019 16:46:25.817 WARNING [Thread-151] org.apache.catalina.servlets.CGIServlet$CGIRunner.sendToLog stderr line: [                                            ^]
24-Oct-2019 16:46:25.817 WARNING [Thread-151] org.apache.catalina.servlets.CGIServlet$CGIRunner.sendToLog stderr line: [SyntaxError: invalid syntax]
24-Oct-2019 16:46:25.822 WARNING [Thread-151] org.apache.catalina.servlets.CGIServlet$CGIRunner.sendToLog Received [4] lines on stderr
24-Oct-2019 17:07:17.510 WARNING [Thread-166] org.apache.catalina.servlets.CGIServlet$CGIRunner.sendToLog stderr line: [Traceback (most recent call last):]
24-Oct-2019 17:07:17.511 WARNING [Thread-166] org.apache.catalina.servlets.CGIServlet$CGIRunner.sendToLog stderr line: [  File "C:\Users\hayde\Desktop\UCI\Fall 2019\EECS 118\MP2\apache-tomcat-9.0.26\webapps\test\WEB-INF\cgi\project_3.py", line 17, in <module>]
24-Oct-2019 17:07:17.512 WARNING [Thread-166] org.apache.catalina.servlets.CGIServlet$CGIRunner.sendToLog stderr line: [    cur.execute(query)]
24-Oct-2019 17:07:17.513 WARNING [Thread-166] org.apache.catalina.servlets.CGIServlet$CGIRunner.sendToLog stderr line: [  File "C:\Users\hayde\AppData\Local\Programs\Python\Python36\lib\site-packages\pymysql\cursors.py", line 170, in execute]
24-Oct-2019 17:07:17.515 WARNING [Thread-166] org.apache.catalina.servlets.CGIServlet$CGIRunner.sendToLog stderr line: [    result = self._query(query)]
24-Oct-2019 17:07:17.516 WARNING [Thread-166] org.apache.catalina.servlets.CGIServlet$CGIRunner.sendToLog stderr line: [  File "C:\Users\hayde\AppData\Local\Programs\Python\Python36\lib\site-packages\pymysql\cursors.py", line 328, in _query]
24-Oct-2019 17:07:17.517 WARNING [Thread-166] org.apache.catalina.servlets.CGIServlet$CGIRunner.sendToLog stderr line: [    conn.query(q)]
24-Oct-2019 17:07:17.518 WARNING [Thread-166] org.apache.catalina.servlets.CGIServlet$CGIRunner.sendToLog stderr line: [  File "C:\Users\hayde\AppData\Local\Programs\Python\Python36\lib\site-packages\pymysql\connections.py", line 517, in query]
24-Oct-2019 17:07:17.519 WARNING [Thread-166] org.apache.catalina.servlets.CGIServlet$CGIRunner.sendToLog stderr line: [    self._affected_rows = self._read_query_result(unbuffered=unbuffered)]
24-Oct-2019 17:07:17.519 WARNING [Thread-166] org.apache.catalina.servlets.CGIServlet$CGIRunner.sendToLog stderr line: [  File "C:\Users\hayde\AppData\Local\Programs\Python\Python36\lib\site-packages\pymysql\connections.py", line 732, in _read_query_result]
24-Oct-2019 17:07:17.520 WARNING [Thread-166] org.apache.catalina.servlets.CGIServlet$CGIRunner.sendToLog stderr line: [    result.read()]
24-Oct-2019 17:07:17.521 WARNING [Thread-166] org.apache.catalina.servlets.CGIServlet$CGIRunner.sendToLog stderr line: [  File "C:\Users\hayde\AppData\Local\Programs\Python\Python36\lib\site-packages\pymysql\connections.py", line 1075, in read]
24-Oct-2019 17:07:17.522 WARNING [Thread-166] org.apache.catalina.servlets.CGIServlet$CGIRunner.sendToLog stderr line: [    first_packet = self.connection._read_packet()]
24-Oct-2019 17:07:17.522 WARNING [Thread-166] org.apache.catalina.servlets.CGIServlet$CGIRunner.sendToLog stderr line: [  File "C:\Users\hayde\AppData\Local\Programs\Python\Python36\lib\site-packages\pymysql\connections.py", line 684, in _read_packet]
24-Oct-2019 17:07:17.523 WARNING [Thread-166] org.apache.catalina.servlets.CGIServlet$CGIRunner.sendToLog stderr line: [    packet.check_error()]
24-Oct-2019 17:07:17.524 WARNING [Thread-166] org.apache.catalina.servlets.CGIServlet$CGIRunner.sendToLog stderr line: [  File "C:\Users\hayde\AppData\Local\Programs\Python\Python36\lib\site-packages\pymysql\protocol.py", line 220, in check_error]
24-Oct-2019 17:07:17.525 WARNING [Thread-166] org.apache.catalina.servlets.CGIServlet$CGIRunner.sendToLog stderr line: [    err.raise_mysql_exception(self._data)]
24-Oct-2019 17:07:17.525 WARNING [Thread-166] org.apache.catalina.servlets.CGIServlet$CGIRunner.sendToLog stderr line: [  File "C:\Users\hayde\AppData\Local\Programs\Python\Python36\lib\site-packages\pymysql\err.py", line 109, in raise_mysql_exception]
24-Oct-2019 17:07:17.526 WARNING [Thread-166] org.apache.catalina.servlets.CGIServlet$CGIRunner.sendToLog stderr line: [    raise errorclass(errno, errval)]
24-Oct-2019 17:07:17.527 WARNING [Thread-166] org.apache.catalina.servlets.CGIServlet$CGIRunner.sendToLog stderr line: [pymysql.err.InternalError: (1054, "Unknown column 'link' in 'field list'")]
24-Oct-2019 17:07:17.532 WARNING [Thread-166] org.apache.catalina.servlets.CGIServlet$CGIRunner.sendToLog Received [20] lines on stderr
24-Oct-2019 17:08:01.941 WARNING [Thread-167] org.apache.catalina.servlets.CGIServlet$CGIRunner.sendToLog stderr line: [Traceback (most recent call last):]
24-Oct-2019 17:08:01.942 WARNING [Thread-167] org.apache.catalina.servlets.CGIServlet$CGIRunner.sendToLog stderr line: [  File "C:\Users\hayde\Desktop\UCI\Fall 2019\EECS 118\MP2\apache-tomcat-9.0.26\webapps\test\WEB-INF\cgi\project_3.py", line 17, in <module>]
24-Oct-2019 17:08:01.944 WARNING [Thread-167] org.apache.catalina.servlets.CGIServlet$CGIRunner.sendToLog stderr line: [    cur.execute(query)]
24-Oct-2019 17:08:01.946 WARNING [Thread-167] org.apache.catalina.servlets.CGIServlet$CGIRunner.sendToLog stderr line: [  File "C:\Users\hayde\AppData\Local\Programs\Python\Python36\lib\site-packages\pymysql\cursors.py", line 170, in execute]
24-Oct-2019 17:08:01.947 WARNING [Thread-167] org.apache.catalina.servlets.CGIServlet$CGIRunner.sendToLog stderr line: [    result = self._query(query)]
24-Oct-2019 17:08:01.949 WARNING [Thread-167] org.apache.catalina.servlets.CGIServlet$CGIRunner.sendToLog stderr line: [  File "C:\Users\hayde\AppData\Local\Programs\Python\Python36\lib\site-packages\pymysql\cursors.py", line 328, in _query]
24-Oct-2019 17:08:01.951 WARNING [Thread-167] org.apache.catalina.servlets.CGIServlet$CGIRunner.sendToLog stderr line: [    conn.query(q)]
24-Oct-2019 17:08:01.955 WARNING [Thread-167] org.apache.catalina.servlets.CGIServlet$CGIRunner.sendToLog stderr line: [  File "C:\Users\hayde\AppData\Local\Programs\Python\Python36\lib\site-packages\pymysql\connections.py", line 517, in query]
24-Oct-2019 17:08:01.956 WARNING [Thread-167] org.apache.catalina.servlets.CGIServlet$CGIRunner.sendToLog stderr line: [    self._affected_rows = self._read_query_result(unbuffered=unbuffered)]
24-Oct-2019 17:08:01.958 WARNING [Thread-167] org.apache.catalina.servlets.CGIServlet$CGIRunner.sendToLog stderr line: [  File "C:\Users\hayde\AppData\Local\Programs\Python\Python36\lib\site-packages\pymysql\connections.py", line 732, in _read_query_result]
24-Oct-2019 17:08:01.960 WARNING [Thread-167] org.apache.catalina.servlets.CGIServlet$CGIRunner.sendToLog stderr line: [    result.read()]
24-Oct-2019 17:08:01.960 WARNING [Thread-167] org.apache.catalina.servlets.CGIServlet$CGIRunner.sendToLog stderr line: [  File "C:\Users\hayde\AppData\Local\Programs\Python\Python36\lib\site-packages\pymysql\connections.py", line 1075, in read]
24-Oct-2019 17:08:01.963 WARNING [Thread-167] org.apache.catalina.servlets.CGIServlet$CGIRunner.sendToLog stderr line: [    first_packet = self.connection._read_packet()]
24-Oct-2019 17:08:01.965 WARNING [Thread-167] org.apache.catalina.servlets.CGIServlet$CGIRunner.sendToLog stderr line: [  File "C:\Users\hayde\AppData\Local\Programs\Python\Python36\lib\site-packages\pymysql\connections.py", line 684, in _read_packet]
24-Oct-2019 17:08:01.966 WARNING [Thread-167] org.apache.catalina.servlets.CGIServlet$CGIRunner.sendToLog stderr line: [    packet.check_error()]
24-Oct-2019 17:08:01.969 WARNING [Thread-167] org.apache.catalina.servlets.CGIServlet$CGIRunner.sendToLog stderr line: [  File "C:\Users\hayde\AppData\Local\Programs\Python\Python36\lib\site-packages\pymysql\protocol.py", line 220, in check_error]
24-Oct-2019 17:08:01.970 WARNING [Thread-167] org.apache.catalina.servlets.CGIServlet$CGIRunner.sendToLog stderr line: [    err.raise_mysql_exception(self._data)]
24-Oct-2019 17:08:01.971 WARNING [Thread-167] org.apache.catalina.servlets.CGIServlet$CGIRunner.sendToLog stderr line: [  File "C:\Users\hayde\AppData\Local\Programs\Python\Python36\lib\site-packages\pymysql\err.py", line 109, in raise_mysql_exception]
24-Oct-2019 17:08:01.973 WARNING [Thread-167] org.apache.catalina.servlets.CGIServlet$CGIRunner.sendToLog stderr line: [    raise errorclass(errno, errval)]
24-Oct-2019 17:08:01.975 WARNING [Thread-167] org.apache.catalina.servlets.CGIServlet$CGIRunner.sendToLog stderr line: [pymysql.err.InternalError: (1054, "Unknown column 'link' in 'field list'")]
24-Oct-2019 17:08:01.982 WARNING [Thread-167] org.apache.catalina.servlets.CGIServlet$CGIRunner.sendToLog Received [20] lines on stderr
24-Oct-2019 17:10:53.957 WARNING [Thread-168] org.apache.catalina.servlets.CGIServlet$CGIRunner.sendToLog stderr line: [Traceback (most recent call last):]
24-Oct-2019 17:10:53.958 WARNING [Thread-168] org.apache.catalina.servlets.CGIServlet$CGIRunner.sendToLog stderr line: [  File "C:\Users\hayde\Desktop\UCI\Fall 2019\EECS 118\MP2\apache-tomcat-9.0.26\webapps\test\WEB-INF\cgi\project_3.py", line 35, in <module>]
24-Oct-2019 17:10:53.959 WARNING [Thread-168] org.apache.catalina.servlets.CGIServlet$CGIRunner.sendToLog stderr line: [    display_gals += "<img src='"+gal_img[0]+"' width=200px height=200px alt='no image found'>"]
24-Oct-2019 17:10:53.960 WARNING [Thread-168] org.apache.catalina.servlets.CGIServlet$CGIRunner.sendToLog stderr line: [TypeError: 'NoneType' object is not subscriptable]
24-Oct-2019 17:10:53.974 WARNING [Thread-168] org.apache.catalina.servlets.CGIServlet$CGIRunner.sendToLog Received [4] lines on stderr
24-Oct-2019 17:11:40.341 WARNING [Thread-169] org.apache.catalina.servlets.CGIServlet$CGIRunner.sendToLog stderr line: [Traceback (most recent call last):]
24-Oct-2019 17:11:40.341 WARNING [Thread-169] org.apache.catalina.servlets.CGIServlet$CGIRunner.sendToLog stderr line: [  File "C:\Users\hayde\Desktop\UCI\Fall 2019\EECS 118\MP2\apache-tomcat-9.0.26\webapps\test\WEB-INF\cgi\project_3.py", line 35, in <module>]
24-Oct-2019 17:11:40.342 WARNING [Thread-169] org.apache.catalina.servlets.CGIServlet$CGIRunner.sendToLog stderr line: [    display_gals += "<img src='"+gal_img[0]+"' width=200px height=200px alt='no image found'>"]
24-Oct-2019 17:11:40.343 WARNING [Thread-169] org.apache.catalina.servlets.CGIServlet$CGIRunner.sendToLog stderr line: [TypeError: 'NoneType' object is not subscriptable]
24-Oct-2019 17:11:40.359 WARNING [Thread-169] org.apache.catalina.servlets.CGIServlet$CGIRunner.sendToLog Received [4] lines on stderr
24-Oct-2019 17:13:06.465 WARNING [Thread-170] org.apache.catalina.servlets.CGIServlet$CGIRunner.sendToLog stderr line: [Traceback (most recent call last):]
24-Oct-2019 17:13:06.465 WARNING [Thread-170] org.apache.catalina.servlets.CGIServlet$CGIRunner.sendToLog stderr line: [  File "C:\Users\hayde\Desktop\UCI\Fall 2019\EECS 118\MP2\apache-tomcat-9.0.26\webapps\test\WEB-INF\cgi\project_3.py", line 35, in <module>]
24-Oct-2019 17:13:06.467 WARNING [Thread-170] org.apache.catalina.servlets.CGIServlet$CGIRunner.sendToLog stderr line: [    display_gals += "<img src='"+gal_img[0]+"' width=200px height=200px alt='no image found'></img>"]
24-Oct-2019 17:13:06.468 WARNING [Thread-170] org.apache.catalina.servlets.CGIServlet$CGIRunner.sendToLog stderr line: [TypeError: 'NoneType' object is not subscriptable]
24-Oct-2019 17:13:06.486 WARNING [Thread-170] org.apache.catalina.servlets.CGIServlet$CGIRunner.sendToLog Received [4] lines on stderr
24-Oct-2019 17:15:21.662 WARNING [Thread-172] org.apache.catalina.servlets.CGIServlet$CGIRunner.sendToLog stderr line: [Traceback (most recent call last):]
24-Oct-2019 17:15:21.662 WARNING [Thread-172] org.apache.catalina.servlets.CGIServlet$CGIRunner.sendToLog stderr line: [  File "C:\Users\hayde\Desktop\UCI\Fall 2019\EECS 118\MP2\apache-tomcat-9.0.26\webapps\test\WEB-INF\cgi\project_3.py", line 36, in <module>]
24-Oct-2019 17:15:21.664 WARNING [Thread-172] org.apache.catalina.servlets.CGIServlet$CGIRunner.sendToLog stderr line: [    display_gals += "<img src='"+gal_img[0]+"' width=200px height=200px alt='no image found'>"]
24-Oct-2019 17:15:21.665 WARNING [Thread-172] org.apache.catalina.servlets.CGIServlet$CGIRunner.sendToLog stderr line: [TypeError: 'NoneType' object is not subscriptable]
24-Oct-2019 17:15:21.679 WARNING [Thread-172] org.apache.catalina.servlets.CGIServlet$CGIRunner.sendToLog Received [4] lines on stderr
24-Oct-2019 17:17:28.731 WARNING [Thread-173] org.apache.catalina.servlets.CGIServlet$CGIRunner.sendToLog stderr line: [Traceback (most recent call last):]
24-Oct-2019 17:17:28.731 WARNING [Thread-173] org.apache.catalina.servlets.CGIServlet$CGIRunner.sendToLog stderr line: [  File "C:\Users\hayde\Desktop\UCI\Fall 2019\EECS 118\MP2\apache-tomcat-9.0.26\webapps\test\WEB-INF\cgi\project_3.py", line 36, in <module>]
24-Oct-2019 17:17:28.733 WARNING [Thread-173] org.apache.catalina.servlets.CGIServlet$CGIRunner.sendToLog stderr line: [    display_gal  = "<img src='"+gal_img[0]+"' width=200px height=200px alt='img not found'>"]
24-Oct-2019 17:17:28.734 WARNING [Thread-173] org.apache.catalina.servlets.CGIServlet$CGIRunner.sendToLog stderr line: [TypeError: 'NoneType' object is not subscriptable]
24-Oct-2019 17:17:28.750 WARNING [Thread-173] org.apache.catalina.servlets.CGIServlet$CGIRunner.sendToLog Received [4] lines on stderr
24-Oct-2019 17:17:47.947 WARNING [Thread-174] org.apache.catalina.servlets.CGIServlet$CGIRunner.sendToLog stderr line: [Traceback (most recent call last):]
24-Oct-2019 17:17:47.948 WARNING [Thread-174] org.apache.catalina.servlets.CGIServlet$CGIRunner.sendToLog stderr line: [  File "C:\Users\hayde\Desktop\UCI\Fall 2019\EECS 118\MP2\apache-tomcat-9.0.26\webapps\test\WEB-INF\cgi\project_3.py", line 34, in <module>]
24-Oct-2019 17:17:47.949 WARNING [Thread-174] org.apache.catalina.servlets.CGIServlet$CGIRunner.sendToLog stderr line: [    display_gals += "<form enctype='multipart/form-data' action='/test/cgi-bin/project_3_gallery1.py' method='POST'>"]
24-Oct-2019 17:17:47.950 WARNING [Thread-174] org.apache.catalina.servlets.CGIServlet$CGIRunner.sendToLog stderr line: [NameError: name 'display_gals' is not defined]
24-Oct-2019 17:17:47.981 WARNING [Thread-174] org.apache.catalina.servlets.CGIServlet$CGIRunner.sendToLog Received [4] lines on stderr
24-Oct-2019 17:18:31.414 WARNING [Thread-175] org.apache.catalina.servlets.CGIServlet$CGIRunner.sendToLog stderr line: [Traceback (most recent call last):]
24-Oct-2019 17:18:31.415 WARNING [Thread-175] org.apache.catalina.servlets.CGIServlet$CGIRunner.sendToLog stderr line: [  File "C:\Users\hayde\Desktop\UCI\Fall 2019\EECS 118\MP2\apache-tomcat-9.0.26\webapps\test\WEB-INF\cgi\project_3.py", line 34, in <module>]
24-Oct-2019 17:18:31.416 WARNING [Thread-175] org.apache.catalina.servlets.CGIServlet$CGIRunner.sendToLog stderr line: [    display_gals += "<form enctype='multipart/form-data' action='/test/cgi-bin/project_3_gallery1.py' method='POST'>"]
24-Oct-2019 17:18:31.417 WARNING [Thread-175] org.apache.catalina.servlets.CGIServlet$CGIRunner.sendToLog stderr line: [NameError: name 'display_gals' is not defined]
24-Oct-2019 17:18:31.432 WARNING [Thread-175] org.apache.catalina.servlets.CGIServlet$CGIRunner.sendToLog Received [4] lines on stderr
24-Oct-2019 17:19:36.815 WARNING [Thread-176] org.apache.catalina.servlets.CGIServlet$CGIRunner.sendToLog stderr line: [Traceback (most recent call last):]
24-Oct-2019 17:19:36.816 WARNING [Thread-176] org.apache.catalina.servlets.CGIServlet$CGIRunner.sendToLog stderr line: [  File "C:\Users\hayde\Desktop\UCI\Fall 2019\EECS 118\MP2\apache-tomcat-9.0.26\webapps\test\WEB-INF\cgi\project_3.py", line 34, in <module>]
24-Oct-2019 17:19:36.818 WARNING [Thread-176] org.apache.catalina.servlets.CGIServlet$CGIRunner.sendToLog stderr line: [    display_gals += "<form enctype='multipart/form-data' action='/test/cgi-bin/project_3_gallery1.py' method='POST'>"]
24-Oct-2019 17:19:36.819 WARNING [Thread-176] org.apache.catalina.servlets.CGIServlet$CGIRunner.sendToLog stderr line: [NameError: name 'display_gals' is not defined]
24-Oct-2019 17:19:36.835 WARNING [Thread-176] org.apache.catalina.servlets.CGIServlet$CGIRunner.sendToLog Received [4] lines on stderr
24-Oct-2019 17:20:38.920 WARNING [Thread-177] org.apache.catalina.servlets.CGIServlet$CGIRunner.sendToLog stderr line: [Traceback (most recent call last):]
24-Oct-2019 17:20:38.920 WARNING [Thread-177] org.apache.catalina.servlets.CGIServlet$CGIRunner.sendToLog stderr line: [  File "C:\Users\hayde\Desktop\UCI\Fall 2019\EECS 118\MP2\apache-tomcat-9.0.26\webapps\test\WEB-INF\cgi\project_3.py", line 34, in <module>]
24-Oct-2019 17:20:38.922 WARNING [Thread-177] org.apache.catalina.servlets.CGIServlet$CGIRunner.sendToLog stderr line: [    display_gals += "<form enctype='multipart/form-data' action='/test/cgi-bin/project_3_gallery1.py' method='POST'>"]
24-Oct-2019 17:20:38.922 WARNING [Thread-177] org.apache.catalina.servlets.CGIServlet$CGIRunner.sendToLog stderr line: [NameError: name 'display_gals' is not defined]
24-Oct-2019 17:20:38.942 WARNING [Thread-177] org.apache.catalina.servlets.CGIServlet$CGIRunner.sendToLog Received [4] lines on stderr
24-Oct-2019 17:21:13.326 WARNING [Thread-178] org.apache.catalina.servlets.CGIServlet$CGIRunner.sendToLog stderr line: [Traceback (most recent call last):]
24-Oct-2019 17:21:13.327 WARNING [Thread-178] org.apache.catalina.servlets.CGIServlet$CGIRunner.sendToLog stderr line: [  File "C:\Users\hayde\Desktop\UCI\Fall 2019\EECS 118\MP2\apache-tomcat-9.0.26\webapps\test\WEB-INF\cgi\project_3.py", line 34, in <module>]
24-Oct-2019 17:21:13.328 WARNING [Thread-178] org.apache.catalina.servlets.CGIServlet$CGIRunner.sendToLog stderr line: [    display_gals += "<form enctype='multipart/form-data' action='/test/cgi-bin/project_3_gallery1.py' method='POST'>"]
24-Oct-2019 17:21:13.329 WARNING [Thread-178] org.apache.catalina.servlets.CGIServlet$CGIRunner.sendToLog stderr line: [NameError: name 'display_gals' is not defined]
24-Oct-2019 17:21:13.352 WARNING [Thread-178] org.apache.catalina.servlets.CGIServlet$CGIRunner.sendToLog Received [4] lines on stderr
24-Oct-2019 17:21:32.989 WARNING [Thread-179] org.apache.catalina.servlets.CGIServlet$CGIRunner.sendToLog stderr line: [Traceback (most recent call last):]
24-Oct-2019 17:21:32.989 WARNING [Thread-179] org.apache.catalina.servlets.CGIServlet$CGIRunner.sendToLog stderr line: [  File "C:\Users\hayde\Desktop\UCI\Fall 2019\EECS 118\MP2\apache-tomcat-9.0.26\webapps\test\WEB-INF\cgi\project_3.py", line 34, in <module>]
24-Oct-2019 17:21:32.991 WARNING [Thread-179] org.apache.catalina.servlets.CGIServlet$CGIRunner.sendToLog stderr line: [    display_gals += "<form enctype='multipart/form-data' action='/test/cgi-bin/project_3_gallery1.py' method='POST'>"]
24-Oct-2019 17:21:32.992 WARNING [Thread-179] org.apache.catalina.servlets.CGIServlet$CGIRunner.sendToLog stderr line: [NameError: name 'display_gals' is not defined]
24-Oct-2019 17:21:33.007 WARNING [Thread-179] org.apache.catalina.servlets.CGIServlet$CGIRunner.sendToLog Received [4] lines on stderr
24-Oct-2019 17:22:28.337 WARNING [Thread-180] org.apache.catalina.servlets.CGIServlet$CGIRunner.sendToLog stderr line: [Traceback (most recent call last):]
24-Oct-2019 17:22:28.338 WARNING [Thread-180] org.apache.catalina.servlets.CGIServlet$CGIRunner.sendToLog stderr line: [  File "C:\Users\hayde\Desktop\UCI\Fall 2019\EECS 118\MP2\apache-tomcat-9.0.26\webapps\test\WEB-INF\cgi\project_3.py", line 34, in <module>]
24-Oct-2019 17:22:28.341 WARNING [Thread-180] org.apache.catalina.servlets.CGIServlet$CGIRunner.sendToLog stderr line: [    display_gals += "<form enctype='multipart/form-data' action='/test/cgi-bin/project_3_gallery1.py' method='POST'>"]
24-Oct-2019 17:22:28.342 WARNING [Thread-180] org.apache.catalina.servlets.CGIServlet$CGIRunner.sendToLog stderr line: [NameError: name 'display_gals' is not defined]
24-Oct-2019 17:22:28.365 WARNING [Thread-180] org.apache.catalina.servlets.CGIServlet$CGIRunner.sendToLog Received [4] lines on stderr
24-Oct-2019 17:25:41.467 WARNING [Thread-183] org.apache.catalina.servlets.CGIServlet$CGIRunner.sendToLog stderr line: [Traceback (most recent call last):]
24-Oct-2019 17:25:41.468 WARNING [Thread-183] org.apache.catalina.servlets.CGIServlet$CGIRunner.sendToLog stderr line: [  File "C:\Users\hayde\Desktop\UCI\Fall 2019\EECS 118\MP2\apache-tomcat-9.0.26\webapps\test\WEB-INF\cgi\project_3.py", line 45, in <module>]
24-Oct-2019 17:25:41.469 WARNING [Thread-183] org.apache.catalina.servlets.CGIServlet$CGIRunner.sendToLog stderr line: [    print("%s"%(gal_img[0]))]
24-Oct-2019 17:25:41.470 WARNING [Thread-183] org.apache.catalina.servlets.CGIServlet$CGIRunner.sendToLog stderr line: [TypeError: 'NoneType' object is not subscriptable]
24-Oct-2019 17:25:41.487 WARNING [Thread-183] org.apache.catalina.servlets.CGIServlet$CGIRunner.sendToLog Received [4] lines on stderr
24-Oct-2019 17:26:37.234 WARNING [Thread-184] org.apache.catalina.servlets.CGIServlet$CGIRunner.sendToLog stderr line: [Traceback (most recent call last):]
24-Oct-2019 17:26:37.235 WARNING [Thread-184] org.apache.catalina.servlets.CGIServlet$CGIRunner.sendToLog stderr line: [  File "C:\Users\hayde\Desktop\UCI\Fall 2019\EECS 118\MP2\apache-tomcat-9.0.26\webapps\test\WEB-INF\cgi\project_3.py", line 45, in <module>]
24-Oct-2019 17:26:37.236 WARNING [Thread-184] org.apache.catalina.servlets.CGIServlet$CGIRunner.sendToLog stderr line: [    print("%s"%(gal_img[0]))]
24-Oct-2019 17:26:37.237 WARNING [Thread-184] org.apache.catalina.servlets.CGIServlet$CGIRunner.sendToLog stderr line: [TypeError: 'NoneType' object is not subscriptable]
24-Oct-2019 17:26:37.254 WARNING [Thread-184] org.apache.catalina.servlets.CGIServlet$CGIRunner.sendToLog Received [4] lines on stderr
24-Oct-2019 17:27:07.928 WARNING [Thread-185] org.apache.catalina.servlets.CGIServlet$CGIRunner.sendToLog stderr line: [  File "C:\Users\hayde\Desktop\UCI\Fall 2019\EECS 118\MP2\apache-tomcat-9.0.26\webapps\test\WEB-INF\cgi\project_3.py", line 46]
24-Oct-2019 17:27:07.929 WARNING [Thread-185] org.apache.catalina.servlets.CGIServlet$CGIRunner.sendToLog stderr line: [    ]
24-Oct-2019 17:27:07.930 WARNING [Thread-185] org.apache.catalina.servlets.CGIServlet$CGIRunner.sendToLog stderr line: [                      ^]
24-Oct-2019 17:27:07.931 WARNING [Thread-185] org.apache.catalina.servlets.CGIServlet$CGIRunner.sendToLog stderr line: [SyntaxError: unexpected EOF while parsing]
24-Oct-2019 17:27:07.942 WARNING [Thread-185] org.apache.catalina.servlets.CGIServlet$CGIRunner.sendToLog Received [4] lines on stderr
24-Oct-2019 17:27:32.117 WARNING [Thread-186] org.apache.catalina.servlets.CGIServlet$CGIRunner.sendToLog stderr line: [  File "C:\Users\hayde\Desktop\UCI\Fall 2019\EECS 118\MP2\apache-tomcat-9.0.26\webapps\test\WEB-INF\cgi\project_3.py", line 46]
24-Oct-2019 17:27:32.117 WARNING [Thread-186] org.apache.catalina.servlets.CGIServlet$CGIRunner.sendToLog stderr line: [    ]
24-Oct-2019 17:27:32.117 WARNING [Thread-186] org.apache.catalina.servlets.CGIServlet$CGIRunner.sendToLog stderr line: [                      ^]
24-Oct-2019 17:27:32.118 WARNING [Thread-186] org.apache.catalina.servlets.CGIServlet$CGIRunner.sendToLog stderr line: [SyntaxError: unexpected EOF while parsing]
24-Oct-2019 17:27:32.123 WARNING [Thread-186] org.apache.catalina.servlets.CGIServlet$CGIRunner.sendToLog Received [4] lines on stderr
24-Oct-2019 17:31:11.473 WARNING [Thread-189] org.apache.catalina.servlets.CGIServlet$CGIRunner.sendToLog stderr line: [Traceback (most recent call last):]
24-Oct-2019 17:31:11.474 WARNING [Thread-189] org.apache.catalina.servlets.CGIServlet$CGIRunner.sendToLog stderr line: [  File "C:\Users\hayde\Desktop\UCI\Fall 2019\EECS 118\MP2\apache-tomcat-9.0.26\webapps\test\WEB-INF\cgi\project_3.py", line 38, in <module>]
24-Oct-2019 17:31:11.475 WARNING [Thread-189] org.apache.catalina.servlets.CGIServlet$CGIRunner.sendToLog stderr line: [    display_gals += "<img src='"+gal_img[0]+"' width=200px height=200px alt='img not found'>"]
24-Oct-2019 17:31:11.476 WARNING [Thread-189] org.apache.catalina.servlets.CGIServlet$CGIRunner.sendToLog stderr line: [TypeError: 'NoneType' object is not subscriptable]
24-Oct-2019 17:31:11.496 WARNING [Thread-189] org.apache.catalina.servlets.CGIServlet$CGIRunner.sendToLog Received [4] lines on stderr
24-Oct-2019 17:31:52.560 WARNING [Thread-190] org.apache.catalina.servlets.CGIServlet$CGIRunner.sendToLog stderr line: [  File "C:\Users\hayde\Desktop\UCI\Fall 2019\EECS 118\MP2\apache-tomcat-9.0.26\webapps\test\WEB-INF\cgi\project_3.py", line 36]
24-Oct-2019 17:31:52.561 WARNING [Thread-190] org.apache.catalina.servlets.CGIServlet$CGIRunner.sendToLog stderr line: [    if !gal_img:]
24-Oct-2019 17:31:52.562 WARNING [Thread-190] org.apache.catalina.servlets.CGIServlet$CGIRunner.sendToLog stderr line: [       ^]
24-Oct-2019 17:31:52.563 WARNING [Thread-190] org.apache.catalina.servlets.CGIServlet$CGIRunner.sendToLog stderr line: [SyntaxError: invalid syntax]
24-Oct-2019 17:31:52.568 WARNING [Thread-190] org.apache.catalina.servlets.CGIServlet$CGIRunner.sendToLog Received [4] lines on stderr
24-Oct-2019 17:32:27.412 WARNING [Thread-191] org.apache.catalina.servlets.CGIServlet$CGIRunner.sendToLog stderr line: [  File "C:\Users\hayde\Desktop\UCI\Fall 2019\EECS 118\MP2\apache-tomcat-9.0.26\webapps\test\WEB-INF\cgi\project_3.py", line 36]
24-Oct-2019 17:32:27.413 WARNING [Thread-191] org.apache.catalina.servlets.CGIServlet$CGIRunner.sendToLog stderr line: [    if !gal_img:]
24-Oct-2019 17:32:27.413 WARNING [Thread-191] org.apache.catalina.servlets.CGIServlet$CGIRunner.sendToLog stderr line: [       ^]
24-Oct-2019 17:32:27.414 WARNING [Thread-191] org.apache.catalina.servlets.CGIServlet$CGIRunner.sendToLog stderr line: [SyntaxError: invalid syntax]
24-Oct-2019 17:32:27.418 WARNING [Thread-191] org.apache.catalina.servlets.CGIServlet$CGIRunner.sendToLog Received [4] lines on stderr
24-Oct-2019 17:33:05.697 WARNING [Thread-192] org.apache.catalina.servlets.CGIServlet$CGIRunner.sendToLog stderr line: [  File "C:\Users\hayde\Desktop\UCI\Fall 2019\EECS 118\MP2\apache-tomcat-9.0.26\webapps\test\WEB-INF\cgi\project_3.py", line 36]
24-Oct-2019 17:33:05.698 WARNING [Thread-192] org.apache.catalina.servlets.CGIServlet$CGIRunner.sendToLog stderr line: [    if !gal_img:]
24-Oct-2019 17:33:05.701 WARNING [Thread-192] org.apache.catalina.servlets.CGIServlet$CGIRunner.sendToLog stderr line: [       ^]
24-Oct-2019 17:33:05.705 WARNING [Thread-192] org.apache.catalina.servlets.CGIServlet$CGIRunner.sendToLog stderr line: [SyntaxError: invalid syntax]
24-Oct-2019 17:33:05.711 WARNING [Thread-192] org.apache.catalina.servlets.CGIServlet$CGIRunner.sendToLog Received [4] lines on stderr
24-Oct-2019 17:34:32.834 WARNING [Thread-194] org.apache.catalina.servlets.CGIServlet$CGIRunner.sendToLog stderr line: [Traceback (most recent call last):]
24-Oct-2019 17:34:32.835 WARNING [Thread-194] org.apache.catalina.servlets.CGIServlet$CGIRunner.sendToLog stderr line: [  File "C:\Users\hayde\Desktop\UCI\Fall 2019\EECS 118\MP2\apache-tomcat-9.0.26\webapps\test\WEB-INF\cgi\project_3.py", line 40, in <module>]
24-Oct-2019 17:34:32.836 WARNING [Thread-194] org.apache.catalina.servlets.CGIServlet$CGIRunner.sendToLog stderr line: [    display_gals += "<img src='"+gal_img[0]+"' width=200px height=200px alt='img not found'>"]
24-Oct-2019 17:34:32.837 WARNING [Thread-194] org.apache.catalina.servlets.CGIServlet$CGIRunner.sendToLog stderr line: [IndexError: string index out of range]
24-Oct-2019 17:34:32.853 WARNING [Thread-194] org.apache.catalina.servlets.CGIServlet$CGIRunner.sendToLog Received [4] lines on stderr
24-Oct-2019 17:38:20.967 WARNING [Thread-201] org.apache.catalina.servlets.CGIServlet$CGIRunner.sendToLog stderr line: [Traceback (most recent call last):]
24-Oct-2019 17:38:20.967 WARNING [Thread-201] org.apache.catalina.servlets.CGIServlet$CGIRunner.sendToLog stderr line: [  File "C:\Users\hayde\Desktop\UCI\Fall 2019\EECS 118\MP2\apache-tomcat-9.0.26\webapps\test\WEB-INF\cgi\project_3_gallery1.py", line 16, in <module>]
24-Oct-2019 17:38:20.969 WARNING [Thread-201] org.apache.catalina.servlets.CGIServlet$CGIRunner.sendToLog stderr line: [    cur.execute(query)]
24-Oct-2019 17:38:20.970 WARNING [Thread-201] org.apache.catalina.servlets.CGIServlet$CGIRunner.sendToLog stderr line: [  File "C:\Users\hayde\AppData\Local\Programs\Python\Python36\lib\site-packages\pymysql\cursors.py", line 170, in execute]
24-Oct-2019 17:38:20.972 WARNING [Thread-201] org.apache.catalina.servlets.CGIServlet$CGIRunner.sendToLog stderr line: [    result = self._query(query)]
24-Oct-2019 17:38:20.973 WARNING [Thread-201] org.apache.catalina.servlets.CGIServlet$CGIRunner.sendToLog stderr line: [  File "C:\Users\hayde\AppData\Local\Programs\Python\Python36\lib\site-packages\pymysql\cursors.py", line 328, in _query]
24-Oct-2019 17:38:20.974 WARNING [Thread-201] org.apache.catalina.servlets.CGIServlet$CGIRunner.sendToLog stderr line: [    conn.query(q)]
24-Oct-2019 17:38:20.976 WARNING [Thread-201] org.apache.catalina.servlets.CGIServlet$CGIRunner.sendToLog stderr line: [  File "C:\Users\hayde\AppData\Local\Programs\Python\Python36\lib\site-packages\pymysql\connections.py", line 517, in query]
24-Oct-2019 17:38:20.978 WARNING [Thread-201] org.apache.catalina.servlets.CGIServlet$CGIRunner.sendToLog stderr line: [    self._affected_rows = self._read_query_result(unbuffered=unbuffered)]
24-Oct-2019 17:38:20.979 WARNING [Thread-201] org.apache.catalina.servlets.CGIServlet$CGIRunner.sendToLog stderr line: [  File "C:\Users\hayde\AppData\Local\Programs\Python\Python36\lib\site-packages\pymysql\connections.py", line 732, in _read_query_result]
24-Oct-2019 17:38:20.980 WARNING [Thread-201] org.apache.catalina.servlets.CGIServlet$CGIRunner.sendToLog stderr line: [    result.read()]
24-Oct-2019 17:38:20.981 WARNING [Thread-201] org.apache.catalina.servlets.CGIServlet$CGIRunner.sendToLog stderr line: [  File "C:\Users\hayde\AppData\Local\Programs\Python\Python36\lib\site-packages\pymysql\connections.py", line 1075, in read]
24-Oct-2019 17:38:20.983 WARNING [Thread-201] org.apache.catalina.servlets.CGIServlet$CGIRunner.sendToLog stderr line: [    first_packet = self.connection._read_packet()]
24-Oct-2019 17:38:20.985 WARNING [Thread-201] org.apache.catalina.servlets.CGIServlet$CGIRunner.sendToLog stderr line: [  File "C:\Users\hayde\AppData\Local\Programs\Python\Python36\lib\site-packages\pymysql\connections.py", line 684, in _read_packet]
24-Oct-2019 17:38:20.987 WARNING [Thread-201] org.apache.catalina.servlets.CGIServlet$CGIRunner.sendToLog stderr line: [    packet.check_error()]
24-Oct-2019 17:38:20.988 WARNING [Thread-201] org.apache.catalina.servlets.CGIServlet$CGIRunner.sendToLog stderr line: [  File "C:\Users\hayde\AppData\Local\Programs\Python\Python36\lib\site-packages\pymysql\protocol.py", line 220, in check_error]
24-Oct-2019 17:38:20.990 WARNING [Thread-201] org.apache.catalina.servlets.CGIServlet$CGIRunner.sendToLog stderr line: [    err.raise_mysql_exception(self._data)]
24-Oct-2019 17:38:20.992 WARNING [Thread-201] org.apache.catalina.servlets.CGIServlet$CGIRunner.sendToLog stderr line: [  File "C:\Users\hayde\AppData\Local\Programs\Python\Python36\lib\site-packages\pymysql\err.py", line 109, in raise_mysql_exception]
24-Oct-2019 17:38:20.993 WARNING [Thread-201] org.apache.catalina.servlets.CGIServlet$CGIRunner.sendToLog stderr line: [    raise errorclass(errno, errval)]
24-Oct-2019 17:38:20.994 WARNING [Thread-201] org.apache.catalina.servlets.CGIServlet$CGIRunner.sendToLog stderr line: [pymysql.err.InternalError: (1054, "Unknown column 'gallery_name' in 'where clause'")]
24-Oct-2019 17:38:21.007 WARNING [Thread-201] org.apache.catalina.servlets.CGIServlet$CGIRunner.sendToLog Received [20] lines on stderr
24-Oct-2019 17:41:02.538 WARNING [Thread-203] org.apache.catalina.servlets.CGIServlet$CGIRunner.sendToLog stderr line: [Traceback (most recent call last):]
24-Oct-2019 17:41:02.538 WARNING [Thread-203] org.apache.catalina.servlets.CGIServlet$CGIRunner.sendToLog stderr line: [  File "C:\Users\hayde\Desktop\UCI\Fall 2019\EECS 118\MP2\apache-tomcat-9.0.26\webapps\test\WEB-INF\cgi\project_3_gallery1.py", line 17, in <module>]
24-Oct-2019 17:41:02.539 WARNING [Thread-203] org.apache.catalina.servlets.CGIServlet$CGIRunner.sendToLog stderr line: [    cur.execute(query)]
24-Oct-2019 17:41:02.540 WARNING [Thread-203] org.apache.catalina.servlets.CGIServlet$CGIRunner.sendToLog stderr line: [  File "C:\Users\hayde\AppData\Local\Programs\Python\Python36\lib\site-packages\pymysql\cursors.py", line 170, in execute]
24-Oct-2019 17:41:02.540 WARNING [Thread-203] org.apache.catalina.servlets.CGIServlet$CGIRunner.sendToLog stderr line: [    result = self._query(query)]
24-Oct-2019 17:41:02.541 WARNING [Thread-203] org.apache.catalina.servlets.CGIServlet$CGIRunner.sendToLog stderr line: [  File "C:\Users\hayde\AppData\Local\Programs\Python\Python36\lib\site-packages\pymysql\cursors.py", line 328, in _query]
24-Oct-2019 17:41:02.541 WARNING [Thread-203] org.apache.catalina.servlets.CGIServlet$CGIRunner.sendToLog stderr line: [    conn.query(q)]
24-Oct-2019 17:41:02.542 WARNING [Thread-203] org.apache.catalina.servlets.CGIServlet$CGIRunner.sendToLog stderr line: [  File "C:\Users\hayde\AppData\Local\Programs\Python\Python36\lib\site-packages\pymysql\connections.py", line 517, in query]
24-Oct-2019 17:41:02.542 WARNING [Thread-203] org.apache.catalina.servlets.CGIServlet$CGIRunner.sendToLog stderr line: [    self._affected_rows = self._read_query_result(unbuffered=unbuffered)]
24-Oct-2019 17:41:02.543 WARNING [Thread-203] org.apache.catalina.servlets.CGIServlet$CGIRunner.sendToLog stderr line: [  File "C:\Users\hayde\AppData\Local\Programs\Python\Python36\lib\site-packages\pymysql\connections.py", line 732, in _read_query_result]
24-Oct-2019 17:41:02.543 WARNING [Thread-203] org.apache.catalina.servlets.CGIServlet$CGIRunner.sendToLog stderr line: [    result.read()]
24-Oct-2019 17:41:02.544 WARNING [Thread-203] org.apache.catalina.servlets.CGIServlet$CGIRunner.sendToLog stderr line: [  File "C:\Users\hayde\AppData\Local\Programs\Python\Python36\lib\site-packages\pymysql\connections.py", line 1075, in read]
24-Oct-2019 17:41:02.545 WARNING [Thread-203] org.apache.catalina.servlets.CGIServlet$CGIRunner.sendToLog stderr line: [    first_packet = self.connection._read_packet()]
24-Oct-2019 17:41:02.545 WARNING [Thread-203] org.apache.catalina.servlets.CGIServlet$CGIRunner.sendToLog stderr line: [  File "C:\Users\hayde\AppData\Local\Programs\Python\Python36\lib\site-packages\pymysql\connections.py", line 684, in _read_packet]
24-Oct-2019 17:41:02.546 WARNING [Thread-203] org.apache.catalina.servlets.CGIServlet$CGIRunner.sendToLog stderr line: [    packet.check_error()]
24-Oct-2019 17:41:02.546 WARNING [Thread-203] org.apache.catalina.servlets.CGIServlet$CGIRunner.sendToLog stderr line: [  File "C:\Users\hayde\AppData\Local\Programs\Python\Python36\lib\site-packages\pymysql\protocol.py", line 220, in check_error]
24-Oct-2019 17:41:02.546 WARNING [Thread-203] org.apache.catalina.servlets.CGIServlet$CGIRunner.sendToLog stderr line: [    err.raise_mysql_exception(self._data)]
24-Oct-2019 17:41:02.547 WARNING [Thread-203] org.apache.catalina.servlets.CGIServlet$CGIRunner.sendToLog stderr line: [  File "C:\Users\hayde\AppData\Local\Programs\Python\Python36\lib\site-packages\pymysql\err.py", line 109, in raise_mysql_exception]
24-Oct-2019 17:41:02.547 WARNING [Thread-203] org.apache.catalina.servlets.CGIServlet$CGIRunner.sendToLog stderr line: [    raise errorclass(errno, errval)]
24-Oct-2019 17:41:02.548 WARNING [Thread-203] org.apache.catalina.servlets.CGIServlet$CGIRunner.sendToLog stderr line: [pymysql.err.InternalError: (1054, "Unknown column 'gallery_name' in 'where clause'")]
24-Oct-2019 17:41:02.553 WARNING [Thread-203] org.apache.catalina.servlets.CGIServlet$CGIRunner.sendToLog Received [20] lines on stderr
24-Oct-2019 17:41:53.829 WARNING [Thread-204] org.apache.catalina.servlets.CGIServlet$CGIRunner.sendToLog stderr line: [Traceback (most recent call last):]
24-Oct-2019 17:41:53.830 WARNING [Thread-204] org.apache.catalina.servlets.CGIServlet$CGIRunner.sendToLog stderr line: [  File "C:\Users\hayde\Desktop\UCI\Fall 2019\EECS 118\MP2\apache-tomcat-9.0.26\webapps\test\WEB-INF\cgi\project_3_gallery1.py", line 17, in <module>]
24-Oct-2019 17:41:53.832 WARNING [Thread-204] org.apache.catalina.servlets.CGIServlet$CGIRunner.sendToLog stderr line: [    cur.execute(query)]
24-Oct-2019 17:41:53.833 WARNING [Thread-204] org.apache.catalina.servlets.CGIServlet$CGIRunner.sendToLog stderr line: [  File "C:\Users\hayde\AppData\Local\Programs\Python\Python36\lib\site-packages\pymysql\cursors.py", line 170, in execute]
24-Oct-2019 17:41:53.834 WARNING [Thread-204] org.apache.catalina.servlets.CGIServlet$CGIRunner.sendToLog stderr line: [    result = self._query(query)]
24-Oct-2019 17:41:53.835 WARNING [Thread-204] org.apache.catalina.servlets.CGIServlet$CGIRunner.sendToLog stderr line: [  File "C:\Users\hayde\AppData\Local\Programs\Python\Python36\lib\site-packages\pymysql\cursors.py", line 328, in _query]
24-Oct-2019 17:41:53.836 WARNING [Thread-204] org.apache.catalina.servlets.CGIServlet$CGIRunner.sendToLog stderr line: [    conn.query(q)]
24-Oct-2019 17:41:53.836 WARNING [Thread-204] org.apache.catalina.servlets.CGIServlet$CGIRunner.sendToLog stderr line: [  File "C:\Users\hayde\AppData\Local\Programs\Python\Python36\lib\site-packages\pymysql\connections.py", line 517, in query]
24-Oct-2019 17:41:53.837 WARNING [Thread-204] org.apache.catalina.servlets.CGIServlet$CGIRunner.sendToLog stderr line: [    self._affected_rows = self._read_query_result(unbuffered=unbuffered)]
24-Oct-2019 17:41:53.838 WARNING [Thread-204] org.apache.catalina.servlets.CGIServlet$CGIRunner.sendToLog stderr line: [  File "C:\Users\hayde\AppData\Local\Programs\Python\Python36\lib\site-packages\pymysql\connections.py", line 732, in _read_query_result]
24-Oct-2019 17:41:53.838 WARNING [Thread-204] org.apache.catalina.servlets.CGIServlet$CGIRunner.sendToLog stderr line: [    result.read()]
24-Oct-2019 17:41:53.839 WARNING [Thread-204] org.apache.catalina.servlets.CGIServlet$CGIRunner.sendToLog stderr line: [  File "C:\Users\hayde\AppData\Local\Programs\Python\Python36\lib\site-packages\pymysql\connections.py", line 1075, in read]
24-Oct-2019 17:41:53.841 WARNING [Thread-204] org.apache.catalina.servlets.CGIServlet$CGIRunner.sendToLog stderr line: [    first_packet = self.connection._read_packet()]
24-Oct-2019 17:41:53.842 WARNING [Thread-204] org.apache.catalina.servlets.CGIServlet$CGIRunner.sendToLog stderr line: [  File "C:\Users\hayde\AppData\Local\Programs\Python\Python36\lib\site-packages\pymysql\connections.py", line 684, in _read_packet]
24-Oct-2019 17:41:53.843 WARNING [Thread-204] org.apache.catalina.servlets.CGIServlet$CGIRunner.sendToLog stderr line: [    packet.check_error()]
24-Oct-2019 17:41:53.844 WARNING [Thread-204] org.apache.catalina.servlets.CGIServlet$CGIRunner.sendToLog stderr line: [  File "C:\Users\hayde\AppData\Local\Programs\Python\Python36\lib\site-packages\pymysql\protocol.py", line 220, in check_error]
24-Oct-2019 17:41:53.844 WARNING [Thread-204] org.apache.catalina.servlets.CGIServlet$CGIRunner.sendToLog stderr line: [    err.raise_mysql_exception(self._data)]
24-Oct-2019 17:41:53.846 WARNING [Thread-204] org.apache.catalina.servlets.CGIServlet$CGIRunner.sendToLog stderr line: [  File "C:\Users\hayde\AppData\Local\Programs\Python\Python36\lib\site-packages\pymysql\err.py", line 109, in raise_mysql_exception]
24-Oct-2019 17:41:53.846 WARNING [Thread-204] org.apache.catalina.servlets.CGIServlet$CGIRunner.sendToLog stderr line: [    raise errorclass(errno, errval)]
24-Oct-2019 17:41:53.848 WARNING [Thread-204] org.apache.catalina.servlets.CGIServlet$CGIRunner.sendToLog stderr line: [pymysql.err.InternalError: (1054, "Unknown column 'gallery_name' in 'where clause'")]
24-Oct-2019 17:41:53.852 WARNING [Thread-204] org.apache.catalina.servlets.CGIServlet$CGIRunner.sendToLog Received [20] lines on stderr
24-Oct-2019 17:42:48.868 WARNING [Thread-207] org.apache.catalina.servlets.CGIServlet$CGIRunner.sendToLog stderr line: [Traceback (most recent call last):]
24-Oct-2019 17:42:48.868 WARNING [Thread-207] org.apache.catalina.servlets.CGIServlet$CGIRunner.sendToLog stderr line: [  File "C:\Users\hayde\Desktop\UCI\Fall 2019\EECS 118\MP2\apache-tomcat-9.0.26\webapps\test\WEB-INF\cgi\project_3_gallery1.py", line 69, in <module>]
24-Oct-2019 17:42:48.868 WARNING [Thread-207] org.apache.catalina.servlets.CGIServlet$CGIRunner.sendToLog stderr line: [    query = "select*from image where link='"+gal_1_img[i][0]+"'"]
24-Oct-2019 17:42:48.869 WARNING [Thread-207] org.apache.catalina.servlets.CGIServlet$CGIRunner.sendToLog stderr line: [IndexError: tuple index out of range]
24-Oct-2019 17:42:48.884 WARNING [Thread-207] org.apache.catalina.servlets.CGIServlet$CGIRunner.sendToLog Received [4] lines on stderr
24-Oct-2019 17:43:31.324 WARNING [Thread-209] org.apache.catalina.servlets.CGIServlet$CGIRunner.sendToLog stderr line: [Traceback (most recent call last):]
24-Oct-2019 17:43:31.325 WARNING [Thread-209] org.apache.catalina.servlets.CGIServlet$CGIRunner.sendToLog stderr line: [  File "C:\Users\hayde\Desktop\UCI\Fall 2019\EECS 118\MP2\apache-tomcat-9.0.26\webapps\test\WEB-INF\cgi\project_3_gallery1.py", line 69, in <module>]
24-Oct-2019 17:43:31.326 WARNING [Thread-209] org.apache.catalina.servlets.CGIServlet$CGIRunner.sendToLog stderr line: [    query = "select*from image where link='"+gal_1_img[i][0]+"'"]
24-Oct-2019 17:43:31.326 WARNING [Thread-209] org.apache.catalina.servlets.CGIServlet$CGIRunner.sendToLog stderr line: [IndexError: tuple index out of range]
24-Oct-2019 17:43:31.342 WARNING [Thread-209] org.apache.catalina.servlets.CGIServlet$CGIRunner.sendToLog Received [4] lines on stderr
24-Oct-2019 17:49:01.344 WARNING [Thread-212] org.apache.catalina.servlets.CGIServlet$CGIRunner.sendToLog stderr line: [Traceback (most recent call last):]
24-Oct-2019 17:49:01.345 WARNING [Thread-212] org.apache.catalina.servlets.CGIServlet$CGIRunner.sendToLog stderr line: [  File "C:\Users\hayde\Desktop\UCI\Fall 2019\EECS 118\MP2\apache-tomcat-9.0.26\webapps\test\WEB-INF\cgi\project_3_gallery1.py", line 67, in <module>]
24-Oct-2019 17:49:01.347 WARNING [Thread-212] org.apache.catalina.servlets.CGIServlet$CGIRunner.sendToLog stderr line: [    query = "select*from image where link='"+gal_1_img[i][0]+"'"]
24-Oct-2019 17:49:01.349 WARNING [Thread-212] org.apache.catalina.servlets.CGIServlet$CGIRunner.sendToLog stderr line: [IndexError: tuple index out of range]
24-Oct-2019 17:49:01.376 WARNING [Thread-212] org.apache.catalina.servlets.CGIServlet$CGIRunner.sendToLog Received [4] lines on stderr
24-Oct-2019 17:49:54.232 WARNING [Thread-213] org.apache.catalina.servlets.CGIServlet$CGIRunner.sendToLog stderr line: [Traceback (most recent call last):]
24-Oct-2019 17:49:54.232 WARNING [Thread-213] org.apache.catalina.servlets.CGIServlet$CGIRunner.sendToLog stderr line: [  File "C:\Users\hayde\Desktop\UCI\Fall 2019\EECS 118\MP2\apache-tomcat-9.0.26\webapps\test\WEB-INF\cgi\project_3_gallery1.py", line 67, in <module>]
24-Oct-2019 17:49:54.233 WARNING [Thread-213] org.apache.catalina.servlets.CGIServlet$CGIRunner.sendToLog stderr line: [    query = "select*from image where link='"+gal_1_img[i][0]+"'"]
24-Oct-2019 17:49:54.234 WARNING [Thread-213] org.apache.catalina.servlets.CGIServlet$CGIRunner.sendToLog stderr line: [IndexError: tuple index out of range]
24-Oct-2019 17:49:54.249 WARNING [Thread-213] org.apache.catalina.servlets.CGIServlet$CGIRunner.sendToLog Received [4] lines on stderr
24-Oct-2019 17:50:37.340 WARNING [Thread-214] org.apache.catalina.servlets.CGIServlet$CGIRunner.sendToLog stderr line: [Traceback (most recent call last):]
24-Oct-2019 17:50:37.341 WARNING [Thread-214] org.apache.catalina.servlets.CGIServlet$CGIRunner.sendToLog stderr line: [  File "C:\Users\hayde\Desktop\UCI\Fall 2019\EECS 118\MP2\apache-tomcat-9.0.26\webapps\test\WEB-INF\cgi\project_3_gallery1.py", line 67, in <module>]
24-Oct-2019 17:50:37.343 WARNING [Thread-214] org.apache.catalina.servlets.CGIServlet$CGIRunner.sendToLog stderr line: [    query = "select*from image where link='"+gal_1_img[i][0]+"'"]
24-Oct-2019 17:50:37.343 WARNING [Thread-214] org.apache.catalina.servlets.CGIServlet$CGIRunner.sendToLog stderr line: [IndexError: tuple index out of range]
24-Oct-2019 17:50:37.359 WARNING [Thread-214] org.apache.catalina.servlets.CGIServlet$CGIRunner.sendToLog Received [4] lines on stderr
24-Oct-2019 17:51:39.514 WARNING [Thread-215] org.apache.catalina.servlets.CGIServlet$CGIRunner.sendToLog stderr line: [Traceback (most recent call last):]
24-Oct-2019 17:51:39.514 WARNING [Thread-215] org.apache.catalina.servlets.CGIServlet$CGIRunner.sendToLog stderr line: [  File "C:\Users\hayde\Desktop\UCI\Fall 2019\EECS 118\MP2\apache-tomcat-9.0.26\webapps\test\WEB-INF\cgi\project_3_gallery1.py", line 67, in <module>]
24-Oct-2019 17:51:39.516 WARNING [Thread-215] org.apache.catalina.servlets.CGIServlet$CGIRunner.sendToLog stderr line: [    query = "select*from image where link='"+gal_1_img[i][0]+"'"]
24-Oct-2019 17:51:39.517 WARNING [Thread-215] org.apache.catalina.servlets.CGIServlet$CGIRunner.sendToLog stderr line: [IndexError: tuple index out of range]
24-Oct-2019 17:51:39.533 WARNING [Thread-215] org.apache.catalina.servlets.CGIServlet$CGIRunner.sendToLog Received [4] lines on stderr
24-Oct-2019 17:53:42.723 WARNING [Thread-217] org.apache.catalina.servlets.CGIServlet$CGIRunner.sendToLog stderr line: [Traceback (most recent call last):]
24-Oct-2019 17:53:42.723 WARNING [Thread-217] org.apache.catalina.servlets.CGIServlet$CGIRunner.sendToLog stderr line: [  File "C:\Users\hayde\Desktop\UCI\Fall 2019\EECS 118\MP2\apache-tomcat-9.0.26\webapps\test\WEB-INF\cgi\project_3_gallery1.py", line 67, in <module>]
24-Oct-2019 17:53:42.724 WARNING [Thread-217] org.apache.catalina.servlets.CGIServlet$CGIRunner.sendToLog stderr line: [    query = "select*from image where link='"+gal_1_img[i][0]+"'"]
24-Oct-2019 17:53:42.725 WARNING [Thread-217] org.apache.catalina.servlets.CGIServlet$CGIRunner.sendToLog stderr line: [IndexError: tuple index out of range]
24-Oct-2019 17:53:42.741 WARNING [Thread-217] org.apache.catalina.servlets.CGIServlet$CGIRunner.sendToLog Received [4] lines on stderr
24-Oct-2019 17:54:17.034 WARNING [Thread-218] org.apache.catalina.servlets.CGIServlet$CGIRunner.sendToLog stderr line: [Traceback (most recent call last):]
24-Oct-2019 17:54:17.035 WARNING [Thread-218] org.apache.catalina.servlets.CGIServlet$CGIRunner.sendToLog stderr line: [  File "C:\Users\hayde\Desktop\UCI\Fall 2019\EECS 118\MP2\apache-tomcat-9.0.26\webapps\test\WEB-INF\cgi\project_3_gallery1.py", line 27, in <module>]
24-Oct-2019 17:54:17.036 WARNING [Thread-218] org.apache.catalina.servlets.CGIServlet$CGIRunner.sendToLog stderr line: [    max_num_img = int(max_num_img[0])]
24-Oct-2019 17:54:17.037 WARNING [Thread-218] org.apache.catalina.servlets.CGIServlet$CGIRunner.sendToLog stderr line: [TypeError: int() argument must be a string, a bytes-like object or a number, not 'NoneType']
24-Oct-2019 17:54:17.054 WARNING [Thread-218] org.apache.catalina.servlets.CGIServlet$CGIRunner.sendToLog Received [4] lines on stderr
24-Oct-2019 17:54:29.679 WARNING [Thread-219] org.apache.catalina.servlets.CGIServlet$CGIRunner.sendToLog stderr line: [Traceback (most recent call last):]
24-Oct-2019 17:54:29.680 WARNING [Thread-219] org.apache.catalina.servlets.CGIServlet$CGIRunner.sendToLog stderr line: [  File "C:\Users\hayde\Desktop\UCI\Fall 2019\EECS 118\MP2\apache-tomcat-9.0.26\webapps\test\WEB-INF\cgi\project_3_gallery1.py", line 16, in <module>]
24-Oct-2019 17:54:29.680 WARNING [Thread-219] org.apache.catalina.servlets.CGIServlet$CGIRunner.sendToLog stderr line: [    query = "select gallery_id from gallery where name='"+gal+"'"]
24-Oct-2019 17:54:29.681 WARNING [Thread-219] org.apache.catalina.servlets.CGIServlet$CGIRunner.sendToLog stderr line: [TypeError: must be str, not NoneType]
24-Oct-2019 17:54:29.698 WARNING [Thread-219] org.apache.catalina.servlets.CGIServlet$CGIRunner.sendToLog Received [4] lines on stderr
24-Oct-2019 17:56:29.244 WARNING [Thread-222] org.apache.catalina.servlets.CGIServlet$CGIRunner.sendToLog stderr line: [Traceback (most recent call last):]
24-Oct-2019 17:56:29.245 WARNING [Thread-222] org.apache.catalina.servlets.CGIServlet$CGIRunner.sendToLog stderr line: [  File "C:\Users\hayde\Desktop\UCI\Fall 2019\EECS 118\MP2\apache-tomcat-9.0.26\webapps\test\WEB-INF\cgi\project_3_gallery1.py", line 52, in <module>]
24-Oct-2019 17:56:29.246 WARNING [Thread-222] org.apache.catalina.servlets.CGIServlet$CGIRunner.sendToLog stderr line: [    max_num_img = int(max_num_img[0])]
24-Oct-2019 17:56:29.247 WARNING [Thread-222] org.apache.catalina.servlets.CGIServlet$CGIRunner.sendToLog stderr line: [TypeError: int() argument must be a string, a bytes-like object or a number, not 'NoneType']
24-Oct-2019 17:56:29.263 WARNING [Thread-222] org.apache.catalina.servlets.CGIServlet$CGIRunner.sendToLog Received [4] lines on stderr
24-Oct-2019 17:57:58.177 WARNING [Thread-223] org.apache.catalina.servlets.CGIServlet$CGIRunner.sendToLog stderr line: [Traceback (most recent call last):]
24-Oct-2019 17:57:58.178 WARNING [Thread-223] org.apache.catalina.servlets.CGIServlet$CGIRunner.sendToLog stderr line: [  File "C:\Users\hayde\Desktop\UCI\Fall 2019\EECS 118\MP2\apache-tomcat-9.0.26\webapps\test\WEB-INF\cgi\project_3_gallery1.py", line 53, in <module>]
24-Oct-2019 17:57:58.180 WARNING [Thread-223] org.apache.catalina.servlets.CGIServlet$CGIRunner.sendToLog stderr line: [    max_num_img = int(max_num_img[0])]
24-Oct-2019 17:57:58.181 WARNING [Thread-223] org.apache.catalina.servlets.CGIServlet$CGIRunner.sendToLog stderr line: [TypeError: int() argument must be a string, a bytes-like object or a number, not 'NoneType']
24-Oct-2019 17:57:58.220 WARNING [Thread-223] org.apache.catalina.servlets.CGIServlet$CGIRunner.sendToLog Received [4] lines on stderr
24-Oct-2019 18:00:25.317 WARNING [Thread-226] org.apache.catalina.servlets.CGIServlet$CGIRunner.sendToLog stderr line: [Traceback (most recent call last):]
24-Oct-2019 18:00:25.318 WARNING [Thread-226] org.apache.catalina.servlets.CGIServlet$CGIRunner.sendToLog stderr line: [  File "C:\Users\hayde\Desktop\UCI\Fall 2019\EECS 118\MP2\apache-tomcat-9.0.26\webapps\test\WEB-INF\cgi\project_3_gallery1.py", line 53, in <module>]
24-Oct-2019 18:00:25.318 WARNING [Thread-226] org.apache.catalina.servlets.CGIServlet$CGIRunner.sendToLog stderr line: [    max_num_img = int(max_num_img[0])]
24-Oct-2019 18:00:25.319 WARNING [Thread-226] org.apache.catalina.servlets.CGIServlet$CGIRunner.sendToLog stderr line: [TypeError: int() argument must be a string, a bytes-like object or a number, not 'NoneType']
24-Oct-2019 18:00:25.333 WARNING [Thread-226] org.apache.catalina.servlets.CGIServlet$CGIRunner.sendToLog Received [4] lines on stderr
24-Oct-2019 19:39:00.483 WARNING [Thread-243] org.apache.catalina.servlets.CGIServlet$CGIRunner.sendToLog stderr line: [Traceback (most recent call last):]
24-Oct-2019 19:39:00.484 WARNING [Thread-243] org.apache.catalina.servlets.CGIServlet$CGIRunner.sendToLog stderr line: [  File "C:\Users\hayde\Desktop\UCI\Fall 2019\EECS 118\MP2\apache-tomcat-9.0.26\webapps\test\WEB-INF\cgi\project_3_gallery1.py", line 111, in <module>]
24-Oct-2019 19:39:00.485 WARNING [Thread-243] org.apache.catalina.servlets.CGIServlet$CGIRunner.sendToLog stderr line: [    display = "<form enctype='multipart/form-data' action='/test/cgi-bin/project_3_upload.py' method='POST'>"+"<input type='hidden' name=upload_img value='"+gal_id[0]+"'>"+"<input type='submit' value='Upload'>"]
24-Oct-2019 19:39:00.486 WARNING [Thread-243] org.apache.catalina.servlets.CGIServlet$CGIRunner.sendToLog stderr line: [TypeError: must be str, not int]
24-Oct-2019 19:39:00.505 WARNING [Thread-243] org.apache.catalina.servlets.CGIServlet$CGIRunner.sendToLog Received [4] lines on stderr
24-Oct-2019 20:03:26.160 WARNING [Thread-244] org.apache.catalina.servlets.CGIServlet$CGIRunner.sendToLog stderr line: [Traceback (most recent call last):]
24-Oct-2019 20:03:26.161 WARNING [Thread-244] org.apache.catalina.servlets.CGIServlet$CGIRunner.sendToLog stderr line: [  File "C:\Users\hayde\Desktop\UCI\Fall 2019\EECS 118\MP2\apache-tomcat-9.0.26\webapps\test\WEB-INF\cgi\project_3_gallery1.py", line 111, in <module>]
24-Oct-2019 20:03:26.164 WARNING [Thread-244] org.apache.catalina.servlets.CGIServlet$CGIRunner.sendToLog stderr line: [    display = "<form enctype='multipart/form-data' action='/test/cgi-bin/project_3_upload.py' method='POST'>"+"<input type='hidden' name='upload_img' value='"+gal_id[0]+"'>"+"<input type='submit' value='Upload'><form>"]
24-Oct-2019 20:03:26.165 WARNING [Thread-244] org.apache.catalina.servlets.CGIServlet$CGIRunner.sendToLog stderr line: [TypeError: must be str, not int]
24-Oct-2019 20:03:26.196 WARNING [Thread-244] org.apache.catalina.servlets.CGIServlet$CGIRunner.sendToLog Received [4] lines on stderr
24-Oct-2019 20:03:59.328 WARNING [Thread-245] org.apache.catalina.servlets.CGIServlet$CGIRunner.sendToLog stderr line: [Traceback (most recent call last):]
24-Oct-2019 20:03:59.328 WARNING [Thread-245] org.apache.catalina.servlets.CGIServlet$CGIRunner.sendToLog stderr line: [  File "C:\Users\hayde\Desktop\UCI\Fall 2019\EECS 118\MP2\apache-tomcat-9.0.26\webapps\test\WEB-INF\cgi\project_3_gallery1.py", line 111, in <module>]
24-Oct-2019 20:03:59.329 WARNING [Thread-245] org.apache.catalina.servlets.CGIServlet$CGIRunner.sendToLog stderr line: [    display = "<form enctype='multipart/form-data' action='/test/cgi-bin/project_3_upload.py' method='POST'>"+"<input type='hidden' name='upload_img' value='"+gal_id[0]+"'>"+"<input type='submit' value='Upload'></form>"]
24-Oct-2019 20:03:59.330 WARNING [Thread-245] org.apache.catalina.servlets.CGIServlet$CGIRunner.sendToLog stderr line: [TypeError: must be str, not int]
24-Oct-2019 20:03:59.348 WARNING [Thread-245] org.apache.catalina.servlets.CGIServlet$CGIRunner.sendToLog Received [4] lines on stderr
24-Oct-2019 20:54:11.780 WARNING [Thread-247] org.apache.catalina.servlets.CGIServlet$CGIRunner.sendToLog stderr line: [C:\Users\hayde\AppData\Local\Programs\Python\Python36\lib\site-packages\pymysql\cursors.py:170: Warning: (1366, "Incorrect integer value: 'unknown' for column 'year' at row 1")]
24-Oct-2019 20:54:11.781 WARNING [Thread-247] org.apache.catalina.servlets.CGIServlet$CGIRunner.sendToLog stderr line: [  result = self._query(query)]
24-Oct-2019 20:54:11.782 WARNING [Thread-247] org.apache.catalina.servlets.CGIServlet$CGIRunner.sendToLog stderr line: [Traceback (most recent call last):]
24-Oct-2019 20:54:11.782 WARNING [Thread-247] org.apache.catalina.servlets.CGIServlet$CGIRunner.sendToLog stderr line: [  File "C:\Users\hayde\Desktop\UCI\Fall 2019\EECS 118\MP2\apache-tomcat-9.0.26\webapps\test\WEB-INF\cgi\project_3_upload.py", line 81, in <module>]
24-Oct-2019 20:54:11.782 WARNING [Thread-247] org.apache.catalina.servlets.CGIServlet$CGIRunner.sendToLog stderr line: [    val = (title, url, str(gallery_id), str(artist_id[0]), str(max_num_detail[0]))]
24-Oct-2019 20:54:11.782 WARNING [Thread-247] org.apache.catalina.servlets.CGIServlet$CGIRunner.sendToLog stderr line: [TypeError: 'NoneType' object is not subscriptable]
24-Oct-2019 20:54:11.793 WARNING [Thread-247] org.apache.catalina.servlets.CGIServlet$CGIRunner.sendToLog Received [6] lines on stderr
24-Oct-2019 20:55:21.752 WARNING [Thread-248] org.apache.catalina.servlets.CGIServlet$CGIRunner.sendToLog stderr line: [C:\Users\hayde\AppData\Local\Programs\Python\Python36\lib\site-packages\pymysql\cursors.py:170: Warning: (1366, "Incorrect integer value: 'unknown' for column 'year' at row 1")]
24-Oct-2019 20:55:21.752 WARNING [Thread-248] org.apache.catalina.servlets.CGIServlet$CGIRunner.sendToLog stderr line: [  result = self._query(query)]
24-Oct-2019 20:55:21.753 WARNING [Thread-248] org.apache.catalina.servlets.CGIServlet$CGIRunner.sendToLog stderr line: [Traceback (most recent call last):]
24-Oct-2019 20:55:21.753 WARNING [Thread-248] org.apache.catalina.servlets.CGIServlet$CGIRunner.sendToLog stderr line: [  File "C:\Users\hayde\Desktop\UCI\Fall 2019\EECS 118\MP2\apache-tomcat-9.0.26\webapps\test\WEB-INF\cgi\project_3_upload.py", line 89, in <module>]
24-Oct-2019 20:55:21.754 WARNING [Thread-248] org.apache.catalina.servlets.CGIServlet$CGIRunner.sendToLog stderr line: [    val = (title, url, str(gallery_id), str(artist_id[0]), str(max_num_detail[0]))]
24-Oct-2019 20:55:21.754 WARNING [Thread-248] org.apache.catalina.servlets.CGIServlet$CGIRunner.sendToLog stderr line: [TypeError: 'NoneType' object is not subscriptable]
24-Oct-2019 20:55:21.762 WARNING [Thread-248] org.apache.catalina.servlets.CGIServlet$CGIRunner.sendToLog Received [6] lines on stderr
24-Oct-2019 20:57:40.521 WARNING [Thread-255] org.apache.catalina.servlets.CGIServlet$CGIRunner.sendToLog stderr line: [C:\Users\hayde\AppData\Local\Programs\Python\Python36\lib\site-packages\pymysql\cursors.py:170: Warning: (1366, "Incorrect integer value: 'unknown' for column 'year' at row 1")]
24-Oct-2019 20:57:40.521 WARNING [Thread-255] org.apache.catalina.servlets.CGIServlet$CGIRunner.sendToLog stderr line: [  result = self._query(query)]
24-Oct-2019 20:57:40.531 WARNING [Thread-255] org.apache.catalina.servlets.CGIServlet$CGIRunner.sendToLog Received [2] lines on stderr
24-Oct-2019 20:57:50.512 WARNING [Thread-256] org.apache.catalina.servlets.CGIServlet$CGIRunner.sendToLog stderr line: [C:\Users\hayde\AppData\Local\Programs\Python\Python36\lib\site-packages\pymysql\cursors.py:170: Warning: (1366, "Incorrect integer value: 'unknown' for column 'year' at row 1")]
24-Oct-2019 20:57:50.512 WARNING [Thread-256] org.apache.catalina.servlets.CGIServlet$CGIRunner.sendToLog stderr line: [  result = self._query(query)]
24-Oct-2019 20:57:50.524 WARNING [Thread-256] org.apache.catalina.servlets.CGIServlet$CGIRunner.sendToLog Received [2] lines on stderr
24-Oct-2019 20:57:58.628 WARNING [Thread-257] org.apache.catalina.servlets.CGIServlet$CGIRunner.sendToLog stderr line: [C:\Users\hayde\AppData\Local\Programs\Python\Python36\lib\site-packages\pymysql\cursors.py:170: Warning: (1366, "Incorrect integer value: 'unknown' for column 'year' at row 1")]
24-Oct-2019 20:57:58.628 WARNING [Thread-257] org.apache.catalina.servlets.CGIServlet$CGIRunner.sendToLog stderr line: [  result = self._query(query)]
24-Oct-2019 20:57:58.637 WARNING [Thread-257] org.apache.catalina.servlets.CGIServlet$CGIRunner.sendToLog Received [2] lines on stderr
24-Oct-2019 20:58:07.911 WARNING [Thread-258] org.apache.catalina.servlets.CGIServlet$CGIRunner.sendToLog stderr line: [C:\Users\hayde\AppData\Local\Programs\Python\Python36\lib\site-packages\pymysql\cursors.py:170: Warning: (1366, "Incorrect integer value: 'unknown' for column 'year' at row 1")]
24-Oct-2019 20:58:07.912 WARNING [Thread-258] org.apache.catalina.servlets.CGIServlet$CGIRunner.sendToLog stderr line: [  result = self._query(query)]
24-Oct-2019 20:58:07.912 WARNING [Thread-258] org.apache.catalina.servlets.CGIServlet$CGIRunner.sendToLog stderr line: [Traceback (most recent call last):]
24-Oct-2019 20:58:07.912 WARNING [Thread-258] org.apache.catalina.servlets.CGIServlet$CGIRunner.sendToLog stderr line: [  File "C:\Users\hayde\Desktop\UCI\Fall 2019\EECS 118\MP2\apache-tomcat-9.0.26\webapps\test\WEB-INF\cgi\project_3_upload.py", line 89, in <module>]
24-Oct-2019 20:58:07.913 WARNING [Thread-258] org.apache.catalina.servlets.CGIServlet$CGIRunner.sendToLog stderr line: [    val = (title, url, str(gallery_id), str(artist_id[0]), str(max_num_detail[0]))]
24-Oct-2019 20:58:07.913 WARNING [Thread-258] org.apache.catalina.servlets.CGIServlet$CGIRunner.sendToLog stderr line: [TypeError: 'NoneType' object is not subscriptable]
24-Oct-2019 20:58:07.926 WARNING [Thread-258] org.apache.catalina.servlets.CGIServlet$CGIRunner.sendToLog Received [6] lines on stderr
24-Oct-2019 20:59:25.621 WARNING [Thread-259] org.apache.catalina.servlets.CGIServlet$CGIRunner.sendToLog stderr line: [C:\Users\hayde\AppData\Local\Programs\Python\Python36\lib\site-packages\pymysql\cursors.py:170: Warning: (1366, "Incorrect integer value: 'unknown' for column 'year' at row 1")]
24-Oct-2019 20:59:25.622 WARNING [Thread-259] org.apache.catalina.servlets.CGIServlet$CGIRunner.sendToLog stderr line: [  result = self._query(query)]
24-Oct-2019 20:59:25.623 WARNING [Thread-259] org.apache.catalina.servlets.CGIServlet$CGIRunner.sendToLog stderr line: [Traceback (most recent call last):]
24-Oct-2019 20:59:25.623 WARNING [Thread-259] org.apache.catalina.servlets.CGIServlet$CGIRunner.sendToLog stderr line: [  File "C:\Users\hayde\Desktop\UCI\Fall 2019\EECS 118\MP2\apache-tomcat-9.0.26\webapps\test\WEB-INF\cgi\project_3_upload.py", line 89, in <module>]
24-Oct-2019 20:59:25.624 WARNING [Thread-259] org.apache.catalina.servlets.CGIServlet$CGIRunner.sendToLog stderr line: [    val = (title, url, str(str(gallery_id)), str(artist_id[0]), str(max_num_detail[0]))]
24-Oct-2019 20:59:25.624 WARNING [Thread-259] org.apache.catalina.servlets.CGIServlet$CGIRunner.sendToLog stderr line: [TypeError: 'NoneType' object is not subscriptable]
24-Oct-2019 20:59:25.634 WARNING [Thread-259] org.apache.catalina.servlets.CGIServlet$CGIRunner.sendToLog Received [6] lines on stderr
24-Oct-2019 20:59:36.109 WARNING [Thread-260] org.apache.catalina.servlets.CGIServlet$CGIRunner.sendToLog stderr line: [C:\Users\hayde\AppData\Local\Programs\Python\Python36\lib\site-packages\pymysql\cursors.py:170: Warning: (1366, "Incorrect integer value: 'unknown' for column 'year' at row 1")]
24-Oct-2019 20:59:36.110 WARNING [Thread-260] org.apache.catalina.servlets.CGIServlet$CGIRunner.sendToLog stderr line: [  result = self._query(query)]
24-Oct-2019 20:59:36.123 WARNING [Thread-260] org.apache.catalina.servlets.CGIServlet$CGIRunner.sendToLog Received [2] lines on stderr
24-Oct-2019 21:05:13.029 WARNING [Thread-261] org.apache.catalina.servlets.CGIServlet$CGIRunner.sendToLog stderr line: [C:\Users\hayde\AppData\Local\Programs\Python\Python36\lib\site-packages\pymysql\cursors.py:170: Warning: (1366, "Incorrect integer value: 'unknown' for column 'year' at row 1")]
24-Oct-2019 21:05:13.029 WARNING [Thread-261] org.apache.catalina.servlets.CGIServlet$CGIRunner.sendToLog stderr line: [  result = self._query(query)]
24-Oct-2019 21:05:13.031 WARNING [Thread-261] org.apache.catalina.servlets.CGIServlet$CGIRunner.sendToLog stderr line: [Traceback (most recent call last):]
24-Oct-2019 21:05:13.032 WARNING [Thread-261] org.apache.catalina.servlets.CGIServlet$CGIRunner.sendToLog stderr line: [  File "C:\Users\hayde\Desktop\UCI\Fall 2019\EECS 118\MP2\apache-tomcat-9.0.26\webapps\test\WEB-INF\cgi\project_3_upload.py", line 89, in <module>]
24-Oct-2019 21:05:13.032 WARNING [Thread-261] org.apache.catalina.servlets.CGIServlet$CGIRunner.sendToLog stderr line: [    val = (title, url, str(str(gallery_id)), str(artist_id[0]), str(max_num_detail[0]))]
24-Oct-2019 21:05:13.033 WARNING [Thread-261] org.apache.catalina.servlets.CGIServlet$CGIRunner.sendToLog stderr line: [TypeError: 'NoneType' object is not subscriptable]
24-Oct-2019 21:05:13.047 WARNING [Thread-261] org.apache.catalina.servlets.CGIServlet$CGIRunner.sendToLog Received [6] lines on stderr
24-Oct-2019 21:05:57.541 WARNING [Thread-262] org.apache.catalina.servlets.CGIServlet$CGIRunner.sendToLog stderr line: [C:\Users\hayde\AppData\Local\Programs\Python\Python36\lib\site-packages\pymysql\cursors.py:170: Warning: (1366, "Incorrect integer value: 'unknown' for column 'year' at row 1")]
24-Oct-2019 21:05:57.542 WARNING [Thread-262] org.apache.catalina.servlets.CGIServlet$CGIRunner.sendToLog stderr line: [  result = self._query(query)]
24-Oct-2019 21:05:57.542 WARNING [Thread-262] org.apache.catalina.servlets.CGIServlet$CGIRunner.sendToLog stderr line: [Traceback (most recent call last):]
24-Oct-2019 21:05:57.542 WARNING [Thread-262] org.apache.catalina.servlets.CGIServlet$CGIRunner.sendToLog stderr line: [  File "C:\Users\hayde\Desktop\UCI\Fall 2019\EECS 118\MP2\apache-tomcat-9.0.26\webapps\test\WEB-INF\cgi\project_3_upload.py", line 89, in <module>]
24-Oct-2019 21:05:57.543 WARNING [Thread-262] org.apache.catalina.servlets.CGIServlet$CGIRunner.sendToLog stderr line: [    val = (title, url, str(gallery_id), str(artist_id[0]), str(max_num_detail[0]))]
24-Oct-2019 21:05:57.543 WARNING [Thread-262] org.apache.catalina.servlets.CGIServlet$CGIRunner.sendToLog stderr line: [TypeError: 'NoneType' object is not subscriptable]
24-Oct-2019 21:05:57.550 WARNING [Thread-262] org.apache.catalina.servlets.CGIServlet$CGIRunner.sendToLog Received [6] lines on stderr
24-Oct-2019 21:06:07.128 WARNING [Thread-263] org.apache.catalina.servlets.CGIServlet$CGIRunner.sendToLog stderr line: [C:\Users\hayde\AppData\Local\Programs\Python\Python36\lib\site-packages\pymysql\cursors.py:170: Warning: (1366, "Incorrect integer value: 'unknown' for column 'year' at row 1")]
24-Oct-2019 21:06:07.129 WARNING [Thread-263] org.apache.catalina.servlets.CGIServlet$CGIRunner.sendToLog stderr line: [  result = self._query(query)]
24-Oct-2019 21:06:07.140 WARNING [Thread-263] org.apache.catalina.servlets.CGIServlet$CGIRunner.sendToLog Received [2] lines on stderr
24-Oct-2019 21:06:16.639 WARNING [Thread-264] org.apache.catalina.servlets.CGIServlet$CGIRunner.sendToLog stderr line: [C:\Users\hayde\AppData\Local\Programs\Python\Python36\lib\site-packages\pymysql\cursors.py:170: Warning: (1366, "Incorrect integer value: 'unknown' for column 'year' at row 1")]
24-Oct-2019 21:06:16.639 WARNING [Thread-264] org.apache.catalina.servlets.CGIServlet$CGIRunner.sendToLog stderr line: [  result = self._query(query)]
24-Oct-2019 21:06:16.678 WARNING [Thread-264] org.apache.catalina.servlets.CGIServlet$CGIRunner.sendToLog stderr line: [Traceback (most recent call last):]
24-Oct-2019 21:06:16.678 WARNING [Thread-264] org.apache.catalina.servlets.CGIServlet$CGIRunner.sendToLog stderr line: [  File "C:\Users\hayde\Desktop\UCI\Fall 2019\EECS 118\MP2\apache-tomcat-9.0.26\webapps\test\WEB-INF\cgi\project_3_upload.py", line 100, in <module>]
24-Oct-2019 21:06:16.678 WARNING [Thread-264] org.apache.catalina.servlets.CGIServlet$CGIRunner.sendToLog stderr line: [    cur.execute(query, val)]
24-Oct-2019 21:06:16.679 WARNING [Thread-264] org.apache.catalina.servlets.CGIServlet$CGIRunner.sendToLog stderr line: [  File "C:\Users\hayde\AppData\Local\Programs\Python\Python36\lib\site-packages\pymysql\cursors.py", line 170, in execute]
24-Oct-2019 21:06:16.679 WARNING [Thread-264] org.apache.catalina.servlets.CGIServlet$CGIRunner.sendToLog stderr line: [    result = self._query(query)]
24-Oct-2019 21:06:16.680 WARNING [Thread-264] org.apache.catalina.servlets.CGIServlet$CGIRunner.sendToLog stderr line: [  File "C:\Users\hayde\AppData\Local\Programs\Python\Python36\lib\site-packages\pymysql\cursors.py", line 328, in _query]
24-Oct-2019 21:06:16.680 WARNING [Thread-264] org.apache.catalina.servlets.CGIServlet$CGIRunner.sendToLog stderr line: [    conn.query(q)]
24-Oct-2019 21:06:16.680 WARNING [Thread-264] org.apache.catalina.servlets.CGIServlet$CGIRunner.sendToLog stderr line: [  File "C:\Users\hayde\AppData\Local\Programs\Python\Python36\lib\site-packages\pymysql\connections.py", line 517, in query]
24-Oct-2019 21:06:16.680 WARNING [Thread-264] org.apache.catalina.servlets.CGIServlet$CGIRunner.sendToLog stderr line: [    self._affected_rows = self._read_query_result(unbuffered=unbuffered)]
24-Oct-2019 21:06:16.681 WARNING [Thread-264] org.apache.catalina.servlets.CGIServlet$CGIRunner.sendToLog stderr line: [  File "C:\Users\hayde\AppData\Local\Programs\Python\Python36\lib\site-packages\pymysql\connections.py", line 732, in _read_query_result]
24-Oct-2019 21:06:16.681 WARNING [Thread-264] org.apache.catalina.servlets.CGIServlet$CGIRunner.sendToLog stderr line: [    result.read()]
24-Oct-2019 21:06:16.681 WARNING [Thread-264] org.apache.catalina.servlets.CGIServlet$CGIRunner.sendToLog stderr line: [  File "C:\Users\hayde\AppData\Local\Programs\Python\Python36\lib\site-packages\pymysql\connections.py", line 1075, in read]
24-Oct-2019 21:06:16.681 WARNING [Thread-264] org.apache.catalina.servlets.CGIServlet$CGIRunner.sendToLog stderr line: [    first_packet = self.connection._read_packet()]
24-Oct-2019 21:06:16.682 WARNING [Thread-264] org.apache.catalina.servlets.CGIServlet$CGIRunner.sendToLog stderr line: [  File "C:\Users\hayde\AppData\Local\Programs\Python\Python36\lib\site-packages\pymysql\connections.py", line 684, in _read_packet]
24-Oct-2019 21:06:16.682 WARNING [Thread-264] org.apache.catalina.servlets.CGIServlet$CGIRunner.sendToLog stderr line: [    packet.check_error()]
24-Oct-2019 21:06:16.682 WARNING [Thread-264] org.apache.catalina.servlets.CGIServlet$CGIRunner.sendToLog stderr line: [  File "C:\Users\hayde\AppData\Local\Programs\Python\Python36\lib\site-packages\pymysql\protocol.py", line 220, in check_error]
24-Oct-2019 21:06:16.682 WARNING [Thread-264] org.apache.catalina.servlets.CGIServlet$CGIRunner.sendToLog stderr line: [    err.raise_mysql_exception(self._data)]
24-Oct-2019 21:06:16.683 WARNING [Thread-264] org.apache.catalina.servlets.CGIServlet$CGIRunner.sendToLog stderr line: [  File "C:\Users\hayde\AppData\Local\Programs\Python\Python36\lib\site-packages\pymysql\err.py", line 109, in raise_mysql_exception]
24-Oct-2019 21:06:16.683 WARNING [Thread-264] org.apache.catalina.servlets.CGIServlet$CGIRunner.sendToLog stderr line: [    raise errorclass(errno, errval)]
24-Oct-2019 21:06:16.683 WARNING [Thread-264] org.apache.catalina.servlets.CGIServlet$CGIRunner.sendToLog stderr line: [pymysql.err.ProgrammingError: (1064, "You have an error in your SQL syntax; check the manual that corresponds to your MySQL server version for the right syntax to use near 'where detail_id='14' \t\t\tvalues(2)' at line 1")]
24-Oct-2019 21:06:16.691 WARNING [Thread-264] org.apache.catalina.servlets.CGIServlet$CGIRunner.sendToLog Received [22] lines on stderr
24-Oct-2019 21:06:24.934 WARNING [Thread-265] org.apache.catalina.servlets.CGIServlet$CGIRunner.sendToLog stderr line: [C:\Users\hayde\AppData\Local\Programs\Python\Python36\lib\site-packages\pymysql\cursors.py:170: Warning: (1366, "Incorrect integer value: 'unknown' for column 'year' at row 1")]
24-Oct-2019 21:06:24.934 WARNING [Thread-265] org.apache.catalina.servlets.CGIServlet$CGIRunner.sendToLog stderr line: [  result = self._query(query)]
24-Oct-2019 21:06:24.935 WARNING [Thread-265] org.apache.catalina.servlets.CGIServlet$CGIRunner.sendToLog stderr line: [Traceback (most recent call last):]
24-Oct-2019 21:06:24.936 WARNING [Thread-265] org.apache.catalina.servlets.CGIServlet$CGIRunner.sendToLog stderr line: [  File "C:\Users\hayde\Desktop\UCI\Fall 2019\EECS 118\MP2\apache-tomcat-9.0.26\webapps\test\WEB-INF\cgi\project_3_upload.py", line 99, in <module>]
24-Oct-2019 21:06:24.936 WARNING [Thread-265] org.apache.catalina.servlets.CGIServlet$CGIRunner.sendToLog stderr line: [    val = (max_num_image[0])]
24-Oct-2019 21:06:24.937 WARNING [Thread-265] org.apache.catalina.servlets.CGIServlet$CGIRunner.sendToLog stderr line: [NameError: name 'max_num_image' is not defined]
24-Oct-2019 21:06:24.948 WARNING [Thread-265] org.apache.catalina.servlets.CGIServlet$CGIRunner.sendToLog Received [6] lines on stderr
24-Oct-2019 21:06:38.199 WARNING [Thread-266] org.apache.catalina.servlets.CGIServlet$CGIRunner.sendToLog stderr line: [C:\Users\hayde\AppData\Local\Programs\Python\Python36\lib\site-packages\pymysql\cursors.py:170: Warning: (1366, "Incorrect integer value: 'unknown' for column 'year' at row 1")]
24-Oct-2019 21:06:38.199 WARNING [Thread-266] org.apache.catalina.servlets.CGIServlet$CGIRunner.sendToLog stderr line: [  result = self._query(query)]
24-Oct-2019 21:06:38.199 WARNING [Thread-266] org.apache.catalina.servlets.CGIServlet$CGIRunner.sendToLog stderr line: [Traceback (most recent call last):]
24-Oct-2019 21:06:38.200 WARNING [Thread-266] org.apache.catalina.servlets.CGIServlet$CGIRunner.sendToLog stderr line: [  File "C:\Users\hayde\Desktop\UCI\Fall 2019\EECS 118\MP2\apache-tomcat-9.0.26\webapps\test\WEB-INF\cgi\project_3_upload.py", line 99, in <module>]
24-Oct-2019 21:06:38.200 WARNING [Thread-266] org.apache.catalina.servlets.CGIServlet$CGIRunner.sendToLog stderr line: [    val = (max_num_image[0])]
24-Oct-2019 21:06:38.200 WARNING [Thread-266] org.apache.catalina.servlets.CGIServlet$CGIRunner.sendToLog stderr line: [NameError: name 'max_num_image' is not defined]
24-Oct-2019 21:06:38.212 WARNING [Thread-266] org.apache.catalina.servlets.CGIServlet$CGIRunner.sendToLog Received [6] lines on stderr
24-Oct-2019 21:08:41.347 WARNING [Thread-267] org.apache.catalina.servlets.CGIServlet$CGIRunner.sendToLog stderr line: [C:\Users\hayde\AppData\Local\Programs\Python\Python36\lib\site-packages\pymysql\cursors.py:170: Warning: (1366, "Incorrect integer value: 'unknown' for column 'year' at row 1")]
24-Oct-2019 21:08:41.348 WARNING [Thread-267] org.apache.catalina.servlets.CGIServlet$CGIRunner.sendToLog stderr line: [  result = self._query(query)]
24-Oct-2019 21:08:41.357 WARNING [Thread-267] org.apache.catalina.servlets.CGIServlet$CGIRunner.sendToLog Received [2] lines on stderr
24-Oct-2019 21:15:16.663 WARNING [Thread-268] org.apache.catalina.servlets.CGIServlet$CGIRunner.sendToLog stderr line: [C:\Users\hayde\AppData\Local\Programs\Python\Python36\lib\site-packages\pymysql\cursors.py:170: Warning: (1366, "Incorrect integer value: 'unknown' for column 'year' at row 1")]
24-Oct-2019 21:15:16.663 WARNING [Thread-268] org.apache.catalina.servlets.CGIServlet$CGIRunner.sendToLog stderr line: [  result = self._query(query)]
24-Oct-2019 21:15:16.672 WARNING [Thread-268] org.apache.catalina.servlets.CGIServlet$CGIRunner.sendToLog Received [2] lines on stderr
24-Oct-2019 21:19:25.188 WARNING [Thread-269] org.apache.catalina.servlets.CGIServlet$CGIRunner.sendToLog stderr line: [C:\Users\hayde\AppData\Local\Programs\Python\Python36\lib\site-packages\pymysql\cursors.py:170: Warning: (1366, "Incorrect integer value: 'unknown' for column 'year' at row 1")]
24-Oct-2019 21:19:25.188 WARNING [Thread-269] org.apache.catalina.servlets.CGIServlet$CGIRunner.sendToLog stderr line: [  result = self._query(query)]
24-Oct-2019 21:19:25.189 WARNING [Thread-269] org.apache.catalina.servlets.CGIServlet$CGIRunner.sendToLog stderr line: [Traceback (most recent call last):]
24-Oct-2019 21:19:25.189 WARNING [Thread-269] org.apache.catalina.servlets.CGIServlet$CGIRunner.sendToLog stderr line: [  File "C:\Users\hayde\Desktop\UCI\Fall 2019\EECS 118\MP2\apache-tomcat-9.0.26\webapps\test\WEB-INF\cgi\project_3_upload.py", line 89, in <module>]
24-Oct-2019 21:19:25.190 WARNING [Thread-269] org.apache.catalina.servlets.CGIServlet$CGIRunner.sendToLog stderr line: [    val = (title, url, str(gallery_id), str(artist_id[0]), str(max_num_detail[0]))]
24-Oct-2019 21:19:25.190 WARNING [Thread-269] org.apache.catalina.servlets.CGIServlet$CGIRunner.sendToLog stderr line: [TypeError: 'NoneType' object is not subscriptable]
24-Oct-2019 21:19:25.197 WARNING [Thread-269] org.apache.catalina.servlets.CGIServlet$CGIRunner.sendToLog Received [6] lines on stderr
24-Oct-2019 21:19:41.622 WARNING [Thread-270] org.apache.catalina.servlets.CGIServlet$CGIRunner.sendToLog stderr line: [Traceback (most recent call last):]
24-Oct-2019 21:19:41.622 WARNING [Thread-270] org.apache.catalina.servlets.CGIServlet$CGIRunner.sendToLog stderr line: [  File "C:\Users\hayde\Desktop\UCI\Fall 2019\EECS 118\MP2\apache-tomcat-9.0.26\webapps\test\WEB-INF\cgi\project_3_upload.py", line 89, in <module>]
24-Oct-2019 21:19:41.623 WARNING [Thread-270] org.apache.catalina.servlets.CGIServlet$CGIRunner.sendToLog stderr line: [    val = (title, url, str(gallery_id), str(artist_id[0]), str(max_num_detail[0]))]
24-Oct-2019 21:19:41.623 WARNING [Thread-270] org.apache.catalina.servlets.CGIServlet$CGIRunner.sendToLog stderr line: [TypeError: 'NoneType' object is not subscriptable]
24-Oct-2019 21:19:41.630 WARNING [Thread-270] org.apache.catalina.servlets.CGIServlet$CGIRunner.sendToLog Received [4] lines on stderr
24-Oct-2019 21:21:39.035 WARNING [Thread-271] org.apache.catalina.servlets.CGIServlet$CGIRunner.sendToLog stderr line: [C:\Users\hayde\AppData\Local\Programs\Python\Python36\lib\site-packages\pymysql\cursors.py:170: Warning: (1366, "Incorrect integer value: 'unknown' for column 'year' at row 1")]
24-Oct-2019 21:21:39.035 WARNING [Thread-271] org.apache.catalina.servlets.CGIServlet$CGIRunner.sendToLog stderr line: [  result = self._query(query)]
24-Oct-2019 21:21:39.036 WARNING [Thread-271] org.apache.catalina.servlets.CGIServlet$CGIRunner.sendToLog stderr line: [Traceback (most recent call last):]
24-Oct-2019 21:21:39.036 WARNING [Thread-271] org.apache.catalina.servlets.CGIServlet$CGIRunner.sendToLog stderr line: [  File "C:\Users\hayde\Desktop\UCI\Fall 2019\EECS 118\MP2\apache-tomcat-9.0.26\webapps\test\WEB-INF\cgi\project_3_upload.py", line 93, in <module>]
24-Oct-2019 21:21:39.037 WARNING [Thread-271] org.apache.catalina.servlets.CGIServlet$CGIRunner.sendToLog stderr line: [    val = (title, url, str(gallery_id), str(artist_id[0]), str(max_num_detail[0]))]
24-Oct-2019 21:21:39.037 WARNING [Thread-271] org.apache.catalina.servlets.CGIServlet$CGIRunner.sendToLog stderr line: [TypeError: 'NoneType' object is not subscriptable]
24-Oct-2019 21:21:39.045 WARNING [Thread-271] org.apache.catalina.servlets.CGIServlet$CGIRunner.sendToLog Received [6] lines on stderr
24-Oct-2019 21:22:20.179 WARNING [Thread-272] org.apache.catalina.servlets.CGIServlet$CGIRunner.sendToLog stderr line: [C:\Users\hayde\AppData\Local\Programs\Python\Python36\lib\site-packages\pymysql\cursors.py:170: Warning: (1366, "Incorrect integer value: 'unknown' for column 'year' at row 1")]
24-Oct-2019 21:22:20.180 WARNING [Thread-272] org.apache.catalina.servlets.CGIServlet$CGIRunner.sendToLog stderr line: [  result = self._query(query)]
24-Oct-2019 21:22:20.180 WARNING [Thread-272] org.apache.catalina.servlets.CGIServlet$CGIRunner.sendToLog stderr line: [Traceback (most recent call last):]
24-Oct-2019 21:22:20.180 WARNING [Thread-272] org.apache.catalina.servlets.CGIServlet$CGIRunner.sendToLog stderr line: [  File "C:\Users\hayde\Desktop\UCI\Fall 2019\EECS 118\MP2\apache-tomcat-9.0.26\webapps\test\WEB-INF\cgi\project_3_upload.py", line 88, in <module>]
24-Oct-2019 21:22:20.181 WARNING [Thread-272] org.apache.catalina.servlets.CGIServlet$CGIRunner.sendToLog stderr line: [    val = (str(title), str(url), str(gallery_id), str(artist_id[0]), str(max_num_detail[0]))]
24-Oct-2019 21:22:20.181 WARNING [Thread-272] org.apache.catalina.servlets.CGIServlet$CGIRunner.sendToLog stderr line: [TypeError: 'NoneType' object is not subscriptable]
24-Oct-2019 21:22:20.187 WARNING [Thread-272] org.apache.catalina.servlets.CGIServlet$CGIRunner.sendToLog Received [6] lines on stderr
24-Oct-2019 21:23:42.584 WARNING [Thread-273] org.apache.catalina.servlets.CGIServlet$CGIRunner.sendToLog stderr line: [C:\Users\hayde\AppData\Local\Programs\Python\Python36\lib\site-packages\pymysql\cursors.py:170: Warning: (1366, "Incorrect integer value: 'unknown' for column 'year' at row 1")]
24-Oct-2019 21:23:42.584 WARNING [Thread-273] org.apache.catalina.servlets.CGIServlet$CGIRunner.sendToLog stderr line: [  result = self._query(query)]
24-Oct-2019 21:23:42.584 WARNING [Thread-273] org.apache.catalina.servlets.CGIServlet$CGIRunner.sendToLog stderr line: [Traceback (most recent call last):]
24-Oct-2019 21:23:42.584 WARNING [Thread-273] org.apache.catalina.servlets.CGIServlet$CGIRunner.sendToLog stderr line: [  File "C:\Users\hayde\Desktop\UCI\Fall 2019\EECS 118\MP2\apache-tomcat-9.0.26\webapps\test\WEB-INF\cgi\project_3_upload.py", line 88, in <module>]
24-Oct-2019 21:23:42.584 WARNING [Thread-273] org.apache.catalina.servlets.CGIServlet$CGIRunner.sendToLog stderr line: [    val = (title, url, str(gallery_id), str(artist_id[0]), str(max_num_detail[0]))]
24-Oct-2019 21:23:42.584 WARNING [Thread-273] org.apache.catalina.servlets.CGIServlet$CGIRunner.sendToLog stderr line: [TypeError: 'NoneType' object is not subscriptable]
24-Oct-2019 21:23:42.592 WARNING [Thread-273] org.apache.catalina.servlets.CGIServlet$CGIRunner.sendToLog Received [6] lines on stderr
24-Oct-2019 21:24:38.517 WARNING [Thread-274] org.apache.catalina.servlets.CGIServlet$CGIRunner.sendToLog stderr line: [C:\Users\hayde\AppData\Local\Programs\Python\Python36\lib\site-packages\pymysql\cursors.py:170: Warning: (1366, "Incorrect integer value: 'unknown' for column 'year' at row 1")]
24-Oct-2019 21:24:38.517 WARNING [Thread-274] org.apache.catalina.servlets.CGIServlet$CGIRunner.sendToLog stderr line: [  result = self._query(query)]
24-Oct-2019 21:24:38.525 WARNING [Thread-274] org.apache.catalina.servlets.CGIServlet$CGIRunner.sendToLog Received [2] lines on stderr
24-Oct-2019 21:26:52.104 WARNING [Thread-275] org.apache.catalina.servlets.CGIServlet$CGIRunner.sendToLog stderr line: [C:\Users\hayde\AppData\Local\Programs\Python\Python36\lib\site-packages\pymysql\cursors.py:170: Warning: (1366, "Incorrect integer value: 'unknown' for column 'year' at row 1")]
24-Oct-2019 21:26:52.104 WARNING [Thread-275] org.apache.catalina.servlets.CGIServlet$CGIRunner.sendToLog stderr line: [  result = self._query(query)]
24-Oct-2019 21:26:52.115 WARNING [Thread-275] org.apache.catalina.servlets.CGIServlet$CGIRunner.sendToLog Received [2] lines on stderr
24-Oct-2019 21:27:40.649 WARNING [Thread-276] org.apache.catalina.servlets.CGIServlet$CGIRunner.sendToLog stderr line: [C:\Users\hayde\AppData\Local\Programs\Python\Python36\lib\site-packages\pymysql\cursors.py:170: Warning: (1366, "Incorrect integer value: 'unknown' for column 'year' at row 1")]
24-Oct-2019 21:27:40.649 WARNING [Thread-276] org.apache.catalina.servlets.CGIServlet$CGIRunner.sendToLog stderr line: [  result = self._query(query)]
24-Oct-2019 21:27:40.660 WARNING [Thread-276] org.apache.catalina.servlets.CGIServlet$CGIRunner.sendToLog Received [2] lines on stderr
24-Oct-2019 21:31:56.845 WARNING [Thread-277] org.apache.catalina.servlets.CGIServlet$CGIRunner.sendToLog stderr line: [  File "C:\Users\hayde\Desktop\UCI\Fall 2019\EECS 118\MP2\apache-tomcat-9.0.26\webapps\test\WEB-INF\cgi\project_3_upload.py", line 27]
24-Oct-2019 21:31:56.846 WARNING [Thread-277] org.apache.catalina.servlets.CGIServlet$CGIRunner.sendToLog stderr line: [    if form.getvalue('url') != 'unknown']
24-Oct-2019 21:31:56.846 WARNING [Thread-277] org.apache.catalina.servlets.CGIServlet$CGIRunner.sendToLog stderr line: [                                       ^]
24-Oct-2019 21:31:56.847 WARNING [Thread-277] org.apache.catalina.servlets.CGIServlet$CGIRunner.sendToLog stderr line: [SyntaxError: invalid syntax]
24-Oct-2019 21:31:56.848 WARNING [Thread-277] org.apache.catalina.servlets.CGIServlet$CGIRunner.sendToLog Received [4] lines on stderr
24-Oct-2019 21:32:32.164 WARNING [Thread-278] org.apache.catalina.servlets.CGIServlet$CGIRunner.sendToLog stderr line: [  File "C:\Users\hayde\Desktop\UCI\Fall 2019\EECS 118\MP2\apache-tomcat-9.0.26\webapps\test\WEB-INF\cgi\project_3_upload.py", line 72]
24-Oct-2019 21:32:32.164 WARNING [Thread-278] org.apache.catalina.servlets.CGIServlet$CGIRunner.sendToLog stderr line: [    if form.getvalue('url') != 'unknown']
24-Oct-2019 21:32:32.165 WARNING [Thread-278] org.apache.catalina.servlets.CGIServlet$CGIRunner.sendToLog stderr line: [                                       ^]
24-Oct-2019 21:32:32.165 WARNING [Thread-278] org.apache.catalina.servlets.CGIServlet$CGIRunner.sendToLog stderr line: [SyntaxError: invalid syntax]
24-Oct-2019 21:32:32.168 WARNING [Thread-278] org.apache.catalina.servlets.CGIServlet$CGIRunner.sendToLog Received [4] lines on stderr
24-Oct-2019 21:33:59.088 WARNING [Thread-279] org.apache.catalina.servlets.CGIServlet$CGIRunner.sendToLog stderr line: [C:\Users\hayde\AppData\Local\Programs\Python\Python36\lib\site-packages\pymysql\cursors.py:170: Warning: (1366, "Incorrect integer value: 'unknown' for column 'year' at row 1")]
24-Oct-2019 21:33:59.089 WARNING [Thread-279] org.apache.catalina.servlets.CGIServlet$CGIRunner.sendToLog stderr line: [  result = self._query(query)]
24-Oct-2019 21:33:59.090 WARNING [Thread-279] org.apache.catalina.servlets.CGIServlet$CGIRunner.sendToLog stderr line: [Traceback (most recent call last):]
24-Oct-2019 21:33:59.091 WARNING [Thread-279] org.apache.catalina.servlets.CGIServlet$CGIRunner.sendToLog stderr line: [  File "C:\Users\hayde\Desktop\UCI\Fall 2019\EECS 118\MP2\apache-tomcat-9.0.26\webapps\test\WEB-INF\cgi\project_3_upload.py", line 107, in <module>]
24-Oct-2019 21:33:59.092 WARNING [Thread-279] org.apache.catalina.servlets.CGIServlet$CGIRunner.sendToLog stderr line: [    print(str(artist_id[0]))]
24-Oct-2019 21:33:59.093 WARNING [Thread-279] org.apache.catalina.servlets.CGIServlet$CGIRunner.sendToLog stderr line: [TypeError: 'NoneType' object is not subscriptable]
24-Oct-2019 21:33:59.104 WARNING [Thread-279] org.apache.catalina.servlets.CGIServlet$CGIRunner.sendToLog Received [6] lines on stderr
24-Oct-2019 21:35:59.791 WARNING [Thread-280] org.apache.catalina.servlets.CGIServlet$CGIRunner.sendToLog stderr line: [Traceback (most recent call last):]
24-Oct-2019 21:35:59.791 WARNING [Thread-280] org.apache.catalina.servlets.CGIServlet$CGIRunner.sendToLog stderr line: [  File "C:\Users\hayde\Desktop\UCI\Fall 2019\EECS 118\MP2\apache-tomcat-9.0.26\webapps\test\WEB-INF\cgi\project_3_upload.py", line 108, in <module>]
24-Oct-2019 21:35:59.792 WARNING [Thread-280] org.apache.catalina.servlets.CGIServlet$CGIRunner.sendToLog stderr line: [    print(str(artist_id[0]))]
24-Oct-2019 21:35:59.792 WARNING [Thread-280] org.apache.catalina.servlets.CGIServlet$CGIRunner.sendToLog stderr line: [NameError: name 'artist_id' is not defined]
24-Oct-2019 21:35:59.799 WARNING [Thread-280] org.apache.catalina.servlets.CGIServlet$CGIRunner.sendToLog Received [4] lines on stderr
24-Oct-2019 21:36:34.648 WARNING [Thread-281] org.apache.catalina.servlets.CGIServlet$CGIRunner.sendToLog stderr line: [Traceback (most recent call last):]
24-Oct-2019 21:36:34.648 WARNING [Thread-281] org.apache.catalina.servlets.CGIServlet$CGIRunner.sendToLog stderr line: [  File "C:\Users\hayde\Desktop\UCI\Fall 2019\EECS 118\MP2\apache-tomcat-9.0.26\webapps\test\WEB-INF\cgi\project_3_upload.py", line 108, in <module>]
24-Oct-2019 21:36:34.648 WARNING [Thread-281] org.apache.catalina.servlets.CGIServlet$CGIRunner.sendToLog stderr line: [    print(str(artist_id[0]))]
24-Oct-2019 21:36:34.649 WARNING [Thread-281] org.apache.catalina.servlets.CGIServlet$CGIRunner.sendToLog stderr line: [NameError: name 'artist_id' is not defined]
24-Oct-2019 21:36:34.659 WARNING [Thread-281] org.apache.catalina.servlets.CGIServlet$CGIRunner.sendToLog Received [4] lines on stderr
24-Oct-2019 21:37:32.936 WARNING [Thread-282] org.apache.catalina.servlets.CGIServlet$CGIRunner.sendToLog stderr line: [C:\Users\hayde\AppData\Local\Programs\Python\Python36\lib\site-packages\pymysql\cursors.py:170: Warning: (1265, "Data truncated for column 'link' at row 1")]
24-Oct-2019 21:37:32.937 WARNING [Thread-282] org.apache.catalina.servlets.CGIServlet$CGIRunner.sendToLog stderr line: [  result = self._query(query)]
24-Oct-2019 21:37:32.938 WARNING [Thread-282] org.apache.catalina.servlets.CGIServlet$CGIRunner.sendToLog stderr line: [C:\Users\hayde\AppData\Local\Programs\Python\Python36\lib\site-packages\pymysql\cursors.py:170: Warning: (1366, "Incorrect integer value: 'None' for column 'gallery_id' at row 1")]
24-Oct-2019 21:37:32.938 WARNING [Thread-282] org.apache.catalina.servlets.CGIServlet$CGIRunner.sendToLog stderr line: [  result = self._query(query)]
24-Oct-2019 21:37:32.942 WARNING [Thread-282] org.apache.catalina.servlets.CGIServlet$CGIRunner.sendToLog stderr line: [Traceback (most recent call last):]
24-Oct-2019 21:37:32.942 WARNING [Thread-282] org.apache.catalina.servlets.CGIServlet$CGIRunner.sendToLog stderr line: [  File "C:\Users\hayde\Desktop\UCI\Fall 2019\EECS 118\MP2\apache-tomcat-9.0.26\webapps\test\WEB-INF\cgi\project_3_upload.py", line 100, in <module>]
24-Oct-2019 21:37:32.943 WARNING [Thread-282] org.apache.catalina.servlets.CGIServlet$CGIRunner.sendToLog stderr line: [    cur.execute(query, val)]
24-Oct-2019 21:37:32.943 WARNING [Thread-282] org.apache.catalina.servlets.CGIServlet$CGIRunner.sendToLog stderr line: [  File "C:\Users\hayde\AppData\Local\Programs\Python\Python36\lib\site-packages\pymysql\cursors.py", line 170, in execute]
24-Oct-2019 21:37:32.944 WARNING [Thread-282] org.apache.catalina.servlets.CGIServlet$CGIRunner.sendToLog stderr line: [    result = self._query(query)]
24-Oct-2019 21:37:32.944 WARNING [Thread-282] org.apache.catalina.servlets.CGIServlet$CGIRunner.sendToLog stderr line: [  File "C:\Users\hayde\AppData\Local\Programs\Python\Python36\lib\site-packages\pymysql\cursors.py", line 328, in _query]
24-Oct-2019 21:37:32.945 WARNING [Thread-282] org.apache.catalina.servlets.CGIServlet$CGIRunner.sendToLog stderr line: [    conn.query(q)]
24-Oct-2019 21:37:32.945 WARNING [Thread-282] org.apache.catalina.servlets.CGIServlet$CGIRunner.sendToLog stderr line: [  File "C:\Users\hayde\AppData\Local\Programs\Python\Python36\lib\site-packages\pymysql\connections.py", line 517, in query]
24-Oct-2019 21:37:32.945 WARNING [Thread-282] org.apache.catalina.servlets.CGIServlet$CGIRunner.sendToLog stderr line: [    self._affected_rows = self._read_query_result(unbuffered=unbuffered)]
24-Oct-2019 21:37:32.946 WARNING [Thread-282] org.apache.catalina.servlets.CGIServlet$CGIRunner.sendToLog stderr line: [  File "C:\Users\hayde\AppData\Local\Programs\Python\Python36\lib\site-packages\pymysql\connections.py", line 732, in _read_query_result]
24-Oct-2019 21:37:32.946 WARNING [Thread-282] org.apache.catalina.servlets.CGIServlet$CGIRunner.sendToLog stderr line: [    result.read()]
24-Oct-2019 21:37:32.946 WARNING [Thread-282] org.apache.catalina.servlets.CGIServlet$CGIRunner.sendToLog stderr line: [  File "C:\Users\hayde\AppData\Local\Programs\Python\Python36\lib\site-packages\pymysql\connections.py", line 1075, in read]
24-Oct-2019 21:37:32.947 WARNING [Thread-282] org.apache.catalina.servlets.CGIServlet$CGIRunner.sendToLog stderr line: [    first_packet = self.connection._read_packet()]
24-Oct-2019 21:37:32.947 WARNING [Thread-282] org.apache.catalina.servlets.CGIServlet$CGIRunner.sendToLog stderr line: [  File "C:\Users\hayde\AppData\Local\Programs\Python\Python36\lib\site-packages\pymysql\connections.py", line 684, in _read_packet]
24-Oct-2019 21:37:32.947 WARNING [Thread-282] org.apache.catalina.servlets.CGIServlet$CGIRunner.sendToLog stderr line: [    packet.check_error()]
24-Oct-2019 21:37:32.947 WARNING [Thread-282] org.apache.catalina.servlets.CGIServlet$CGIRunner.sendToLog stderr line: [  File "C:\Users\hayde\AppData\Local\Programs\Python\Python36\lib\site-packages\pymysql\protocol.py", line 220, in check_error]
24-Oct-2019 21:37:32.948 WARNING [Thread-282] org.apache.catalina.servlets.CGIServlet$CGIRunner.sendToLog stderr line: [    err.raise_mysql_exception(self._data)]
24-Oct-2019 21:37:32.948 WARNING [Thread-282] org.apache.catalina.servlets.CGIServlet$CGIRunner.sendToLog stderr line: [  File "C:\Users\hayde\AppData\Local\Programs\Python\Python36\lib\site-packages\pymysql\err.py", line 109, in raise_mysql_exception]
24-Oct-2019 21:37:32.948 WARNING [Thread-282] org.apache.catalina.servlets.CGIServlet$CGIRunner.sendToLog stderr line: [    raise errorclass(errno, errval)]
24-Oct-2019 21:37:32.948 WARNING [Thread-282] org.apache.catalina.servlets.CGIServlet$CGIRunner.sendToLog stderr line: [pymysql.err.ProgrammingError: (1064, "You have an error in your SQL syntax; check the manual that corresponds to your MySQL server version for the right syntax to use near 'where detail_id='28' \t\t\t\tvalues(3)' at line 1")]
24-Oct-2019 21:37:32.952 WARNING [Thread-282] org.apache.catalina.servlets.CGIServlet$CGIRunner.sendToLog Received [24] lines on stderr
24-Oct-2019 21:42:34.301 WARNING [Thread-283] org.apache.catalina.servlets.CGIServlet$CGIRunner.sendToLog stderr line: [Traceback (most recent call last):]
24-Oct-2019 21:42:34.301 WARNING [Thread-283] org.apache.catalina.servlets.CGIServlet$CGIRunner.sendToLog stderr line: [  File "C:\Users\hayde\Desktop\UCI\Fall 2019\EECS 118\MP2\apache-tomcat-9.0.26\webapps\test\WEB-INF\cgi\project_3_upload.py", line 108, in <module>]
24-Oct-2019 21:42:34.301 WARNING [Thread-283] org.apache.catalina.servlets.CGIServlet$CGIRunner.sendToLog stderr line: [    print(gallery_id.type())]
24-Oct-2019 21:42:34.302 WARNING [Thread-283] org.apache.catalina.servlets.CGIServlet$CGIRunner.sendToLog stderr line: [AttributeError: 'str' object has no attribute 'type']
24-Oct-2019 21:42:34.309 WARNING [Thread-283] org.apache.catalina.servlets.CGIServlet$CGIRunner.sendToLog Received [4] lines on stderr
24-Oct-2019 21:42:49.294 WARNING [Thread-284] org.apache.catalina.servlets.CGIServlet$CGIRunner.sendToLog stderr line: [Traceback (most recent call last):]
24-Oct-2019 21:42:49.294 WARNING [Thread-284] org.apache.catalina.servlets.CGIServlet$CGIRunner.sendToLog stderr line: [  File "C:\Users\hayde\Desktop\UCI\Fall 2019\EECS 118\MP2\apache-tomcat-9.0.26\webapps\test\WEB-INF\cgi\project_3_upload.py", line 108, in <module>]
24-Oct-2019 21:42:49.294 WARNING [Thread-284] org.apache.catalina.servlets.CGIServlet$CGIRunner.sendToLog stderr line: [    print(type(gallery_id))]
24-Oct-2019 21:42:49.295 WARNING [Thread-284] org.apache.catalina.servlets.CGIServlet$CGIRunner.sendToLog stderr line: [TypeError: 'str' object is not callable]
24-Oct-2019 21:42:49.302 WARNING [Thread-284] org.apache.catalina.servlets.CGIServlet$CGIRunner.sendToLog Received [4] lines on stderr
24-Oct-2019 21:44:24.748 WARNING [Thread-285] org.apache.catalina.servlets.CGIServlet$CGIRunner.sendToLog stderr line: [Traceback (most recent call last):]
24-Oct-2019 21:44:24.748 WARNING [Thread-285] org.apache.catalina.servlets.CGIServlet$CGIRunner.sendToLog stderr line: [  File "C:\Users\hayde\Desktop\UCI\Fall 2019\EECS 118\MP2\apache-tomcat-9.0.26\webapps\test\WEB-INF\cgi\project_3_upload.py", line 108, in <module>]
24-Oct-2019 21:44:24.749 WARNING [Thread-285] org.apache.catalina.servlets.CGIServlet$CGIRunner.sendToLog stderr line: [    print("%s"%s(type(gallery_id)))]
24-Oct-2019 21:44:24.749 WARNING [Thread-285] org.apache.catalina.servlets.CGIServlet$CGIRunner.sendToLog stderr line: [NameError: name 's' is not defined]
24-Oct-2019 21:44:24.758 WARNING [Thread-285] org.apache.catalina.servlets.CGIServlet$CGIRunner.sendToLog Received [4] lines on stderr
24-Oct-2019 21:44:46.201 WARNING [Thread-286] org.apache.catalina.servlets.CGIServlet$CGIRunner.sendToLog stderr line: [Traceback (most recent call last):]
24-Oct-2019 21:44:46.202 WARNING [Thread-286] org.apache.catalina.servlets.CGIServlet$CGIRunner.sendToLog stderr line: [  File "C:\Users\hayde\Desktop\UCI\Fall 2019\EECS 118\MP2\apache-tomcat-9.0.26\webapps\test\WEB-INF\cgi\project_3_upload.py", line 108, in <module>]
24-Oct-2019 21:44:46.202 WARNING [Thread-286] org.apache.catalina.servlets.CGIServlet$CGIRunner.sendToLog stderr line: [    print("%s"%s(gallery_id))]
24-Oct-2019 21:44:46.203 WARNING [Thread-286] org.apache.catalina.servlets.CGIServlet$CGIRunner.sendToLog stderr line: [NameError: name 's' is not defined]
24-Oct-2019 21:44:46.211 WARNING [Thread-286] org.apache.catalina.servlets.CGIServlet$CGIRunner.sendToLog Received [4] lines on stderr
24-Oct-2019 21:45:05.147 WARNING [Thread-288] org.apache.catalina.servlets.CGIServlet$CGIRunner.sendToLog stderr line: [Traceback (most recent call last):]
24-Oct-2019 21:45:05.147 WARNING [Thread-288] org.apache.catalina.servlets.CGIServlet$CGIRunner.sendToLog stderr line: [  File "C:\Users\hayde\Desktop\UCI\Fall 2019\EECS 118\MP2\apache-tomcat-9.0.26\webapps\test\WEB-INF\cgi\project_3_upload.py", line 108, in <module>]
24-Oct-2019 21:45:05.148 WARNING [Thread-288] org.apache.catalina.servlets.CGIServlet$CGIRunner.sendToLog stderr line: [    print("%s"%(type(gallery_id)))]
24-Oct-2019 21:45:05.148 WARNING [Thread-288] org.apache.catalina.servlets.CGIServlet$CGIRunner.sendToLog stderr line: [TypeError: 'str' object is not callable]
24-Oct-2019 21:45:05.155 WARNING [Thread-288] org.apache.catalina.servlets.CGIServlet$CGIRunner.sendToLog Received [4] lines on stderr
24-Oct-2019 21:45:28.081 WARNING [Thread-289] org.apache.catalina.servlets.CGIServlet$CGIRunner.sendToLog stderr line: [Traceback (most recent call last):]
24-Oct-2019 21:45:28.081 WARNING [Thread-289] org.apache.catalina.servlets.CGIServlet$CGIRunner.sendToLog stderr line: [  File "C:\Users\hayde\Desktop\UCI\Fall 2019\EECS 118\MP2\apache-tomcat-9.0.26\webapps\test\WEB-INF\cgi\project_3_upload.py", line 108, in <module>]
24-Oct-2019 21:45:28.081 WARNING [Thread-289] org.apache.catalina.servlets.CGIServlet$CGIRunner.sendToLog stderr line: [    print("%s"%str(type(gallery_id)))]
24-Oct-2019 21:45:28.081 WARNING [Thread-289] org.apache.catalina.servlets.CGIServlet$CGIRunner.sendToLog stderr line: [TypeError: 'str' object is not callable]
24-Oct-2019 21:45:28.089 WARNING [Thread-289] org.apache.catalina.servlets.CGIServlet$CGIRunner.sendToLog Received [4] lines on stderr
24-Oct-2019 21:50:46.563 WARNING [Thread-291] org.apache.catalina.servlets.CGIServlet$CGIRunner.sendToLog stderr line: [Traceback (most recent call last):]
24-Oct-2019 21:50:46.564 WARNING [Thread-291] org.apache.catalina.servlets.CGIServlet$CGIRunner.sendToLog stderr line: [  File "C:\Users\hayde\Desktop\UCI\Fall 2019\EECS 118\MP2\apache-tomcat-9.0.26\webapps\test\WEB-INF\cgi\project_3_upload.py", line 111, in <module>]
24-Oct-2019 21:50:46.564 WARNING [Thread-291] org.apache.catalina.servlets.CGIServlet$CGIRunner.sendToLog stderr line: [    print(id[0])]
24-Oct-2019 21:50:46.564 WARNING [Thread-291] org.apache.catalina.servlets.CGIServlet$CGIRunner.sendToLog stderr line: [TypeError: 'NoneType' object is not subscriptable]
24-Oct-2019 21:50:46.571 WARNING [Thread-291] org.apache.catalina.servlets.CGIServlet$CGIRunner.sendToLog Received [4] lines on stderr
24-Oct-2019 21:51:05.797 WARNING [Thread-292] org.apache.catalina.servlets.CGIServlet$CGIRunner.sendToLog stderr line: [Traceback (most recent call last):]
24-Oct-2019 21:51:05.798 WARNING [Thread-292] org.apache.catalina.servlets.CGIServlet$CGIRunner.sendToLog stderr line: [  File "C:\Users\hayde\Desktop\UCI\Fall 2019\EECS 118\MP2\apache-tomcat-9.0.26\webapps\test\WEB-INF\cgi\project_3_upload.py", line 111, in <module>]
24-Oct-2019 21:51:05.798 WARNING [Thread-292] org.apache.catalina.servlets.CGIServlet$CGIRunner.sendToLog stderr line: [    print(str(id[0]))]
24-Oct-2019 21:51:05.798 WARNING [Thread-292] org.apache.catalina.servlets.CGIServlet$CGIRunner.sendToLog stderr line: [TypeError: 'NoneType' object is not subscriptable]
24-Oct-2019 21:51:05.807 WARNING [Thread-292] org.apache.catalina.servlets.CGIServlet$CGIRunner.sendToLog Received [4] lines on stderr
24-Oct-2019 21:51:28.812 WARNING [Thread-293] org.apache.catalina.servlets.CGIServlet$CGIRunner.sendToLog stderr line: [Traceback (most recent call last):]
24-Oct-2019 21:51:28.812 WARNING [Thread-293] org.apache.catalina.servlets.CGIServlet$CGIRunner.sendToLog stderr line: [  File "C:\Users\hayde\Desktop\UCI\Fall 2019\EECS 118\MP2\apache-tomcat-9.0.26\webapps\test\WEB-INF\cgi\project_3_upload.py", line 112, in <module>]
24-Oct-2019 21:51:28.813 WARNING [Thread-293] org.apache.catalina.servlets.CGIServlet$CGIRunner.sendToLog stderr line: [    print(str(id[0]))]
24-Oct-2019 21:51:28.814 WARNING [Thread-293] org.apache.catalina.servlets.CGIServlet$CGIRunner.sendToLog stderr line: [TypeError: 'NoneType' object is not subscriptable]
24-Oct-2019 21:51:28.824 WARNING [Thread-293] org.apache.catalina.servlets.CGIServlet$CGIRunner.sendToLog Received [4] lines on stderr
24-Oct-2019 22:02:10.880 WARNING [Thread-304] org.apache.catalina.servlets.CGIServlet$CGIRunner.sendToLog stderr line: [Traceback (most recent call last):]
24-Oct-2019 22:02:10.882 WARNING [Thread-304] org.apache.catalina.servlets.CGIServlet$CGIRunner.sendToLog stderr line: [  File "C:\Users\hayde\Desktop\UCI\Fall 2019\EECS 118\MP2\apache-tomcat-9.0.26\webapps\test\WEB-INF\cgi\project_3_gallery1.py", line 69, in <module>]
24-Oct-2019 22:02:10.882 WARNING [Thread-304] org.apache.catalina.servlets.CGIServlet$CGIRunner.sendToLog stderr line: [    cur.execute(query)]
24-Oct-2019 22:02:10.882 WARNING [Thread-304] org.apache.catalina.servlets.CGIServlet$CGIRunner.sendToLog stderr line: [  File "C:\Users\hayde\AppData\Local\Programs\Python\Python36\lib\site-packages\pymysql\cursors.py", line 170, in execute]
24-Oct-2019 22:02:10.883 WARNING [Thread-304] org.apache.catalina.servlets.CGIServlet$CGIRunner.sendToLog stderr line: [    result = self._query(query)]
24-Oct-2019 22:02:10.883 WARNING [Thread-304] org.apache.catalina.servlets.CGIServlet$CGIRunner.sendToLog stderr line: [  File "C:\Users\hayde\AppData\Local\Programs\Python\Python36\lib\site-packages\pymysql\cursors.py", line 328, in _query]
24-Oct-2019 22:02:10.883 WARNING [Thread-304] org.apache.catalina.servlets.CGIServlet$CGIRunner.sendToLog stderr line: [    conn.query(q)]
24-Oct-2019 22:02:10.884 WARNING [Thread-304] org.apache.catalina.servlets.CGIServlet$CGIRunner.sendToLog stderr line: [  File "C:\Users\hayde\AppData\Local\Programs\Python\Python36\lib\site-packages\pymysql\connections.py", line 517, in query]
24-Oct-2019 22:02:10.884 WARNING [Thread-304] org.apache.catalina.servlets.CGIServlet$CGIRunner.sendToLog stderr line: [    self._affected_rows = self._read_query_result(unbuffered=unbuffered)]
24-Oct-2019 22:02:10.884 WARNING [Thread-304] org.apache.catalina.servlets.CGIServlet$CGIRunner.sendToLog stderr line: [  File "C:\Users\hayde\AppData\Local\Programs\Python\Python36\lib\site-packages\pymysql\connections.py", line 732, in _read_query_result]
24-Oct-2019 22:02:10.885 WARNING [Thread-304] org.apache.catalina.servlets.CGIServlet$CGIRunner.sendToLog stderr line: [    result.read()]
24-Oct-2019 22:02:10.885 WARNING [Thread-304] org.apache.catalina.servlets.CGIServlet$CGIRunner.sendToLog stderr line: [  File "C:\Users\hayde\AppData\Local\Programs\Python\Python36\lib\site-packages\pymysql\connections.py", line 1075, in read]
24-Oct-2019 22:02:10.885 WARNING [Thread-304] org.apache.catalina.servlets.CGIServlet$CGIRunner.sendToLog stderr line: [    first_packet = self.connection._read_packet()]
24-Oct-2019 22:02:10.886 WARNING [Thread-304] org.apache.catalina.servlets.CGIServlet$CGIRunner.sendToLog stderr line: [  File "C:\Users\hayde\AppData\Local\Programs\Python\Python36\lib\site-packages\pymysql\connections.py", line 684, in _read_packet]
24-Oct-2019 22:02:10.886 WARNING [Thread-304] org.apache.catalina.servlets.CGIServlet$CGIRunner.sendToLog stderr line: [    packet.check_error()]
24-Oct-2019 22:02:10.886 WARNING [Thread-304] org.apache.catalina.servlets.CGIServlet$CGIRunner.sendToLog stderr line: [  File "C:\Users\hayde\AppData\Local\Programs\Python\Python36\lib\site-packages\pymysql\protocol.py", line 220, in check_error]
24-Oct-2019 22:02:10.886 WARNING [Thread-304] org.apache.catalina.servlets.CGIServlet$CGIRunner.sendToLog stderr line: [    err.raise_mysql_exception(self._data)]
24-Oct-2019 22:02:10.887 WARNING [Thread-304] org.apache.catalina.servlets.CGIServlet$CGIRunner.sendToLog stderr line: [  File "C:\Users\hayde\AppData\Local\Programs\Python\Python36\lib\site-packages\pymysql\err.py", line 109, in raise_mysql_exception]
24-Oct-2019 22:02:10.887 WARNING [Thread-304] org.apache.catalina.servlets.CGIServlet$CGIRunner.sendToLog stderr line: [    raise errorclass(errno, errval)]
24-Oct-2019 22:02:10.887 WARNING [Thread-304] org.apache.catalina.servlets.CGIServlet$CGIRunner.sendToLog stderr line: [pymysql.err.ProgrammingError: (1064, "You have an error in your SQL syntax; check the manual that corresponds to your MySQL server version for the right syntax to use near 'link' at row 1'' at line 1")]
24-Oct-2019 22:02:10.890 WARNING [Thread-304] org.apache.catalina.servlets.CGIServlet$CGIRunner.sendToLog Received [20] lines on stderr
24-Oct-2019 22:04:44.326 WARNING [Thread-308] org.apache.catalina.servlets.CGIServlet$CGIRunner.sendToLog stderr line: [Traceback (most recent call last):]
24-Oct-2019 22:04:44.326 WARNING [Thread-308] org.apache.catalina.servlets.CGIServlet$CGIRunner.sendToLog stderr line: [  File "C:\Users\hayde\Desktop\UCI\Fall 2019\EECS 118\MP2\apache-tomcat-9.0.26\webapps\test\WEB-INF\cgi\project_3_upload.py", line 27, in <module>]
24-Oct-2019 22:04:44.327 WARNING [Thread-308] org.apache.catalina.servlets.CGIServlet$CGIRunner.sendToLog stderr line: [    query = "select gallery_id from gallery where name='"+gallery_name+"'"]
24-Oct-2019 22:04:44.328 WARNING [Thread-308] org.apache.catalina.servlets.CGIServlet$CGIRunner.sendToLog stderr line: [TypeError: must be str, not NoneType]
24-Oct-2019 22:04:44.335 WARNING [Thread-308] org.apache.catalina.servlets.CGIServlet$CGIRunner.sendToLog Received [4] lines on stderr
24-Oct-2019 22:07:25.273 WARNING [Thread-309] org.apache.catalina.servlets.CGIServlet$CGIRunner.sendToLog stderr line: [Traceback (most recent call last):]
24-Oct-2019 22:07:25.273 WARNING [Thread-309] org.apache.catalina.servlets.CGIServlet$CGIRunner.sendToLog stderr line: [  File "C:\Users\hayde\Desktop\UCI\Fall 2019\EECS 118\MP2\apache-tomcat-9.0.26\webapps\test\WEB-INF\cgi\project_3_upload.py", line 27, in <module>]
24-Oct-2019 22:07:25.274 WARNING [Thread-309] org.apache.catalina.servlets.CGIServlet$CGIRunner.sendToLog stderr line: [    query = "select gallery_id from gallery where name='"+gallery_name+"'"]
24-Oct-2019 22:07:25.274 WARNING [Thread-309] org.apache.catalina.servlets.CGIServlet$CGIRunner.sendToLog stderr line: [TypeError: must be str, not NoneType]
24-Oct-2019 22:07:25.281 WARNING [Thread-309] org.apache.catalina.servlets.CGIServlet$CGIRunner.sendToLog Received [4] lines on stderr
24-Oct-2019 22:08:35.405 WARNING [Thread-310] org.apache.catalina.servlets.CGIServlet$CGIRunner.sendToLog stderr line: [Traceback (most recent call last):]
24-Oct-2019 22:08:35.406 WARNING [Thread-310] org.apache.catalina.servlets.CGIServlet$CGIRunner.sendToLog stderr line: [  File "C:\Users\hayde\Desktop\UCI\Fall 2019\EECS 118\MP2\apache-tomcat-9.0.26\webapps\test\WEB-INF\cgi\project_3_upload.py", line 27, in <module>]
24-Oct-2019 22:08:35.407 WARNING [Thread-310] org.apache.catalina.servlets.CGIServlet$CGIRunner.sendToLog stderr line: [    query = "select gallery_id from gallery where name='"+gallery_name+"'"]
24-Oct-2019 22:08:35.407 WARNING [Thread-310] org.apache.catalina.servlets.CGIServlet$CGIRunner.sendToLog stderr line: [TypeError: must be str, not NoneType]
24-Oct-2019 22:08:35.414 WARNING [Thread-310] org.apache.catalina.servlets.CGIServlet$CGIRunner.sendToLog Received [4] lines on stderr
24-Oct-2019 22:13:01.341 WARNING [Thread-314] org.apache.catalina.servlets.CGIServlet$CGIRunner.sendToLog stderr line: [Traceback (most recent call last):]
24-Oct-2019 22:13:01.342 WARNING [Thread-314] org.apache.catalina.servlets.CGIServlet$CGIRunner.sendToLog stderr line: [  File "C:\Users\hayde\Desktop\UCI\Fall 2019\EECS 118\MP2\apache-tomcat-9.0.26\webapps\test\WEB-INF\cgi\project_3_upload.py", line 27, in <module>]
24-Oct-2019 22:13:01.343 WARNING [Thread-314] org.apache.catalina.servlets.CGIServlet$CGIRunner.sendToLog stderr line: [    query = "select gallery_id from gallery where name='"+gallery_name+"'"]
24-Oct-2019 22:13:01.343 WARNING [Thread-314] org.apache.catalina.servlets.CGIServlet$CGIRunner.sendToLog stderr line: [TypeError: must be str, not NoneType]
24-Oct-2019 22:13:01.350 WARNING [Thread-314] org.apache.catalina.servlets.CGIServlet$CGIRunner.sendToLog Received [4] lines on stderr
24-Oct-2019 22:14:55.545 WARNING [Thread-317] org.apache.catalina.servlets.CGIServlet$CGIRunner.sendToLog stderr line: [Traceback (most recent call last):]
24-Oct-2019 22:14:55.545 WARNING [Thread-317] org.apache.catalina.servlets.CGIServlet$CGIRunner.sendToLog stderr line: [  File "C:\Users\hayde\Desktop\UCI\Fall 2019\EECS 118\MP2\apache-tomcat-9.0.26\webapps\test\WEB-INF\cgi\project_3_upload.py", line 27, in <module>]
24-Oct-2019 22:14:55.546 WARNING [Thread-317] org.apache.catalina.servlets.CGIServlet$CGIRunner.sendToLog stderr line: [    query = "select gallery_id from gallery where name='"+gallery_name+"'"]
24-Oct-2019 22:14:55.546 WARNING [Thread-317] org.apache.catalina.servlets.CGIServlet$CGIRunner.sendToLog stderr line: [TypeError: must be str, not NoneType]
24-Oct-2019 22:14:55.554 WARNING [358] org.apache.catalina.servlets.CGIServlet$CGIRunner.sendToLog Received [4] lines on stderr
24-Oct-2019 22:19:03.798 WARNING [Thread-318] org.apache.catalina.servlets.CGIServlet$CGIRunner.sendToLog stderr line: [Traceback (most recent call last):]
24-Oct-2019 22:19:03.799 WARNING [Thread-318] org.apache.catalina.servlets.CGIServlet$CGIRunner.sendToLog stderr line: [  File "C:\Users\hayde\Desktop\UCI\Fall 2019\EECS 118\MP2\apache-tomcat-9.0.26\webapps\test\WEB-INF\cgi\project_3_upload.py", line 32, in <module>]
24-Oct-2019 22:19:03.799 WARNING [Thread-318] org.apache.catalina.servlets.CGIServlet$CGIRunner.sendToLog stderr line: [    print(id[0])]
24-Oct-2019 22:19:03.799 WARNING [Thread-318] org.apache.catalina.servlets.CGIServlet$CGIRunner.sendToLog stderr line: [TypeError: 'builtin_function_or_method' object is not subscriptable]
24-Oct-2019 22:19:03.807 WARNING [Thread-318] org.apache.catalina.servlets.CGIServlet$CGIRunner.sendToLog Received [4] lines on stderr
24-Oct-2019 22:20:17.769 WARNING [Thread-320] org.apache.catalina.servlets.CGIServlet$CGIRunner.sendToLog stderr line: [Traceback (most recent call last):]
24-Oct-2019 22:20:17.769 WARNING [Thread-320] org.apache.catalina.servlets.CGIServlet$CGIRunner.sendToLog stderr line: [  File "C:\Users\hayde\Desktop\UCI\Fall 2019\EECS 118\MP2\apache-tomcat-9.0.26\webapps\test\WEB-INF\cgi\project_3_uploaded.py", line 13, in <module>]
24-Oct-2019 22:20:17.769 WARNING [Thread-320] org.apache.catalina.servlets.CGIServlet$CGIRunner.sendToLog stderr line: [    query = "select gallery_id from gallery where name='"+gallery_name+"'"]
24-Oct-2019 22:20:17.770 WARNING [Thread-320] org.apache.catalina.servlets.CGIServlet$CGIRunner.sendToLog stderr line: [TypeError: must be str, not NoneType]
24-Oct-2019 22:20:17.777 WARNING [Thread-320] org.apache.catalina.servlets.CGIServlet$CGIRunner.sendToLog Received [4] lines on stderr
24-Oct-2019 22:20:56.212 WARNING [Thread-321] org.apache.catalina.servlets.CGIServlet$CGIRunner.sendToLog stderr line: [Traceback (most recent call last):]
24-Oct-2019 22:20:56.212 WARNING [Thread-321] org.apache.catalina.servlets.CGIServlet$CGIRunner.sendToLog stderr line: [  File "C:\Users\hayde\Desktop\UCI\Fall 2019\EECS 118\MP2\apache-tomcat-9.0.26\webapps\test\WEB-INF\cgi\project_3_uploaded.py", line 13, in <module>]
24-Oct-2019 22:20:56.213 WARNING [Thread-321] org.apache.catalina.servlets.CGIServlet$CGIRunner.sendToLog stderr line: [    query = "select gallery_id from gallery where name='"+gallery_name+"'"]
24-Oct-2019 22:20:56.213 WARNING [Thread-321] org.apache.catalina.servlets.CGIServlet$CGIRunner.sendToLog stderr line: [TypeError: must be str, not NoneType]
24-Oct-2019 22:20:56.220 WARNING [Thread-321] org.apache.catalina.servlets.CGIServlet$CGIRunner.sendToLog Received [4] lines on stderr
24-Oct-2019 22:21:35.682 WARNING [Thread-322] org.apache.catalina.servlets.CGIServlet$CGIRunner.sendToLog stderr line: [Traceback (most recent call last):]
24-Oct-2019 22:21:35.682 WARNING [Thread-322] org.apache.catalina.servlets.CGIServlet$CGIRunner.sendToLog stderr line: [  File "C:\Users\hayde\Desktop\UCI\Fall 2019\EECS 118\MP2\apache-tomcat-9.0.26\webapps\test\WEB-INF\cgi\project_3_uploaded.py", line 13, in <module>]
24-Oct-2019 22:21:35.683 WARNING [Thread-322] org.apache.catalina.servlets.CGIServlet$CGIRunner.sendToLog stderr line: [    query = "select gallery_id from gallery where name='"+gallery_name+"'"]
24-Oct-2019 22:21:35.683 WARNING [Thread-322] org.apache.catalina.servlets.CGIServlet$CGIRunner.sendToLog stderr line: [TypeError: must be str, not NoneType]
24-Oct-2019 22:21:35.690 WARNING [Thread-322] org.apache.catalina.servlets.CGIServlet$CGIRunner.sendToLog Received [4] lines on stderr
24-Oct-2019 22:23:41.257 WARNING [Thread-323] org.apache.catalina.servlets.CGIServlet$CGIRunner.sendToLog stderr line: [Traceback (most recent call last):]
24-Oct-2019 22:23:41.257 WARNING [Thread-323] org.apache.catalina.servlets.CGIServlet$CGIRunner.sendToLog stderr line: [  File "C:\Users\hayde\Desktop\UCI\Fall 2019\EECS 118\MP2\apache-tomcat-9.0.26\webapps\test\WEB-INF\cgi\project_3_uploaded.py", line 13, in <module>]
24-Oct-2019 22:23:41.257 WARNING [Thread-323] org.apache.catalina.servlets.CGIServlet$CGIRunner.sendToLog stderr line: [    query = "select gallery_id from gallery where name='"+gallery_name+"'"]
24-Oct-2019 22:23:41.258 WARNING [Thread-323] org.apache.catalina.servlets.CGIServlet$CGIRunner.sendToLog stderr line: [TypeError: must be str, not NoneType]
24-Oct-2019 22:23:41.265 WARNING [Thread-323] org.apache.catalina.servlets.CGIServlet$CGIRunner.sendToLog Received [4] lines on stderr
24-Oct-2019 22:26:08.571 WARNING [Thread-324] org.apache.catalina.servlets.CGIServlet$CGIRunner.sendToLog stderr line: [Traceback (most recent call last):]
24-Oct-2019 22:26:08.571 WARNING [Thread-324] org.apache.catalina.servlets.CGIServlet$CGIRunner.sendToLog stderr line: [  File "C:\Users\hayde\Desktop\UCI\Fall 2019\EECS 118\MP2\apache-tomcat-9.0.26\webapps\test\WEB-INF\cgi\project_3_uploaded.py", line 13, in <module>]
24-Oct-2019 22:26:08.572 WARNING [Thread-324] org.apache.catalina.servlets.CGIServlet$CGIRunner.sendToLog stderr line: [    query = "select gallery_id from gallery where name='"+gallery_name+"'"]
24-Oct-2019 22:26:08.572 WARNING [Thread-324] org.apache.catalina.servlets.CGIServlet$CGIRunner.sendToLog stderr line: [TypeError: must be str, not NoneType]
24-Oct-2019 22:26:08.579 WARNING [Thread-324] org.apache.catalina.servlets.CGIServlet$CGIRunner.sendToLog Received [4] lines on stderr
24-Oct-2019 22:26:37.507 WARNING [Thread-325] org.apache.catalina.servlets.CGIServlet$CGIRunner.sendToLog stderr line: [Traceback (most recent call last):]
24-Oct-2019 22:26:37.508 WARNING [Thread-325] org.apache.catalina.servlets.CGIServlet$CGIRunner.sendToLog stderr line: [  File "C:\Users\hayde\Desktop\UCI\Fall 2019\EECS 118\MP2\apache-tomcat-9.0.26\webapps\test\WEB-INF\cgi\project_3_uploaded.py", line 99, in <module>]
24-Oct-2019 22:26:37.508 WARNING [Thread-325] org.apache.catalina.servlets.CGIServlet$CGIRunner.sendToLog stderr line: [    print(id[0])]
24-Oct-2019 22:26:37.508 WARNING [Thread-325] org.apache.catalina.servlets.CGIServlet$CGIRunner.sendToLog stderr line: [TypeError: 'builtin_function_or_method' object is not subscriptable]
24-Oct-2019 22:26:37.516 WARNING [Thread-325] org.apache.catalina.servlets.CGIServlet$CGIRunner.sendToLog Received [4] lines on stderr
24-Oct-2019 22:27:29.797 WARNING [Thread-327] org.apache.catalina.servlets.CGIServlet$CGIRunner.sendToLog stderr line: [Traceback (most recent call last):]
24-Oct-2019 22:27:29.798 WARNING [Thread-327] org.apache.catalina.servlets.CGIServlet$CGIRunner.sendToLog stderr line: [  File "C:\Users\hayde\Desktop\UCI\Fall 2019\EECS 118\MP2\apache-tomcat-9.0.26\webapps\test\WEB-INF\cgi\project_3_uploaded.py", line 99, in <module>]
24-Oct-2019 22:27:29.798 WARNING [Thread-327] org.apache.catalina.servlets.CGIServlet$CGIRunner.sendToLog stderr line: [    print(id[0])]
24-Oct-2019 22:27:29.799 WARNING [Thread-327] org.apache.catalina.servlets.CGIServlet$CGIRunner.sendToLog stderr line: [TypeError: 'builtin_function_or_method' object is not subscriptable]
24-Oct-2019 22:27:29.806 WARNING [Thread-327] org.apache.catalina.servlets.CGIServlet$CGIRunner.sendToLog Received [4] lines on stderr
24-Oct-2019 22:32:01.297 WARNING [Thread-332] org.apache.catalina.servlets.CGIServlet$CGIRunner.sendToLog stderr line: [C:\Users\hayde\AppData\Local\Programs\Python\Python36\lib\site-packages\pymysql\cursors.py:170: Warning: (1366, "Incorrect integer value: 'unknown' for column 'year' at row 1")]
24-Oct-2019 22:32:01.298 WARNING [Thread-332] org.apache.catalina.servlets.CGIServlet$CGIRunner.sendToLog stderr line: [  result = self._query(query)]
24-Oct-2019 22:32:01.303 WARNING [Thread-332] org.apache.catalina.servlets.CGIServlet$CGIRunner.sendToLog stderr line: [Traceback (most recent call last):]
24-Oct-2019 22:32:01.303 WARNING [Thread-332] org.apache.catalina.servlets.CGIServlet$CGIRunner.sendToLog stderr line: [  File "C:\Users\hayde\Desktop\UCI\Fall 2019\EECS 118\MP2\apache-tomcat-9.0.26\webapps\test\WEB-INF\cgi\project_3_uploaded.py", line 90, in <module>]
24-Oct-2019 22:32:01.304 WARNING [Thread-332] org.apache.catalina.servlets.CGIServlet$CGIRunner.sendToLog stderr line: [    cur.execute(query, val)]
24-Oct-2019 22:32:01.305 WARNING [Thread-332] org.apache.catalina.servlets.CGIServlet$CGIRunner.sendToLog stderr line: [  File "C:\Users\hayde\AppData\Local\Programs\Python\Python36\lib\site-packages\pymysql\cursors.py", line 170, in execute]
24-Oct-2019 22:32:01.305 WARNING [Thread-332] org.apache.catalina.servlets.CGIServlet$CGIRunner.sendToLog stderr line: [    result = self._query(query)]
24-Oct-2019 22:32:01.306 WARNING [Thread-332] org.apache.catalina.servlets.CGIServlet$CGIRunner.sendToLog stderr line: [  File "C:\Users\hayde\AppData\Local\Programs\Python\Python36\lib\site-packages\pymysql\cursors.py", line 328, in _query]
24-Oct-2019 22:32:01.306 WARNING [Thread-332] org.apache.catalina.servlets.CGIServlet$CGIRunner.sendToLog stderr line: [    conn.query(q)]
24-Oct-2019 22:32:01.307 WARNING [Thread-332] org.apache.catalina.servlets.CGIServlet$CGIRunner.sendToLog stderr line: [  File "C:\Users\hayde\AppData\Local\Programs\Python\Python36\lib\site-packages\pymysql\connections.py", line 517, in query]
24-Oct-2019 22:32:01.307 WARNING [Thread-332] org.apache.catalina.servlets.CGIServlet$CGIRunner.sendToLog stderr line: [    self._affected_rows = self._read_query_result(unbuffered=unbuffered)]
24-Oct-2019 22:32:01.308 WARNING [Thread-332] org.apache.catalina.servlets.CGIServlet$CGIRunner.sendToLog stderr line: [  File "C:\Users\hayde\AppData\Local\Programs\Python\Python36\lib\site-packages\pymysql\connections.py", line 732, in _read_query_result]
24-Oct-2019 22:32:01.308 WARNING [Thread-332] org.apache.catalina.servlets.CGIServlet$CGIRunner.sendToLog stderr line: [    result.read()]
24-Oct-2019 22:32:01.308 WARNING [Thread-332] org.apache.catalina.servlets.CGIServlet$CGIRunner.sendToLog stderr line: [  File "C:\Users\hayde\AppData\Local\Programs\Python\Python36\lib\site-packages\pymysql\connections.py", line 1075, in read]
24-Oct-2019 22:32:01.309 WARNING [Thread-332] org.apache.catalina.servlets.CGIServlet$CGIRunner.sendToLog stderr line: [    first_packet = self.connection._read_packet()]
24-Oct-2019 22:32:01.309 WARNING [Thread-332] org.apache.catalina.servlets.CGIServlet$CGIRunner.sendToLog stderr line: [  File "C:\Users\hayde\AppData\Local\Programs\Python\Python36\lib\site-packages\pymysql\connections.py", line 684, in _read_packet]
24-Oct-2019 22:32:01.309 WARNING [Thread-332] org.apache.catalina.servlets.CGIServlet$CGIRunner.sendToLog stderr line: [    packet.check_error()]
24-Oct-2019 22:32:01.310 WARNING [Thread-332] org.apache.catalina.servlets.CGIServlet$CGIRunner.sendToLog stderr line: [  File "C:\Users\hayde\AppData\Local\Programs\Python\Python36\lib\site-packages\pymysql\protocol.py", line 220, in check_error]
24-Oct-2019 22:32:01.310 WARNING [Thread-332] org.apache.catalina.servlets.CGIServlet$CGIRunner.sendToLog stderr line: [    err.raise_mysql_exception(self._data)]
24-Oct-2019 22:32:01.310 WARNING [Thread-332] org.apache.catalina.servlets.CGIServlet$CGIRunner.sendToLog stderr line: [  File "C:\Users\hayde\AppData\Local\Programs\Python\Python36\lib\site-packages\pymysql\err.py", line 109, in raise_mysql_exception]
24-Oct-2019 22:32:01.311 WARNING [Thread-332] org.apache.catalina.servlets.CGIServlet$CGIRunner.sendToLog stderr line: [    raise errorclass(errno, errval)]
24-Oct-2019 22:32:01.311 WARNING [Thread-332] org.apache.catalina.servlets.CGIServlet$CGIRunner.sendToLog stderr line: [pymysql.err.ProgrammingError: (1064, "You have an error in your SQL syntax; check the manual that corresponds to your MySQL server version for the right syntax to use near 'where detail_id='29' \t\t\tVALUES('4')' at line 1")]
24-Oct-2019 22:32:01.315 WARNING [Thread-332] org.apache.catalina.servlets.CGIServlet$CGIRunner.sendToLog Received [22] lines on stderr
24-Oct-2019 22:36:06.120 WARNING [Thread-334] org.apache.catalina.servlets.CGIServlet$CGIRunner.sendToLog stderr line: [Traceback (most recent call last):]
24-Oct-2019 22:36:06.120 WARNING [Thread-334] org.apache.catalina.servlets.CGIServlet$CGIRunner.sendToLog stderr line: [  File "C:\Users\hayde\Desktop\UCI\Fall 2019\EECS 118\MP2\apache-tomcat-9.0.26\webapps\test\WEB-INF\cgi\project_3_uploaded.py", line 87, in <module>]
24-Oct-2019 22:36:06.121 WARNING [Thread-334] org.apache.catalina.servlets.CGIServlet$CGIRunner.sendToLog stderr line: [    query = "INSERT IGNORE INTO detail(image_id) where detail_id='"+str(max_num_detail[0])+"' \]
24-Oct-2019 22:36:06.121 WARNING [Thread-334] org.apache.catalina.servlets.CGIServlet$CGIRunner.sendToLog stderr line: [NameError: name 'max_num_detail' is not defined]
24-Oct-2019 22:36:06.128 WARNING [Thread-334] org.apache.catalina.servlets.CGIServlet$CGIRunner.sendToLog Received [4] lines on stderr
24-Oct-2019 22:37:25.947 WARNING [Thread-335] org.apache.catalina.servlets.CGIServlet$CGIRunner.sendToLog stderr line: [Traceback (most recent call last):]
24-Oct-2019 22:37:25.948 WARNING [Thread-335] org.apache.catalina.servlets.CGIServlet$CGIRunner.sendToLog stderr line: [  File "C:\Users\hayde\Desktop\UCI\Fall 2019\EECS 118\MP2\apache-tomcat-9.0.26\webapps\test\WEB-INF\cgi\project_3_uploaded.py", line 90, in <module>]
24-Oct-2019 22:37:25.948 WARNING [Thread-335] org.apache.catalina.servlets.CGIServlet$CGIRunner.sendToLog stderr line: [    cur.execute(query, val)]
24-Oct-2019 22:37:25.948 WARNING [Thread-335] org.apache.catalina.servlets.CGIServlet$CGIRunner.sendToLog stderr line: [  File "C:\Users\hayde\AppData\Local\Programs\Python\Python36\lib\site-packages\pymysql\cursors.py", line 170, in execute]
24-Oct-2019 22:37:25.949 WARNING [Thread-335] org.apache.catalina.servlets.CGIServlet$CGIRunner.sendToLog stderr line: [    result = self._query(query)]
24-Oct-2019 22:37:25.949 WARNING [Thread-335] org.apache.catalina.servlets.CGIServlet$CGIRunner.sendToLog stderr line: [  File "C:\Users\hayde\AppData\Local\Programs\Python\Python36\lib\site-packages\pymysql\cursors.py", line 328, in _query]
24-Oct-2019 22:37:25.949 WARNING [Thread-335] org.apache.catalina.servlets.CGIServlet$CGIRunner.sendToLog stderr line: [    conn.query(q)]
24-Oct-2019 22:37:25.949 WARNING [Thread-335] org.apache.catalina.servlets.CGIServlet$CGIRunner.sendToLog stderr line: [  File "C:\Users\hayde\AppData\Local\Programs\Python\Python36\lib\site-packages\pymysql\connections.py", line 517, in query]
24-Oct-2019 22:37:25.950 WARNING [Thread-335] org.apache.catalina.servlets.CGIServlet$CGIRunner.sendToLog stderr line: [    self._affected_rows = self._read_query_result(unbuffered=unbuffered)]
24-Oct-2019 22:37:25.950 WARNING [Thread-335] org.apache.catalina.servlets.CGIServlet$CGIRunner.sendToLog stderr line: [  File "C:\Users\hayde\AppData\Local\Programs\Python\Python36\lib\site-packages\pymysql\connections.py", line 732, in _read_query_result]
24-Oct-2019 22:37:25.950 WARNING [Thread-335] org.apache.catalina.servlets.CGIServlet$CGIRunner.sendToLog stderr line: [    result.read()]
24-Oct-2019 22:37:25.950 WARNING [Thread-335] org.apache.catalina.servlets.CGIServlet$CGIRunner.sendToLog stderr line: [  File "C:\Users\hayde\AppData\Local\Programs\Python\Python36\lib\site-packages\pymysql\connections.py", line 1075, in read]
24-Oct-2019 22:37:25.950 WARNING [Thread-335] org.apache.catalina.servlets.CGIServlet$CGIRunner.sendToLog stderr line: [    first_packet = self.connection._read_packet()]
24-Oct-2019 22:37:25.951 WARNING [Thread-335] org.apache.catalina.servlets.CGIServlet$CGIRunner.sendToLog stderr line: [  File "C:\Users\hayde\AppData\Local\Programs\Python\Python36\lib\site-packages\pymysql\connections.py", line 684, in _read_packet]
24-Oct-2019 22:37:25.951 WARNING [Thread-335] org.apache.catalina.servlets.CGIServlet$CGIRunner.sendToLog stderr line: [    packet.check_error()]
24-Oct-2019 22:37:25.951 WARNING [Thread-335] org.apache.catalina.servlets.CGIServlet$CGIRunner.sendToLog stderr line: [  File "C:\Users\hayde\AppData\Local\Programs\Python\Python36\lib\site-packages\pymysql\protocol.py", line 220, in check_error]
24-Oct-2019 22:37:25.951 WARNING [Thread-335] org.apache.catalina.servlets.CGIServlet$CGIRunner.sendToLog stderr line: [    err.raise_mysql_exception(self._data)]
24-Oct-2019 22:37:25.952 WARNING [Thread-335] org.apache.catalina.servlets.CGIServlet$CGIRunner.sendToLog stderr line: [  File "C:\Users\hayde\AppData\Local\Programs\Python\Python36\lib\site-packages\pymysql\err.py", line 109, in raise_mysql_exception]
24-Oct-2019 22:37:25.952 WARNING [Thread-335] org.apache.catalina.servlets.CGIServlet$CGIRunner.sendToLog stderr line: [    raise errorclass(errno, errval)]
24-Oct-2019 22:37:25.952 WARNING [Thread-335] org.apache.catalina.servlets.CGIServlet$CGIRunner.sendToLog stderr line: [pymysql.err.ProgrammingError: (1064, "You have an error in your SQL syntax; check the manual that corresponds to your MySQL server version for the right syntax to use near 'where detail_id='29' \t\t\tVALUES('4')' at line 1")]
24-Oct-2019 22:37:25.957 WARNING [Thread-335] org.apache.catalina.servlets.CGIServlet$CGIRunner.sendToLog Received [20] lines on stderr
24-Oct-2019 22:40:18.585 WARNING [Thread-338] org.apache.catalina.servlets.CGIServlet$CGIRunner.sendToLog stderr line: [Traceback (most recent call last):]
24-Oct-2019 22:40:18.586 WARNING [Thread-338] org.apache.catalina.servlets.CGIServlet$CGIRunner.sendToLog stderr line: [  File "C:\Users\hayde\Desktop\UCI\Fall 2019\EECS 118\MP2\apache-tomcat-9.0.26\webapps\test\WEB-INF\cgi\project_3_uploaded.py", line 90, in <module>]
24-Oct-2019 22:40:18.586 WARNING [Thread-338] org.apache.catalina.servlets.CGIServlet$CGIRunner.sendToLog stderr line: [    cur.execute(query, val)]
24-Oct-2019 22:40:18.586 WARNING [Thread-338] org.apache.catalina.servlets.CGIServlet$CGIRunner.sendToLog stderr line: [  File "C:\Users\hayde\AppData\Local\Programs\Python\Python36\lib\site-packages\pymysql\cursors.py", line 170, in execute]
24-Oct-2019 22:40:18.587 WARNING [Thread-338] org.apache.catalina.servlets.CGIServlet$CGIRunner.sendToLog stderr line: [    result = self._query(query)]
24-Oct-2019 22:40:18.588 WARNING [Thread-338] org.apache.catalina.servlets.CGIServlet$CGIRunner.sendToLog stderr line: [  File "C:\Users\hayde\AppData\Local\Programs\Python\Python36\lib\site-packages\pymysql\cursors.py", line 328, in _query]
24-Oct-2019 22:40:18.589 WARNING [Thread-338] org.apache.catalina.servlets.CGIServlet$CGIRunner.sendToLog stderr line: [    conn.query(q)]
24-Oct-2019 22:40:18.589 WARNING [Thread-338] org.apache.catalina.servlets.CGIServlet$CGIRunner.sendToLog stderr line: [  File "C:\Users\hayde\AppData\Local\Programs\Python\Python36\lib\site-packages\pymysql\connections.py", line 517, in query]
24-Oct-2019 22:40:18.590 WARNING [Thread-338] org.apache.catalina.servlets.CGIServlet$CGIRunner.sendToLog stderr line: [    self._affected_rows = self._read_query_result(unbuffered=unbuffered)]
24-Oct-2019 22:40:18.590 WARNING [Thread-338] org.apache.catalina.servlets.CGIServlet$CGIRunner.sendToLog stderr line: [  File "C:\Users\hayde\AppData\Local\Programs\Python\Python36\lib\site-packages\pymysql\connections.py", line 732, in _read_query_result]
24-Oct-2019 22:40:18.590 WARNING [Thread-338] org.apache.catalina.servlets.CGIServlet$CGIRunner.sendToLog stderr line: [    result.read()]
24-Oct-2019 22:40:18.591 WARNING [Thread-338] org.apache.catalina.servlets.CGIServlet$CGIRunner.sendToLog stderr line: [  File "C:\Users\hayde\AppData\Local\Programs\Python\Python36\lib\site-packages\pymysql\connections.py", line 1075, in read]
24-Oct-2019 22:40:18.591 WARNING [Thread-338] org.apache.catalina.servlets.CGIServlet$CGIRunner.sendToLog stderr line: [    first_packet = self.connection._read_packet()]
24-Oct-2019 22:40:18.591 WARNING [Thread-338] org.apache.catalina.servlets.CGIServlet$CGIRunner.sendToLog stderr line: [  File "C:\Users\hayde\AppData\Local\Programs\Python\Python36\lib\site-packages\pymysql\connections.py", line 684, in _read_packet]
24-Oct-2019 22:40:18.591 WARNING [Thread-338] org.apache.catalina.servlets.CGIServlet$CGIRunner.sendToLog stderr line: [    packet.check_error()]
24-Oct-2019 22:40:18.592 WARNING [Thread-338] org.apache.catalina.servlets.CGIServlet$CGIRunner.sendToLog stderr line: [  File "C:\Users\hayde\AppData\Local\Programs\Python\Python36\lib\site-packages\pymysql\protocol.py", line 220, in check_error]
24-Oct-2019 22:40:18.592 WARNING [Thread-338] org.apache.catalina.servlets.CGIServlet$CGIRunner.sendToLog stderr line: [    err.raise_mysql_exception(self._data)]
24-Oct-2019 22:40:18.592 WARNING [Thread-338] org.apache.catalina.servlets.CGIServlet$CGIRunner.sendToLog stderr line: [  File "C:\Users\hayde\AppData\Local\Programs\Python\Python36\lib\site-packages\pymysql\err.py", line 109, in raise_mysql_exception]
24-Oct-2019 22:40:18.592 WARNING [Thread-338] org.apache.catalina.servlets.CGIServlet$CGIRunner.sendToLog stderr line: [    raise errorclass(errno, errval)]
24-Oct-2019 22:40:18.593 WARNING [Thread-338] org.apache.catalina.servlets.CGIServlet$CGIRunner.sendToLog stderr line: [pymysql.err.ProgrammingError: (1064, "You have an error in your SQL syntax; check the manual that corresponds to your MySQL server version for the right syntax to use near 'where detail_id='29' \t\t\tVALUES('4')' at line 1")]
24-Oct-2019 22:40:18.596 WARNING [Thread-338] org.apache.catalina.servlets.CGIServlet$CGIRunner.sendToLog Received [20] lines on stderr
24-Oct-2019 22:42:33.838 WARNING [Thread-339] org.apache.catalina.servlets.CGIServlet$CGIRunner.sendToLog stderr line: [Traceback (most recent call last):]
24-Oct-2019 22:42:33.839 WARNING [Thread-339] org.apache.catalina.servlets.CGIServlet$CGIRunner.sendToLog stderr line: [  File "C:\Users\hayde\Desktop\UCI\Fall 2019\EECS 118\MP2\apache-tomcat-9.0.26\webapps\test\WEB-INF\cgi\project_3_uploaded.py", line 90, in <module>]
24-Oct-2019 22:42:33.839 WARNING [Thread-339] org.apache.catalina.servlets.CGIServlet$CGIRunner.sendToLog stderr line: [    cur.execute(query, str(val))]
24-Oct-2019 22:42:33.839 WARNING [Thread-339] org.apache.catalina.servlets.CGIServlet$CGIRunner.sendToLog stderr line: [  File "C:\Users\hayde\AppData\Local\Programs\Python\Python36\lib\site-packages\pymysql\cursors.py", line 170, in execute]
24-Oct-2019 22:42:33.840 WARNING [Thread-339] org.apache.catalina.servlets.CGIServlet$CGIRunner.sendToLog stderr line: [    result = self._query(query)]
24-Oct-2019 22:42:33.840 WARNING [Thread-339] org.apache.catalina.servlets.CGIServlet$CGIRunner.sendToLog stderr line: [  File "C:\Users\hayde\AppData\Local\Programs\Python\Python36\lib\site-packages\pymysql\cursors.py", line 328, in _query]
24-Oct-2019 22:42:33.840 WARNING [Thread-339] org.apache.catalina.servlets.CGIServlet$CGIRunner.sendToLog stderr line: [    conn.query(q)]
24-Oct-2019 22:42:33.841 WARNING [Thread-339] org.apache.catalina.servlets.CGIServlet$CGIRunner.sendToLog stderr line: [  File "C:\Users\hayde\AppData\Local\Programs\Python\Python36\lib\site-packages\pymysql\connections.py", line 517, in query]
24-Oct-2019 22:42:33.841 WARNING [Thread-339] org.apache.catalina.servlets.CGIServlet$CGIRunner.sendToLog stderr line: [    self._affected_rows = self._read_query_result(unbuffered=unbuffered)]
24-Oct-2019 22:42:33.841 WARNING [Thread-339] org.apache.catalina.servlets.CGIServlet$CGIRunner.sendToLog stderr line: [  File "C:\Users\hayde\AppData\Local\Programs\Python\Python36\lib\site-packages\pymysql\connections.py", line 732, in _read_query_result]
24-Oct-2019 22:42:33.841 WARNING [Thread-339] org.apache.catalina.servlets.CGIServlet$CGIRunner.sendToLog stderr line: [    result.read()]
24-Oct-2019 22:42:33.842 WARNING [Thread-339] org.apache.catalina.servlets.CGIServlet$CGIRunner.sendToLog stderr line: [  File "C:\Users\hayde\AppData\Local\Programs\Python\Python36\lib\site-packages\pymysql\connections.py", line 1075, in read]
24-Oct-2019 22:42:33.842 WARNING [Thread-339] org.apache.catalina.servlets.CGIServlet$CGIRunner.sendToLog stderr line: [    first_packet = self.connection._read_packet()]
24-Oct-2019 22:42:33.842 WARNING [Thread-339] org.apache.catalina.servlets.CGIServlet$CGIRunner.sendToLog stderr line: [  File "C:\Users\hayde\AppData\Local\Programs\Python\Python36\lib\site-packages\pymysql\connections.py", line 684, in _read_packet]
24-Oct-2019 22:42:33.842 WARNING [Thread-339] org.apache.catalina.servlets.CGIServlet$CGIRunner.sendToLog stderr line: [    packet.check_error()]
24-Oct-2019 22:42:33.843 WARNING [Thread-339] org.apache.catalina.servlets.CGIServlet$CGIRunner.sendToLog stderr line: [  File "C:\Users\hayde\AppData\Local\Programs\Python\Python36\lib\site-packages\pymysql\protocol.py", line 220, in check_error]
24-Oct-2019 22:42:33.843 WARNING [Thread-339] org.apache.catalina.servlets.CGIServlet$CGIRunner.sendToLog stderr line: [    err.raise_mysql_exception(self._data)]
24-Oct-2019 22:42:33.843 WARNING [Thread-339] org.apache.catalina.servlets.CGIServlet$CGIRunner.sendToLog stderr line: [  File "C:\Users\hayde\AppData\Local\Programs\Python\Python36\lib\site-packages\pymysql\err.py", line 109, in raise_mysql_exception]
24-Oct-2019 22:42:33.844 WARNING [Thread-339] org.apache.catalina.servlets.CGIServlet$CGIRunner.sendToLog stderr line: [    raise errorclass(errno, errval)]
24-Oct-2019 22:42:33.844 WARNING [Thread-339] org.apache.catalina.servlets.CGIServlet$CGIRunner.sendToLog stderr line: [pymysql.err.ProgrammingError: (1064, "You have an error in your SQL syntax; check the manual that corresponds to your MySQL server version for the right syntax to use near 'where detail_id='29' \t\t\tVALUES('4')' at line 1")]
24-Oct-2019 22:42:33.848 WARNING [Thread-339] org.apache.catalina.servlets.CGIServlet$CGIRunner.sendToLog Received [20] lines on stderr
24-Oct-2019 22:44:59.689 WARNING [Thread-341] org.apache.catalina.servlets.CGIServlet$CGIRunner.sendToLog stderr line: [Traceback (most recent call last):]
24-Oct-2019 22:44:59.690 WARNING [Thread-341] org.apache.catalina.servlets.CGIServlet$CGIRunner.sendToLog stderr line: [  File "C:\Users\hayde\Desktop\UCI\Fall 2019\EECS 118\MP2\apache-tomcat-9.0.26\webapps\test\WEB-INF\cgi\project_3_uploaded.py", line 86, in <module>]
24-Oct-2019 22:44:59.690 WARNING [Thread-341] org.apache.catalina.servlets.CGIServlet$CGIRunner.sendToLog stderr line: [    max_num_image = int(max_num_image)]
24-Oct-2019 22:44:59.690 WARNING [Thread-341] org.apache.catalina.servlets.CGIServlet$CGIRunner.sendToLog stderr line: [TypeError: int() argument must be a string, a bytes-like object or a number, not 'tuple']
24-Oct-2019 22:44:59.699 WARNING [Thread-341] org.apache.catalina.servlets.CGIServlet$CGIRunner.sendToLog Received [4] lines on stderr
24-Oct-2019 22:45:17.591 WARNING [Thread-342] org.apache.catalina.servlets.CGIServlet$CGIRunner.sendToLog stderr line: [Traceback (most recent call last):]
24-Oct-2019 22:45:17.591 WARNING [Thread-342] org.apache.catalina.servlets.CGIServlet$CGIRunner.sendToLog stderr line: [  File "C:\Users\hayde\Desktop\UCI\Fall 2019\EECS 118\MP2\apache-tomcat-9.0.26\webapps\test\WEB-INF\cgi\project_3_uploaded.py", line 86, in <module>]
24-Oct-2019 22:45:17.592 WARNING [Thread-342] org.apache.catalina.servlets.CGIServlet$CGIRunner.sendToLog stderr line: [    max_num_image = int(max_num_image)]
24-Oct-2019 22:45:17.592 WARNING [Thread-342] org.apache.catalina.servlets.CGIServlet$CGIRunner.sendToLog stderr line: [TypeError: int() argument must be a string, a bytes-like object or a number, not 'tuple']
24-Oct-2019 22:45:17.599 WARNING [Thread-342] org.apache.catalina.servlets.CGIServlet$CGIRunner.sendToLog Received [4] lines on stderr
24-Oct-2019 22:45:56.479 WARNING [Thread-343] org.apache.catalina.servlets.CGIServlet$CGIRunner.sendToLog stderr line: [Traceback (most recent call last):]
24-Oct-2019 22:45:56.480 WARNING [Thread-343] org.apache.catalina.servlets.CGIServlet$CGIRunner.sendToLog stderr line: [  File "C:\Users\hayde\Desktop\UCI\Fall 2019\EECS 118\MP2\apache-tomcat-9.0.26\webapps\test\WEB-INF\cgi\project_3_uploaded.py", line 86, in <module>]
24-Oct-2019 22:45:56.480 WARNING [Thread-343] org.apache.catalina.servlets.CGIServlet$CGIRunner.sendToLog stderr line: [    max_num_image = int(max_num_image)]
24-Oct-2019 22:45:56.480 WARNING [Thread-343] org.apache.catalina.servlets.CGIServlet$CGIRunner.sendToLog stderr line: [TypeError: int() argument must be a string, a bytes-like object or a number, not 'tuple']
24-Oct-2019 22:45:56.488 WARNING [Thread-343] org.apache.catalina.servlets.CGIServlet$CGIRunner.sendToLog Received [4] lines on stderr
24-Oct-2019 22:46:06.759 WARNING [Thread-344] org.apache.catalina.servlets.CGIServlet$CGIRunner.sendToLog stderr line: [Traceback (most recent call last):]
24-Oct-2019 22:46:06.760 WARNING [Thread-344] org.apache.catalina.servlets.CGIServlet$CGIRunner.sendToLog stderr line: [  File "C:\Users\hayde\Desktop\UCI\Fall 2019\EECS 118\MP2\apache-tomcat-9.0.26\webapps\test\WEB-INF\cgi\project_3_uploaded.py", line 86, in <module>]
24-Oct-2019 22:46:06.760 WARNING [Thread-344] org.apache.catalina.servlets.CGIServlet$CGIRunner.sendToLog stderr line: [    max_num_image = int(max_num_image)]
24-Oct-2019 22:46:06.760 WARNING [Thread-344] org.apache.catalina.servlets.CGIServlet$CGIRunner.sendToLog stderr line: [TypeError: int() argument must be a string, a bytes-like object or a number, not 'tuple']
24-Oct-2019 22:46:06.767 WARNING [Thread-344] org.apache.catalina.servlets.CGIServlet$CGIRunner.sendToLog Received [4] lines on stderr
24-Oct-2019 22:46:43.245 WARNING [Thread-346] org.apache.catalina.servlets.CGIServlet$CGIRunner.sendToLog stderr line: [Traceback (most recent call last):]
24-Oct-2019 22:46:43.245 WARNING [Thread-346] org.apache.catalina.servlets.CGIServlet$CGIRunner.sendToLog stderr line: [  File "C:\Users\hayde\Desktop\UCI\Fall 2019\EECS 118\MP2\apache-tomcat-9.0.26\webapps\test\WEB-INF\cgi\project_3_uploaded.py", line 91, in <module>]
24-Oct-2019 22:46:43.246 WARNING [Thread-346] org.apache.catalina.servlets.CGIServlet$CGIRunner.sendToLog stderr line: [    cur.execute(query, val)]
24-Oct-2019 22:46:43.246 WARNING [Thread-346] org.apache.catalina.servlets.CGIServlet$CGIRunner.sendToLog stderr line: [  File "C:\Users\hayde\AppData\Local\Programs\Python\Python36\lib\site-packages\pymysql\cursors.py", line 170, in execute]
24-Oct-2019 22:46:43.247 WARNING [Thread-346] org.apache.catalina.servlets.CGIServlet$CGIRunner.sendToLog stderr line: [    result = self._query(query)]
24-Oct-2019 22:46:43.247 WARNING [Thread-346] org.apache.catalina.servlets.CGIServlet$CGIRunner.sendToLog stderr line: [  File "C:\Users\hayde\AppData\Local\Programs\Python\Python36\lib\site-packages\pymysql\cursors.py", line 328, in _query]
24-Oct-2019 22:46:43.247 WARNING [Thread-346] org.apache.catalina.servlets.CGIServlet$CGIRunner.sendToLog stderr line: [    conn.query(q)]
24-Oct-2019 22:46:43.248 WARNING [Thread-346] org.apache.catalina.servlets.CGIServlet$CGIRunner.sendToLog stderr line: [  File "C:\Users\hayde\AppData\Local\Programs\Python\Python36\lib\site-packages\pymysql\connections.py", line 517, in query]
24-Oct-2019 22:46:43.248 WARNING [Thread-346] org.apache.catalina.servlets.CGIServlet$CGIRunner.sendToLog stderr line: [    self._affected_rows = self._read_query_result(unbuffered=unbuffered)]
24-Oct-2019 22:46:43.248 WARNING [Thread-346] org.apache.catalina.servlets.CGIServlet$CGIRunner.sendToLog stderr line: [  File "C:\Users\hayde\AppData\Local\Programs\Python\Python36\lib\site-packages\pymysql\connections.py", line 732, in _read_query_result]
24-Oct-2019 22:46:43.248 WARNING [Thread-346] org.apache.catalina.servlets.CGIServlet$CGIRunner.sendToLog stderr line: [    result.read()]
24-Oct-2019 22:46:43.248 WARNING [Thread-346] org.apache.catalina.servlets.CGIServlet$CGIRunner.sendToLog stderr line: [  File "C:\Users\hayde\AppData\Local\Programs\Python\Python36\lib\site-packages\pymysql\connections.py", line 1075, in read]
24-Oct-2019 22:46:43.249 WARNING [Thread-346] org.apache.catalina.servlets.CGIServlet$CGIRunner.sendToLog stderr line: [    first_packet = self.connection._read_packet()]
24-Oct-2019 22:46:43.249 WARNING [Thread-346] org.apache.catalina.servlets.CGIServlet$CGIRunner.sendToLog stderr line: [  File "C:\Users\hayde\AppData\Local\Programs\Python\Python36\lib\site-packages\pymysql\connections.py", line 684, in _read_packet]
24-Oct-2019 22:46:43.249 WARNING [Thread-346] org.apache.catalina.servlets.CGIServlet$CGIRunner.sendToLog stderr line: [    packet.check_error()]
24-Oct-2019 22:46:43.249 WARNING [Thread-346] org.apache.catalina.servlets.CGIServlet$CGIRunner.sendToLog stderr line: [  File "C:\Users\hayde\AppData\Local\Programs\Python\Python36\lib\site-packages\pymysql\protocol.py", line 220, in check_error]
24-Oct-2019 22:46:43.250 WARNING [Thread-346] org.apache.catalina.servlets.CGIServlet$CGIRunner.sendToLog stderr line: [    err.raise_mysql_exception(self._data)]
24-Oct-2019 22:46:43.250 WARNING [Thread-346] org.apache.catalina.servlets.CGIServlet$CGIRunner.sendToLog stderr line: [  File "C:\Users\hayde\AppData\Local\Programs\Python\Python36\lib\site-packages\pymysql\err.py", line 109, in raise_mysql_exception]
24-Oct-2019 22:46:43.250 WARNING [Thread-346] org.apache.catalina.servlets.CGIServlet$CGIRunner.sendToLog stderr line: [    raise errorclass(errno, errval)]
24-Oct-2019 22:46:43.250 WARNING [Thread-346] org.apache.catalina.servlets.CGIServlet$CGIRunner.sendToLog stderr line: [pymysql.err.ProgrammingError: (1064, "You have an error in your SQL syntax; check the manual that corresponds to your MySQL server version for the right syntax to use near 'where detail_id='29' \t\t\tVALUES('4')' at line 1")]
24-Oct-2019 22:46:43.256 WARNING [Thread-346] org.apache.catalina.servlets.CGIServlet$CGIRunner.sendToLog Received [20] lines on stderr
24-Oct-2019 22:47:04.912 WARNING [Thread-347] org.apache.catalina.servlets.CGIServlet$CGIRunner.sendToLog stderr line: [  File "C:\Users\hayde\Desktop\UCI\Fall 2019\EECS 118\MP2\apache-tomcat-9.0.26\webapps\test\WEB-INF\cgi\project_3_uploaded.py", line 94]
24-Oct-2019 22:47:04.912 WARNING [Thread-347] org.apache.catalina.servlets.CGIServlet$CGIRunner.sendToLog stderr line: [    db.close()]
24-Oct-2019 22:47:04.913 WARNING [Thread-347] org.apache.catalina.servlets.CGIServlet$CGIRunner.sendToLog stderr line: [     ^]
24-Oct-2019 22:47:04.913 WARNING [Thread-347] org.apache.catalina.servlets.CGIServlet$CGIRunner.sendToLog stderr line: [SyntaxError: invalid syntax]
24-Oct-2019 22:47:04.916 WARNING [Thread-347] org.apache.catalina.servlets.CGIServlet$CGIRunner.sendToLog Received [4] lines on stderr
24-Oct-2019 22:47:11.124 WARNING [Thread-348] org.apache.catalina.servlets.CGIServlet$CGIRunner.sendToLog stderr line: [  File "C:\Users\hayde\Desktop\UCI\Fall 2019\EECS 118\MP2\apache-tomcat-9.0.26\webapps\test\WEB-INF\cgi\project_3_uploaded.py", line 92]
24-Oct-2019 22:47:11.124 WARNING [Thread-348] org.apache.catalina.servlets.CGIServlet$CGIRunner.sendToLog stderr line: [    db.commit()]
24-Oct-2019 22:47:11.125 WARNING [Thread-348] org.apache.catalina.servlets.CGIServlet$CGIRunner.sendToLog stderr line: [     ^]
24-Oct-2019 22:47:11.125 WARNING [Thread-348] org.apache.catalina.servlets.CGIServlet$CGIRunner.sendToLog stderr line: [SyntaxError: invalid syntax]
24-Oct-2019 22:47:11.127 WARNING [Thread-348] org.apache.catalina.servlets.CGIServlet$CGIRunner.sendToLog Received [4] lines on stderr
24-Oct-2019 22:47:27.406 WARNING [Thread-349] org.apache.catalina.servlets.CGIServlet$CGIRunner.sendToLog stderr line: [Traceback (most recent call last):]
24-Oct-2019 22:47:27.407 WARNING [Thread-349] org.apache.catalina.servlets.CGIServlet$CGIRunner.sendToLog stderr line: [  File "C:\Users\hayde\Desktop\UCI\Fall 2019\EECS 118\MP2\apache-tomcat-9.0.26\webapps\test\WEB-INF\cgi\project_3_uploaded.py", line 91, in <module>]
24-Oct-2019 22:47:27.407 WARNING [Thread-349] org.apache.catalina.servlets.CGIServlet$CGIRunner.sendToLog stderr line: [    cur.execute(query, str(max_num_image))]
24-Oct-2019 22:47:27.408 WARNING [Thread-349] org.apache.catalina.servlets.CGIServlet$CGIRunner.sendToLog stderr line: [  File "C:\Users\hayde\AppData\Local\Programs\Python\Python36\lib\site-packages\pymysql\cursors.py", line 170, in execute]
24-Oct-2019 22:47:27.408 WARNING [Thread-349] org.apache.catalina.servlets.CGIServlet$CGIRunner.sendToLog stderr line: [    result = self._query(query)]
24-Oct-2019 22:47:27.408 WARNING [Thread-349] org.apache.catalina.servlets.CGIServlet$CGIRunner.sendToLog stderr line: [  File "C:\Users\hayde\AppData\Local\Programs\Python\Python36\lib\site-packages\pymysql\cursors.py", line 328, in _query]
24-Oct-2019 22:47:27.409 WARNING [Thread-349] org.apache.catalina.servlets.CGIServlet$CGIRunner.sendToLog stderr line: [    conn.query(q)]
24-Oct-2019 22:47:27.409 WARNING [Thread-349] org.apache.catalina.servlets.CGIServlet$CGIRunner.sendToLog stderr line: [  File "C:\Users\hayde\AppData\Local\Programs\Python\Python36\lib\site-packages\pymysql\connections.py", line 517, in query]
24-Oct-2019 22:47:27.410 WARNING [Thread-349] org.apache.catalina.servlets.CGIServlet$CGIRunner.sendToLog stderr line: [    self._affected_rows = self._read_query_result(unbuffered=unbuffered)]
24-Oct-2019 22:47:27.410 WARNING [Thread-349] org.apache.catalina.servlets.CGIServlet$CGIRunner.sendToLog stderr line: [  File "C:\Users\hayde\AppData\Local\Programs\Python\Python36\lib\site-packages\pymysql\connections.py", line 732, in _read_query_result]
24-Oct-2019 22:47:27.410 WARNING [Thread-349] org.apache.catalina.servlets.CGIServlet$CGIRunner.sendToLog stderr line: [    result.read()]
24-Oct-2019 22:47:27.411 WARNING [Thread-349] org.apache.catalina.servlets.CGIServlet$CGIRunner.sendToLog stderr line: [  File "C:\Users\hayde\AppData\Local\Programs\Python\Python36\lib\site-packages\pymysql\connections.py", line 1075, in read]
24-Oct-2019 22:47:27.411 WARNING [Thread-349] org.apache.catalina.servlets.CGIServlet$CGIRunner.sendToLog stderr line: [    first_packet = self.connection._read_packet()]
24-Oct-2019 22:47:27.411 WARNING [Thread-349] org.apache.catalina.servlets.CGIServlet$CGIRunner.sendToLog stderr line: [  File "C:\Users\hayde\AppData\Local\Programs\Python\Python36\lib\site-packages\pymysql\connections.py", line 684, in _read_packet]
24-Oct-2019 22:47:27.411 WARNING [Thread-349] org.apache.catalina.servlets.CGIServlet$CGIRunner.sendToLog stderr line: [    packet.check_error()]
24-Oct-2019 22:47:27.411 WARNING [Thread-349] org.apache.catalina.servlets.CGIServlet$CGIRunner.sendToLog stderr line: [  File "C:\Users\hayde\AppData\Local\Programs\Python\Python36\lib\site-packages\pymysql\protocol.py", line 220, in check_error]
24-Oct-2019 22:47:27.411 WARNING [Thread-349] org.apache.catalina.servlets.CGIServlet$CGIRunner.sendToLog stderr line: [    err.raise_mysql_exception(self._data)]
24-Oct-2019 22:47:27.411 WARNING [Thread-349] org.apache.catalina.servlets.CGIServlet$CGIRunner.sendToLog stderr line: [  File "C:\Users\hayde\AppData\Local\Programs\Python\Python36\lib\site-packages\pymysql\err.py", line 109, in raise_mysql_exception]
24-Oct-2019 22:47:27.411 WARNING [Thread-349] org.apache.catalina.servlets.CGIServlet$CGIRunner.sendToLog stderr line: [    raise errorclass(errno, errval)]
24-Oct-2019 22:47:27.411 WARNING [Thread-349] org.apache.catalina.servlets.CGIServlet$CGIRunner.sendToLog stderr line: [pymysql.err.ProgrammingError: (1064, "You have an error in your SQL syntax; check the manual that corresponds to your MySQL server version for the right syntax to use near 'where detail_id='29' \t\t\tVALUES('4')' at line 1")]
24-Oct-2019 22:47:27.416 WARNING [Thread-349] org.apache.catalina.servlets.CGIServlet$CGIRunner.sendToLog Received [20] lines on stderr
24-Oct-2019 22:47:32.989 WARNING [Thread-350] org.apache.catalina.servlets.CGIServlet$CGIRunner.sendToLog stderr line: [Traceback (most recent call last):]
24-Oct-2019 22:47:32.989 WARNING [Thread-350] org.apache.catalina.servlets.CGIServlet$CGIRunner.sendToLog stderr line: [  File "C:\Users\hayde\Desktop\UCI\Fall 2019\EECS 118\MP2\apache-tomcat-9.0.26\webapps\test\WEB-INF\cgi\project_3_uploaded.py", line 91, in <module>]
24-Oct-2019 22:47:32.990 WARNING [Thread-350] org.apache.catalina.servlets.CGIServlet$CGIRunner.sendToLog stderr line: [    cur.execute(query, str(max_num_image))]
24-Oct-2019 22:47:32.990 WARNING [Thread-350] org.apache.catalina.servlets.CGIServlet$CGIRunner.sendToLog stderr line: [  File "C:\Users\hayde\AppData\Local\Programs\Python\Python36\lib\site-packages\pymysql\cursors.py", line 170, in execute]
24-Oct-2019 22:47:32.990 WARNING [Thread-350] org.apache.catalina.servlets.CGIServlet$CGIRunner.sendToLog stderr line: [    result = self._query(query)]
24-Oct-2019 22:47:32.991 WARNING [Thread-350] org.apache.catalina.servlets.CGIServlet$CGIRunner.sendToLog stderr line: [  File "C:\Users\hayde\AppData\Local\Programs\Python\Python36\lib\site-packages\pymysql\cursors.py", line 328, in _query]
24-Oct-2019 22:47:32.991 WARNING [Thread-350] org.apache.catalina.servlets.CGIServlet$CGIRunner.sendToLog stderr line: [    conn.query(q)]
24-Oct-2019 22:47:32.991 WARNING [Thread-350] org.apache.catalina.servlets.CGIServlet$CGIRunner.sendToLog stderr line: [  File "C:\Users\hayde\AppData\Local\Programs\Python\Python36\lib\site-packages\pymysql\connections.py", line 517, in query]
24-Oct-2019 22:47:32.991 WARNING [Thread-350] org.apache.catalina.servlets.CGIServlet$CGIRunner.sendToLog stderr line: [    self._affected_rows = self._read_query_result(unbuffered=unbuffered)]
24-Oct-2019 22:47:32.992 WARNING [Thread-350] org.apache.catalina.servlets.CGIServlet$CGIRunner.sendToLog stderr line: [  File "C:\Users\hayde\AppData\Local\Programs\Python\Python36\lib\site-packages\pymysql\connections.py", line 732, in _read_query_result]
24-Oct-2019 22:47:32.992 WARNING [Thread-350] org.apache.catalina.servlets.CGIServlet$CGIRunner.sendToLog stderr line: [    result.read()]
24-Oct-2019 22:47:32.992 WARNING [Thread-350] org.apache.catalina.servlets.CGIServlet$CGIRunner.sendToLog stderr line: [  File "C:\Users\hayde\AppData\Local\Programs\Python\Python36\lib\site-packages\pymysql\connections.py", line 1075, in read]
24-Oct-2019 22:47:32.993 WARNING [Thread-350] org.apache.catalina.servlets.CGIServlet$CGIRunner.sendToLog stderr line: [    first_packet = self.connection._read_packet()]
24-Oct-2019 22:47:32.993 WARNING [Thread-350] org.apache.catalina.servlets.CGIServlet$CGIRunner.sendToLog stderr line: [  File "C:\Users\hayde\AppData\Local\Programs\Python\Python36\lib\site-packages\pymysql\connections.py", line 684, in _read_packet]
24-Oct-2019 22:47:32.993 WARNING [Thread-350] org.apache.catalina.servlets.CGIServlet$CGIRunner.sendToLog stderr line: [    packet.check_error()]
24-Oct-2019 22:47:32.993 WARNING [Thread-350] org.apache.catalina.servlets.CGIServlet$CGIRunner.sendToLog stderr line: [  File "C:\Users\hayde\AppData\Local\Programs\Python\Python36\lib\site-packages\pymysql\protocol.py", line 220, in check_error]
24-Oct-2019 22:47:32.994 WARNING [Thread-350] org.apache.catalina.servlets.CGIServlet$CGIRunner.sendToLog stderr line: [    err.raise_mysql_exception(self._data)]
24-Oct-2019 22:47:32.994 WARNING [Thread-350] org.apache.catalina.servlets.CGIServlet$CGIRunner.sendToLog stderr line: [  File "C:\Users\hayde\AppData\Local\Programs\Python\Python36\lib\site-packages\pymysql\err.py", line 109, in raise_mysql_exception]
24-Oct-2019 22:47:32.994 WARNING [Thread-350] org.apache.catalina.servlets.CGIServlet$CGIRunner.sendToLog stderr line: [    raise errorclass(errno, errval)]
24-Oct-2019 22:47:32.995 WARNING [Thread-350] org.apache.catalina.servlets.CGIServlet$CGIRunner.sendToLog stderr line: [pymysql.err.ProgrammingError: (1064, "You have an error in your SQL syntax; check the manual that corresponds to your MySQL server version for the right syntax to use near 'where detail_id='29' \t\t\tVALUES('4')' at line 1")]
24-Oct-2019 22:47:33.000 WARNING [Thread-350] org.apache.catalina.servlets.CGIServlet$CGIRunner.sendToLog Received [20] lines on stderr
24-Oct-2019 22:47:44.894 WARNING [Thread-351] org.apache.catalina.servlets.CGIServlet$CGIRunner.sendToLog stderr line: [Traceback (most recent call last):]
24-Oct-2019 22:47:44.894 WARNING [Thread-351] org.apache.catalina.servlets.CGIServlet$CGIRunner.sendToLog stderr line: [  File "C:\Users\hayde\Desktop\UCI\Fall 2019\EECS 118\MP2\apache-tomcat-9.0.26\webapps\test\WEB-INF\cgi\project_3_uploaded.py", line 91, in <module>]
24-Oct-2019 22:47:44.895 WARNING [Thread-351] org.apache.catalina.servlets.CGIServlet$CGIRunner.sendToLog stderr line: [    cur.execute(query, 1)]
24-Oct-2019 22:47:44.895 WARNING [Thread-351] org.apache.catalina.servlets.CGIServlet$CGIRunner.sendToLog stderr line: [  File "C:\Users\hayde\AppData\Local\Programs\Python\Python36\lib\site-packages\pymysql\cursors.py", line 170, in execute]
24-Oct-2019 22:47:44.895 WARNING [Thread-351] org.apache.catalina.servlets.CGIServlet$CGIRunner.sendToLog stderr line: [    result = self._query(query)]
24-Oct-2019 22:47:44.896 WARNING [Thread-351] org.apache.catalina.servlets.CGIServlet$CGIRunner.sendToLog stderr line: [  File "C:\Users\hayde\AppData\Local\Programs\Python\Python36\lib\site-packages\pymysql\cursors.py", line 328, in _query]
24-Oct-2019 22:47:44.896 WARNING [Thread-351] org.apache.catalina.servlets.CGIServlet$CGIRunner.sendToLog stderr line: [    conn.query(q)]
24-Oct-2019 22:47:44.896 WARNING [Thread-351] org.apache.catalina.servlets.CGIServlet$CGIRunner.sendToLog stderr line: [  File "C:\Users\hayde\AppData\Local\Programs\Python\Python36\lib\site-packages\pymysql\connections.py", line 517, in query]
24-Oct-2019 22:47:44.896 WARNING [Thread-351] org.apache.catalina.servlets.CGIServlet$CGIRunner.sendToLog stderr line: [    self._affected_rows = self._read_query_result(unbuffered=unbuffered)]
24-Oct-2019 22:47:44.897 WARNING [Thread-351] org.apache.catalina.servlets.CGIServlet$CGIRunner.sendToLog stderr line: [  File "C:\Users\hayde\AppData\Local\Programs\Python\Python36\lib\site-packages\pymysql\connections.py", line 732, in _read_query_result]
24-Oct-2019 22:47:44.897 WARNING [Thread-351] org.apache.catalina.servlets.CGIServlet$CGIRunner.sendToLog stderr line: [    result.read()]
24-Oct-2019 22:47:44.897 WARNING [Thread-351] org.apache.catalina.servlets.CGIServlet$CGIRunner.sendToLog stderr line: [  File "C:\Users\hayde\AppData\Local\Programs\Python\Python36\lib\site-packages\pymysql\connections.py", line 1075, in read]
24-Oct-2019 22:47:44.897 WARNING [Thread-351] org.apache.catalina.servlets.CGIServlet$CGIRunner.sendToLog stderr line: [    first_packet = self.connection._read_packet()]
24-Oct-2019 22:47:44.898 WARNING [Thread-351] org.apache.catalina.servlets.CGIServlet$CGIRunner.sendToLog stderr line: [  File "C:\Users\hayde\AppData\Local\Programs\Python\Python36\lib\site-packages\pymysql\connections.py", line 684, in _read_packet]
24-Oct-2019 22:47:44.898 WARNING [Thread-351] org.apache.catalina.servlets.CGIServlet$CGIRunner.sendToLog stderr line: [    packet.check_error()]
24-Oct-2019 22:47:44.898 WARNING [Thread-351] org.apache.catalina.servlets.CGIServlet$CGIRunner.sendToLog stderr line: [  File "C:\Users\hayde\AppData\Local\Programs\Python\Python36\lib\site-packages\pymysql\protocol.py", line 220, in check_error]
24-Oct-2019 22:47:44.898 WARNING [Thread-351] org.apache.catalina.servlets.CGIServlet$CGIRunner.sendToLog stderr line: [    err.raise_mysql_exception(self._data)]
24-Oct-2019 22:47:44.899 WARNING [Thread-351] org.apache.catalina.servlets.CGIServlet$CGIRunner.sendToLog stderr line: [  File "C:\Users\hayde\AppData\Local\Programs\Python\Python36\lib\site-packages\pymysql\err.py", line 109, in raise_mysql_exception]
24-Oct-2019 22:47:44.899 WARNING [Thread-351] org.apache.catalina.servlets.CGIServlet$CGIRunner.sendToLog stderr line: [    raise errorclass(errno, errval)]
24-Oct-2019 22:47:44.899 WARNING [Thread-351] org.apache.catalina.servlets.CGIServlet$CGIRunner.sendToLog stderr line: [pymysql.err.ProgrammingError: (1064, "You have an error in your SQL syntax; check the manual that corresponds to your MySQL server version for the right syntax to use near 'where detail_id='29' \t\t\tVALUES(1)' at line 1")]
24-Oct-2019 22:47:44.903 WARNING [Thread-351] org.apache.catalina.servlets.CGIServlet$CGIRunner.sendToLog Received [20] lines on stderr
24-Oct-2019 22:47:55.320 WARNING [Thread-352] org.apache.catalina.servlets.CGIServlet$CGIRunner.sendToLog stderr line: [Traceback (most recent call last):]
24-Oct-2019 22:47:55.320 WARNING [Thread-352] org.apache.catalina.servlets.CGIServlet$CGIRunner.sendToLog stderr line: [  File "C:\Users\hayde\Desktop\UCI\Fall 2019\EECS 118\MP2\apache-tomcat-9.0.26\webapps\test\WEB-INF\cgi\project_3_uploaded.py", line 91, in <module>]
24-Oct-2019 22:47:55.321 WARNING [Thread-352] org.apache.catalina.servlets.CGIServlet$CGIRunner.sendToLog stderr line: [    cur.execute(query, '1')]
24-Oct-2019 22:47:55.321 WARNING [Thread-352] org.apache.catalina.servlets.CGIServlet$CGIRunner.sendToLog stderr line: [  File "C:\Users\hayde\AppData\Local\Programs\Python\Python36\lib\site-packages\pymysql\cursors.py", line 170, in execute]
24-Oct-2019 22:47:55.321 WARNING [Thread-352] org.apache.catalina.servlets.CGIServlet$CGIRunner.sendToLog stderr line: [    result = self._query(query)]
24-Oct-2019 22:47:55.322 WARNING [Thread-352] org.apache.catalina.servlets.CGIServlet$CGIRunner.sendToLog stderr line: [  File "C:\Users\hayde\AppData\Local\Programs\Python\Python36\lib\site-packages\pymysql\cursors.py", line 328, in _query]
24-Oct-2019 22:47:55.322 WARNING [Thread-352] org.apache.catalina.servlets.CGIServlet$CGIRunner.sendToLog stderr line: [    conn.query(q)]
24-Oct-2019 22:47:55.322 WARNING [Thread-352] org.apache.catalina.servlets.CGIServlet$CGIRunner.sendToLog stderr line: [  File "C:\Users\hayde\AppData\Local\Programs\Python\Python36\lib\site-packages\pymysql\connections.py", line 517, in query]
24-Oct-2019 22:47:55.323 WARNING [Thread-352] org.apache.catalina.servlets.CGIServlet$CGIRunner.sendToLog stderr line: [    self._affected_rows = self._read_query_result(unbuffered=unbuffered)]
24-Oct-2019 22:47:55.323 WARNING [Thread-352] org.apache.catalina.servlets.CGIServlet$CGIRunner.sendToLog stderr line: [  File "C:\Users\hayde\AppData\Local\Programs\Python\Python36\lib\site-packages\pymysql\connections.py", line 732, in _read_query_result]
24-Oct-2019 22:47:55.323 WARNING [Thread-352] org.apache.catalina.servlets.CGIServlet$CGIRunner.sendToLog stderr line: [    result.read()]
24-Oct-2019 22:47:55.323 WARNING [Thread-352] org.apache.catalina.servlets.CGIServlet$CGIRunner.sendToLog stderr line: [  File "C:\Users\hayde\AppData\Local\Programs\Python\Python36\lib\site-packages\pymysql\connections.py", line 1075, in read]
24-Oct-2019 22:47:55.323 WARNING [Thread-352] org.apache.catalina.servlets.CGIServlet$CGIRunner.sendToLog stderr line: [    first_packet = self.connection._read_packet()]
24-Oct-2019 22:47:55.324 WARNING [Thread-352] org.apache.catalina.servlets.CGIServlet$CGIRunner.sendToLog stderr line: [  File "C:\Users\hayde\AppData\Local\Programs\Python\Python36\lib\site-packages\pymysql\connections.py", line 684, in _read_packet]
24-Oct-2019 22:47:55.324 WARNING [Thread-352] org.apache.catalina.servlets.CGIServlet$CGIRunner.sendToLog stderr line: [    packet.check_error()]
24-Oct-2019 22:47:55.324 WARNING [Thread-352] org.apache.catalina.servlets.CGIServlet$CGIRunner.sendToLog stderr line: [  File "C:\Users\hayde\AppData\Local\Programs\Python\Python36\lib\site-packages\pymysql\protocol.py", line 220, in check_error]
24-Oct-2019 22:47:55.324 WARNING [Thread-352] org.apache.catalina.servlets.CGIServlet$CGIRunner.sendToLog stderr line: [    err.raise_mysql_exception(self._data)]
24-Oct-2019 22:47:55.325 WARNING [Thread-352] org.apache.catalina.servlets.CGIServlet$CGIRunner.sendToLog stderr line: [  File "C:\Users\hayde\AppData\Local\Programs\Python\Python36\lib\site-packages\pymysql\err.py", line 109, in raise_mysql_exception]
24-Oct-2019 22:47:55.325 WARNING [Thread-352] org.apache.catalina.servlets.CGIServlet$CGIRunner.sendToLog stderr line: [    raise errorclass(errno, errval)]
24-Oct-2019 22:47:55.325 WARNING [Thread-352] org.apache.catalina.servlets.CGIServlet$CGIRunner.sendToLog stderr line: [pymysql.err.ProgrammingError: (1064, "You have an error in your SQL syntax; check the manual that corresponds to your MySQL server version for the right syntax to use near 'where detail_id='29' \t\t\tVALUES('1')' at line 1")]
24-Oct-2019 22:47:55.335 WARNING [Thread-352] org.apache.catalina.servlets.CGIServlet$CGIRunner.sendToLog Received [20] lines on stderr
24-Oct-2019 22:48:03.838 WARNING [Thread-353] org.apache.catalina.servlets.CGIServlet$CGIRunner.sendToLog stderr line: [Traceback (most recent call last):]
24-Oct-2019 22:48:03.838 WARNING [Thread-353] org.apache.catalina.servlets.CGIServlet$CGIRunner.sendToLog stderr line: [  File "C:\Users\hayde\Desktop\UCI\Fall 2019\EECS 118\MP2\apache-tomcat-9.0.26\webapps\test\WEB-INF\cgi\project_3_uploaded.py", line 91, in <module>]
24-Oct-2019 22:48:03.839 WARNING [Thread-353] org.apache.catalina.servlets.CGIServlet$CGIRunner.sendToLog stderr line: [    cur.execute(query, '1')]
24-Oct-2019 22:48:03.839 WARNING [Thread-353] org.apache.catalina.servlets.CGIServlet$CGIRunner.sendToLog stderr line: [  File "C:\Users\hayde\AppData\Local\Programs\Python\Python36\lib\site-packages\pymysql\cursors.py", line 170, in execute]
24-Oct-2019 22:48:03.839 WARNING [Thread-353] org.apache.catalina.servlets.CGIServlet$CGIRunner.sendToLog stderr line: [    result = self._query(query)]
24-Oct-2019 22:48:03.839 WARNING [Thread-353] org.apache.catalina.servlets.CGIServlet$CGIRunner.sendToLog stderr line: [  File "C:\Users\hayde\AppData\Local\Programs\Python\Python36\lib\site-packages\pymysql\cursors.py", line 328, in _query]
24-Oct-2019 22:48:03.840 WARNING [Thread-353] org.apache.catalina.servlets.CGIServlet$CGIRunner.sendToLog stderr line: [    conn.query(q)]
24-Oct-2019 22:48:03.840 WARNING [Thread-353] org.apache.catalina.servlets.CGIServlet$CGIRunner.sendToLog stderr line: [  File "C:\Users\hayde\AppData\Local\Programs\Python\Python36\lib\site-packages\pymysql\connections.py", line 517, in query]
24-Oct-2019 22:48:03.841 WARNING [Thread-353] org.apache.catalina.servlets.CGIServlet$CGIRunner.sendToLog stderr line: [    self._affected_rows = self._read_query_result(unbuffered=unbuffered)]
24-Oct-2019 22:48:03.841 WARNING [Thread-353] org.apache.catalina.servlets.CGIServlet$CGIRunner.sendToLog stderr line: [  File "C:\Users\hayde\AppData\Local\Programs\Python\Python36\lib\site-packages\pymysql\connections.py", line 732, in _read_query_result]
24-Oct-2019 22:48:03.841 WARNING [Thread-353] org.apache.catalina.servlets.CGIServlet$CGIRunner.sendToLog stderr line: [    result.read()]
24-Oct-2019 22:48:03.841 WARNING [Thread-353] org.apache.catalina.servlets.CGIServlet$CGIRunner.sendToLog stderr line: [  File "C:\Users\hayde\AppData\Local\Programs\Python\Python36\lib\site-packages\pymysql\connections.py", line 1075, in read]
24-Oct-2019 22:48:03.842 WARNING [Thread-353] org.apache.catalina.servlets.CGIServlet$CGIRunner.sendToLog stderr line: [    first_packet = self.connection._read_packet()]
24-Oct-2019 22:48:03.842 WARNING [Thread-353] org.apache.catalina.servlets.CGIServlet$CGIRunner.sendToLog stderr line: [  File "C:\Users\hayde\AppData\Local\Programs\Python\Python36\lib\site-packages\pymysql\connections.py", line 684, in _read_packet]
24-Oct-2019 22:48:03.842 WARNING [Thread-353] org.apache.catalina.servlets.CGIServlet$CGIRunner.sendToLog stderr line: [    packet.check_error()]
24-Oct-2019 22:48:03.842 WARNING [Thread-353] org.apache.catalina.servlets.CGIServlet$CGIRunner.sendToLog stderr line: [  File "C:\Users\hayde\AppData\Local\Programs\Python\Python36\lib\site-packages\pymysql\protocol.py", line 220, in check_error]
24-Oct-2019 22:48:03.843 WARNING [Thread-353] org.apache.catalina.servlets.CGIServlet$CGIRunner.sendToLog stderr line: [    err.raise_mysql_exception(self._data)]
24-Oct-2019 22:48:03.843 WARNING [Thread-353] org.apache.catalina.servlets.CGIServlet$CGIRunner.sendToLog stderr line: [  File "C:\Users\hayde\AppData\Local\Programs\Python\Python36\lib\site-packages\pymysql\err.py", line 109, in raise_mysql_exception]
24-Oct-2019 22:48:03.843 WARNING [Thread-353] org.apache.catalina.servlets.CGIServlet$CGIRunner.sendToLog stderr line: [    raise errorclass(errno, errval)]
24-Oct-2019 22:48:03.843 WARNING [Thread-353] org.apache.catalina.servlets.CGIServlet$CGIRunner.sendToLog stderr line: [pymysql.err.ProgrammingError: (1064, "You have an error in your SQL syntax; check the manual that corresponds to your MySQL server version for the right syntax to use near 'where detail_id='29' \t\t\tVALUES('1')' at line 1")]
24-Oct-2019 22:48:03.847 WARNING [Thread-353] org.apache.catalina.servlets.CGIServlet$CGIRunner.sendToLog Received [20] lines on stderr
24-Oct-2019 22:56:56.202 WARNING [Thread-357] org.apache.catalina.servlets.CGIServlet$CGIRunner.sendToLog stderr line: [Traceback (most recent call last):]
24-Oct-2019 22:56:56.202 WARNING [Thread-357] org.apache.catalina.servlets.CGIServlet$CGIRunner.sendToLog stderr line: [  File "C:\Users\hayde\Desktop\UCI\Fall 2019\EECS 118\MP2\apache-tomcat-9.0.26\webapps\test\WEB-INF\cgi\project_3_uploaded.py", line 65, in <module>]
24-Oct-2019 22:56:56.202 WARNING [Thread-357] org.apache.catalina.servlets.CGIServlet$CGIRunner.sendToLog stderr line: [    val = (year, type, width, height, location, description)]
24-Oct-2019 22:56:56.203 WARNING [Thread-357] org.apache.catalina.servlets.CGIServlet$CGIRunner.sendToLog stderr line: [NameError: name 'year' is not defined]
24-Oct-2019 22:56:56.210 WARNING [Thread-357] org.apache.catalina.servlets.CGIServlet$CGIRunner.sendToLog Received [4] lines on stderr
24-Oct-2019 23:02:40.461 WARNING [Thread-363] org.apache.catalina.servlets.CGIServlet$CGIRunner.sendToLog stderr line: [Traceback (most recent call last):]
24-Oct-2019 23:02:40.462 WARNING [Thread-363] org.apache.catalina.servlets.CGIServlet$CGIRunner.sendToLog stderr line: [  File "C:\Users\hayde\Desktop\UCI\Fall 2019\EECS 118\MP2\apache-tomcat-9.0.26\webapps\test\WEB-INF\cgi\project_3_gallery1.py", line 68, in <module>]
24-Oct-2019 23:02:40.462 WARNING [Thread-363] org.apache.catalina.servlets.CGIServlet$CGIRunner.sendToLog stderr line: [    query = "select*from image where link='"+gal_1_img[i][0]+"'"]
24-Oct-2019 23:02:40.463 WARNING [Thread-363] org.apache.catalina.servlets.CGIServlet$CGIRunner.sendToLog stderr line: [IndexError: tuple index out of range]
24-Oct-2019 23:02:40.470 WARNING [Thread-363] org.apache.catalina.servlets.CGIServlet$CGIRunner.sendToLog Received [4] lines on stderr
24-Oct-2019 23:02:45.634 WARNING [Thread-364] org.apache.catalina.servlets.CGIServlet$CGIRunner.sendToLog stderr line: [Traceback (most recent call last):]
24-Oct-2019 23:02:45.634 WARNING [Thread-364] org.apache.catalina.servlets.CGIServlet$CGIRunner.sendToLog stderr line: [  File "C:\Users\hayde\Desktop\UCI\Fall 2019\EECS 118\MP2\apache-tomcat-9.0.26\webapps\test\WEB-INF\cgi\project_3_gallery1.py", line 68, in <module>]
24-Oct-2019 23:02:45.634 WARNING [Thread-364] org.apache.catalina.servlets.CGIServlet$CGIRunner.sendToLog stderr line: [    query = "select*from image where link='"+gal_1_img[i][0]+"'"]
24-Oct-2019 23:02:45.635 WARNING [Thread-364] org.apache.catalina.servlets.CGIServlet$CGIRunner.sendToLog stderr line: [IndexError: tuple index out of range]
24-Oct-2019 23:02:45.642 WARNING [Thread-364] org.apache.catalina.servlets.CGIServlet$CGIRunner.sendToLog Received [4] lines on stderr
24-Oct-2019 23:03:53.098 WARNING [Thread-366] org.apache.catalina.servlets.CGIServlet$CGIRunner.sendToLog stderr line: [Traceback (most recent call last):]
24-Oct-2019 23:03:53.098 WARNING [Thread-366] org.apache.catalina.servlets.CGIServlet$CGIRunner.sendToLog stderr line: [  File "C:\Users\hayde\Desktop\UCI\Fall 2019\EECS 118\MP2\apache-tomcat-9.0.26\webapps\test\WEB-INF\cgi\project_3_gallery1.py", line 68, in <module>]
24-Oct-2019 23:03:53.099 WARNING [Thread-366] org.apache.catalina.servlets.CGIServlet$CGIRunner.sendToLog stderr line: [    query = "select*from image where link='"+gal_1_img[i][0]+"'"]
24-Oct-2019 23:03:53.099 WARNING [Thread-366] org.apache.catalina.servlets.CGIServlet$CGIRunner.sendToLog stderr line: [IndexError: tuple index out of range]
24-Oct-2019 23:03:53.107 WARNING [Thread-366] org.apache.catalina.servlets.CGIServlet$CGIRunner.sendToLog Received [4] lines on stderr
24-Oct-2019 23:07:11.488 WARNING [Thread-368] org.apache.catalina.servlets.CGIServlet$CGIRunner.sendToLog stderr line: [Traceback (most recent call last):]
24-Oct-2019 23:07:11.488 WARNING [Thread-368] org.apache.catalina.servlets.CGIServlet$CGIRunner.sendToLog stderr line: [  File "C:\Users\hayde\Desktop\UCI\Fall 2019\EECS 118\MP2\apache-tomcat-9.0.26\webapps\test\WEB-INF\cgi\project_3_gallery1.py", line 68, in <module>]
24-Oct-2019 23:07:11.489 WARNING [Thread-368] org.apache.catalina.servlets.CGIServlet$CGIRunner.sendToLog stderr line: [    query = "select*from image where link='"+gal_1_img[i][0]+"'"]
24-Oct-2019 23:07:11.489 WARNING [Thread-368] org.apache.catalina.servlets.CGIServlet$CGIRunner.sendToLog stderr line: [IndexError: tuple index out of range]
24-Oct-2019 23:07:11.499 WARNING [Thread-368] org.apache.catalina.servlets.CGIServlet$CGIRunner.sendToLog Received [4] lines on stderr
24-Oct-2019 23:07:46.469 WARNING [Thread-369] org.apache.catalina.servlets.CGIServlet$CGIRunner.sendToLog stderr line: [Traceback (most recent call last):]
24-Oct-2019 23:07:46.470 WARNING [Thread-369] org.apache.catalina.servlets.CGIServlet$CGIRunner.sendToLog stderr line: [  File "C:\Users\hayde\Desktop\UCI\Fall 2019\EECS 118\MP2\apache-tomcat-9.0.26\webapps\test\WEB-INF\cgi\project_3_gallery1.py", line 68, in <module>]
24-Oct-2019 23:07:46.470 WARNING [Thread-369] org.apache.catalina.servlets.CGIServlet$CGIRunner.sendToLog stderr line: [    query = "select*from image where link='"+gal_1_img[i][0]+"'"]
24-Oct-2019 23:07:46.470 WARNING [Thread-369] org.apache.catalina.servlets.CGIServlet$CGIRunner.sendToLog stderr line: [IndexError: tuple index out of range]
24-Oct-2019 23:07:46.478 WARNING [Thread-369] org.apache.catalina.servlets.CGIServlet$CGIRunner.sendToLog Received [4] lines on stderr
24-Oct-2019 23:08:40.748 WARNING [Thread-370] org.apache.catalina.servlets.CGIServlet$CGIRunner.sendToLog stderr line: [Traceback (most recent call last):]
24-Oct-2019 23:08:40.748 WARNING [Thread-370] org.apache.catalina.servlets.CGIServlet$CGIRunner.sendToLog stderr line: [  File "C:\Users\hayde\Desktop\UCI\Fall 2019\EECS 118\MP2\apache-tomcat-9.0.26\webapps\test\WEB-INF\cgi\project_3_gallery1.py", line 68, in <module>]
24-Oct-2019 23:08:40.749 WARNING [Thread-370] org.apache.catalina.servlets.CGIServlet$CGIRunner.sendToLog stderr line: [    query = "select*from image where link='"+gal_1_img[i][0]+"'"]
24-Oct-2019 23:08:40.750 WARNING [Thread-370] org.apache.catalina.servlets.CGIServlet$CGIRunner.sendToLog stderr line: [NameError: name 'i' is not defined]
24-Oct-2019 23:08:40.760 WARNING [Thread-370] org.apache.catalina.servlets.CGIServlet$CGIRunner.sendToLog Received [4] lines on stderr
24-Oct-2019 23:08:48.593 WARNING [Thread-371] org.apache.catalina.servlets.CGIServlet$CGIRunner.sendToLog stderr line: [Traceback (most recent call last):]
24-Oct-2019 23:08:48.593 WARNING [Thread-371] org.apache.catalina.servlets.CGIServlet$CGIRunner.sendToLog stderr line: [  File "C:\Users\hayde\Desktop\UCI\Fall 2019\EECS 118\MP2\apache-tomcat-9.0.26\webapps\test\WEB-INF\cgi\project_3_gallery1.py", line 68, in <module>]
24-Oct-2019 23:08:48.594 WARNING [Thread-371] org.apache.catalina.servlets.CGIServlet$CGIRunner.sendToLog stderr line: [    query = "select*from image where link='"+gal_1_img[i][0]+"'"]
24-Oct-2019 23:08:48.594 WARNING [Thread-371] org.apache.catalina.servlets.CGIServlet$CGIRunner.sendToLog stderr line: [NameError: name 'i' is not defined]
24-Oct-2019 23:08:48.601 WARNING [Thread-371] org.apache.catalina.servlets.CGIServlet$CGIRunner.sendToLog Received [4] lines on stderr
24-Oct-2019 23:09:21.825 WARNING [Thread-372] org.apache.catalina.servlets.CGIServlet$CGIRunner.sendToLog stderr line: [Traceback (most recent call last):]
24-Oct-2019 23:09:21.825 WARNING [Thread-372] org.apache.catalina.servlets.CGIServlet$CGIRunner.sendToLog stderr line: [  File "C:\Users\hayde\Desktop\UCI\Fall 2019\EECS 118\MP2\apache-tomcat-9.0.26\webapps\test\WEB-INF\cgi\project_3_gallery1.py", line 69, in <module>]
24-Oct-2019 23:09:21.826 WARNING [Thread-372] org.apache.catalina.servlets.CGIServlet$CGIRunner.sendToLog stderr line: [    query = "select*from image where link='"+gal_1_img[i][0]+"'"]
24-Oct-2019 23:09:21.827 WARNING [Thread-372] org.apache.catalina.servlets.CGIServlet$CGIRunner.sendToLog stderr line: [NameError: name 'i' is not defined]
24-Oct-2019 23:09:21.833 WARNING [Thread-372] org.apache.catalina.servlets.CGIServlet$CGIRunner.sendToLog Received [4] lines on stderr
24-Oct-2019 23:12:53.743 WARNING [Thread-373] org.apache.catalina.servlets.CGIServlet$CGIRunner.sendToLog stderr line: [Traceback (most recent call last):]
24-Oct-2019 23:12:53.743 WARNING [Thread-373] org.apache.catalina.servlets.CGIServlet$CGIRunner.sendToLog stderr line: [  File "C:\Users\hayde\Desktop\UCI\Fall 2019\EECS 118\MP2\apache-tomcat-9.0.26\webapps\test\WEB-INF\cgi\project_3_gallery1.py", line 71, in <module>]
24-Oct-2019 23:12:53.744 WARNING [Thread-373] org.apache.catalina.servlets.CGIServlet$CGIRunner.sendToLog stderr line: [    query = "select*from image where link='"+gal_1_img[i][0]+"'"]
24-Oct-2019 23:12:53.744 WARNING [Thread-373] org.apache.catalina.servlets.CGIServlet$CGIRunner.sendToLog stderr line: [NameError: name 'i' is not defined]
24-Oct-2019 23:12:53.751 WARNING [Thread-373] org.apache.catalina.servlets.CGIServlet$CGIRunner.sendToLog Received [4] lines on stderr
24-Oct-2019 23:13:45.050 WARNING [Thread-374] org.apache.catalina.servlets.CGIServlet$CGIRunner.sendToLog stderr line: [Traceback (most recent call last):]
24-Oct-2019 23:13:45.051 WARNING [Thread-374] org.apache.catalina.servlets.CGIServlet$CGIRunner.sendToLog stderr line: [  File "C:\Users\hayde\Desktop\UCI\Fall 2019\EECS 118\MP2\apache-tomcat-9.0.26\webapps\test\WEB-INF\cgi\project_3_gallery1.py", line 69, in <module>]
24-Oct-2019 23:13:45.051 WARNING [Thread-374] org.apache.catalina.servlets.CGIServlet$CGIRunner.sendToLog stderr line: [    for i in range(size(max_num_img)):]
24-Oct-2019 23:13:45.051 WARNING [Thread-374] org.apache.catalina.servlets.CGIServlet$CGIRunner.sendToLog stderr line: [NameError: name 'size' is not defined]
24-Oct-2019 23:13:45.058 WARNING [Thread-374] org.apache.catalina.servlets.CGIServlet$CGIRunner.sendToLog Received [4] lines on stderr
