27-Oct-2019 12:15:00.084 INFO [main] org.apache.catalina.startup.VersionLoggerListener.log Server version name:   Apache Tomcat/9.0.26
27-Oct-2019 12:15:00.089 INFO [main] org.apache.catalina.startup.VersionLoggerListener.log Server built:          Sep 16 2019 15:51:39 UTC
27-Oct-2019 12:15:00.090 INFO [main] org.apache.catalina.startup.VersionLoggerListener.log Server version number: 9.0.26.0
27-Oct-2019 12:15:00.090 INFO [main] org.apache.catalina.startup.VersionLoggerListener.log OS Name:               Windows 10
27-Oct-2019 12:15:00.091 INFO [main] org.apache.catalina.startup.VersionLoggerListener.log OS Version:            10.0
27-Oct-2019 12:15:00.091 INFO [main] org.apache.catalina.startup.VersionLoggerListener.log Architecture:          amd64
27-Oct-2019 12:15:00.091 INFO [main] org.apache.catalina.startup.VersionLoggerListener.log Java Home:             C:\Program Files\Java\jdk-13
27-Oct-2019 12:15:00.091 INFO [main] org.apache.catalina.startup.VersionLoggerListener.log JVM Version:           13+33
27-Oct-2019 12:15:00.092 INFO [main] org.apache.catalina.startup.VersionLoggerListener.log JVM Vendor:            Oracle Corporation
27-Oct-2019 12:15:00.092 INFO [main] org.apache.catalina.startup.VersionLoggerListener.log CATALINA_BASE:         C:\Users\hayde\Desktop\UCI\Fall 2019\EECS 118\MP2\apache-tomcat-9.0.26
27-Oct-2019 12:15:00.093 INFO [main] org.apache.catalina.startup.VersionLoggerListener.log CATALINA_HOME:         C:\Users\hayde\Desktop\UCI\Fall 2019\EECS 118\MP2\apache-tomcat-9.0.26
27-Oct-2019 12:15:00.166 INFO [main] org.apache.catalina.startup.VersionLoggerListener.log Command line argument: --add-opens=java.base/java.lang=ALL-UNNAMED
27-Oct-2019 12:15:00.167 INFO [main] org.apache.catalina.startup.VersionLoggerListener.log Command line argument: --add-opens=java.base/java.io=ALL-UNNAMED
27-Oct-2019 12:15:00.167 INFO [main] org.apache.catalina.startup.VersionLoggerListener.log Command line argument: --add-opens=java.rmi/sun.rmi.transport=ALL-UNNAMED
27-Oct-2019 12:15:00.168 INFO [main] org.apache.catalina.startup.VersionLoggerListener.log Command line argument: -Djava.util.logging.config.file=C:\Users\hayde\Desktop\UCI\Fall 2019\EECS 118\MP2\apache-tomcat-9.0.26\conf\logging.properties
27-Oct-2019 12:15:00.168 INFO [main] org.apache.catalina.startup.VersionLoggerListener.log Command line argument: -Djava.util.logging.manager=org.apache.juli.ClassLoaderLogManager
27-Oct-2019 12:15:00.169 INFO [main] org.apache.catalina.startup.VersionLoggerListener.log Command line argument: -Djdk.tls.ephemeralDHKeySize=2048
27-Oct-2019 12:15:00.170 INFO [main] org.apache.catalina.startup.VersionLoggerListener.log Command line argument: -Djava.protocol.handler.pkgs=org.apache.catalina.webresources
27-Oct-2019 12:15:00.171 INFO [main] org.apache.catalina.startup.VersionLoggerListener.log Command line argument: -Dignore.endorsed.dirs=
27-Oct-2019 12:15:00.171 INFO [main] org.apache.catalina.startup.VersionLoggerListener.log Command line argument: -Dcatalina.base=C:\Users\hayde\Desktop\UCI\Fall 2019\EECS 118\MP2\apache-tomcat-9.0.26
27-Oct-2019 12:15:00.172 INFO [main] org.apache.catalina.startup.VersionLoggerListener.log Command line argument: -Dcatalina.home=C:\Users\hayde\Desktop\UCI\Fall 2019\EECS 118\MP2\apache-tomcat-9.0.26
27-Oct-2019 12:15:00.173 INFO [main] org.apache.catalina.startup.VersionLoggerListener.log Command line argument: -Djava.io.tmpdir=C:\Users\hayde\Desktop\UCI\Fall 2019\EECS 118\MP2\apache-tomcat-9.0.26\temp
27-Oct-2019 12:15:00.174 INFO [main] org.apache.catalina.core.AprLifecycleListener.lifecycleEvent Loaded APR based Apache Tomcat Native library [1.2.23] using APR version [1.7.0].
27-Oct-2019 12:15:00.175 INFO [main] org.apache.catalina.core.AprLifecycleListener.lifecycleEvent APR capabilities: IPv6 [true], sendfile [true], accept filters [false], random [true].
27-Oct-2019 12:15:00.175 INFO [main] org.apache.catalina.core.AprLifecycleListener.lifecycleEvent APR/OpenSSL configuration: useAprConnector [false], useOpenSSL [true]
27-Oct-2019 12:15:00.186 INFO [main] org.apache.catalina.core.AprLifecycleListener.initializeSSL OpenSSL successfully initialized [OpenSSL 1.1.1c  28 May 2019]
27-Oct-2019 12:15:00.685 INFO [main] org.apache.coyote.AbstractProtocol.init Initializing ProtocolHandler ["http-nio-8080"]
27-Oct-2019 12:15:02.407 INFO [main] org.apache.coyote.AbstractProtocol.init Initializing ProtocolHandler ["ajp-nio-8009"]
27-Oct-2019 12:15:02.412 INFO [main] org.apache.catalina.startup.Catalina.load Server initialization in [2,830] milliseconds
27-Oct-2019 12:15:02.496 INFO [main] org.apache.catalina.core.StandardService.startInternal Starting service [Catalina]
27-Oct-2019 12:15:02.496 INFO [main] org.apache.catalina.core.StandardEngine.startInternal Starting Servlet engine: [Apache Tomcat/9.0.26]
27-Oct-2019 12:15:02.519 INFO [main] org.apache.catalina.startup.HostConfig.deployDirectory Deploying web application directory [C:\Users\hayde\Desktop\UCI\Fall 2019\EECS 118\MP2\apache-tomcat-9.0.26\webapps\docs]
27-Oct-2019 12:15:03.322 WARNING [main] org.apache.catalina.util.SessionIdGeneratorBase.createSecureRandom Creation of SecureRandom instance for session ID generation using [SHA1PRNG] took [309] milliseconds.
27-Oct-2019 12:15:03.368 INFO [main] org.apache.catalina.startup.HostConfig.deployDirectory Deployment of web application directory [C:\Users\hayde\Desktop\UCI\Fall 2019\EECS 118\MP2\apache-tomcat-9.0.26\webapps\docs] has finished in [849] ms
27-Oct-2019 12:15:03.369 INFO [main] org.apache.catalina.startup.HostConfig.deployDirectory Deploying web application directory [C:\Users\hayde\Desktop\UCI\Fall 2019\EECS 118\MP2\apache-tomcat-9.0.26\webapps\examples]
27-Oct-2019 12:15:06.947 INFO [main] org.apache.catalina.startup.HostConfig.deployDirectory Deployment of web application directory [C:\Users\hayde\Desktop\UCI\Fall 2019\EECS 118\MP2\apache-tomcat-9.0.26\webapps\examples] has finished in [3,578] ms
27-Oct-2019 12:15:06.948 INFO [main] org.apache.catalina.startup.HostConfig.deployDirectory Deploying web application directory [C:\Users\hayde\Desktop\UCI\Fall 2019\EECS 118\MP2\apache-tomcat-9.0.26\webapps\host-manager]
27-Oct-2019 12:15:07.095 INFO [main] org.apache.catalina.startup.HostConfig.deployDirectory Deployment of web application directory [C:\Users\hayde\Desktop\UCI\Fall 2019\EECS 118\MP2\apache-tomcat-9.0.26\webapps\host-manager] has finished in [147] ms
27-Oct-2019 12:15:07.100 INFO [main] org.apache.catalina.startup.HostConfig.deployDirectory Deploying web application directory [C:\Users\hayde\Desktop\UCI\Fall 2019\EECS 118\MP2\apache-tomcat-9.0.26\webapps\manager]
27-Oct-2019 12:15:07.226 INFO [main] org.apache.catalina.startup.HostConfig.deployDirectory Deployment of web application directory [C:\Users\hayde\Desktop\UCI\Fall 2019\EECS 118\MP2\apache-tomcat-9.0.26\webapps\manager] has finished in [126] ms
27-Oct-2019 12:15:07.232 INFO [main] org.apache.catalina.startup.HostConfig.deployDirectory Deploying web application directory [C:\Users\hayde\Desktop\UCI\Fall 2019\EECS 118\MP2\apache-tomcat-9.0.26\webapps\ROOT]
27-Oct-2019 12:15:07.342 INFO [main] org.apache.catalina.startup.HostConfig.deployDirectory Deployment of web application directory [C:\Users\hayde\Desktop\UCI\Fall 2019\EECS 118\MP2\apache-tomcat-9.0.26\webapps\ROOT] has finished in [109] ms
27-Oct-2019 12:15:07.342 INFO [main] org.apache.catalina.startup.HostConfig.deployDirectory Deploying web application directory [C:\Users\hayde\Desktop\UCI\Fall 2019\EECS 118\MP2\apache-tomcat-9.0.26\webapps\test]
27-Oct-2019 12:15:07.442 INFO [main] org.apache.catalina.startup.HostConfig.deployDirectory Deployment of web application directory [C:\Users\hayde\Desktop\UCI\Fall 2019\EECS 118\MP2\apache-tomcat-9.0.26\webapps\test] has finished in [100] ms
27-Oct-2019 12:15:07.451 INFO [main] org.apache.coyote.AbstractProtocol.start Starting ProtocolHandler ["http-nio-8080"]
27-Oct-2019 12:15:07.463 INFO [main] org.apache.coyote.AbstractProtocol.start Starting ProtocolHandler ["ajp-nio-8009"]
27-Oct-2019 12:15:07.472 INFO [main] org.apache.catalina.startup.Catalina.start Server startup in [5,058] milliseconds
27-Oct-2019 12:15:59.662 WARNING [Thread-5] org.apache.catalina.servlets.CGIServlet$CGIRunner.sendToLog stderr line: [Traceback (most recent call last):]
27-Oct-2019 12:15:59.664 WARNING [Thread-5] org.apache.catalina.servlets.CGIServlet$CGIRunner.sendToLog stderr line: [  File "C:\Users\hayde\Desktop\UCI\Fall 2019\EECS 118\MP2\apache-tomcat-9.0.26\webapps\test\WEB-INF\cgi\project_3.py", line 47, in <module>]
27-Oct-2019 12:15:59.667 WARNING [Thread-5] org.apache.catalina.servlets.CGIServlet$CGIRunner.sendToLog stderr line: [    print(js)]
27-Oct-2019 12:15:59.670 WARNING [Thread-5] org.apache.catalina.servlets.CGIServlet$CGIRunner.sendToLog stderr line: [NameError: name 'js' is not defined]
27-Oct-2019 12:15:59.687 WARNING [Thread-5] org.apache.catalina.servlets.CGIServlet$CGIRunner.sendToLog Received [4] lines on stderr
27-Oct-2019 12:16:18.143 WARNING [Thread-9] org.apache.catalina.servlets.CGIServlet$CGIRunner.sendToLog stderr line: [Traceback (most recent call last):]
27-Oct-2019 12:16:18.144 WARNING [Thread-9] org.apache.catalina.servlets.CGIServlet$CGIRunner.sendToLog stderr line: [  File "C:\Users\hayde\Desktop\UCI\Fall 2019\EECS 118\MP2\apache-tomcat-9.0.26\webapps\test\WEB-INF\cgi\project_3.py", line 47, in <module>]
27-Oct-2019 12:16:18.151 WARNING [Thread-9] org.apache.catalina.servlets.CGIServlet$CGIRunner.sendToLog stderr line: [    print(js)]
27-Oct-2019 12:16:18.152 WARNING [Thread-9] org.apache.catalina.servlets.CGIServlet$CGIRunner.sendToLog stderr line: [NameError: name 'js' is not defined]
27-Oct-2019 12:16:18.166 WARNING [Thread-9] org.apache.catalina.servlets.CGIServlet$CGIRunner.sendToLog Received [4] lines on stderr
27-Oct-2019 12:28:49.033 WARNING [Thread-14] org.apache.catalina.servlets.CGIServlet$CGIRunner.sendToLog stderr line: [Traceback (most recent call last):]
27-Oct-2019 12:28:49.034 WARNING [Thread-14] org.apache.catalina.servlets.CGIServlet$CGIRunner.sendToLog stderr line: [  File "C:\Users\hayde\Desktop\UCI\Fall 2019\EECS 118\MP2\apache-tomcat-9.0.26\webapps\test\WEB-INF\cgi\project_3.py", line 47, in <module>]
27-Oct-2019 12:28:49.034 WARNING [Thread-14] org.apache.catalina.servlets.CGIServlet$CGIRunner.sendToLog stderr line: [    print(js)]
27-Oct-2019 12:28:49.037 WARNING [Thread-14] org.apache.catalina.servlets.CGIServlet$CGIRunner.sendToLog stderr line: [NameError: name 'js' is not defined]
27-Oct-2019 12:28:49.057 WARNING [Thread-14] org.apache.catalina.servlets.CGIServlet$CGIRunner.sendToLog Received [4] lines on stderr
27-Oct-2019 12:33:33.311 WARNING [Thread-16] org.apache.catalina.servlets.CGIServlet$CGIRunner.sendToLog stderr line: [Traceback (most recent call last):]
27-Oct-2019 12:33:33.313 WARNING [Thread-16] org.apache.catalina.servlets.CGIServlet$CGIRunner.sendToLog stderr line: [  File "C:\Users\hayde\Desktop\UCI\Fall 2019\EECS 118\MP2\apache-tomcat-9.0.26\webapps\test\WEB-INF\cgi\project_3.py", line 47, in <module>]
27-Oct-2019 12:33:33.314 WARNING [Thread-16] org.apache.catalina.servlets.CGIServlet$CGIRunner.sendToLog stderr line: [    print(js)]
27-Oct-2019 12:33:33.315 WARNING [Thread-16] org.apache.catalina.servlets.CGIServlet$CGIRunner.sendToLog stderr line: [NameError: name 'js' is not defined]
27-Oct-2019 12:33:33.330 WARNING [Thread-16] org.apache.catalina.servlets.CGIServlet$CGIRunner.sendToLog Received [4] lines on stderr
27-Oct-2019 12:33:35.065 WARNING [Thread-17] org.apache.catalina.servlets.CGIServlet$CGIRunner.sendToLog stderr line: [  File "C:\Users\hayde\Desktop\UCI\Fall 2019\EECS 118\MP2\apache-tomcat-9.0.26\webapps\test\WEB-INF\cgi\project_3_gallery1.py", line 112]
27-Oct-2019 12:33:35.066 WARNING [Thread-17] org.apache.catalina.servlets.CGIServlet$CGIRunner.sendToLog stderr line: [    edit_artist_button = "<form enctype='multipart/form-data' action='/test/cgi-bin/project_3_edit_detail.py' method='POST'><input type='hidden' name='edit_detail' value='"+gal_1_img[i][0]+"'><input type='submit' value='Edit Detail'></form>""]
27-Oct-2019 12:33:35.067 WARNING [Thread-17] org.apache.catalina.servlets.CGIServlet$CGIRunner.sendToLog stderr line: [                                                                                                                                                                                                                                                 ^]
27-Oct-2019 12:33:35.068 WARNING [Thread-17] org.apache.catalina.servlets.CGIServlet$CGIRunner.sendToLog stderr line: [SyntaxError: EOL while scanning string literal]
27-Oct-2019 12:33:35.072 WARNING [Thread-17] org.apache.catalina.servlets.CGIServlet$CGIRunner.sendToLog Received [4] lines on stderr
27-Oct-2019 12:33:51.378 WARNING [Thread-18] org.apache.catalina.servlets.CGIServlet$CGIRunner.sendToLog stderr line: [Traceback (most recent call last):]
27-Oct-2019 12:33:51.379 WARNING [Thread-18] org.apache.catalina.servlets.CGIServlet$CGIRunner.sendToLog stderr line: [  File "C:\Users\hayde\Desktop\UCI\Fall 2019\EECS 118\MP2\apache-tomcat-9.0.26\webapps\test\WEB-INF\cgi\project_3.py", line 47, in <module>]
27-Oct-2019 12:33:51.381 WARNING [Thread-18] org.apache.catalina.servlets.CGIServlet$CGIRunner.sendToLog stderr line: [    print(js)]
27-Oct-2019 12:33:51.382 WARNING [Thread-18] org.apache.catalina.servlets.CGIServlet$CGIRunner.sendToLog stderr line: [NameError: name 'js' is not defined]
27-Oct-2019 12:33:51.398 WARNING [Thread-18] org.apache.catalina.servlets.CGIServlet$CGIRunner.sendToLog Received [4] lines on stderr
27-Oct-2019 12:33:53.545 WARNING [Thread-19] org.apache.catalina.servlets.CGIServlet$CGIRunner.sendToLog stderr line: [  File "C:\Users\hayde\Desktop\UCI\Fall 2019\EECS 118\MP2\apache-tomcat-9.0.26\webapps\test\WEB-INF\cgi\project_3_gallery1.py", line 111]
27-Oct-2019 12:33:53.547 WARNING [Thread-19] org.apache.catalina.servlets.CGIServlet$CGIRunner.sendToLog stderr line: [    edit_artist_button = "<form enctype='multipart/form-data' action='/test/cgi-bin/project_3_edit_detail.py' method='POST'><input type='hidden' name='edit_detail' value='"+gal_1_img[i][0]+"'><input type='submit' value='Edit Detail'></form>""]
27-Oct-2019 12:33:53.548 WARNING [Thread-19] org.apache.catalina.servlets.CGIServlet$CGIRunner.sendToLog stderr line: [                                                                                                                                                                                                                                                 ^]
27-Oct-2019 12:33:53.560 WARNING [Thread-19] org.apache.catalina.servlets.CGIServlet$CGIRunner.sendToLog stderr line: [SyntaxError: EOL while scanning string literal]
27-Oct-2019 12:33:53.562 WARNING [Thread-19] org.apache.catalina.servlets.CGIServlet$CGIRunner.sendToLog Received [4] lines on stderr
27-Oct-2019 17:04:49.614 WARNING [Thread-30] org.apache.catalina.servlets.CGIServlet$CGIRunner.sendToLog stderr line: [Traceback (most recent call last):]
27-Oct-2019 17:04:49.614 WARNING [Thread-30] org.apache.catalina.servlets.CGIServlet$CGIRunner.sendToLog stderr line: [  File "C:\Users\hayde\Desktop\UCI\Fall 2019\EECS 118\MP2\apache-tomcat-9.0.26\webapps\test\WEB-INF\cgi\project_3_gallery1.py", line 108, in <module>]
27-Oct-2019 17:04:49.619 WARNING [Thread-30] org.apache.catalina.servlets.CGIServlet$CGIRunner.sendToLog stderr line: [    edit_detail_button = "<form enctype='multipart/form-data' action='/test/cgi-bin/project_3_edit_detail.py' method='POST'><input type='hidden' name='edit_detail' value='"+detail_id+"'><input type='submit' value='Edit Detail'></form>"]
27-Oct-2019 17:04:49.620 WARNING [Thread-30] org.apache.catalina.servlets.CGIServlet$CGIRunner.sendToLog stderr line: [TypeError: must be str, not tuple]
27-Oct-2019 17:04:49.641 WARNING [Thread-30] org.apache.catalina.servlets.CGIServlet$CGIRunner.sendToLog Received [4] lines on stderr
27-Oct-2019 17:04:57.634 WARNING [Thread-31] org.apache.catalina.servlets.CGIServlet$CGIRunner.sendToLog stderr line: [Traceback (most recent call last):]
27-Oct-2019 17:04:57.634 WARNING [Thread-31] org.apache.catalina.servlets.CGIServlet$CGIRunner.sendToLog stderr line: [  File "C:\Users\hayde\Desktop\UCI\Fall 2019\EECS 118\MP2\apache-tomcat-9.0.26\webapps\test\WEB-INF\cgi\project_3_gallery1.py", line 108, in <module>]
27-Oct-2019 17:04:57.634 WARNING [Thread-31] org.apache.catalina.servlets.CGIServlet$CGIRunner.sendToLog stderr line: [    edit_detail_button = "<form enctype='multipart/form-data' action='/test/cgi-bin/project_3_edit_detail.py' method='POST'><input type='hidden' name='edit_detail' value='"+detail_id+"'><input type='submit' value='Edit Detail'></form>"]
27-Oct-2019 17:04:57.638 WARNING [Thread-31] org.apache.catalina.servlets.CGIServlet$CGIRunner.sendToLog stderr line: [TypeError: must be str, not tuple]
27-Oct-2019 17:04:57.652 WARNING [Thread-31] org.apache.catalina.servlets.CGIServlet$CGIRunner.sendToLog Received [4] lines on stderr
27-Oct-2019 17:05:44.995 WARNING [Thread-32] org.apache.catalina.servlets.CGIServlet$CGIRunner.sendToLog stderr line: [Traceback (most recent call last):]
27-Oct-2019 17:05:44.995 WARNING [Thread-32] org.apache.catalina.servlets.CGIServlet$CGIRunner.sendToLog stderr line: [  File "C:\Users\hayde\Desktop\UCI\Fall 2019\EECS 118\MP2\apache-tomcat-9.0.26\webapps\test\WEB-INF\cgi\project_3_gallery1.py", line 108, in <module>]
27-Oct-2019 17:05:44.998 WARNING [Thread-32] org.apache.catalina.servlets.CGIServlet$CGIRunner.sendToLog stderr line: [    edit_detail_button = "<form enctype='multipart/form-data' action='/test/cgi-bin/project_3_edit_detail.py' method='POST'><input type='hidden' name='edit_detail' value='"+detail_id+"'><input type='submit' value='Edit_Detail'></form>"]
27-Oct-2019 17:05:44.999 WARNING [Thread-32] org.apache.catalina.servlets.CGIServlet$CGIRunner.sendToLog stderr line: [TypeError: must be str, not tuple]
27-Oct-2019 17:05:45.015 WARNING [Thread-32] org.apache.catalina.servlets.CGIServlet$CGIRunner.sendToLog Received [4] lines on stderr
27-Oct-2019 17:06:49.819 WARNING [Thread-33] org.apache.catalina.servlets.CGIServlet$CGIRunner.sendToLog stderr line: [Traceback (most recent call last):]
27-Oct-2019 17:06:49.819 WARNING [Thread-33] org.apache.catalina.servlets.CGIServlet$CGIRunner.sendToLog stderr line: [  File "C:\Users\hayde\Desktop\UCI\Fall 2019\EECS 118\MP2\apache-tomcat-9.0.26\webapps\test\WEB-INF\cgi\project_3_gallery1.py", line 108, in <module>]
27-Oct-2019 17:06:49.823 WARNING [Thread-33] org.apache.catalina.servlets.CGIServlet$CGIRunner.sendToLog stderr line: [    edit_detail_button = "<form enctype='multipart/form-data' action='/test/cgi-bin/project_3_edit_detail.py' method='POST'><input type='hidden' name='edit_detail' value='"+detail_id+"'><input type='submit' value='Edit_Detail'></form>"]
27-Oct-2019 17:06:49.825 WARNING [Thread-33] org.apache.catalina.servlets.CGIServlet$CGIRunner.sendToLog stderr line: [TypeError: must be str, not tuple]
27-Oct-2019 17:06:49.840 WARNING [Thread-33] org.apache.catalina.servlets.CGIServlet$CGIRunner.sendToLog Received [4] lines on stderr
27-Oct-2019 17:09:04.305 WARNING [Thread-36] org.apache.catalina.servlets.CGIServlet$CGIRunner.sendToLog stderr line: [Traceback (most recent call last):]
27-Oct-2019 17:09:04.306 WARNING [Thread-36] org.apache.catalina.servlets.CGIServlet$CGIRunner.sendToLog stderr line: [  File "C:\Users\hayde\Desktop\UCI\Fall 2019\EECS 118\MP2\apache-tomcat-9.0.26\webapps\test\WEB-INF\cgi\project_3_edited_detail.py", line 26, in <module>]
27-Oct-2019 17:09:04.306 WARNING [Thread-36] org.apache.catalina.servlets.CGIServlet$CGIRunner.sendToLog stderr line: [    cur.execute(query, title)]
27-Oct-2019 17:09:04.307 WARNING [Thread-36] org.apache.catalina.servlets.CGIServlet$CGIRunner.sendToLog stderr line: [  File "C:\Users\hayde\AppData\Local\Programs\Python\Python36\lib\site-packages\pymysql\cursors.py", line 170, in execute]
27-Oct-2019 17:09:04.307 WARNING [Thread-36] org.apache.catalina.servlets.CGIServlet$CGIRunner.sendToLog stderr line: [    result = self._query(query)]
27-Oct-2019 17:09:04.309 WARNING [Thread-36] org.apache.catalina.servlets.CGIServlet$CGIRunner.sendToLog stderr line: [  File "C:\Users\hayde\AppData\Local\Programs\Python\Python36\lib\site-packages\pymysql\cursors.py", line 328, in _query]
27-Oct-2019 17:09:04.310 WARNING [Thread-36] org.apache.catalina.servlets.CGIServlet$CGIRunner.sendToLog stderr line: [    conn.query(q)]
27-Oct-2019 17:09:04.311 WARNING [Thread-36] org.apache.catalina.servlets.CGIServlet$CGIRunner.sendToLog stderr line: [  File "C:\Users\hayde\AppData\Local\Programs\Python\Python36\lib\site-packages\pymysql\connections.py", line 517, in query]
27-Oct-2019 17:09:04.313 WARNING [Thread-36] org.apache.catalina.servlets.CGIServlet$CGIRunner.sendToLog stderr line: [    self._affected_rows = self._read_query_result(unbuffered=unbuffered)]
27-Oct-2019 17:09:04.314 WARNING [Thread-36] org.apache.catalina.servlets.CGIServlet$CGIRunner.sendToLog stderr line: [  File "C:\Users\hayde\AppData\Local\Programs\Python\Python36\lib\site-packages\pymysql\connections.py", line 732, in _read_query_result]
27-Oct-2019 17:09:04.315 WARNING [Thread-36] org.apache.catalina.servlets.CGIServlet$CGIRunner.sendToLog stderr line: [    result.read()]
27-Oct-2019 17:09:04.316 WARNING [Thread-36] org.apache.catalina.servlets.CGIServlet$CGIRunner.sendToLog stderr line: [  File "C:\Users\hayde\AppData\Local\Programs\Python\Python36\lib\site-packages\pymysql\connections.py", line 1075, in read]
27-Oct-2019 17:09:04.316 WARNING [Thread-36] org.apache.catalina.servlets.CGIServlet$CGIRunner.sendToLog stderr line: [    first_packet = self.connection._read_packet()]
27-Oct-2019 17:09:04.317 WARNING [Thread-36] org.apache.catalina.servlets.CGIServlet$CGIRunner.sendToLog stderr line: [  File "C:\Users\hayde\AppData\Local\Programs\Python\Python36\lib\site-packages\pymysql\connections.py", line 684, in _read_packet]
27-Oct-2019 17:09:04.317 WARNING [Thread-36] org.apache.catalina.servlets.CGIServlet$CGIRunner.sendToLog stderr line: [    packet.check_error()]
27-Oct-2019 17:09:04.319 WARNING [Thread-36] org.apache.catalina.servlets.CGIServlet$CGIRunner.sendToLog stderr line: [  File "C:\Users\hayde\AppData\Local\Programs\Python\Python36\lib\site-packages\pymysql\protocol.py", line 220, in check_error]
27-Oct-2019 17:09:04.320 WARNING [Thread-36] org.apache.catalina.servlets.CGIServlet$CGIRunner.sendToLog stderr line: [    err.raise_mysql_exception(self._data)]
27-Oct-2019 17:09:04.321 WARNING [Thread-36] org.apache.catalina.servlets.CGIServlet$CGIRunner.sendToLog stderr line: [  File "C:\Users\hayde\AppData\Local\Programs\Python\Python36\lib\site-packages\pymysql\err.py", line 109, in raise_mysql_exception]
27-Oct-2019 17:09:04.321 WARNING [Thread-36] org.apache.catalina.servlets.CGIServlet$CGIRunner.sendToLog stderr line: [    raise errorclass(errno, errval)]
27-Oct-2019 17:09:04.322 WARNING [Thread-36] org.apache.catalina.servlets.CGIServlet$CGIRunner.sendToLog stderr line: [pymysql.err.InternalError: (1054, "Unknown column 'title' in 'field list'")]
27-Oct-2019 17:09:04.326 WARNING [Thread-36] org.apache.catalina.servlets.CGIServlet$CGIRunner.sendToLog Received [20] lines on stderr
27-Oct-2019 17:24:10.577 WARNING [Thread-38] org.apache.catalina.servlets.CGIServlet$CGIRunner.sendToLog stderr line: [Traceback (most recent call last):]
27-Oct-2019 17:24:10.578 WARNING [Thread-38] org.apache.catalina.servlets.CGIServlet$CGIRunner.sendToLog stderr line: [  File "C:\Users\hayde\Desktop\UCI\Fall 2019\EECS 118\MP2\apache-tomcat-9.0.26\webapps\test\WEB-INF\cgi\project_3_edited_detail.py", line 27, in <module>]
27-Oct-2019 17:24:10.579 WARNING [Thread-38] org.apache.catalina.servlets.CGIServlet$CGIRunner.sendToLog stderr line: [    cur.execute(query, title)]
27-Oct-2019 17:24:10.579 WARNING [Thread-38] org.apache.catalina.servlets.CGIServlet$CGIRunner.sendToLog stderr line: [  File "C:\Users\hayde\AppData\Local\Programs\Python\Python36\lib\site-packages\pymysql\cursors.py", line 170, in execute]
27-Oct-2019 17:24:10.581 WARNING [Thread-38] org.apache.catalina.servlets.CGIServlet$CGIRunner.sendToLog stderr line: [    result = self._query(query)]
27-Oct-2019 17:24:10.581 WARNING [Thread-38] org.apache.catalina.servlets.CGIServlet$CGIRunner.sendToLog stderr line: [  File "C:\Users\hayde\AppData\Local\Programs\Python\Python36\lib\site-packages\pymysql\cursors.py", line 328, in _query]
27-Oct-2019 17:24:10.582 WARNING [Thread-38] org.apache.catalina.servlets.CGIServlet$CGIRunner.sendToLog stderr line: [    conn.query(q)]
27-Oct-2019 17:24:10.583 WARNING [Thread-38] org.apache.catalina.servlets.CGIServlet$CGIRunner.sendToLog stderr line: [  File "C:\Users\hayde\AppData\Local\Programs\Python\Python36\lib\site-packages\pymysql\connections.py", line 517, in query]
27-Oct-2019 17:24:10.584 WARNING [Thread-38] org.apache.catalina.servlets.CGIServlet$CGIRunner.sendToLog stderr line: [    self._affected_rows = self._read_query_result(unbuffered=unbuffered)]
27-Oct-2019 17:24:10.585 WARNING [Thread-38] org.apache.catalina.servlets.CGIServlet$CGIRunner.sendToLog stderr line: [  File "C:\Users\hayde\AppData\Local\Programs\Python\Python36\lib\site-packages\pymysql\connections.py", line 732, in _read_query_result]
27-Oct-2019 17:24:10.586 WARNING [Thread-38] org.apache.catalina.servlets.CGIServlet$CGIRunner.sendToLog stderr line: [    result.read()]
27-Oct-2019 17:24:10.586 WARNING [Thread-38] org.apache.catalina.servlets.CGIServlet$CGIRunner.sendToLog stderr line: [  File "C:\Users\hayde\AppData\Local\Programs\Python\Python36\lib\site-packages\pymysql\connections.py", line 1075, in read]
27-Oct-2019 17:24:10.587 WARNING [Thread-38] org.apache.catalina.servlets.CGIServlet$CGIRunner.sendToLog stderr line: [    first_packet = self.connection._read_packet()]
27-Oct-2019 17:24:10.587 WARNING [Thread-38] org.apache.catalina.servlets.CGIServlet$CGIRunner.sendToLog stderr line: [  File "C:\Users\hayde\AppData\Local\Programs\Python\Python36\lib\site-packages\pymysql\connections.py", line 684, in _read_packet]
27-Oct-2019 17:24:10.589 WARNING [Thread-38] org.apache.catalina.servlets.CGIServlet$CGIRunner.sendToLog stderr line: [    packet.check_error()]
27-Oct-2019 17:24:10.590 WARNING [Thread-38] org.apache.catalina.servlets.CGIServlet$CGIRunner.sendToLog stderr line: [  File "C:\Users\hayde\AppData\Local\Programs\Python\Python36\lib\site-packages\pymysql\protocol.py", line 220, in check_error]
27-Oct-2019 17:24:10.590 WARNING [Thread-38] org.apache.catalina.servlets.CGIServlet$CGIRunner.sendToLog stderr line: [    err.raise_mysql_exception(self._data)]
27-Oct-2019 17:24:10.591 WARNING [Thread-38] org.apache.catalina.servlets.CGIServlet$CGIRunner.sendToLog stderr line: [  File "C:\Users\hayde\AppData\Local\Programs\Python\Python36\lib\site-packages\pymysql\err.py", line 109, in raise_mysql_exception]
27-Oct-2019 17:24:10.592 WARNING [Thread-38] org.apache.catalina.servlets.CGIServlet$CGIRunner.sendToLog stderr line: [    raise errorclass(errno, errval)]
27-Oct-2019 17:24:10.593 WARNING [Thread-38] org.apache.catalina.servlets.CGIServlet$CGIRunner.sendToLog stderr line: [pymysql.err.InternalError: (1054, "Unknown column 'title' in 'field list'")]
27-Oct-2019 17:24:10.597 WARNING [Thread-38] org.apache.catalina.servlets.CGIServlet$CGIRunner.sendToLog Received [20] lines on stderr
27-Oct-2019 17:25:25.316 WARNING [Thread-39] org.apache.catalina.servlets.CGIServlet$CGIRunner.sendToLog stderr line: [Traceback (most recent call last):]
27-Oct-2019 17:25:25.316 WARNING [Thread-39] org.apache.catalina.servlets.CGIServlet$CGIRunner.sendToLog stderr line: [  File "C:\Users\hayde\Desktop\UCI\Fall 2019\EECS 118\MP2\apache-tomcat-9.0.26\webapps\test\WEB-INF\cgi\project_3_edited_detail.py", line 27, in <module>]
27-Oct-2019 17:25:25.316 WARNING [Thread-39] org.apache.catalina.servlets.CGIServlet$CGIRunner.sendToLog stderr line: [    cur.execute(query, title)]
27-Oct-2019 17:25:25.319 WARNING [Thread-39] org.apache.catalina.servlets.CGIServlet$CGIRunner.sendToLog stderr line: [  File "C:\Users\hayde\AppData\Local\Programs\Python\Python36\lib\site-packages\pymysql\cursors.py", line 170, in execute]
27-Oct-2019 17:25:25.320 WARNING [Thread-39] org.apache.catalina.servlets.CGIServlet$CGIRunner.sendToLog stderr line: [    result = self._query(query)]
27-Oct-2019 17:25:25.320 WARNING [Thread-39] org.apache.catalina.servlets.CGIServlet$CGIRunner.sendToLog stderr line: [  File "C:\Users\hayde\AppData\Local\Programs\Python\Python36\lib\site-packages\pymysql\cursors.py", line 328, in _query]
27-Oct-2019 17:25:25.321 WARNING [Thread-39] org.apache.catalina.servlets.CGIServlet$CGIRunner.sendToLog stderr line: [    conn.query(q)]
27-Oct-2019 17:25:25.322 WARNING [Thread-39] org.apache.catalina.servlets.CGIServlet$CGIRunner.sendToLog stderr line: [  File "C:\Users\hayde\AppData\Local\Programs\Python\Python36\lib\site-packages\pymysql\connections.py", line 517, in query]
27-Oct-2019 17:25:25.322 WARNING [Thread-39] org.apache.catalina.servlets.CGIServlet$CGIRunner.sendToLog stderr line: [    self._affected_rows = self._read_query_result(unbuffered=unbuffered)]
27-Oct-2019 17:25:25.324 WARNING [Thread-39] org.apache.catalina.servlets.CGIServlet$CGIRunner.sendToLog stderr line: [  File "C:\Users\hayde\AppData\Local\Programs\Python\Python36\lib\site-packages\pymysql\connections.py", line 732, in _read_query_result]
27-Oct-2019 17:25:25.325 WARNING [Thread-39] org.apache.catalina.servlets.CGIServlet$CGIRunner.sendToLog stderr line: [    result.read()]
27-Oct-2019 17:25:25.326 WARNING [Thread-39] org.apache.catalina.servlets.CGIServlet$CGIRunner.sendToLog stderr line: [  File "C:\Users\hayde\AppData\Local\Programs\Python\Python36\lib\site-packages\pymysql\connections.py", line 1075, in read]
27-Oct-2019 17:25:25.327 WARNING [Thread-39] org.apache.catalina.servlets.CGIServlet$CGIRunner.sendToLog stderr line: [    first_packet = self.connection._read_packet()]
27-Oct-2019 17:25:25.327 WARNING [Thread-39] org.apache.catalina.servlets.CGIServlet$CGIRunner.sendToLog stderr line: [  File "C:\Users\hayde\AppData\Local\Programs\Python\Python36\lib\site-packages\pymysql\connections.py", line 684, in _read_packet]
27-Oct-2019 17:25:25.328 WARNING [Thread-39] org.apache.catalina.servlets.CGIServlet$CGIRunner.sendToLog stderr line: [    packet.check_error()]
27-Oct-2019 17:25:25.329 WARNING [Thread-39] org.apache.catalina.servlets.CGIServlet$CGIRunner.sendToLog stderr line: [  File "C:\Users\hayde\AppData\Local\Programs\Python\Python36\lib\site-packages\pymysql\protocol.py", line 220, in check_error]
27-Oct-2019 17:25:25.329 WARNING [Thread-39] org.apache.catalina.servlets.CGIServlet$CGIRunner.sendToLog stderr line: [    err.raise_mysql_exception(self._data)]
27-Oct-2019 17:25:25.331 WARNING [Thread-39] org.apache.catalina.servlets.CGIServlet$CGIRunner.sendToLog stderr line: [  File "C:\Users\hayde\AppData\Local\Programs\Python\Python36\lib\site-packages\pymysql\err.py", line 109, in raise_mysql_exception]
27-Oct-2019 17:25:25.332 WARNING [Thread-39] org.apache.catalina.servlets.CGIServlet$CGIRunner.sendToLog stderr line: [    raise errorclass(errno, errval)]
27-Oct-2019 17:25:25.332 WARNING [Thread-39] org.apache.catalina.servlets.CGIServlet$CGIRunner.sendToLog stderr line: [pymysql.err.InternalError: (1054, "Unknown column 'title' in 'field list'")]
27-Oct-2019 17:25:25.342 WARNING [Thread-39] org.apache.catalina.servlets.CGIServlet$CGIRunner.sendToLog Received [20] lines on stderr
27-Oct-2019 17:26:11.657 WARNING [Thread-40] org.apache.catalina.servlets.CGIServlet$CGIRunner.sendToLog stderr line: [Traceback (most recent call last):]
27-Oct-2019 17:26:11.657 WARNING [Thread-40] org.apache.catalina.servlets.CGIServlet$CGIRunner.sendToLog stderr line: [  File "C:\Users\hayde\Desktop\UCI\Fall 2019\EECS 118\MP2\apache-tomcat-9.0.26\webapps\test\WEB-INF\cgi\project_3_edited_detail.py", line 27, in <module>]
27-Oct-2019 17:26:11.657 WARNING [Thread-40] org.apache.catalina.servlets.CGIServlet$CGIRunner.sendToLog stderr line: [    cur.execute(query, title)]
27-Oct-2019 17:26:11.657 WARNING [Thread-40] org.apache.catalina.servlets.CGIServlet$CGIRunner.sendToLog stderr line: [  File "C:\Users\hayde\AppData\Local\Programs\Python\Python36\lib\site-packages\pymysql\cursors.py", line 170, in execute]
27-Oct-2019 17:26:11.660 WARNING [Thread-40] org.apache.catalina.servlets.CGIServlet$CGIRunner.sendToLog stderr line: [    result = self._query(query)]
27-Oct-2019 17:26:11.661 WARNING [Thread-40] org.apache.catalina.servlets.CGIServlet$CGIRunner.sendToLog stderr line: [  File "C:\Users\hayde\AppData\Local\Programs\Python\Python36\lib\site-packages\pymysql\cursors.py", line 328, in _query]
27-Oct-2019 17:26:11.662 WARNING [Thread-40] org.apache.catalina.servlets.CGIServlet$CGIRunner.sendToLog stderr line: [    conn.query(q)]
27-Oct-2019 17:26:11.663 WARNING [Thread-40] org.apache.catalina.servlets.CGIServlet$CGIRunner.sendToLog stderr line: [  File "C:\Users\hayde\AppData\Local\Programs\Python\Python36\lib\site-packages\pymysql\connections.py", line 517, in query]
27-Oct-2019 17:26:11.664 WARNING [Thread-40] org.apache.catalina.servlets.CGIServlet$CGIRunner.sendToLog stderr line: [    self._affected_rows = self._read_query_result(unbuffered=unbuffered)]
27-Oct-2019 17:26:11.664 WARNING [Thread-40] org.apache.catalina.servlets.CGIServlet$CGIRunner.sendToLog stderr line: [  File "C:\Users\hayde\AppData\Local\Programs\Python\Python36\lib\site-packages\pymysql\connections.py", line 732, in _read_query_result]
27-Oct-2019 17:26:11.666 WARNING [Thread-40] org.apache.catalina.servlets.CGIServlet$CGIRunner.sendToLog stderr line: [    result.read()]
27-Oct-2019 17:26:11.666 WARNING [Thread-40] org.apache.catalina.servlets.CGIServlet$CGIRunner.sendToLog stderr line: [  File "C:\Users\hayde\AppData\Local\Programs\Python\Python36\lib\site-packages\pymysql\connections.py", line 1075, in read]
27-Oct-2019 17:26:11.668 WARNING [Thread-40] org.apache.catalina.servlets.CGIServlet$CGIRunner.sendToLog stderr line: [    first_packet = self.connection._read_packet()]
27-Oct-2019 17:26:11.668 WARNING [Thread-40] org.apache.catalina.servlets.CGIServlet$CGIRunner.sendToLog stderr line: [  File "C:\Users\hayde\AppData\Local\Programs\Python\Python36\lib\site-packages\pymysql\connections.py", line 684, in _read_packet]
27-Oct-2019 17:26:11.668 WARNING [Thread-40] org.apache.catalina.servlets.CGIServlet$CGIRunner.sendToLog stderr line: [    packet.check_error()]
27-Oct-2019 17:26:11.670 WARNING [Thread-40] org.apache.catalina.servlets.CGIServlet$CGIRunner.sendToLog stderr line: [  File "C:\Users\hayde\AppData\Local\Programs\Python\Python36\lib\site-packages\pymysql\protocol.py", line 220, in check_error]
27-Oct-2019 17:26:11.671 WARNING [Thread-40] org.apache.catalina.servlets.CGIServlet$CGIRunner.sendToLog stderr line: [    err.raise_mysql_exception(self._data)]
27-Oct-2019 17:26:11.672 WARNING [Thread-40] org.apache.catalina.servlets.CGIServlet$CGIRunner.sendToLog stderr line: [  File "C:\Users\hayde\AppData\Local\Programs\Python\Python36\lib\site-packages\pymysql\err.py", line 109, in raise_mysql_exception]
27-Oct-2019 17:26:11.673 WARNING [Thread-40] org.apache.catalina.servlets.CGIServlet$CGIRunner.sendToLog stderr line: [    raise errorclass(errno, errval)]
27-Oct-2019 17:26:11.674 WARNING [Thread-40] org.apache.catalina.servlets.CGIServlet$CGIRunner.sendToLog stderr line: [pymysql.err.InternalError: (1054, "Unknown column 'title' in 'field list'")]
27-Oct-2019 17:26:11.682 WARNING [Thread-40] org.apache.catalina.servlets.CGIServlet$CGIRunner.sendToLog Received [20] lines on stderr
27-Oct-2019 17:26:38.377 WARNING [Thread-41] org.apache.catalina.servlets.CGIServlet$CGIRunner.sendToLog stderr line: [Traceback (most recent call last):]
27-Oct-2019 17:26:38.377 WARNING [Thread-41] org.apache.catalina.servlets.CGIServlet$CGIRunner.sendToLog stderr line: [  File "C:\Users\hayde\Desktop\UCI\Fall 2019\EECS 118\MP2\apache-tomcat-9.0.26\webapps\test\WEB-INF\cgi\project_3_edit_detail.py", line 25, in <module>]
27-Oct-2019 17:26:38.377 WARNING [Thread-41] org.apache.catalina.servlets.CGIServlet$CGIRunner.sendToLog stderr line: [    display_detail += "<input type='hidden' name='edited_detail' value='"+detail_id+"'>" + "<input type='hidden' name='gal_name' value='"+gal_name+"'>" + "<input type='submit' value='Confirm'/></form>"]
27-Oct-2019 17:26:38.381 WARNING [Thread-41] org.apache.catalina.servlets.CGIServlet$CGIRunner.sendToLog stderr line: [TypeError: must be str, not NoneType]
27-Oct-2019 17:26:38.398 WARNING [Thread-41] org.apache.catalina.servlets.CGIServlet$CGIRunner.sendToLog Received [4] lines on stderr
27-Oct-2019 17:28:26.819 WARNING [Thread-42] org.apache.catalina.servlets.CGIServlet$CGIRunner.sendToLog stderr line: [Traceback (most recent call last):]
27-Oct-2019 17:28:26.819 WARNING [Thread-42] org.apache.catalina.servlets.CGIServlet$CGIRunner.sendToLog stderr line: [  File "C:\Users\hayde\Desktop\UCI\Fall 2019\EECS 118\MP2\apache-tomcat-9.0.26\webapps\test\WEB-INF\cgi\project_3_edit_detail.py", line 25, in <module>]
27-Oct-2019 17:28:26.821 WARNING [Thread-42] org.apache.catalina.servlets.CGIServlet$CGIRunner.sendToLog stderr line: [    display_detail += "<input type='hidden' name='edited_detail' value='"+detail_id+"'>" + "<input type='hidden' name='gal' value='"+gal_name+"'>" + "<input type='submit' value='Confirm'/></form>"]
27-Oct-2019 17:28:26.822 WARNING [Thread-42] org.apache.catalina.servlets.CGIServlet$CGIRunner.sendToLog stderr line: [TypeError: must be str, not NoneType]
27-Oct-2019 17:28:26.839 WARNING [Thread-42] org.apache.catalina.servlets.CGIServlet$CGIRunner.sendToLog Received [4] lines on stderr
27-Oct-2019 17:29:38.839 WARNING [Thread-44] org.apache.catalina.servlets.CGIServlet$CGIRunner.sendToLog stderr line: [Traceback (most recent call last):]
27-Oct-2019 17:29:38.843 WARNING [Thread-44] org.apache.catalina.servlets.CGIServlet$CGIRunner.sendToLog stderr line: [  File "C:\Users\hayde\Desktop\UCI\Fall 2019\EECS 118\MP2\apache-tomcat-9.0.26\webapps\test\WEB-INF\cgi\project_3_edit_detail.py", line 25, in <module>]
27-Oct-2019 17:29:38.843 WARNING [Thread-44] org.apache.catalina.servlets.CGIServlet$CGIRunner.sendToLog stderr line: [    display_detail += "<input type='hidden' name='edited_detail' value='"+detail_id+"'>" + "<input type='hidden' name='gal' value='"+gal_name+"'>" + "<input type='submit' value='Confirm'/></form>"]
27-Oct-2019 17:29:38.843 WARNING [Thread-44] org.apache.catalina.servlets.CGIServlet$CGIRunner.sendToLog stderr line: [NameError: name 'gal_name' is not defined]
27-Oct-2019 17:29:38.860 WARNING [Thread-44] org.apache.catalina.servlets.CGIServlet$CGIRunner.sendToLog Received [4] lines on stderr
27-Oct-2019 17:32:19.109 WARNING [Thread-46] org.apache.catalina.servlets.CGIServlet$CGIRunner.sendToLog stderr line: [Traceback (most recent call last):]
27-Oct-2019 17:32:19.110 WARNING [Thread-46] org.apache.catalina.servlets.CGIServlet$CGIRunner.sendToLog stderr line: [  File "C:\Users\hayde\Desktop\UCI\Fall 2019\EECS 118\MP2\apache-tomcat-9.0.26\webapps\test\WEB-INF\cgi\project_3_edited_detail.py", line 27, in <module>]
27-Oct-2019 17:32:19.111 WARNING [Thread-46] org.apache.catalina.servlets.CGIServlet$CGIRunner.sendToLog stderr line: [    cur.execute(query, title)]
27-Oct-2019 17:32:19.112 WARNING [Thread-46] org.apache.catalina.servlets.CGIServlet$CGIRunner.sendToLog stderr line: [  File "C:\Users\hayde\AppData\Local\Programs\Python\Python36\lib\site-packages\pymysql\cursors.py", line 170, in execute]
27-Oct-2019 17:32:19.112 WARNING [Thread-46] org.apache.catalina.servlets.CGIServlet$CGIRunner.sendToLog stderr line: [    result = self._query(query)]
27-Oct-2019 17:32:19.112 WARNING [Thread-46] org.apache.catalina.servlets.CGIServlet$CGIRunner.sendToLog stderr line: [  File "C:\Users\hayde\AppData\Local\Programs\Python\Python36\lib\site-packages\pymysql\cursors.py", line 328, in _query]
27-Oct-2019 17:32:19.114 WARNING [Thread-46] org.apache.catalina.servlets.CGIServlet$CGIRunner.sendToLog stderr line: [    conn.query(q)]
27-Oct-2019 17:32:19.115 WARNING [Thread-46] org.apache.catalina.servlets.CGIServlet$CGIRunner.sendToLog stderr line: [  File "C:\Users\hayde\AppData\Local\Programs\Python\Python36\lib\site-packages\pymysql\connections.py", line 517, in query]
27-Oct-2019 17:32:19.116 WARNING [Thread-46] org.apache.catalina.servlets.CGIServlet$CGIRunner.sendToLog stderr line: [    self._affected_rows = self._read_query_result(unbuffered=unbuffered)]
27-Oct-2019 17:32:19.117 WARNING [Thread-46] org.apache.catalina.servlets.CGIServlet$CGIRunner.sendToLog stderr line: [  File "C:\Users\hayde\AppData\Local\Programs\Python\Python36\lib\site-packages\pymysql\connections.py", line 732, in _read_query_result]
27-Oct-2019 17:32:19.118 WARNING [Thread-46] org.apache.catalina.servlets.CGIServlet$CGIRunner.sendToLog stderr line: [    result.read()]
27-Oct-2019 17:32:19.118 WARNING [Thread-46] org.apache.catalina.servlets.CGIServlet$CGIRunner.sendToLog stderr line: [  File "C:\Users\hayde\AppData\Local\Programs\Python\Python36\lib\site-packages\pymysql\connections.py", line 1075, in read]
27-Oct-2019 17:32:19.119 WARNING [Thread-46] org.apache.catalina.servlets.CGIServlet$CGIRunner.sendToLog stderr line: [    first_packet = self.connection._read_packet()]
27-Oct-2019 17:32:19.120 WARNING [Thread-46] org.apache.catalina.servlets.CGIServlet$CGIRunner.sendToLog stderr line: [  File "C:\Users\hayde\AppData\Local\Programs\Python\Python36\lib\site-packages\pymysql\connections.py", line 684, in _read_packet]
27-Oct-2019 17:32:19.120 WARNING [Thread-46] org.apache.catalina.servlets.CGIServlet$CGIRunner.sendToLog stderr line: [    packet.check_error()]
27-Oct-2019 17:32:19.120 WARNING [Thread-46] org.apache.catalina.servlets.CGIServlet$CGIRunner.sendToLog stderr line: [  File "C:\Users\hayde\AppData\Local\Programs\Python\Python36\lib\site-packages\pymysql\protocol.py", line 220, in check_error]
27-Oct-2019 17:32:19.123 WARNING [Thread-46] org.apache.catalina.servlets.CGIServlet$CGIRunner.sendToLog stderr line: [    err.raise_mysql_exception(self._data)]
27-Oct-2019 17:32:19.123 WARNING [Thread-46] org.apache.catalina.servlets.CGIServlet$CGIRunner.sendToLog stderr line: [  File "C:\Users\hayde\AppData\Local\Programs\Python\Python36\lib\site-packages\pymysql\err.py", line 109, in raise_mysql_exception]
27-Oct-2019 17:32:19.124 WARNING [Thread-46] org.apache.catalina.servlets.CGIServlet$CGIRunner.sendToLog stderr line: [    raise errorclass(errno, errval)]
27-Oct-2019 17:32:19.124 WARNING [Thread-46] org.apache.catalina.servlets.CGIServlet$CGIRunner.sendToLog stderr line: [pymysql.err.InternalError: (1054, "Unknown column 'title' in 'field list'")]
27-Oct-2019 17:32:19.131 WARNING [Thread-46] org.apache.catalina.servlets.CGIServlet$CGIRunner.sendToLog Received [20] lines on stderr
27-Oct-2019 17:33:02.792 WARNING [Thread-47] org.apache.catalina.servlets.CGIServlet$CGIRunner.sendToLog stderr line: [Traceback (most recent call last):]
27-Oct-2019 17:33:02.793 WARNING [Thread-47] org.apache.catalina.servlets.CGIServlet$CGIRunner.sendToLog stderr line: [  File "C:\Users\hayde\Desktop\UCI\Fall 2019\EECS 118\MP2\apache-tomcat-9.0.26\webapps\test\WEB-INF\cgi\project_3_edited_detail.py", line 25, in <module>]
27-Oct-2019 17:33:02.794 WARNING [Thread-47] org.apache.catalina.servlets.CGIServlet$CGIRunner.sendToLog stderr line: [    if title !="":]
27-Oct-2019 17:33:02.794 WARNING [Thread-47] org.apache.catalina.servlets.CGIServlet$CGIRunner.sendToLog stderr line: [NameError: name 'title' is not defined]
27-Oct-2019 17:33:02.810 WARNING [Thread-47] org.apache.catalina.servlets.CGIServlet$CGIRunner.sendToLog Received [4] lines on stderr
27-Oct-2019 17:37:20.773 WARNING [Thread-50] org.apache.catalina.servlets.CGIServlet$CGIRunner.sendToLog stderr line: [Traceback (most recent call last):]
27-Oct-2019 17:37:20.773 WARNING [Thread-50] org.apache.catalina.servlets.CGIServlet$CGIRunner.sendToLog stderr line: [  File "C:\Users\hayde\Desktop\UCI\Fall 2019\EECS 118\MP2\apache-tomcat-9.0.26\webapps\test\WEB-INF\cgi\project_3_edited_detail.py", line 27, in <module>]
27-Oct-2019 17:37:20.774 WARNING [Thread-50] org.apache.catalina.servlets.CGIServlet$CGIRunner.sendToLog stderr line: [    cur.execute(query, title)]
27-Oct-2019 17:37:20.774 WARNING [Thread-50] org.apache.catalina.servlets.CGIServlet$CGIRunner.sendToLog stderr line: [  File "C:\Users\hayde\AppData\Local\Programs\Python\Python36\lib\site-packages\pymysql\cursors.py", line 170, in execute]
27-Oct-2019 17:37:20.774 WARNING [Thread-50] org.apache.catalina.servlets.CGIServlet$CGIRunner.sendToLog stderr line: [    result = self._query(query)]
27-Oct-2019 17:37:20.774 WARNING [Thread-50] org.apache.catalina.servlets.CGIServlet$CGIRunner.sendToLog stderr line: [  File "C:\Users\hayde\AppData\Local\Programs\Python\Python36\lib\site-packages\pymysql\cursors.py", line 328, in _query]
27-Oct-2019 17:37:20.779 WARNING [Thread-50] org.apache.catalina.servlets.CGIServlet$CGIRunner.sendToLog stderr line: [    conn.query(q)]
27-Oct-2019 17:37:20.780 WARNING [Thread-50] org.apache.catalina.servlets.CGIServlet$CGIRunner.sendToLog stderr line: [  File "C:\Users\hayde\AppData\Local\Programs\Python\Python36\lib\site-packages\pymysql\connections.py", line 517, in query]
27-Oct-2019 17:37:20.781 WARNING [Thread-50] org.apache.catalina.servlets.CGIServlet$CGIRunner.sendToLog stderr line: [    self._affected_rows = self._read_query_result(unbuffered=unbuffered)]
27-Oct-2019 17:37:20.782 WARNING [Thread-50] org.apache.catalina.servlets.CGIServlet$CGIRunner.sendToLog stderr line: [  File "C:\Users\hayde\AppData\Local\Programs\Python\Python36\lib\site-packages\pymysql\connections.py", line 732, in _read_query_result]
27-Oct-2019 17:37:20.783 WARNING [Thread-50] org.apache.catalina.servlets.CGIServlet$CGIRunner.sendToLog stderr line: [    result.read()]
27-Oct-2019 17:37:20.783 WARNING [Thread-50] org.apache.catalina.servlets.CGIServlet$CGIRunner.sendToLog stderr line: [  File "C:\Users\hayde\AppData\Local\Programs\Python\Python36\lib\site-packages\pymysql\connections.py", line 1075, in read]
27-Oct-2019 17:37:20.784 WARNING [Thread-50] org.apache.catalina.servlets.CGIServlet$CGIRunner.sendToLog stderr line: [    first_packet = self.connection._read_packet()]
27-Oct-2019 17:37:20.784 WARNING [Thread-50] org.apache.catalina.servlets.CGIServlet$CGIRunner.sendToLog stderr line: [  File "C:\Users\hayde\AppData\Local\Programs\Python\Python36\lib\site-packages\pymysql\connections.py", line 684, in _read_packet]
27-Oct-2019 17:37:20.785 WARNING [Thread-50] org.apache.catalina.servlets.CGIServlet$CGIRunner.sendToLog stderr line: [    packet.check_error()]
27-Oct-2019 17:37:20.785 WARNING [Thread-50] org.apache.catalina.servlets.CGIServlet$CGIRunner.sendToLog stderr line: [  File "C:\Users\hayde\AppData\Local\Programs\Python\Python36\lib\site-packages\pymysql\protocol.py", line 220, in check_error]
27-Oct-2019 17:37:20.786 WARNING [Thread-50] org.apache.catalina.servlets.CGIServlet$CGIRunner.sendToLog stderr line: [    err.raise_mysql_exception(self._data)]
27-Oct-2019 17:37:20.786 WARNING [Thread-50] org.apache.catalina.servlets.CGIServlet$CGIRunner.sendToLog stderr line: [  File "C:\Users\hayde\AppData\Local\Programs\Python\Python36\lib\site-packages\pymysql\err.py", line 109, in raise_mysql_exception]
27-Oct-2019 17:37:20.786 WARNING [Thread-50] org.apache.catalina.servlets.CGIServlet$CGIRunner.sendToLog stderr line: [    raise errorclass(errno, errval)]
27-Oct-2019 17:37:20.787 WARNING [Thread-50] org.apache.catalina.servlets.CGIServlet$CGIRunner.sendToLog stderr line: [pymysql.err.InternalError: (1054, "Unknown column 'title' in 'field list'")]
27-Oct-2019 17:37:20.792 WARNING [Thread-50] org.apache.catalina.servlets.CGIServlet$CGIRunner.sendToLog Received [20] lines on stderr
27-Oct-2019 17:39:43.320 WARNING [Thread-51] org.apache.catalina.servlets.CGIServlet$CGIRunner.sendToLog stderr line: [Traceback (most recent call last):]
27-Oct-2019 17:39:43.321 WARNING [Thread-51] org.apache.catalina.servlets.CGIServlet$CGIRunner.sendToLog stderr line: [  File "C:\Users\hayde\Desktop\UCI\Fall 2019\EECS 118\MP2\apache-tomcat-9.0.26\webapps\test\WEB-INF\cgi\project_3_edited_detail.py", line 27, in <module>]
27-Oct-2019 17:39:43.321 WARNING [Thread-51] org.apache.catalina.servlets.CGIServlet$CGIRunner.sendToLog stderr line: [    cur.execute(query, title)]
27-Oct-2019 17:39:43.321 WARNING [Thread-51] org.apache.catalina.servlets.CGIServlet$CGIRunner.sendToLog stderr line: [  File "C:\Users\hayde\AppData\Local\Programs\Python\Python36\lib\site-packages\pymysql\cursors.py", line 170, in execute]
27-Oct-2019 17:39:43.321 WARNING [Thread-51] org.apache.catalina.servlets.CGIServlet$CGIRunner.sendToLog stderr line: [    result = self._query(query)]
27-Oct-2019 17:39:43.323 WARNING [Thread-51] org.apache.catalina.servlets.CGIServlet$CGIRunner.sendToLog stderr line: [  File "C:\Users\hayde\AppData\Local\Programs\Python\Python36\lib\site-packages\pymysql\cursors.py", line 328, in _query]
27-Oct-2019 17:39:43.324 WARNING [Thread-51] org.apache.catalina.servlets.CGIServlet$CGIRunner.sendToLog stderr line: [    conn.query(q)]
27-Oct-2019 17:39:43.325 WARNING [Thread-51] org.apache.catalina.servlets.CGIServlet$CGIRunner.sendToLog stderr line: [  File "C:\Users\hayde\AppData\Local\Programs\Python\Python36\lib\site-packages\pymysql\connections.py", line 517, in query]
27-Oct-2019 17:39:43.325 WARNING [Thread-51] org.apache.catalina.servlets.CGIServlet$CGIRunner.sendToLog stderr line: [    self._affected_rows = self._read_query_result(unbuffered=unbuffered)]
27-Oct-2019 17:39:43.327 WARNING [Thread-51] org.apache.catalina.servlets.CGIServlet$CGIRunner.sendToLog stderr line: [  File "C:\Users\hayde\AppData\Local\Programs\Python\Python36\lib\site-packages\pymysql\connections.py", line 732, in _read_query_result]
27-Oct-2019 17:39:43.328 WARNING [Thread-51] org.apache.catalina.servlets.CGIServlet$CGIRunner.sendToLog stderr line: [    result.read()]
27-Oct-2019 17:39:43.329 WARNING [Thread-51] org.apache.catalina.servlets.CGIServlet$CGIRunner.sendToLog stderr line: [  File "C:\Users\hayde\AppData\Local\Programs\Python\Python36\lib\site-packages\pymysql\connections.py", line 1075, in read]
27-Oct-2019 17:39:43.329 WARNING [Thread-51] org.apache.catalina.servlets.CGIServlet$CGIRunner.sendToLog stderr line: [    first_packet = self.connection._read_packet()]
27-Oct-2019 17:39:43.331 WARNING [Thread-51] org.apache.catalina.servlets.CGIServlet$CGIRunner.sendToLog stderr line: [  File "C:\Users\hayde\AppData\Local\Programs\Python\Python36\lib\site-packages\pymysql\connections.py", line 684, in _read_packet]
27-Oct-2019 17:39:43.334 WARNING [Thread-51] org.apache.catalina.servlets.CGIServlet$CGIRunner.sendToLog stderr line: [    packet.check_error()]
27-Oct-2019 17:39:43.336 WARNING [Thread-51] org.apache.catalina.servlets.CGIServlet$CGIRunner.sendToLog stderr line: [  File "C:\Users\hayde\AppData\Local\Programs\Python\Python36\lib\site-packages\pymysql\protocol.py", line 220, in check_error]
27-Oct-2019 17:39:43.336 WARNING [Thread-51] org.apache.catalina.servlets.CGIServlet$CGIRunner.sendToLog stderr line: [    err.raise_mysql_exception(self._data)]
27-Oct-2019 17:39:43.337 WARNING [Thread-51] org.apache.catalina.servlets.CGIServlet$CGIRunner.sendToLog stderr line: [  File "C:\Users\hayde\AppData\Local\Programs\Python\Python36\lib\site-packages\pymysql\err.py", line 109, in raise_mysql_exception]
27-Oct-2019 17:39:43.337 WARNING [Thread-51] org.apache.catalina.servlets.CGIServlet$CGIRunner.sendToLog stderr line: [    raise errorclass(errno, errval)]
27-Oct-2019 17:39:43.338 WARNING [Thread-51] org.apache.catalina.servlets.CGIServlet$CGIRunner.sendToLog stderr line: [pymysql.err.InternalError: (1054, "Unknown column 'title' in 'field list'")]
27-Oct-2019 17:39:43.339 WARNING [Thread-51] org.apache.catalina.servlets.CGIServlet$CGIRunner.sendToLog Received [20] lines on stderr
27-Oct-2019 17:39:49.245 WARNING [Thread-52] org.apache.catalina.servlets.CGIServlet$CGIRunner.sendToLog stderr line: [Traceback (most recent call last):]
27-Oct-2019 17:39:49.245 WARNING [Thread-52] org.apache.catalina.servlets.CGIServlet$CGIRunner.sendToLog stderr line: [  File "C:\Users\hayde\Desktop\UCI\Fall 2019\EECS 118\MP2\apache-tomcat-9.0.26\webapps\test\WEB-INF\cgi\project_3_edited_detail.py", line 27, in <module>]
27-Oct-2019 17:39:49.246 WARNING [Thread-52] org.apache.catalina.servlets.CGIServlet$CGIRunner.sendToLog stderr line: [    cur.execute(query, title)]
27-Oct-2019 17:39:49.246 WARNING [Thread-52] org.apache.catalina.servlets.CGIServlet$CGIRunner.sendToLog stderr line: [  File "C:\Users\hayde\AppData\Local\Programs\Python\Python36\lib\site-packages\pymysql\cursors.py", line 170, in execute]
27-Oct-2019 17:39:49.246 WARNING [Thread-52] org.apache.catalina.servlets.CGIServlet$CGIRunner.sendToLog stderr line: [    result = self._query(query)]
27-Oct-2019 17:39:49.248 WARNING [Thread-52] org.apache.catalina.servlets.CGIServlet$CGIRunner.sendToLog stderr line: [  File "C:\Users\hayde\AppData\Local\Programs\Python\Python36\lib\site-packages\pymysql\cursors.py", line 328, in _query]
27-Oct-2019 17:39:49.248 WARNING [Thread-52] org.apache.catalina.servlets.CGIServlet$CGIRunner.sendToLog stderr line: [    conn.query(q)]
27-Oct-2019 17:39:49.250 WARNING [Thread-52] org.apache.catalina.servlets.CGIServlet$CGIRunner.sendToLog stderr line: [  File "C:\Users\hayde\AppData\Local\Programs\Python\Python36\lib\site-packages\pymysql\connections.py", line 517, in query]
27-Oct-2019 17:39:49.251 WARNING [Thread-52] org.apache.catalina.servlets.CGIServlet$CGIRunner.sendToLog stderr line: [    self._affected_rows = self._read_query_result(unbuffered=unbuffered)]
27-Oct-2019 17:39:49.252 WARNING [Thread-52] org.apache.catalina.servlets.CGIServlet$CGIRunner.sendToLog stderr line: [  File "C:\Users\hayde\AppData\Local\Programs\Python\Python36\lib\site-packages\pymysql\connections.py", line 732, in _read_query_result]
27-Oct-2019 17:39:49.253 WARNING [Thread-52] org.apache.catalina.servlets.CGIServlet$CGIRunner.sendToLog stderr line: [    result.read()]
27-Oct-2019 17:39:49.253 WARNING [Thread-52] org.apache.catalina.servlets.CGIServlet$CGIRunner.sendToLog stderr line: [  File "C:\Users\hayde\AppData\Local\Programs\Python\Python36\lib\site-packages\pymysql\connections.py", line 1075, in read]
27-Oct-2019 17:39:49.254 WARNING [Thread-52] org.apache.catalina.servlets.CGIServlet$CGIRunner.sendToLog stderr line: [    first_packet = self.connection._read_packet()]
27-Oct-2019 17:39:49.256 WARNING [Thread-52] org.apache.catalina.servlets.CGIServlet$CGIRunner.sendToLog stderr line: [  File "C:\Users\hayde\AppData\Local\Programs\Python\Python36\lib\site-packages\pymysql\connections.py", line 684, in _read_packet]
27-Oct-2019 17:39:49.256 WARNING [Thread-52] org.apache.catalina.servlets.CGIServlet$CGIRunner.sendToLog stderr line: [    packet.check_error()]
27-Oct-2019 17:39:49.258 WARNING [Thread-52] org.apache.catalina.servlets.CGIServlet$CGIRunner.sendToLog stderr line: [  File "C:\Users\hayde\AppData\Local\Programs\Python\Python36\lib\site-packages\pymysql\protocol.py", line 220, in check_error]
27-Oct-2019 17:39:49.258 WARNING [Thread-52] org.apache.catalina.servlets.CGIServlet$CGIRunner.sendToLog stderr line: [    err.raise_mysql_exception(self._data)]
27-Oct-2019 17:39:49.260 WARNING [Thread-52] org.apache.catalina.servlets.CGIServlet$CGIRunner.sendToLog stderr line: [  File "C:\Users\hayde\AppData\Local\Programs\Python\Python36\lib\site-packages\pymysql\err.py", line 109, in raise_mysql_exception]
27-Oct-2019 17:39:49.261 WARNING [Thread-52] org.apache.catalina.servlets.CGIServlet$CGIRunner.sendToLog stderr line: [    raise errorclass(errno, errval)]
27-Oct-2019 17:39:49.262 WARNING [Thread-52] org.apache.catalina.servlets.CGIServlet$CGIRunner.sendToLog stderr line: [pymysql.err.InternalError: (1054, "Unknown column 'title' in 'field list'")]
27-Oct-2019 17:39:49.267 WARNING [Thread-52] org.apache.catalina.servlets.CGIServlet$CGIRunner.sendToLog Received [20] lines on stderr
27-Oct-2019 17:40:08.925 WARNING [Thread-53] org.apache.catalina.servlets.CGIServlet$CGIRunner.sendToLog stderr line: [Traceback (most recent call last):]
27-Oct-2019 17:40:08.926 WARNING [Thread-53] org.apache.catalina.servlets.CGIServlet$CGIRunner.sendToLog stderr line: [  File "C:\Users\hayde\Desktop\UCI\Fall 2019\EECS 118\MP2\apache-tomcat-9.0.26\webapps\test\WEB-INF\cgi\project_3_edited_detail.py", line 59, in <module>]
27-Oct-2019 17:40:08.927 WARNING [Thread-53] org.apache.catalina.servlets.CGIServlet$CGIRunner.sendToLog stderr line: [    display = "<form enctype='multipart/form-data' action='/test/cgi-bin/project_3_gallery1.py' method='POST'><input type='hidden' name='gal_name' value='"+gallery_name+"'><button type='submit'>Go Back</button></form>"]
27-Oct-2019 17:40:08.927 WARNING [Thread-53] org.apache.catalina.servlets.CGIServlet$CGIRunner.sendToLog stderr line: [TypeError: must be str, not NoneType]
27-Oct-2019 17:40:08.945 WARNING [Thread-53] org.apache.catalina.servlets.CGIServlet$CGIRunner.sendToLog Received [4] lines on stderr
27-Oct-2019 17:40:34.447 WARNING [Thread-55] org.apache.catalina.servlets.CGIServlet$CGIRunner.sendToLog stderr line: [Traceback (most recent call last):]
27-Oct-2019 17:40:34.451 WARNING [Thread-55] org.apache.catalina.servlets.CGIServlet$CGIRunner.sendToLog stderr line: [  File "C:\Users\hayde\Desktop\UCI\Fall 2019\EECS 118\MP2\apache-tomcat-9.0.26\webapps\test\WEB-INF\cgi\project_3_edited_detail.py", line 66, in <module>]
27-Oct-2019 17:40:34.452 WARNING [Thread-55] org.apache.catalina.servlets.CGIServlet$CGIRunner.sendToLog stderr line: [    print(artist)]
27-Oct-2019 17:40:34.453 WARNING [Thread-55] org.apache.catalina.servlets.CGIServlet$CGIRunner.sendToLog stderr line: [NameError: name 'artist' is not defined]
27-Oct-2019 17:40:34.468 WARNING [Thread-55] org.apache.catalina.servlets.CGIServlet$CGIRunner.sendToLog Received [4] lines on stderr
27-Oct-2019 17:42:38.727 WARNING [Thread-62] org.apache.catalina.servlets.CGIServlet$CGIRunner.sendToLog stderr line: [Traceback (most recent call last):]
27-Oct-2019 17:42:38.727 WARNING [Thread-62] org.apache.catalina.servlets.CGIServlet$CGIRunner.sendToLog stderr line: [  File "C:\Users\hayde\Desktop\UCI\Fall 2019\EECS 118\MP2\apache-tomcat-9.0.26\webapps\test\WEB-INF\cgi\project_3_edited_detail.py", line 27, in <module>]
27-Oct-2019 17:42:38.727 WARNING [Thread-62] org.apache.catalina.servlets.CGIServlet$CGIRunner.sendToLog stderr line: [    cur.execute(query, title)]
27-Oct-2019 17:42:38.727 WARNING [Thread-62] org.apache.catalina.servlets.CGIServlet$CGIRunner.sendToLog stderr line: [  File "C:\Users\hayde\AppData\Local\Programs\Python\Python36\lib\site-packages\pymysql\cursors.py", line 170, in execute]
27-Oct-2019 17:42:38.727 WARNING [Thread-62] org.apache.catalina.servlets.CGIServlet$CGIRunner.sendToLog stderr line: [    result = self._query(query)]
27-Oct-2019 17:42:38.731 WARNING [Thread-62] org.apache.catalina.servlets.CGIServlet$CGIRunner.sendToLog stderr line: [  File "C:\Users\hayde\AppData\Local\Programs\Python\Python36\lib\site-packages\pymysql\cursors.py", line 328, in _query]
27-Oct-2019 17:42:38.732 WARNING [Thread-62] org.apache.catalina.servlets.CGIServlet$CGIRunner.sendToLog stderr line: [    conn.query(q)]
27-Oct-2019 17:42:38.733 WARNING [Thread-62] org.apache.catalina.servlets.CGIServlet$CGIRunner.sendToLog stderr line: [  File "C:\Users\hayde\AppData\Local\Programs\Python\Python36\lib\site-packages\pymysql\connections.py", line 517, in query]
27-Oct-2019 17:42:38.733 WARNING [Thread-62] org.apache.catalina.servlets.CGIServlet$CGIRunner.sendToLog stderr line: [    self._affected_rows = self._read_query_result(unbuffered=unbuffered)]
27-Oct-2019 17:42:38.734 WARNING [Thread-62] org.apache.catalina.servlets.CGIServlet$CGIRunner.sendToLog stderr line: [  File "C:\Users\hayde\AppData\Local\Programs\Python\Python36\lib\site-packages\pymysql\connections.py", line 732, in _read_query_result]
27-Oct-2019 17:42:38.735 WARNING [Thread-62] org.apache.catalina.servlets.CGIServlet$CGIRunner.sendToLog stderr line: [    result.read()]
27-Oct-2019 17:42:38.736 WARNING [Thread-62] org.apache.catalina.servlets.CGIServlet$CGIRunner.sendToLog stderr line: [  File "C:\Users\hayde\AppData\Local\Programs\Python\Python36\lib\site-packages\pymysql\connections.py", line 1075, in read]
27-Oct-2019 17:42:38.737 WARNING [Thread-62] org.apache.catalina.servlets.CGIServlet$CGIRunner.sendToLog stderr line: [    first_packet = self.connection._read_packet()]
27-Oct-2019 17:42:38.738 WARNING [Thread-62] org.apache.catalina.servlets.CGIServlet$CGIRunner.sendToLog stderr line: [  File "C:\Users\hayde\AppData\Local\Programs\Python\Python36\lib\site-packages\pymysql\connections.py", line 684, in _read_packet]
27-Oct-2019 17:42:38.739 WARNING [Thread-62] org.apache.catalina.servlets.CGIServlet$CGIRunner.sendToLog stderr line: [    packet.check_error()]
27-Oct-2019 17:42:38.739 WARNING [Thread-62] org.apache.catalina.servlets.CGIServlet$CGIRunner.sendToLog stderr line: [  File "C:\Users\hayde\AppData\Local\Programs\Python\Python36\lib\site-packages\pymysql\protocol.py", line 220, in check_error]
27-Oct-2019 17:42:38.740 WARNING [Thread-62] org.apache.catalina.servlets.CGIServlet$CGIRunner.sendToLog stderr line: [    err.raise_mysql_exception(self._data)]
27-Oct-2019 17:42:38.740 WARNING [Thread-62] org.apache.catalina.servlets.CGIServlet$CGIRunner.sendToLog stderr line: [  File "C:\Users\hayde\AppData\Local\Programs\Python\Python36\lib\site-packages\pymysql\err.py", line 109, in raise_mysql_exception]
27-Oct-2019 17:42:38.741 WARNING [Thread-62] org.apache.catalina.servlets.CGIServlet$CGIRunner.sendToLog stderr line: [    raise errorclass(errno, errval)]
27-Oct-2019 17:42:38.741 WARNING [Thread-62] org.apache.catalina.servlets.CGIServlet$CGIRunner.sendToLog stderr line: [pymysql.err.InternalError: (1054, "Unknown column 'title' in 'field list'")]
27-Oct-2019 17:42:38.748 WARNING [Thread-62] org.apache.catalina.servlets.CGIServlet$CGIRunner.sendToLog Received [20] lines on stderr
27-Oct-2019 17:44:26.672 WARNING [Thread-63] org.apache.catalina.servlets.CGIServlet$CGIRunner.sendToLog stderr line: [Traceback (most recent call last):]
27-Oct-2019 17:44:26.672 WARNING [Thread-63] org.apache.catalina.servlets.CGIServlet$CGIRunner.sendToLog stderr line: [  File "C:\Users\hayde\Desktop\UCI\Fall 2019\EECS 118\MP2\apache-tomcat-9.0.26\webapps\test\WEB-INF\cgi\project_3_edited_detail.py", line 27, in <module>]
27-Oct-2019 17:44:26.672 WARNING [Thread-63] org.apache.catalina.servlets.CGIServlet$CGIRunner.sendToLog stderr line: [    cur.execute(query, title)]
27-Oct-2019 17:44:26.674 WARNING [Thread-63] org.apache.catalina.servlets.CGIServlet$CGIRunner.sendToLog stderr line: [  File "C:\Users\hayde\AppData\Local\Programs\Python\Python36\lib\site-packages\pymysql\cursors.py", line 170, in execute]
27-Oct-2019 17:44:26.674 WARNING [Thread-63] org.apache.catalina.servlets.CGIServlet$CGIRunner.sendToLog stderr line: [    result = self._query(query)]
27-Oct-2019 17:44:26.675 WARNING [Thread-63] org.apache.catalina.servlets.CGIServlet$CGIRunner.sendToLog stderr line: [  File "C:\Users\hayde\AppData\Local\Programs\Python\Python36\lib\site-packages\pymysql\cursors.py", line 328, in _query]
27-Oct-2019 17:44:26.675 WARNING [Thread-63] org.apache.catalina.servlets.CGIServlet$CGIRunner.sendToLog stderr line: [    conn.query(q)]
27-Oct-2019 17:44:26.677 WARNING [Thread-63] org.apache.catalina.servlets.CGIServlet$CGIRunner.sendToLog stderr line: [  File "C:\Users\hayde\AppData\Local\Programs\Python\Python36\lib\site-packages\pymysql\connections.py", line 517, in query]
27-Oct-2019 17:44:26.677 WARNING [Thread-63] org.apache.catalina.servlets.CGIServlet$CGIRunner.sendToLog stderr line: [    self._affected_rows = self._read_query_result(unbuffered=unbuffered)]
27-Oct-2019 17:44:26.678 WARNING [Thread-63] org.apache.catalina.servlets.CGIServlet$CGIRunner.sendToLog stderr line: [  File "C:\Users\hayde\AppData\Local\Programs\Python\Python36\lib\site-packages\pymysql\connections.py", line 732, in _read_query_result]
27-Oct-2019 17:44:26.678 WARNING [Thread-63] org.apache.catalina.servlets.CGIServlet$CGIRunner.sendToLog stderr line: [    result.read()]
27-Oct-2019 17:44:26.679 WARNING [Thread-63] org.apache.catalina.servlets.CGIServlet$CGIRunner.sendToLog stderr line: [  File "C:\Users\hayde\AppData\Local\Programs\Python\Python36\lib\site-packages\pymysql\connections.py", line 1075, in read]
27-Oct-2019 17:44:26.680 WARNING [Thread-63] org.apache.catalina.servlets.CGIServlet$CGIRunner.sendToLog stderr line: [    first_packet = self.connection._read_packet()]
27-Oct-2019 17:44:26.681 WARNING [Thread-63] org.apache.catalina.servlets.CGIServlet$CGIRunner.sendToLog stderr line: [  File "C:\Users\hayde\AppData\Local\Programs\Python\Python36\lib\site-packages\pymysql\connections.py", line 684, in _read_packet]
27-Oct-2019 17:44:26.682 WARNING [Thread-63] org.apache.catalina.servlets.CGIServlet$CGIRunner.sendToLog stderr line: [    packet.check_error()]
27-Oct-2019 17:44:26.682 WARNING [Thread-63] org.apache.catalina.servlets.CGIServlet$CGIRunner.sendToLog stderr line: [  File "C:\Users\hayde\AppData\Local\Programs\Python\Python36\lib\site-packages\pymysql\protocol.py", line 220, in check_error]
27-Oct-2019 17:44:26.683 WARNING [Thread-63] org.apache.catalina.servlets.CGIServlet$CGIRunner.sendToLog stderr line: [    err.raise_mysql_exception(self._data)]
27-Oct-2019 17:44:26.684 WARNING [Thread-63] org.apache.catalina.servlets.CGIServlet$CGIRunner.sendToLog stderr line: [  File "C:\Users\hayde\AppData\Local\Programs\Python\Python36\lib\site-packages\pymysql\err.py", line 109, in raise_mysql_exception]
27-Oct-2019 17:44:26.684 WARNING [Thread-63] org.apache.catalina.servlets.CGIServlet$CGIRunner.sendToLog stderr line: [    raise errorclass(errno, errval)]
27-Oct-2019 17:44:26.685 WARNING [Thread-63] org.apache.catalina.servlets.CGIServlet$CGIRunner.sendToLog stderr line: [pymysql.err.InternalError: (1054, "Unknown column 'title' in 'field list'")]
27-Oct-2019 17:44:26.690 WARNING [Thread-63] org.apache.catalina.servlets.CGIServlet$CGIRunner.sendToLog Received [20] lines on stderr
27-Oct-2019 17:47:30.503 WARNING [Thread-64] org.apache.catalina.servlets.CGIServlet$CGIRunner.sendToLog stderr line: [Traceback (most recent call last):]
27-Oct-2019 17:47:30.504 WARNING [Thread-64] org.apache.catalina.servlets.CGIServlet$CGIRunner.sendToLog stderr line: [  File "C:\Users\hayde\Desktop\UCI\Fall 2019\EECS 118\MP2\apache-tomcat-9.0.26\webapps\test\WEB-INF\cgi\project_3_edited_detail.py", line 27, in <module>]
27-Oct-2019 17:47:30.505 WARNING [Thread-64] org.apache.catalina.servlets.CGIServlet$CGIRunner.sendToLog stderr line: [    cur.execute(query, title)]
27-Oct-2019 17:47:30.506 WARNING [Thread-64] org.apache.catalina.servlets.CGIServlet$CGIRunner.sendToLog stderr line: [  File "C:\Users\hayde\AppData\Local\Programs\Python\Python36\lib\site-packages\pymysql\cursors.py", line 170, in execute]
27-Oct-2019 17:47:30.506 WARNING [Thread-64] org.apache.catalina.servlets.CGIServlet$CGIRunner.sendToLog stderr line: [    result = self._query(query)]
27-Oct-2019 17:47:30.506 WARNING [Thread-64] org.apache.catalina.servlets.CGIServlet$CGIRunner.sendToLog stderr line: [  File "C:\Users\hayde\AppData\Local\Programs\Python\Python36\lib\site-packages\pymysql\cursors.py", line 328, in _query]
27-Oct-2019 17:47:30.508 WARNING [Thread-64] org.apache.catalina.servlets.CGIServlet$CGIRunner.sendToLog stderr line: [    conn.query(q)]
27-Oct-2019 17:47:30.509 WARNING [Thread-64] org.apache.catalina.servlets.CGIServlet$CGIRunner.sendToLog stderr line: [  File "C:\Users\hayde\AppData\Local\Programs\Python\Python36\lib\site-packages\pymysql\connections.py", line 517, in query]
27-Oct-2019 17:47:30.510 WARNING [Thread-64] org.apache.catalina.servlets.CGIServlet$CGIRunner.sendToLog stderr line: [    self._affected_rows = self._read_query_result(unbuffered=unbuffered)]
27-Oct-2019 17:47:30.511 WARNING [Thread-64] org.apache.catalina.servlets.CGIServlet$CGIRunner.sendToLog stderr line: [  File "C:\Users\hayde\AppData\Local\Programs\Python\Python36\lib\site-packages\pymysql\connections.py", line 732, in _read_query_result]
27-Oct-2019 17:47:30.512 WARNING [Thread-64] org.apache.catalina.servlets.CGIServlet$CGIRunner.sendToLog stderr line: [    result.read()]
27-Oct-2019 17:47:30.513 WARNING [Thread-64] org.apache.catalina.servlets.CGIServlet$CGIRunner.sendToLog stderr line: [  File "C:\Users\hayde\AppData\Local\Programs\Python\Python36\lib\site-packages\pymysql\connections.py", line 1075, in read]
27-Oct-2019 17:47:30.514 WARNING [Thread-64] org.apache.catalina.servlets.CGIServlet$CGIRunner.sendToLog stderr line: [    first_packet = self.connection._read_packet()]
27-Oct-2019 17:47:30.514 WARNING [Thread-64] org.apache.catalina.servlets.CGIServlet$CGIRunner.sendToLog stderr line: [  File "C:\Users\hayde\AppData\Local\Programs\Python\Python36\lib\site-packages\pymysql\connections.py", line 684, in _read_packet]
27-Oct-2019 17:47:30.515 WARNING [Thread-64] org.apache.catalina.servlets.CGIServlet$CGIRunner.sendToLog stderr line: [    packet.check_error()]
27-Oct-2019 17:47:30.515 WARNING [Thread-64] org.apache.catalina.servlets.CGIServlet$CGIRunner.sendToLog stderr line: [  File "C:\Users\hayde\AppData\Local\Programs\Python\Python36\lib\site-packages\pymysql\protocol.py", line 220, in check_error]
27-Oct-2019 17:47:30.516 WARNING [Thread-64] org.apache.catalina.servlets.CGIServlet$CGIRunner.sendToLog stderr line: [    err.raise_mysql_exception(self._data)]
27-Oct-2019 17:47:30.516 WARNING [Thread-64] org.apache.catalina.servlets.CGIServlet$CGIRunner.sendToLog stderr line: [  File "C:\Users\hayde\AppData\Local\Programs\Python\Python36\lib\site-packages\pymysql\err.py", line 109, in raise_mysql_exception]
27-Oct-2019 17:47:30.517 WARNING [Thread-64] org.apache.catalina.servlets.CGIServlet$CGIRunner.sendToLog stderr line: [    raise errorclass(errno, errval)]
27-Oct-2019 17:47:30.517 WARNING [Thread-64] org.apache.catalina.servlets.CGIServlet$CGIRunner.sendToLog stderr line: [pymysql.err.InternalError: (1054, "Unknown column 'title' in 'field list'")]
27-Oct-2019 17:47:30.525 WARNING [Thread-64] org.apache.catalina.servlets.CGIServlet$CGIRunner.sendToLog Received [20] lines on stderr
27-Oct-2019 17:51:58.405 WARNING [Thread-66] org.apache.catalina.servlets.CGIServlet$CGIRunner.sendToLog stderr line: [Traceback (most recent call last):]
27-Oct-2019 17:51:58.405 WARNING [Thread-66] org.apache.catalina.servlets.CGIServlet$CGIRunner.sendToLog stderr line: [  File "C:\Users\hayde\Desktop\UCI\Fall 2019\EECS 118\MP2\apache-tomcat-9.0.26\webapps\test\WEB-INF\cgi\project_3_edited_detail.py", line 28, in <module>]
27-Oct-2019 17:51:58.405 WARNING [Thread-66] org.apache.catalina.servlets.CGIServlet$CGIRunner.sendToLog stderr line: [    cur.execute(query, title)]
27-Oct-2019 17:51:58.409 WARNING [Thread-66] org.apache.catalina.servlets.CGIServlet$CGIRunner.sendToLog stderr line: [  File "C:\Users\hayde\AppData\Local\Programs\Python\Python36\lib\site-packages\pymysql\cursors.py", line 170, in execute]
27-Oct-2019 17:51:58.410 WARNING [Thread-66] org.apache.catalina.servlets.CGIServlet$CGIRunner.sendToLog stderr line: [    result = self._query(query)]
27-Oct-2019 17:51:58.411 WARNING [Thread-66] org.apache.catalina.servlets.CGIServlet$CGIRunner.sendToLog stderr line: [  File "C:\Users\hayde\AppData\Local\Programs\Python\Python36\lib\site-packages\pymysql\cursors.py", line 328, in _query]
27-Oct-2019 17:51:58.412 WARNING [Thread-66] org.apache.catalina.servlets.CGIServlet$CGIRunner.sendToLog stderr line: [    conn.query(q)]
27-Oct-2019 17:51:58.413 WARNING [Thread-66] org.apache.catalina.servlets.CGIServlet$CGIRunner.sendToLog stderr line: [  File "C:\Users\hayde\AppData\Local\Programs\Python\Python36\lib\site-packages\pymysql\connections.py", line 517, in query]
27-Oct-2019 17:51:58.414 WARNING [Thread-66] org.apache.catalina.servlets.CGIServlet$CGIRunner.sendToLog stderr line: [    self._affected_rows = self._read_query_result(unbuffered=unbuffered)]
27-Oct-2019 17:51:58.414 WARNING [Thread-66] org.apache.catalina.servlets.CGIServlet$CGIRunner.sendToLog stderr line: [  File "C:\Users\hayde\AppData\Local\Programs\Python\Python36\lib\site-packages\pymysql\connections.py", line 732, in _read_query_result]
27-Oct-2019 17:51:58.415 WARNING [Thread-66] org.apache.catalina.servlets.CGIServlet$CGIRunner.sendToLog stderr line: [    result.read()]
27-Oct-2019 17:51:58.416 WARNING [Thread-66] org.apache.catalina.servlets.CGIServlet$CGIRunner.sendToLog stderr line: [  File "C:\Users\hayde\AppData\Local\Programs\Python\Python36\lib\site-packages\pymysql\connections.py", line 1075, in read]
27-Oct-2019 17:51:58.416 WARNING [Thread-66] org.apache.catalina.servlets.CGIServlet$CGIRunner.sendToLog stderr line: [    first_packet = self.connection._read_packet()]
27-Oct-2019 17:51:58.418 WARNING [Thread-66] org.apache.catalina.servlets.CGIServlet$CGIRunner.sendToLog stderr line: [  File "C:\Users\hayde\AppData\Local\Programs\Python\Python36\lib\site-packages\pymysql\connections.py", line 684, in _read_packet]
27-Oct-2019 17:51:58.419 WARNING [Thread-66] org.apache.catalina.servlets.CGIServlet$CGIRunner.sendToLog stderr line: [    packet.check_error()]
27-Oct-2019 17:51:58.420 WARNING [Thread-66] org.apache.catalina.servlets.CGIServlet$CGIRunner.sendToLog stderr line: [  File "C:\Users\hayde\AppData\Local\Programs\Python\Python36\lib\site-packages\pymysql\protocol.py", line 220, in check_error]
27-Oct-2019 17:51:58.420 WARNING [Thread-66] org.apache.catalina.servlets.CGIServlet$CGIRunner.sendToLog stderr line: [    err.raise_mysql_exception(self._data)]
27-Oct-2019 17:51:58.421 WARNING [Thread-66] org.apache.catalina.servlets.CGIServlet$CGIRunner.sendToLog stderr line: [  File "C:\Users\hayde\AppData\Local\Programs\Python\Python36\lib\site-packages\pymysql\err.py", line 109, in raise_mysql_exception]
27-Oct-2019 17:51:58.421 WARNING [Thread-66] org.apache.catalina.servlets.CGIServlet$CGIRunner.sendToLog stderr line: [    raise errorclass(errno, errval)]
27-Oct-2019 17:51:58.423 WARNING [Thread-66] org.apache.catalina.servlets.CGIServlet$CGIRunner.sendToLog stderr line: [pymysql.err.InternalError: (1054, "Unknown column 'title' in 'field list'")]
27-Oct-2019 17:51:58.431 WARNING [Thread-66] org.apache.catalina.servlets.CGIServlet$CGIRunner.sendToLog Received [20] lines on stderr
27-Oct-2019 17:54:03.925 WARNING [Thread-67] org.apache.catalina.servlets.CGIServlet$CGIRunner.sendToLog stderr line: [Traceback (most recent call last):]
27-Oct-2019 17:54:03.926 WARNING [Thread-67] org.apache.catalina.servlets.CGIServlet$CGIRunner.sendToLog stderr line: [  File "C:\Users\hayde\Desktop\UCI\Fall 2019\EECS 118\MP2\apache-tomcat-9.0.26\webapps\test\WEB-INF\cgi\project_3_edited_detail.py", line 28, in <module>]
27-Oct-2019 17:54:03.927 WARNING [Thread-67] org.apache.catalina.servlets.CGIServlet$CGIRunner.sendToLog stderr line: [    cur.execute(query, title)]
27-Oct-2019 17:54:03.927 WARNING [Thread-67] org.apache.catalina.servlets.CGIServlet$CGIRunner.sendToLog stderr line: [  File "C:\Users\hayde\AppData\Local\Programs\Python\Python36\lib\site-packages\pymysql\cursors.py", line 170, in execute]
27-Oct-2019 17:54:03.928 WARNING [Thread-67] org.apache.catalina.servlets.CGIServlet$CGIRunner.sendToLog stderr line: [    result = self._query(query)]
27-Oct-2019 17:54:03.928 WARNING [Thread-67] org.apache.catalina.servlets.CGIServlet$CGIRunner.sendToLog stderr line: [  File "C:\Users\hayde\AppData\Local\Programs\Python\Python36\lib\site-packages\pymysql\cursors.py", line 328, in _query]
27-Oct-2019 17:54:03.930 WARNING [Thread-67] org.apache.catalina.servlets.CGIServlet$CGIRunner.sendToLog stderr line: [    conn.query(q)]
27-Oct-2019 17:54:03.931 WARNING [Thread-67] org.apache.catalina.servlets.CGIServlet$CGIRunner.sendToLog stderr line: [  File "C:\Users\hayde\AppData\Local\Programs\Python\Python36\lib\site-packages\pymysql\connections.py", line 517, in query]
27-Oct-2019 17:54:03.932 WARNING [Thread-67] org.apache.catalina.servlets.CGIServlet$CGIRunner.sendToLog stderr line: [    self._affected_rows = self._read_query_result(unbuffered=unbuffered)]
27-Oct-2019 17:54:03.933 WARNING [Thread-67] org.apache.catalina.servlets.CGIServlet$CGIRunner.sendToLog stderr line: [  File "C:\Users\hayde\AppData\Local\Programs\Python\Python36\lib\site-packages\pymysql\connections.py", line 732, in _read_query_result]
27-Oct-2019 17:54:03.933 WARNING [Thread-67] org.apache.catalina.servlets.CGIServlet$CGIRunner.sendToLog stderr line: [    result.read()]
27-Oct-2019 17:54:03.934 WARNING [Thread-67] org.apache.catalina.servlets.CGIServlet$CGIRunner.sendToLog stderr line: [  File "C:\Users\hayde\AppData\Local\Programs\Python\Python36\lib\site-packages\pymysql\connections.py", line 1075, in read]
27-Oct-2019 17:54:03.935 WARNING [Thread-67] org.apache.catalina.servlets.CGIServlet$CGIRunner.sendToLog stderr line: [    first_packet = self.connection._read_packet()]
27-Oct-2019 17:54:03.935 WARNING [Thread-67] org.apache.catalina.servlets.CGIServlet$CGIRunner.sendToLog stderr line: [  File "C:\Users\hayde\AppData\Local\Programs\Python\Python36\lib\site-packages\pymysql\connections.py", line 684, in _read_packet]
27-Oct-2019 17:54:03.935 WARNING [Thread-67] org.apache.catalina.servlets.CGIServlet$CGIRunner.sendToLog stderr line: [    packet.check_error()]
27-Oct-2019 17:54:03.935 WARNING [Thread-67] org.apache.catalina.servlets.CGIServlet$CGIRunner.sendToLog stderr line: [  File "C:\Users\hayde\AppData\Local\Programs\Python\Python36\lib\site-packages\pymysql\protocol.py", line 220, in check_error]
27-Oct-2019 17:54:03.938 WARNING [Thread-67] org.apache.catalina.servlets.CGIServlet$CGIRunner.sendToLog stderr line: [    err.raise_mysql_exception(self._data)]
27-Oct-2019 17:54:03.938 WARNING [Thread-67] org.apache.catalina.servlets.CGIServlet$CGIRunner.sendToLog stderr line: [  File "C:\Users\hayde\AppData\Local\Programs\Python\Python36\lib\site-packages\pymysql\err.py", line 109, in raise_mysql_exception]
27-Oct-2019 17:54:03.939 WARNING [Thread-67] org.apache.catalina.servlets.CGIServlet$CGIRunner.sendToLog stderr line: [    raise errorclass(errno, errval)]
27-Oct-2019 17:54:03.940 WARNING [Thread-67] org.apache.catalina.servlets.CGIServlet$CGIRunner.sendToLog stderr line: [pymysql.err.InternalError: (1054, "Unknown column 'title' in 'field list'")]
27-Oct-2019 17:54:03.945 WARNING [Thread-67] org.apache.catalina.servlets.CGIServlet$CGIRunner.sendToLog Received [20] lines on stderr
27-Oct-2019 18:01:46.085 WARNING [Thread-71] org.apache.catalina.servlets.CGIServlet$CGIRunner.sendToLog stderr line: [Traceback (most recent call last):]
27-Oct-2019 18:01:46.089 WARNING [Thread-71] org.apache.catalina.servlets.CGIServlet$CGIRunner.sendToLog stderr line: [  File "C:\Users\hayde\Desktop\UCI\Fall 2019\EECS 118\MP2\apache-tomcat-9.0.26\webapps\test\WEB-INF\cgi\project_3_edited_detail.py", line 28, in <module>]
27-Oct-2019 18:01:46.090 WARNING [Thread-71] org.apache.catalina.servlets.CGIServlet$CGIRunner.sendToLog stderr line: [    cur.execute(query, title)]
27-Oct-2019 18:01:46.091 WARNING [Thread-71] org.apache.catalina.servlets.CGIServlet$CGIRunner.sendToLog stderr line: [  File "C:\Users\hayde\AppData\Local\Programs\Python\Python36\lib\site-packages\pymysql\cursors.py", line 170, in execute]
27-Oct-2019 18:01:46.092 WARNING [Thread-71] org.apache.catalina.servlets.CGIServlet$CGIRunner.sendToLog stderr line: [    result = self._query(query)]
27-Oct-2019 18:01:46.092 WARNING [Thread-71] org.apache.catalina.servlets.CGIServlet$CGIRunner.sendToLog stderr line: [  File "C:\Users\hayde\AppData\Local\Programs\Python\Python36\lib\site-packages\pymysql\cursors.py", line 328, in _query]
27-Oct-2019 18:01:46.093 WARNING [Thread-71] org.apache.catalina.servlets.CGIServlet$CGIRunner.sendToLog stderr line: [    conn.query(q)]
27-Oct-2019 18:01:46.094 WARNING [Thread-71] org.apache.catalina.servlets.CGIServlet$CGIRunner.sendToLog stderr line: [  File "C:\Users\hayde\AppData\Local\Programs\Python\Python36\lib\site-packages\pymysql\connections.py", line 517, in query]
27-Oct-2019 18:01:46.095 WARNING [Thread-71] org.apache.catalina.servlets.CGIServlet$CGIRunner.sendToLog stderr line: [    self._affected_rows = self._read_query_result(unbuffered=unbuffered)]
27-Oct-2019 18:01:46.095 WARNING [Thread-71] org.apache.catalina.servlets.CGIServlet$CGIRunner.sendToLog stderr line: [  File "C:\Users\hayde\AppData\Local\Programs\Python\Python36\lib\site-packages\pymysql\connections.py", line 732, in _read_query_result]
27-Oct-2019 18:01:46.097 WARNING [Thread-71] org.apache.catalina.servlets.CGIServlet$CGIRunner.sendToLog stderr line: [    result.read()]
27-Oct-2019 18:01:46.098 WARNING [Thread-71] org.apache.catalina.servlets.CGIServlet$CGIRunner.sendToLog stderr line: [  File "C:\Users\hayde\AppData\Local\Programs\Python\Python36\lib\site-packages\pymysql\connections.py", line 1075, in read]
27-Oct-2019 18:01:46.099 WARNING [Thread-71] org.apache.catalina.servlets.CGIServlet$CGIRunner.sendToLog stderr line: [    first_packet = self.connection._read_packet()]
27-Oct-2019 18:01:46.099 WARNING [Thread-71] org.apache.catalina.servlets.CGIServlet$CGIRunner.sendToLog stderr line: [  File "C:\Users\hayde\AppData\Local\Programs\Python\Python36\lib\site-packages\pymysql\connections.py", line 684, in _read_packet]
27-Oct-2019 18:01:46.099 WARNING [Thread-71] org.apache.catalina.servlets.CGIServlet$CGIRunner.sendToLog stderr line: [    packet.check_error()]
27-Oct-2019 18:01:46.101 WARNING [Thread-71] org.apache.catalina.servlets.CGIServlet$CGIRunner.sendToLog stderr line: [  File "C:\Users\hayde\AppData\Local\Programs\Python\Python36\lib\site-packages\pymysql\protocol.py", line 220, in check_error]
27-Oct-2019 18:01:46.101 WARNING [Thread-71] org.apache.catalina.servlets.CGIServlet$CGIRunner.sendToLog stderr line: [    err.raise_mysql_exception(self._data)]
27-Oct-2019 18:01:46.102 WARNING [Thread-71] org.apache.catalina.servlets.CGIServlet$CGIRunner.sendToLog stderr line: [  File "C:\Users\hayde\AppData\Local\Programs\Python\Python36\lib\site-packages\pymysql\err.py", line 109, in raise_mysql_exception]
27-Oct-2019 18:01:46.103 WARNING [Thread-71] org.apache.catalina.servlets.CGIServlet$CGIRunner.sendToLog stderr line: [    raise errorclass(errno, errval)]
27-Oct-2019 18:01:46.104 WARNING [Thread-71] org.apache.catalina.servlets.CGIServlet$CGIRunner.sendToLog stderr line: [pymysql.err.InternalError: (1054, "Unknown column 'title' in 'field list'")]
27-Oct-2019 18:01:46.110 WARNING [Thread-71] org.apache.catalina.servlets.CGIServlet$CGIRunner.sendToLog Received [20] lines on stderr
27-Oct-2019 18:04:25.060 WARNING [Thread-72] org.apache.catalina.servlets.CGIServlet$CGIRunner.sendToLog stderr line: [Traceback (most recent call last):]
27-Oct-2019 18:04:25.060 WARNING [Thread-72] org.apache.catalina.servlets.CGIServlet$CGIRunner.sendToLog stderr line: [  File "C:\Users\hayde\Desktop\UCI\Fall 2019\EECS 118\MP2\apache-tomcat-9.0.26\webapps\test\WEB-INF\cgi\project_3_edited_detail.py", line 28, in <module>]
27-Oct-2019 18:04:25.061 WARNING [Thread-72] org.apache.catalina.servlets.CGIServlet$CGIRunner.sendToLog stderr line: [    cur.execute(query, title)]
27-Oct-2019 18:04:25.061 WARNING [Thread-72] org.apache.catalina.servlets.CGIServlet$CGIRunner.sendToLog stderr line: [  File "C:\Users\hayde\AppData\Local\Programs\Python\Python36\lib\site-packages\pymysql\cursors.py", line 170, in execute]
27-Oct-2019 18:04:25.063 WARNING [Thread-72] org.apache.catalina.servlets.CGIServlet$CGIRunner.sendToLog stderr line: [    result = self._query(query)]
27-Oct-2019 18:04:25.063 WARNING [Thread-72] org.apache.catalina.servlets.CGIServlet$CGIRunner.sendToLog stderr line: [  File "C:\Users\hayde\AppData\Local\Programs\Python\Python36\lib\site-packages\pymysql\cursors.py", line 328, in _query]
27-Oct-2019 18:04:25.065 WARNING [Thread-72] org.apache.catalina.servlets.CGIServlet$CGIRunner.sendToLog stderr line: [    conn.query(q)]
27-Oct-2019 18:04:25.066 WARNING [Thread-72] org.apache.catalina.servlets.CGIServlet$CGIRunner.sendToLog stderr line: [  File "C:\Users\hayde\AppData\Local\Programs\Python\Python36\lib\site-packages\pymysql\connections.py", line 517, in query]
27-Oct-2019 18:04:25.066 WARNING [Thread-72] org.apache.catalina.servlets.CGIServlet$CGIRunner.sendToLog stderr line: [    self._affected_rows = self._read_query_result(unbuffered=unbuffered)]
27-Oct-2019 18:04:25.067 WARNING [Thread-72] org.apache.catalina.servlets.CGIServlet$CGIRunner.sendToLog stderr line: [  File "C:\Users\hayde\AppData\Local\Programs\Python\Python36\lib\site-packages\pymysql\connections.py", line 732, in _read_query_result]
27-Oct-2019 18:04:25.068 WARNING [Thread-72] org.apache.catalina.servlets.CGIServlet$CGIRunner.sendToLog stderr line: [    result.read()]
27-Oct-2019 18:04:25.068 WARNING [Thread-72] org.apache.catalina.servlets.CGIServlet$CGIRunner.sendToLog stderr line: [  File "C:\Users\hayde\AppData\Local\Programs\Python\Python36\lib\site-packages\pymysql\connections.py", line 1075, in read]
27-Oct-2019 18:04:25.070 WARNING [Thread-72] org.apache.catalina.servlets.CGIServlet$CGIRunner.sendToLog stderr line: [    first_packet = self.connection._read_packet()]
27-Oct-2019 18:04:25.071 WARNING [Thread-72] org.apache.catalina.servlets.CGIServlet$CGIRunner.sendToLog stderr line: [  File "C:\Users\hayde\AppData\Local\Programs\Python\Python36\lib\site-packages\pymysql\connections.py", line 684, in _read_packet]
27-Oct-2019 18:04:25.071 WARNING [Thread-72] org.apache.catalina.servlets.CGIServlet$CGIRunner.sendToLog stderr line: [    packet.check_error()]
27-Oct-2019 18:04:25.072 WARNING [Thread-72] org.apache.catalina.servlets.CGIServlet$CGIRunner.sendToLog stderr line: [  File "C:\Users\hayde\AppData\Local\Programs\Python\Python36\lib\site-packages\pymysql\protocol.py", line 220, in check_error]
27-Oct-2019 18:04:25.072 WARNING [Thread-72] org.apache.catalina.servlets.CGIServlet$CGIRunner.sendToLog stderr line: [    err.raise_mysql_exception(self._data)]
27-Oct-2019 18:04:25.073 WARNING [Thread-72] org.apache.catalina.servlets.CGIServlet$CGIRunner.sendToLog stderr line: [  File "C:\Users\hayde\AppData\Local\Programs\Python\Python36\lib\site-packages\pymysql\err.py", line 109, in raise_mysql_exception]
27-Oct-2019 18:04:25.074 WARNING [Thread-72] org.apache.catalina.servlets.CGIServlet$CGIRunner.sendToLog stderr line: [    raise errorclass(errno, errval)]
27-Oct-2019 18:04:25.075 WARNING [Thread-72] org.apache.catalina.servlets.CGIServlet$CGIRunner.sendToLog stderr line: [pymysql.err.InternalError: (1054, "Unknown column 'title' in 'field list'")]
27-Oct-2019 18:04:25.081 WARNING [Thread-72] org.apache.catalina.servlets.CGIServlet$CGIRunner.sendToLog Received [20] lines on stderr
27-Oct-2019 18:14:14.785 WARNING [Thread-78] org.apache.catalina.servlets.CGIServlet$CGIRunner.sendToLog stderr line: [Traceback (most recent call last):]
27-Oct-2019 18:14:14.785 WARNING [Thread-78] org.apache.catalina.servlets.CGIServlet$CGIRunner.sendToLog stderr line: [  File "C:\Users\hayde\Desktop\UCI\Fall 2019\EECS 118\MP2\apache-tomcat-9.0.26\webapps\test\WEB-INF\cgi\project_3_edited_detail.py", line 28, in <module>]
27-Oct-2019 18:14:14.790 WARNING [Thread-78] org.apache.catalina.servlets.CGIServlet$CGIRunner.sendToLog stderr line: [    cur.execute(query, title)]
27-Oct-2019 18:14:14.790 WARNING [Thread-78] org.apache.catalina.servlets.CGIServlet$CGIRunner.sendToLog stderr line: [  File "C:\Users\hayde\AppData\Local\Programs\Python\Python36\lib\site-packages\pymysql\cursors.py", line 170, in execute]
27-Oct-2019 18:14:14.791 WARNING [Thread-78] org.apache.catalina.servlets.CGIServlet$CGIRunner.sendToLog stderr line: [    result = self._query(query)]
27-Oct-2019 18:14:14.792 WARNING [Thread-78] org.apache.catalina.servlets.CGIServlet$CGIRunner.sendToLog stderr line: [  File "C:\Users\hayde\AppData\Local\Programs\Python\Python36\lib\site-packages\pymysql\cursors.py", line 328, in _query]
27-Oct-2019 18:14:14.792 WARNING [Thread-78] org.apache.catalina.servlets.CGIServlet$CGIRunner.sendToLog stderr line: [    conn.query(q)]
27-Oct-2019 18:14:14.793 WARNING [Thread-78] org.apache.catalina.servlets.CGIServlet$CGIRunner.sendToLog stderr line: [  File "C:\Users\hayde\AppData\Local\Programs\Python\Python36\lib\site-packages\pymysql\connections.py", line 517, in query]
27-Oct-2019 18:14:14.794 WARNING [Thread-78] org.apache.catalina.servlets.CGIServlet$CGIRunner.sendToLog stderr line: [    self._affected_rows = self._read_query_result(unbuffered=unbuffered)]
27-Oct-2019 18:14:14.794 WARNING [Thread-78] org.apache.catalina.servlets.CGIServlet$CGIRunner.sendToLog stderr line: [  File "C:\Users\hayde\AppData\Local\Programs\Python\Python36\lib\site-packages\pymysql\connections.py", line 732, in _read_query_result]
27-Oct-2019 18:14:14.795 WARNING [Thread-78] org.apache.catalina.servlets.CGIServlet$CGIRunner.sendToLog stderr line: [    result.read()]
27-Oct-2019 18:14:14.796 WARNING [Thread-78] org.apache.catalina.servlets.CGIServlet$CGIRunner.sendToLog stderr line: [  File "C:\Users\hayde\AppData\Local\Programs\Python\Python36\lib\site-packages\pymysql\connections.py", line 1075, in read]
27-Oct-2019 18:14:14.796 WARNING [Thread-78] org.apache.catalina.servlets.CGIServlet$CGIRunner.sendToLog stderr line: [    first_packet = self.connection._read_packet()]
27-Oct-2019 18:14:14.798 WARNING [Thread-78] org.apache.catalina.servlets.CGIServlet$CGIRunner.sendToLog stderr line: [  File "C:\Users\hayde\AppData\Local\Programs\Python\Python36\lib\site-packages\pymysql\connections.py", line 684, in _read_packet]
27-Oct-2019 18:14:14.799 WARNING [Thread-78] org.apache.catalina.servlets.CGIServlet$CGIRunner.sendToLog stderr line: [    packet.check_error()]
27-Oct-2019 18:14:14.800 WARNING [Thread-78] org.apache.catalina.servlets.CGIServlet$CGIRunner.sendToLog stderr line: [  File "C:\Users\hayde\AppData\Local\Programs\Python\Python36\lib\site-packages\pymysql\protocol.py", line 220, in check_error]
27-Oct-2019 18:14:14.800 WARNING [Thread-78] org.apache.catalina.servlets.CGIServlet$CGIRunner.sendToLog stderr line: [    err.raise_mysql_exception(self._data)]
27-Oct-2019 18:14:14.801 WARNING [Thread-78] org.apache.catalina.servlets.CGIServlet$CGIRunner.sendToLog stderr line: [  File "C:\Users\hayde\AppData\Local\Programs\Python\Python36\lib\site-packages\pymysql\err.py", line 109, in raise_mysql_exception]
27-Oct-2019 18:14:14.802 WARNING [Thread-78] org.apache.catalina.servlets.CGIServlet$CGIRunner.sendToLog stderr line: [    raise errorclass(errno, errval)]
27-Oct-2019 18:14:14.803 WARNING [Thread-78] org.apache.catalina.servlets.CGIServlet$CGIRunner.sendToLog stderr line: [pymysql.err.InternalError: (1054, "Unknown column 'title' in 'field list'")]
27-Oct-2019 18:14:14.810 WARNING [Thread-78] org.apache.catalina.servlets.CGIServlet$CGIRunner.sendToLog Received [20] lines on stderr
27-Oct-2019 18:18:17.477 WARNING [Thread-79] org.apache.catalina.servlets.CGIServlet$CGIRunner.sendToLog stderr line: [Traceback (most recent call last):]
27-Oct-2019 18:18:17.478 WARNING [Thread-79] org.apache.catalina.servlets.CGIServlet$CGIRunner.sendToLog stderr line: [  File "C:\Users\hayde\Desktop\UCI\Fall 2019\EECS 118\MP2\apache-tomcat-9.0.26\webapps\test\WEB-INF\cgi\project_3_edited_detail.py", line 28, in <module>]
27-Oct-2019 18:18:17.479 WARNING [Thread-79] org.apache.catalina.servlets.CGIServlet$CGIRunner.sendToLog stderr line: [    cur.execute(query, title)]
27-Oct-2019 18:18:17.481 WARNING [Thread-79] org.apache.catalina.servlets.CGIServlet$CGIRunner.sendToLog stderr line: [  File "C:\Users\hayde\AppData\Local\Programs\Python\Python36\lib\site-packages\pymysql\cursors.py", line 170, in execute]
27-Oct-2019 18:18:17.481 WARNING [Thread-79] org.apache.catalina.servlets.CGIServlet$CGIRunner.sendToLog stderr line: [    result = self._query(query)]
27-Oct-2019 18:18:17.482 WARNING [Thread-79] org.apache.catalina.servlets.CGIServlet$CGIRunner.sendToLog stderr line: [  File "C:\Users\hayde\AppData\Local\Programs\Python\Python36\lib\site-packages\pymysql\cursors.py", line 328, in _query]
27-Oct-2019 18:18:17.483 WARNING [Thread-79] org.apache.catalina.servlets.CGIServlet$CGIRunner.sendToLog stderr line: [    conn.query(q)]
27-Oct-2019 18:18:17.484 WARNING [Thread-79] org.apache.catalina.servlets.CGIServlet$CGIRunner.sendToLog stderr line: [  File "C:\Users\hayde\AppData\Local\Programs\Python\Python36\lib\site-packages\pymysql\connections.py", line 517, in query]
27-Oct-2019 18:18:17.485 WARNING [Thread-79] org.apache.catalina.servlets.CGIServlet$CGIRunner.sendToLog stderr line: [    self._affected_rows = self._read_query_result(unbuffered=unbuffered)]
27-Oct-2019 18:18:17.485 WARNING [Thread-79] org.apache.catalina.servlets.CGIServlet$CGIRunner.sendToLog stderr line: [  File "C:\Users\hayde\AppData\Local\Programs\Python\Python36\lib\site-packages\pymysql\connections.py", line 732, in _read_query_result]
27-Oct-2019 18:18:17.485 WARNING [Thread-79] org.apache.catalina.servlets.CGIServlet$CGIRunner.sendToLog stderr line: [    result.read()]
27-Oct-2019 18:18:17.486 WARNING [Thread-79] org.apache.catalina.servlets.CGIServlet$CGIRunner.sendToLog stderr line: [  File "C:\Users\hayde\AppData\Local\Programs\Python\Python36\lib\site-packages\pymysql\connections.py", line 1075, in read]
27-Oct-2019 18:18:17.487 WARNING [Thread-79] org.apache.catalina.servlets.CGIServlet$CGIRunner.sendToLog stderr line: [    first_packet = self.connection._read_packet()]
27-Oct-2019 18:18:17.488 WARNING [Thread-79] org.apache.catalina.servlets.CGIServlet$CGIRunner.sendToLog stderr line: [  File "C:\Users\hayde\AppData\Local\Programs\Python\Python36\lib\site-packages\pymysql\connections.py", line 684, in _read_packet]
27-Oct-2019 18:18:17.488 WARNING [Thread-79] org.apache.catalina.servlets.CGIServlet$CGIRunner.sendToLog stderr line: [    packet.check_error()]
27-Oct-2019 18:18:17.490 WARNING [Thread-79] org.apache.catalina.servlets.CGIServlet$CGIRunner.sendToLog stderr line: [  File "C:\Users\hayde\AppData\Local\Programs\Python\Python36\lib\site-packages\pymysql\protocol.py", line 220, in check_error]
27-Oct-2019 18:18:17.491 WARNING [Thread-79] org.apache.catalina.servlets.CGIServlet$CGIRunner.sendToLog stderr line: [    err.raise_mysql_exception(self._data)]
27-Oct-2019 18:18:17.492 WARNING [Thread-79] org.apache.catalina.servlets.CGIServlet$CGIRunner.sendToLog stderr line: [  File "C:\Users\hayde\AppData\Local\Programs\Python\Python36\lib\site-packages\pymysql\err.py", line 109, in raise_mysql_exception]
27-Oct-2019 18:18:17.492 WARNING [Thread-79] org.apache.catalina.servlets.CGIServlet$CGIRunner.sendToLog stderr line: [    raise errorclass(errno, errval)]
27-Oct-2019 18:18:17.492 WARNING [Thread-79] org.apache.catalina.servlets.CGIServlet$CGIRunner.sendToLog stderr line: [pymysql.err.InternalError: (1054, "Unknown column 'title' in 'field list'")]
27-Oct-2019 18:18:17.501 WARNING [Thread-79] org.apache.catalina.servlets.CGIServlet$CGIRunner.sendToLog Received [20] lines on stderr
27-Oct-2019 18:18:21.928 WARNING [Thread-80] org.apache.catalina.servlets.CGIServlet$CGIRunner.sendToLog stderr line: [Traceback (most recent call last):]
27-Oct-2019 18:18:21.928 WARNING [Thread-80] org.apache.catalina.servlets.CGIServlet$CGIRunner.sendToLog stderr line: [  File "C:\Users\hayde\Desktop\UCI\Fall 2019\EECS 118\MP2\apache-tomcat-9.0.26\webapps\test\WEB-INF\cgi\project_3_edited_detail.py", line 28, in <module>]
27-Oct-2019 18:18:21.933 WARNING [Thread-80] org.apache.catalina.servlets.CGIServlet$CGIRunner.sendToLog stderr line: [    cur.execute(query, title)]
27-Oct-2019 18:18:21.933 WARNING [Thread-80] org.apache.catalina.servlets.CGIServlet$CGIRunner.sendToLog stderr line: [  File "C:\Users\hayde\AppData\Local\Programs\Python\Python36\lib\site-packages\pymysql\cursors.py", line 170, in execute]
27-Oct-2019 18:18:21.934 WARNING [Thread-80] org.apache.catalina.servlets.CGIServlet$CGIRunner.sendToLog stderr line: [    result = self._query(query)]
27-Oct-2019 18:18:21.934 WARNING [Thread-80] org.apache.catalina.servlets.CGIServlet$CGIRunner.sendToLog stderr line: [  File "C:\Users\hayde\AppData\Local\Programs\Python\Python36\lib\site-packages\pymysql\cursors.py", line 328, in _query]
27-Oct-2019 18:18:21.936 WARNING [Thread-80] org.apache.catalina.servlets.CGIServlet$CGIRunner.sendToLog stderr line: [    conn.query(q)]
27-Oct-2019 18:18:21.936 WARNING [Thread-80] org.apache.catalina.servlets.CGIServlet$CGIRunner.sendToLog stderr line: [  File "C:\Users\hayde\AppData\Local\Programs\Python\Python36\lib\site-packages\pymysql\connections.py", line 517, in query]
27-Oct-2019 18:18:21.937 WARNING [Thread-80] org.apache.catalina.servlets.CGIServlet$CGIRunner.sendToLog stderr line: [    self._affected_rows = self._read_query_result(unbuffered=unbuffered)]
27-Oct-2019 18:18:21.938 WARNING [Thread-80] org.apache.catalina.servlets.CGIServlet$CGIRunner.sendToLog stderr line: [  File "C:\Users\hayde\AppData\Local\Programs\Python\Python36\lib\site-packages\pymysql\connections.py", line 732, in _read_query_result]
27-Oct-2019 18:18:21.939 WARNING [Thread-80] org.apache.catalina.servlets.CGIServlet$CGIRunner.sendToLog stderr line: [    result.read()]
27-Oct-2019 18:18:21.940 WARNING [Thread-80] org.apache.catalina.servlets.CGIServlet$CGIRunner.sendToLog stderr line: [  File "C:\Users\hayde\AppData\Local\Programs\Python\Python36\lib\site-packages\pymysql\connections.py", line 1075, in read]
27-Oct-2019 18:18:21.941 WARNING [Thread-80] org.apache.catalina.servlets.CGIServlet$CGIRunner.sendToLog stderr line: [    first_packet = self.connection._read_packet()]
27-Oct-2019 18:18:21.941 WARNING [Thread-80] org.apache.catalina.servlets.CGIServlet$CGIRunner.sendToLog stderr line: [  File "C:\Users\hayde\AppData\Local\Programs\Python\Python36\lib\site-packages\pymysql\connections.py", line 684, in _read_packet]
27-Oct-2019 18:18:21.942 WARNING [Thread-80] org.apache.catalina.servlets.CGIServlet$CGIRunner.sendToLog stderr line: [    packet.check_error()]
27-Oct-2019 18:18:21.942 WARNING [Thread-80] org.apache.catalina.servlets.CGIServlet$CGIRunner.sendToLog stderr line: [  File "C:\Users\hayde\AppData\Local\Programs\Python\Python36\lib\site-packages\pymysql\protocol.py", line 220, in check_error]
27-Oct-2019 18:18:21.942 WARNING [Thread-80] org.apache.catalina.servlets.CGIServlet$CGIRunner.sendToLog stderr line: [    err.raise_mysql_exception(self._data)]
27-Oct-2019 18:18:21.942 WARNING [Thread-80] org.apache.catalina.servlets.CGIServlet$CGIRunner.sendToLog stderr line: [  File "C:\Users\hayde\AppData\Local\Programs\Python\Python36\lib\site-packages\pymysql\err.py", line 109, in raise_mysql_exception]
27-Oct-2019 18:18:21.942 WARNING [Thread-80] org.apache.catalina.servlets.CGIServlet$CGIRunner.sendToLog stderr line: [    raise errorclass(errno, errval)]
27-Oct-2019 18:18:21.946 WARNING [Thread-80] org.apache.catalina.servlets.CGIServlet$CGIRunner.sendToLog stderr line: [pymysql.err.InternalError: (1054, "Unknown column 'title' in 'field list'")]
27-Oct-2019 18:18:21.953 WARNING [Thread-80] org.apache.catalina.servlets.CGIServlet$CGIRunner.sendToLog Received [20] lines on stderr
27-Oct-2019 18:18:37.495 WARNING [Thread-81] org.apache.catalina.servlets.CGIServlet$CGIRunner.sendToLog stderr line: [Traceback (most recent call last):]
27-Oct-2019 18:18:37.495 WARNING [Thread-81] org.apache.catalina.servlets.CGIServlet$CGIRunner.sendToLog stderr line: [  File "C:\Users\hayde\Desktop\UCI\Fall 2019\EECS 118\MP2\apache-tomcat-9.0.26\webapps\test\WEB-INF\cgi\project_3_edited_detail.py", line 28, in <module>]
27-Oct-2019 18:18:37.495 WARNING [Thread-81] org.apache.catalina.servlets.CGIServlet$CGIRunner.sendToLog stderr line: [    cur.execute(query, title)]
27-Oct-2019 18:18:37.499 WARNING [Thread-81] org.apache.catalina.servlets.CGIServlet$CGIRunner.sendToLog stderr line: [  File "C:\Users\hayde\AppData\Local\Programs\Python\Python36\lib\site-packages\pymysql\cursors.py", line 170, in execute]
27-Oct-2019 18:18:37.499 WARNING [Thread-81] org.apache.catalina.servlets.CGIServlet$CGIRunner.sendToLog stderr line: [    result = self._query(query)]
27-Oct-2019 18:18:37.499 WARNING [Thread-81] org.apache.catalina.servlets.CGIServlet$CGIRunner.sendToLog stderr line: [  File "C:\Users\hayde\AppData\Local\Programs\Python\Python36\lib\site-packages\pymysql\cursors.py", line 328, in _query]
27-Oct-2019 18:18:37.501 WARNING [Thread-81] org.apache.catalina.servlets.CGIServlet$CGIRunner.sendToLog stderr line: [    conn.query(q)]
27-Oct-2019 18:18:37.502 WARNING [Thread-81] org.apache.catalina.servlets.CGIServlet$CGIRunner.sendToLog stderr line: [  File "C:\Users\hayde\AppData\Local\Programs\Python\Python36\lib\site-packages\pymysql\connections.py", line 517, in query]
27-Oct-2019 18:18:37.502 WARNING [Thread-81] org.apache.catalina.servlets.CGIServlet$CGIRunner.sendToLog stderr line: [    self._affected_rows = self._read_query_result(unbuffered=unbuffered)]
27-Oct-2019 18:18:37.502 WARNING [Thread-81] org.apache.catalina.servlets.CGIServlet$CGIRunner.sendToLog stderr line: [  File "C:\Users\hayde\AppData\Local\Programs\Python\Python36\lib\site-packages\pymysql\connections.py", line 732, in _read_query_result]
27-Oct-2019 18:18:37.502 WARNING [Thread-81] org.apache.catalina.servlets.CGIServlet$CGIRunner.sendToLog stderr line: [    result.read()]
27-Oct-2019 18:18:37.505 WARNING [Thread-81] org.apache.catalina.servlets.CGIServlet$CGIRunner.sendToLog stderr line: [  File "C:\Users\hayde\AppData\Local\Programs\Python\Python36\lib\site-packages\pymysql\connections.py", line 1075, in read]
27-Oct-2019 18:18:37.505 WARNING [Thread-81] org.apache.catalina.servlets.CGIServlet$CGIRunner.sendToLog stderr line: [    first_packet = self.connection._read_packet()]
27-Oct-2019 18:18:37.506 WARNING [Thread-81] org.apache.catalina.servlets.CGIServlet$CGIRunner.sendToLog stderr line: [  File "C:\Users\hayde\AppData\Local\Programs\Python\Python36\lib\site-packages\pymysql\connections.py", line 684, in _read_packet]
27-Oct-2019 18:18:37.507 WARNING [Thread-81] org.apache.catalina.servlets.CGIServlet$CGIRunner.sendToLog stderr line: [    packet.check_error()]
27-Oct-2019 18:18:37.507 WARNING [Thread-81] org.apache.catalina.servlets.CGIServlet$CGIRunner.sendToLog stderr line: [  File "C:\Users\hayde\AppData\Local\Programs\Python\Python36\lib\site-packages\pymysql\protocol.py", line 220, in check_error]
27-Oct-2019 18:18:37.509 WARNING [Thread-81] org.apache.catalina.servlets.CGIServlet$CGIRunner.sendToLog stderr line: [    err.raise_mysql_exception(self._data)]
27-Oct-2019 18:18:37.509 WARNING [Thread-81] org.apache.catalina.servlets.CGIServlet$CGIRunner.sendToLog stderr line: [  File "C:\Users\hayde\AppData\Local\Programs\Python\Python36\lib\site-packages\pymysql\err.py", line 109, in raise_mysql_exception]
27-Oct-2019 18:18:37.510 WARNING [Thread-81] org.apache.catalina.servlets.CGIServlet$CGIRunner.sendToLog stderr line: [    raise errorclass(errno, errval)]
27-Oct-2019 18:18:37.510 WARNING [Thread-81] org.apache.catalina.servlets.CGIServlet$CGIRunner.sendToLog stderr line: [pymysql.err.InternalError: (1054, "Unknown column 'title' in 'field list'")]
27-Oct-2019 18:18:37.515 WARNING [Thread-81] org.apache.catalina.servlets.CGIServlet$CGIRunner.sendToLog Received [20] lines on stderr
27-Oct-2019 18:25:25.710 WARNING [Thread-87] org.apache.catalina.servlets.CGIServlet$CGIRunner.sendToLog stderr line: [  File "C:\Users\hayde\Desktop\UCI\Fall 2019\EECS 118\MP2\apache-tomcat-9.0.26\webapps\test\WEB-INF\cgi\project_3_edited_detail.py", line 67]
27-Oct-2019 18:25:25.710 WARNING [Thread-87] org.apache.catalina.servlets.CGIServlet$CGIRunner.sendToLog stderr line: [    db.close()]
27-Oct-2019 18:25:25.711 WARNING [Thread-87] org.apache.catalina.servlets.CGIServlet$CGIRunner.sendToLog stderr line: [             ^]
27-Oct-2019 18:25:25.711 WARNING [Thread-87] org.apache.catalina.servlets.CGIServlet$CGIRunner.sendToLog stderr line: [SyntaxError: EOF while scanning triple-quoted string literal]
27-Oct-2019 18:25:25.716 WARNING [Thread-87] org.apache.catalina.servlets.CGIServlet$CGIRunner.sendToLog Received [4] lines on stderr
27-Oct-2019 18:25:40.111 WARNING [Thread-88] org.apache.catalina.servlets.CGIServlet$CGIRunner.sendToLog stderr line: [Traceback (most recent call last):]
27-Oct-2019 18:25:40.112 WARNING [Thread-88] org.apache.catalina.servlets.CGIServlet$CGIRunner.sendToLog stderr line: [  File "C:\Users\hayde\Desktop\UCI\Fall 2019\EECS 118\MP2\apache-tomcat-9.0.26\webapps\test\WEB-INF\cgi\project_3_edited_detail.py", line 25, in <module>]
27-Oct-2019 18:25:40.112 WARNING [Thread-88] org.apache.catalina.servlets.CGIServlet$CGIRunner.sendToLog stderr line: [    query = "update detail set title = %s where detail_id='"+id[1]+"'"]
27-Oct-2019 18:25:40.112 WARNING [Thread-88] org.apache.catalina.servlets.CGIServlet$CGIRunner.sendToLog stderr line: [IndexError: string index out of range]
27-Oct-2019 18:25:40.132 WARNING [Thread-88] org.apache.catalina.servlets.CGIServlet$CGIRunner.sendToLog Received [4] lines on stderr
27-Oct-2019 18:26:56.053 WARNING [Thread-90] org.apache.catalina.servlets.CGIServlet$CGIRunner.sendToLog stderr line: [Traceback (most recent call last):]
27-Oct-2019 18:26:56.054 WARNING [Thread-90] org.apache.catalina.servlets.CGIServlet$CGIRunner.sendToLog stderr line: [  File "C:\Users\hayde\Desktop\UCI\Fall 2019\EECS 118\MP2\apache-tomcat-9.0.26\webapps\test\WEB-INF\cgi\project_3_edited_detail.py", line 24, in <module>]
27-Oct-2019 18:26:56.055 WARNING [Thread-90] org.apache.catalina.servlets.CGIServlet$CGIRunner.sendToLog stderr line: [    query = "update detail set year = %s where detail_id='"+id[1]+"'"]
27-Oct-2019 18:26:56.056 WARNING [Thread-90] org.apache.catalina.servlets.CGIServlet$CGIRunner.sendToLog stderr line: [IndexError: string index out of range]
27-Oct-2019 18:26:56.073 WARNING [Thread-90] org.apache.catalina.servlets.CGIServlet$CGIRunner.sendToLog Received [4] lines on stderr
27-Oct-2019 18:54:49.140 WARNING [Thread-102] org.apache.catalina.servlets.CGIServlet$CGIRunner.sendToLog stderr line: [Traceback (most recent call last):]
27-Oct-2019 18:54:49.141 WARNING [Thread-102] org.apache.catalina.servlets.CGIServlet$CGIRunner.sendToLog stderr line: [  File "C:\Users\hayde\Desktop\UCI\Fall 2019\EECS 118\MP2\apache-tomcat-9.0.26\webapps\test\WEB-INF\cgi\project_3_edited_detail.py", line 25, in <module>]
27-Oct-2019 18:54:49.142 WARNING [Thread-102] org.apache.catalina.servlets.CGIServlet$CGIRunner.sendToLog stderr line: [    cur.execute(query, str(year))]
27-Oct-2019 18:54:49.143 WARNING [Thread-102] org.apache.catalina.servlets.CGIServlet$CGIRunner.sendToLog stderr line: [  File "C:\Users\hayde\AppData\Local\Programs\Python\Python36\lib\site-packages\pymysql\cursors.py", line 170, in execute]
27-Oct-2019 18:54:49.144 WARNING [Thread-102] org.apache.catalina.servlets.CGIServlet$CGIRunner.sendToLog stderr line: [    result = self._query(query)]
27-Oct-2019 18:54:49.145 WARNING [Thread-102] org.apache.catalina.servlets.CGIServlet$CGIRunner.sendToLog stderr line: [  File "C:\Users\hayde\AppData\Local\Programs\Python\Python36\lib\site-packages\pymysql\cursors.py", line 328, in _query]
27-Oct-2019 18:54:49.146 WARNING [Thread-102] org.apache.catalina.servlets.CGIServlet$CGIRunner.sendToLog stderr line: [    conn.query(q)]
27-Oct-2019 18:54:49.146 WARNING [Thread-102] org.apache.catalina.servlets.CGIServlet$CGIRunner.sendToLog stderr line: [  File "C:\Users\hayde\AppData\Local\Programs\Python\Python36\lib\site-packages\pymysql\connections.py", line 517, in query]
27-Oct-2019 18:54:49.147 WARNING [Thread-102] org.apache.catalina.servlets.CGIServlet$CGIRunner.sendToLog stderr line: [    self._affected_rows = self._read_query_result(unbuffered=unbuffered)]
27-Oct-2019 18:54:49.148 WARNING [Thread-102] org.apache.catalina.servlets.CGIServlet$CGIRunner.sendToLog stderr line: [  File "C:\Users\hayde\AppData\Local\Programs\Python\Python36\lib\site-packages\pymysql\connections.py", line 732, in _read_query_result]
27-Oct-2019 18:54:49.148 WARNING [Thread-102] org.apache.catalina.servlets.CGIServlet$CGIRunner.sendToLog stderr line: [    result.read()]
27-Oct-2019 18:54:49.150 WARNING [Thread-102] org.apache.catalina.servlets.CGIServlet$CGIRunner.sendToLog stderr line: [  File "C:\Users\hayde\AppData\Local\Programs\Python\Python36\lib\site-packages\pymysql\connections.py", line 1075, in read]
27-Oct-2019 18:54:49.150 WARNING [Thread-102] org.apache.catalina.servlets.CGIServlet$CGIRunner.sendToLog stderr line: [    first_packet = self.connection._read_packet()]
27-Oct-2019 18:54:49.151 WARNING [Thread-102] org.apache.catalina.servlets.CGIServlet$CGIRunner.sendToLog stderr line: [  File "C:\Users\hayde\AppData\Local\Programs\Python\Python36\lib\site-packages\pymysql\connections.py", line 684, in _read_packet]
27-Oct-2019 18:54:49.152 WARNING [Thread-102] org.apache.catalina.servlets.CGIServlet$CGIRunner.sendToLog stderr line: [    packet.check_error()]
27-Oct-2019 18:54:49.154 WARNING [Thread-102] org.apache.catalina.servlets.CGIServlet$CGIRunner.sendToLog stderr line: [  File "C:\Users\hayde\AppData\Local\Programs\Python\Python36\lib\site-packages\pymysql\protocol.py", line 220, in check_error]
27-Oct-2019 18:54:49.155 WARNING [Thread-102] org.apache.catalina.servlets.CGIServlet$CGIRunner.sendToLog stderr line: [    err.raise_mysql_exception(self._data)]
27-Oct-2019 18:54:49.155 WARNING [Thread-102] org.apache.catalina.servlets.CGIServlet$CGIRunner.sendToLog stderr line: [  File "C:\Users\hayde\AppData\Local\Programs\Python\Python36\lib\site-packages\pymysql\err.py", line 109, in raise_mysql_exception]
27-Oct-2019 18:54:49.155 WARNING [Thread-102] org.apache.catalina.servlets.CGIServlet$CGIRunner.sendToLog stderr line: [    raise errorclass(errno, errval)]
27-Oct-2019 18:54:49.157 WARNING [Thread-102] org.apache.catalina.servlets.CGIServlet$CGIRunner.sendToLog stderr line: [pymysql.err.InternalError: (1292, "Truncated incorrect DOUBLE value: 'None'")]
27-Oct-2019 18:54:49.161 WARNING [Thread-102] org.apache.catalina.servlets.CGIServlet$CGIRunner.sendToLog Received [20] lines on stderr
27-Oct-2019 18:55:17.206 WARNING [Thread-103] org.apache.catalina.servlets.CGIServlet$CGIRunner.sendToLog stderr line: [Traceback (most recent call last):]
27-Oct-2019 18:55:17.206 WARNING [Thread-103] org.apache.catalina.servlets.CGIServlet$CGIRunner.sendToLog stderr line: [  File "C:\Users\hayde\Desktop\UCI\Fall 2019\EECS 118\MP2\apache-tomcat-9.0.26\webapps\test\WEB-INF\cgi\project_3_edited_detail.py", line 25, in <module>]
27-Oct-2019 18:55:17.207 WARNING [Thread-103] org.apache.catalina.servlets.CGIServlet$CGIRunner.sendToLog stderr line: [    cur.execute(query, str(year))]
27-Oct-2019 18:55:17.209 WARNING [Thread-103] org.apache.catalina.servlets.CGIServlet$CGIRunner.sendToLog stderr line: [  File "C:\Users\hayde\AppData\Local\Programs\Python\Python36\lib\site-packages\pymysql\cursors.py", line 170, in execute]
27-Oct-2019 18:55:17.210 WARNING [Thread-103] org.apache.catalina.servlets.CGIServlet$CGIRunner.sendToLog stderr line: [    result = self._query(query)]
27-Oct-2019 18:55:17.210 WARNING [Thread-103] org.apache.catalina.servlets.CGIServlet$CGIRunner.sendToLog stderr line: [  File "C:\Users\hayde\AppData\Local\Programs\Python\Python36\lib\site-packages\pymysql\cursors.py", line 328, in _query]
27-Oct-2019 18:55:17.211 WARNING [Thread-103] org.apache.catalina.servlets.CGIServlet$CGIRunner.sendToLog stderr line: [    conn.query(q)]
27-Oct-2019 18:55:17.212 WARNING [Thread-103] org.apache.catalina.servlets.CGIServlet$CGIRunner.sendToLog stderr line: [  File "C:\Users\hayde\AppData\Local\Programs\Python\Python36\lib\site-packages\pymysql\connections.py", line 517, in query]
27-Oct-2019 18:55:17.212 WARNING [Thread-103] org.apache.catalina.servlets.CGIServlet$CGIRunner.sendToLog stderr line: [    self._affected_rows = self._read_query_result(unbuffered=unbuffered)]
27-Oct-2019 18:55:17.212 WARNING [Thread-103] org.apache.catalina.servlets.CGIServlet$CGIRunner.sendToLog stderr line: [  File "C:\Users\hayde\AppData\Local\Programs\Python\Python36\lib\site-packages\pymysql\connections.py", line 732, in _read_query_result]
27-Oct-2019 18:55:17.214 WARNING [Thread-103] org.apache.catalina.servlets.CGIServlet$CGIRunner.sendToLog stderr line: [    result.read()]
27-Oct-2019 18:55:17.214 WARNING [Thread-103] org.apache.catalina.servlets.CGIServlet$CGIRunner.sendToLog stderr line: [  File "C:\Users\hayde\AppData\Local\Programs\Python\Python36\lib\site-packages\pymysql\connections.py", line 1075, in read]
27-Oct-2019 18:55:17.215 WARNING [Thread-103] org.apache.catalina.servlets.CGIServlet$CGIRunner.sendToLog stderr line: [    first_packet = self.connection._read_packet()]
27-Oct-2019 18:55:17.216 WARNING [Thread-103] org.apache.catalina.servlets.CGIServlet$CGIRunner.sendToLog stderr line: [  File "C:\Users\hayde\AppData\Local\Programs\Python\Python36\lib\site-packages\pymysql\connections.py", line 684, in _read_packet]
27-Oct-2019 18:55:17.217 WARNING [Thread-103] org.apache.catalina.servlets.CGIServlet$CGIRunner.sendToLog stderr line: [    packet.check_error()]
27-Oct-2019 18:55:17.218 WARNING [Thread-103] org.apache.catalina.servlets.CGIServlet$CGIRunner.sendToLog stderr line: [  File "C:\Users\hayde\AppData\Local\Programs\Python\Python36\lib\site-packages\pymysql\protocol.py", line 220, in check_error]
27-Oct-2019 18:55:17.219 WARNING [Thread-103] org.apache.catalina.servlets.CGIServlet$CGIRunner.sendToLog stderr line: [    err.raise_mysql_exception(self._data)]
27-Oct-2019 18:55:17.220 WARNING [Thread-103] org.apache.catalina.servlets.CGIServlet$CGIRunner.sendToLog stderr line: [  File "C:\Users\hayde\AppData\Local\Programs\Python\Python36\lib\site-packages\pymysql\err.py", line 109, in raise_mysql_exception]
27-Oct-2019 18:55:17.220 WARNING [Thread-103] org.apache.catalina.servlets.CGIServlet$CGIRunner.sendToLog stderr line: [    raise errorclass(errno, errval)]
27-Oct-2019 18:55:17.221 WARNING [Thread-103] org.apache.catalina.servlets.CGIServlet$CGIRunner.sendToLog stderr line: [pymysql.err.InternalError: (1292, "Truncated incorrect DOUBLE value: 'None'")]
27-Oct-2019 18:55:17.230 WARNING [Thread-103] org.apache.catalina.servlets.CGIServlet$CGIRunner.sendToLog Received [20] lines on stderr
27-Oct-2019 19:03:57.353 WARNING [Thread-110] org.apache.catalina.servlets.CGIServlet$CGIRunner.sendToLog stderr line: [Traceback (most recent call last):]
27-Oct-2019 19:03:57.357 WARNING [Thread-110] org.apache.catalina.servlets.CGIServlet$CGIRunner.sendToLog stderr line: [  File "C:\Users\hayde\Desktop\UCI\Fall 2019\EECS 118\MP2\apache-tomcat-9.0.26\webapps\test\WEB-INF\cgi\project_3_edited_artist.py", line 23, in <module>]
27-Oct-2019 19:03:57.358 WARNING [Thread-110] org.apache.catalina.servlets.CGIServlet$CGIRunner.sendToLog stderr line: [    cur.execute(query, str(birth_year))]
27-Oct-2019 19:03:57.358 WARNING [Thread-110] org.apache.catalina.servlets.CGIServlet$CGIRunner.sendToLog stderr line: [  File "C:\Users\hayde\AppData\Local\Programs\Python\Python36\lib\site-packages\pymysql\cursors.py", line 170, in execute]
27-Oct-2019 19:03:57.358 WARNING [Thread-110] org.apache.catalina.servlets.CGIServlet$CGIRunner.sendToLog stderr line: [    result = self._query(query)]
27-Oct-2019 19:03:57.361 WARNING [Thread-110] org.apache.catalina.servlets.CGIServlet$CGIRunner.sendToLog stderr line: [  File "C:\Users\hayde\AppData\Local\Programs\Python\Python36\lib\site-packages\pymysql\cursors.py", line 328, in _query]
27-Oct-2019 19:03:57.362 WARNING [Thread-110] org.apache.catalina.servlets.CGIServlet$CGIRunner.sendToLog stderr line: [    conn.query(q)]
27-Oct-2019 19:03:57.363 WARNING [Thread-110] org.apache.catalina.servlets.CGIServlet$CGIRunner.sendToLog stderr line: [  File "C:\Users\hayde\AppData\Local\Programs\Python\Python36\lib\site-packages\pymysql\connections.py", line 517, in query]
27-Oct-2019 19:03:57.363 WARNING [Thread-110] org.apache.catalina.servlets.CGIServlet$CGIRunner.sendToLog stderr line: [    self._affected_rows = self._read_query_result(unbuffered=unbuffered)]
27-Oct-2019 19:03:57.364 WARNING [Thread-110] org.apache.catalina.servlets.CGIServlet$CGIRunner.sendToLog stderr line: [  File "C:\Users\hayde\AppData\Local\Programs\Python\Python36\lib\site-packages\pymysql\connections.py", line 732, in _read_query_result]
27-Oct-2019 19:03:57.365 WARNING [Thread-110] org.apache.catalina.servlets.CGIServlet$CGIRunner.sendToLog stderr line: [    result.read()]
27-Oct-2019 19:03:57.365 WARNING [Thread-110] org.apache.catalina.servlets.CGIServlet$CGIRunner.sendToLog stderr line: [  File "C:\Users\hayde\AppData\Local\Programs\Python\Python36\lib\site-packages\pymysql\connections.py", line 1075, in read]
27-Oct-2019 19:03:57.366 WARNING [Thread-110] org.apache.catalina.servlets.CGIServlet$CGIRunner.sendToLog stderr line: [    first_packet = self.connection._read_packet()]
27-Oct-2019 19:03:57.366 WARNING [Thread-110] org.apache.catalina.servlets.CGIServlet$CGIRunner.sendToLog stderr line: [  File "C:\Users\hayde\AppData\Local\Programs\Python\Python36\lib\site-packages\pymysql\connections.py", line 684, in _read_packet]
27-Oct-2019 19:03:57.368 WARNING [Thread-110] org.apache.catalina.servlets.CGIServlet$CGIRunner.sendToLog stderr line: [    packet.check_error()]
27-Oct-2019 19:03:57.368 WARNING [Thread-110] org.apache.catalina.servlets.CGIServlet$CGIRunner.sendToLog stderr line: [  File "C:\Users\hayde\AppData\Local\Programs\Python\Python36\lib\site-packages\pymysql\protocol.py", line 220, in check_error]
27-Oct-2019 19:03:57.368 WARNING [Thread-110] org.apache.catalina.servlets.CGIServlet$CGIRunner.sendToLog stderr line: [    err.raise_mysql_exception(self._data)]
27-Oct-2019 19:03:57.370 WARNING [Thread-110] org.apache.catalina.servlets.CGIServlet$CGIRunner.sendToLog stderr line: [  File "C:\Users\hayde\AppData\Local\Programs\Python\Python36\lib\site-packages\pymysql\err.py", line 109, in raise_mysql_exception]
27-Oct-2019 19:03:57.371 WARNING [Thread-110] org.apache.catalina.servlets.CGIServlet$CGIRunner.sendToLog stderr line: [    raise errorclass(errno, errval)]
27-Oct-2019 19:03:57.372 WARNING [Thread-110] org.apache.catalina.servlets.CGIServlet$CGIRunner.sendToLog stderr line: [pymysql.err.InternalError: (1292, "Truncated incorrect DOUBLE value: '(1,)'")]
27-Oct-2019 19:03:57.378 WARNING [Thread-110] org.apache.catalina.servlets.CGIServlet$CGIRunner.sendToLog Received [20] lines on stderr
27-Oct-2019 19:14:57.182 WARNING [Thread-121] org.apache.catalina.servlets.CGIServlet$CGIRunner.sendToLog stderr line: [Traceback (most recent call last):]
27-Oct-2019 19:14:57.182 WARNING [Thread-121] org.apache.catalina.servlets.CGIServlet$CGIRunner.sendToLog stderr line: [  File "C:\Users\hayde\Desktop\UCI\Fall 2019\EECS 118\MP2\apache-tomcat-9.0.26\webapps\test\WEB-INF\cgi\project_3.py", line 47, in <module>]
27-Oct-2019 19:14:57.183 WARNING [Thread-121] org.apache.catalina.servlets.CGIServlet$CGIRunner.sendToLog stderr line: [    print(js)]
27-Oct-2019 19:14:57.183 WARNING [Thread-121] org.apache.catalina.servlets.CGIServlet$CGIRunner.sendToLog stderr line: [NameError: name 'js' is not defined]
27-Oct-2019 19:14:57.200 WARNING [Thread-121] org.apache.catalina.servlets.CGIServlet$CGIRunner.sendToLog Received [4] lines on stderr
27-Oct-2019 19:26:24.780 WARNING [Thread-123] org.apache.catalina.servlets.CGIServlet$CGIRunner.sendToLog stderr line: [Traceback (most recent call last):]
27-Oct-2019 19:26:24.780 WARNING [Thread-123] org.apache.catalina.servlets.CGIServlet$CGIRunner.sendToLog stderr line: [  File "C:\Users\hayde\Desktop\UCI\Fall 2019\EECS 118\MP2\apache-tomcat-9.0.26\webapps\test\WEB-INF\cgi\project_3.py", line 47, in <module>]
27-Oct-2019 19:26:24.784 WARNING [Thread-123] org.apache.catalina.servlets.CGIServlet$CGIRunner.sendToLog stderr line: [    print(js)]
27-Oct-2019 19:26:24.786 WARNING [Thread-123] org.apache.catalina.servlets.CGIServlet$CGIRunner.sendToLog stderr line: [NameError: name 'js' is not defined]
27-Oct-2019 19:26:24.801 WARNING [Thread-123] org.apache.catalina.servlets.CGIServlet$CGIRunner.sendToLog Received [4] lines on stderr
27-Oct-2019 19:26:32.315 WARNING [Thread-125] org.apache.catalina.servlets.CGIServlet$CGIRunner.sendToLog stderr line: [Traceback (most recent call last):]
27-Oct-2019 19:26:32.315 WARNING [Thread-125] org.apache.catalina.servlets.CGIServlet$CGIRunner.sendToLog stderr line: [  File "C:\Users\hayde\Desktop\UCI\Fall 2019\EECS 118\MP2\apache-tomcat-9.0.26\webapps\test\WEB-INF\cgi\project_3.py", line 47, in <module>]
27-Oct-2019 19:26:32.315 WARNING [Thread-125] org.apache.catalina.servlets.CGIServlet$CGIRunner.sendToLog stderr line: [    print(js)]
27-Oct-2019 19:26:32.315 WARNING [Thread-125] org.apache.catalina.servlets.CGIServlet$CGIRunner.sendToLog stderr line: [NameError: name 'js' is not defined]
27-Oct-2019 19:26:32.333 WARNING [Thread-125] org.apache.catalina.servlets.CGIServlet$CGIRunner.sendToLog Received [4] lines on stderr
27-Oct-2019 19:40:38.088 WARNING [Thread-126] org.apache.catalina.servlets.CGIServlet$CGIRunner.sendToLog stderr line: [Traceback (most recent call last):]
27-Oct-2019 19:40:38.088 WARNING [Thread-126] org.apache.catalina.servlets.CGIServlet$CGIRunner.sendToLog stderr line: [  File "C:\Users\hayde\Desktop\UCI\Fall 2019\EECS 118\MP2\apache-tomcat-9.0.26\webapps\test\WEB-INF\cgi\project_3.py", line 57, in <module>]
27-Oct-2019 19:40:38.088 WARNING [Thread-126] org.apache.catalina.servlets.CGIServlet$CGIRunner.sendToLog stderr line: [    print(js)]
27-Oct-2019 19:40:38.091 WARNING [Thread-126] org.apache.catalina.servlets.CGIServlet$CGIRunner.sendToLog stderr line: [NameError: name 'js' is not defined]
27-Oct-2019 19:40:38.107 WARNING [Thread-126] org.apache.catalina.servlets.CGIServlet$CGIRunner.sendToLog Received [4] lines on stderr
27-Oct-2019 19:40:53.201 WARNING [Thread-127] org.apache.catalina.servlets.CGIServlet$CGIRunner.sendToLog stderr line: [Traceback (most recent call last):]
27-Oct-2019 19:40:53.201 WARNING [Thread-127] org.apache.catalina.servlets.CGIServlet$CGIRunner.sendToLog stderr line: [  File "C:\Users\hayde\Desktop\UCI\Fall 2019\EECS 118\MP2\apache-tomcat-9.0.26\webapps\test\WEB-INF\cgi\project_3.py", line 57, in <module>]
27-Oct-2019 19:40:53.203 WARNING [Thread-127] org.apache.catalina.servlets.CGIServlet$CGIRunner.sendToLog stderr line: [    print(js)]
27-Oct-2019 19:40:53.204 WARNING [Thread-127] org.apache.catalina.servlets.CGIServlet$CGIRunner.sendToLog stderr line: [NameError: name 'js' is not defined]
27-Oct-2019 19:40:53.227 WARNING [Thread-127] org.apache.catalina.servlets.CGIServlet$CGIRunner.sendToLog Received [4] lines on stderr
27-Oct-2019 19:44:02.708 WARNING [Thread-128] org.apache.catalina.servlets.CGIServlet$CGIRunner.sendToLog stderr line: [Traceback (most recent call last):]
27-Oct-2019 19:44:02.708 WARNING [Thread-128] org.apache.catalina.servlets.CGIServlet$CGIRunner.sendToLog stderr line: [  File "C:\Users\hayde\Desktop\UCI\Fall 2019\EECS 118\MP2\apache-tomcat-9.0.26\webapps\test\WEB-INF\cgi\project_3.py", line 63, in <module>]
27-Oct-2019 19:44:02.708 WARNING [Thread-128] org.apache.catalina.servlets.CGIServlet$CGIRunner.sendToLog stderr line: [    print(js)]
27-Oct-2019 19:44:02.708 WARNING [Thread-128] org.apache.catalina.servlets.CGIServlet$CGIRunner.sendToLog stderr line: [NameError: name 'js' is not defined]
27-Oct-2019 19:44:02.728 WARNING [Thread-128] org.apache.catalina.servlets.CGIServlet$CGIRunner.sendToLog Received [4] lines on stderr
27-Oct-2019 20:04:34.368 WARNING [Thread-142] org.apache.catalina.servlets.CGIServlet$CGIRunner.sendToLog stderr line: [Traceback (most recent call last):]
27-Oct-2019 20:04:34.368 WARNING [Thread-142] org.apache.catalina.servlets.CGIServlet$CGIRunner.sendToLog stderr line: [  File "C:\Users\hayde\Desktop\UCI\Fall 2019\EECS 118\MP2\apache-tomcat-9.0.26\webapps\test\WEB-INF\cgi\project_3.py", line 63, in <module>]
27-Oct-2019 20:04:34.373 WARNING [Thread-142] org.apache.catalina.servlets.CGIServlet$CGIRunner.sendToLog stderr line: [    print(js)]
27-Oct-2019 20:04:34.373 WARNING [Thread-142] org.apache.catalina.servlets.CGIServlet$CGIRunner.sendToLog stderr line: [NameError: name 'js' is not defined]
27-Oct-2019 20:04:34.392 WARNING [Thread-142] org.apache.catalina.servlets.CGIServlet$CGIRunner.sendToLog Received [4] lines on stderr
27-Oct-2019 20:47:23.213 WARNING [Thread-148] org.apache.catalina.servlets.CGIServlet$CGIRunner.sendToLog stderr line: [Traceback (most recent call last):]
27-Oct-2019 20:47:23.213 WARNING [Thread-148] org.apache.catalina.servlets.CGIServlet$CGIRunner.sendToLog stderr line: [  File "C:\Users\hayde\Desktop\UCI\Fall 2019\EECS 118\MP2\apache-tomcat-9.0.26\webapps\test\WEB-INF\cgi\project_3_search.py", line 73, in <module>]
27-Oct-2019 20:47:23.215 WARNING [Thread-148] org.apache.catalina.servlets.CGIServlet$CGIRunner.sendToLog stderr line: [    query = "select link from image where image_id ='"+imgs[i][0]+"'"]
27-Oct-2019 20:47:23.216 WARNING [Thread-148] org.apache.catalina.servlets.CGIServlet$CGIRunner.sendToLog stderr line: [TypeError: must be str, not int]
27-Oct-2019 20:47:23.232 WARNING [Thread-148] org.apache.catalina.servlets.CGIServlet$CGIRunner.sendToLog Received [4] lines on stderr
27-Oct-2019 20:48:20.586 WARNING [Thread-149] org.apache.catalina.servlets.CGIServlet$CGIRunner.sendToLog stderr line: [Traceback (most recent call last):]
27-Oct-2019 20:48:20.586 WARNING [Thread-149] org.apache.catalina.servlets.CGIServlet$CGIRunner.sendToLog stderr line: [  File "C:\Users\hayde\Desktop\UCI\Fall 2019\EECS 118\MP2\apache-tomcat-9.0.26\webapps\test\WEB-INF\cgi\project_3_search.py", line 77, in <module>]
27-Oct-2019 20:48:20.586 WARNING [Thread-149] org.apache.catalina.servlets.CGIServlet$CGIRunner.sendToLog stderr line: [    query = "select link from image where image_id ='"+imgs[i][0]+"'"]
27-Oct-2019 20:48:20.586 WARNING [Thread-149] org.apache.catalina.servlets.CGIServlet$CGIRunner.sendToLog stderr line: [TypeError: must be str, not int]
27-Oct-2019 20:48:20.603 WARNING [Thread-149] org.apache.catalina.servlets.CGIServlet$CGIRunner.sendToLog Received [4] lines on stderr
27-Oct-2019 20:57:45.662 WARNING [Thread-155] org.apache.catalina.servlets.CGIServlet$CGIRunner.sendToLog stderr line: [Traceback (most recent call last):]
27-Oct-2019 20:57:45.664 WARNING [Thread-155] org.apache.catalina.servlets.CGIServlet$CGIRunner.sendToLog stderr line: [  File "C:\Users\hayde\Desktop\UCI\Fall 2019\EECS 118\MP2\apache-tomcat-9.0.26\webapps\test\WEB-INF\cgi\project_3_search.py", line 77, in <module>]
27-Oct-2019 20:57:45.665 WARNING [Thread-155] org.apache.catalina.servlets.CGIServlet$CGIRunner.sendToLog stderr line: [    query = "select link from image where image_id ='"+imgs[i][0]+"'"]
27-Oct-2019 20:57:45.665 WARNING [Thread-155] org.apache.catalina.servlets.CGIServlet$CGIRunner.sendToLog stderr line: [TypeError: must be str, not int]
27-Oct-2019 20:57:45.683 WARNING [Thread-155] org.apache.catalina.servlets.CGIServlet$CGIRunner.sendToLog Received [4] lines on stderr
27-Oct-2019 21:00:14.599 WARNING [Thread-156] org.apache.catalina.servlets.CGIServlet$CGIRunner.sendToLog stderr line: [Traceback (most recent call last):]
27-Oct-2019 21:00:14.600 WARNING [Thread-156] org.apache.catalina.servlets.CGIServlet$CGIRunner.sendToLog stderr line: [  File "C:\Users\hayde\Desktop\UCI\Fall 2019\EECS 118\MP2\apache-tomcat-9.0.26\webapps\test\WEB-INF\cgi\project_3_search.py", line 77, in <module>]
27-Oct-2019 21:00:14.601 WARNING [Thread-156] org.apache.catalina.servlets.CGIServlet$CGIRunner.sendToLog stderr line: [    query = "select link from image where image_id ='"+imgs[i][0]+"'"]
27-Oct-2019 21:00:14.602 WARNING [Thread-156] org.apache.catalina.servlets.CGIServlet$CGIRunner.sendToLog stderr line: [TypeError: must be str, not int]
27-Oct-2019 21:00:14.618 WARNING [Thread-156] org.apache.catalina.servlets.CGIServlet$CGIRunner.sendToLog Received [4] lines on stderr
27-Oct-2019 21:00:36.672 WARNING [Thread-157] org.apache.catalina.servlets.CGIServlet$CGIRunner.sendToLog stderr line: [Traceback (most recent call last):]
27-Oct-2019 21:00:36.673 WARNING [Thread-157] org.apache.catalina.servlets.CGIServlet$CGIRunner.sendToLog stderr line: [  File "C:\Users\hayde\Desktop\UCI\Fall 2019\EECS 118\MP2\apache-tomcat-9.0.26\webapps\test\WEB-INF\cgi\project_3_search.py", line 77, in <module>]
27-Oct-2019 21:00:36.674 WARNING [Thread-157] org.apache.catalina.servlets.CGIServlet$CGIRunner.sendToLog stderr line: [    query = "select link from image where image_id ='"+imgs[i][0]+"'"]
27-Oct-2019 21:00:36.674 WARNING [Thread-157] org.apache.catalina.servlets.CGIServlet$CGIRunner.sendToLog stderr line: [TypeError: must be str, not int]
27-Oct-2019 21:00:36.690 WARNING [Thread-157] org.apache.catalina.servlets.CGIServlet$CGIRunner.sendToLog Received [4] lines on stderr
27-Oct-2019 21:00:38.355 WARNING [Thread-158] org.apache.catalina.servlets.CGIServlet$CGIRunner.sendToLog stderr line: [Traceback (most recent call last):]
27-Oct-2019 21:00:38.355 WARNING [Thread-158] org.apache.catalina.servlets.CGIServlet$CGIRunner.sendToLog stderr line: [  File "C:\Users\hayde\Desktop\UCI\Fall 2019\EECS 118\MP2\apache-tomcat-9.0.26\webapps\test\WEB-INF\cgi\project_3_search.py", line 77, in <module>]
27-Oct-2019 21:00:38.361 WARNING [Thread-158] org.apache.catalina.servlets.CGIServlet$CGIRunner.sendToLog stderr line: [    query = "select link from image where image_id ='"+imgs[i][0]+"'"]
27-Oct-2019 21:00:38.362 WARNING [Thread-158] org.apache.catalina.servlets.CGIServlet$CGIRunner.sendToLog stderr line: [TypeError: must be str, not int]
27-Oct-2019 21:00:38.374 WARNING [Thread-158] org.apache.catalina.servlets.CGIServlet$CGIRunner.sendToLog Received [4] lines on stderr
27-Oct-2019 21:02:04.686 WARNING [Thread-160] org.apache.catalina.servlets.CGIServlet$CGIRunner.sendToLog stderr line: [Traceback (most recent call last):]
27-Oct-2019 21:02:04.688 WARNING [Thread-160] org.apache.catalina.servlets.CGIServlet$CGIRunner.sendToLog stderr line: [  File "C:\Users\hayde\Desktop\UCI\Fall 2019\EECS 118\MP2\apache-tomcat-9.0.26\webapps\test\WEB-INF\cgi\project_3_search.py", line 77, in <module>]
27-Oct-2019 21:02:04.690 WARNING [Thread-160] org.apache.catalina.servlets.CGIServlet$CGIRunner.sendToLog stderr line: [    query = "select link from image where image_id ='"+imgs[i][0]+"'"]
27-Oct-2019 21:02:04.691 WARNING [Thread-160] org.apache.catalina.servlets.CGIServlet$CGIRunner.sendToLog stderr line: [TypeError: must be str, not int]
27-Oct-2019 21:02:04.706 WARNING [Thread-160] org.apache.catalina.servlets.CGIServlet$CGIRunner.sendToLog Received [4] lines on stderr
27-Oct-2019 21:04:26.412 WARNING [Thread-162] org.apache.catalina.servlets.CGIServlet$CGIRunner.sendToLog stderr line: [Traceback (most recent call last):]
27-Oct-2019 21:04:26.412 WARNING [Thread-162] org.apache.catalina.servlets.CGIServlet$CGIRunner.sendToLog stderr line: [  File "C:\Users\hayde\Desktop\UCI\Fall 2019\EECS 118\MP2\apache-tomcat-9.0.26\webapps\test\WEB-INF\cgi\project_3_search.py", line 95, in <module>]
27-Oct-2019 21:04:26.412 WARNING [Thread-162] org.apache.catalina.servlets.CGIServlet$CGIRunner.sendToLog stderr line: [    if artist_id[0] == 0:]
27-Oct-2019 21:04:26.416 WARNING [Thread-162] org.apache.catalina.servlets.CGIServlet$CGIRunner.sendToLog stderr line: [TypeError: 'NoneType' object is not subscriptable]
27-Oct-2019 21:04:26.431 WARNING [Thread-162] org.apache.catalina.servlets.CGIServlet$CGIRunner.sendToLog Received [4] lines on stderr
27-Oct-2019 21:06:29.545 WARNING [Thread-164] org.apache.catalina.servlets.CGIServlet$CGIRunner.sendToLog stderr line: [Traceback (most recent call last):]
27-Oct-2019 21:06:29.545 WARNING [Thread-164] org.apache.catalina.servlets.CGIServlet$CGIRunner.sendToLog stderr line: [  File "C:\Users\hayde\Desktop\UCI\Fall 2019\EECS 118\MP2\apache-tomcat-9.0.26\webapps\test\WEB-INF\cgi\project_3_search.py", line 95, in <module>]
27-Oct-2019 21:06:29.545 WARNING [Thread-164] org.apache.catalina.servlets.CGIServlet$CGIRunner.sendToLog stderr line: [    if artist_id[0] == 0:]
27-Oct-2019 21:06:29.545 WARNING [Thread-164] org.apache.catalina.servlets.CGIServlet$CGIRunner.sendToLog stderr line: [TypeError: 'NoneType' object is not subscriptable]
27-Oct-2019 21:06:29.566 WARNING [Thread-164] org.apache.catalina.servlets.CGIServlet$CGIRunner.sendToLog Received [4] lines on stderr
27-Oct-2019 21:07:29.023 WARNING [Thread-165] org.apache.catalina.servlets.CGIServlet$CGIRunner.sendToLog stderr line: [Traceback (most recent call last):]
27-Oct-2019 21:07:29.023 WARNING [Thread-165] org.apache.catalina.servlets.CGIServlet$CGIRunner.sendToLog stderr line: [  File "C:\Users\hayde\Desktop\UCI\Fall 2019\EECS 118\MP2\apache-tomcat-9.0.26\webapps\test\WEB-INF\cgi\project_3_search.py", line 90, in <module>]
27-Oct-2019 21:07:29.023 WARNING [Thread-165] org.apache.catalina.servlets.CGIServlet$CGIRunner.sendToLog stderr line: [    query = "select artist_id from image where link='"+img_link[i][0]+"'"]
27-Oct-2019 21:07:29.027 WARNING [Thread-165] org.apache.catalina.servlets.CGIServlet$CGIRunner.sendToLog stderr line: [IndexError: tuple index out of range]
27-Oct-2019 21:07:29.045 WARNING [Thread-165] org.apache.catalina.servlets.CGIServlet$CGIRunner.sendToLog Received [4] lines on stderr
27-Oct-2019 21:09:58.752 WARNING [Thread-169] org.apache.catalina.servlets.CGIServlet$CGIRunner.sendToLog stderr line: [Traceback (most recent call last):]
27-Oct-2019 21:09:58.752 WARNING [Thread-169] org.apache.catalina.servlets.CGIServlet$CGIRunner.sendToLog stderr line: [  File "C:\Users\hayde\Desktop\UCI\Fall 2019\EECS 118\MP2\apache-tomcat-9.0.26\webapps\test\WEB-INF\cgi\project_3_search.py", line 112, in <module>]
27-Oct-2019 21:09:58.752 WARNING [Thread-169] org.apache.catalina.servlets.CGIServlet$CGIRunner.sendToLog stderr line: [    display_imgs = "<img src='"+img_link[i][0]+"' width="+str(detail[4])+"px height="+str(detail[5])+"px alt='img not found'>"]
27-Oct-2019 21:09:58.755 WARNING [Thread-169] org.apache.catalina.servlets.CGIServlet$CGIRunner.sendToLog stderr line: [IndexError: tuple index out of range]
27-Oct-2019 21:09:58.773 WARNING [Thread-169] org.apache.catalina.servlets.CGIServlet$CGIRunner.sendToLog Received [4] lines on stderr
27-Oct-2019 21:11:59.252 WARNING [Thread-173] org.apache.catalina.servlets.CGIServlet$CGIRunner.sendToLog stderr line: [Traceback (most recent call last):]
27-Oct-2019 21:11:59.252 WARNING [Thread-173] org.apache.catalina.servlets.CGIServlet$CGIRunner.sendToLog stderr line: [  File "C:\Users\hayde\Desktop\UCI\Fall 2019\EECS 118\MP2\apache-tomcat-9.0.26\webapps\test\WEB-INF\cgi\project_3_search.py", line 70, in <module>]
27-Oct-2019 21:11:59.253 WARNING [Thread-173] org.apache.catalina.servlets.CGIServlet$CGIRunner.sendToLog stderr line: [    query = "select image_id from image where artist_id='"+artist_id+"'"]
27-Oct-2019 21:11:59.254 WARNING [Thread-173] org.apache.catalina.servlets.CGIServlet$CGIRunner.sendToLog stderr line: [TypeError: must be str, not tuple]
27-Oct-2019 21:11:59.269 WARNING [Thread-173] org.apache.catalina.servlets.CGIServlet$CGIRunner.sendToLog Received [4] lines on stderr
27-Oct-2019 21:12:15.774 WARNING [Thread-174] org.apache.catalina.servlets.CGIServlet$CGIRunner.sendToLog stderr line: [Traceback (most recent call last):]
27-Oct-2019 21:12:15.774 WARNING [Thread-174] org.apache.catalina.servlets.CGIServlet$CGIRunner.sendToLog stderr line: [  File "C:\Users\hayde\Desktop\UCI\Fall 2019\EECS 118\MP2\apache-tomcat-9.0.26\webapps\test\WEB-INF\cgi\project_3_search.py", line 70, in <module>]
27-Oct-2019 21:12:15.775 WARNING [Thread-174] org.apache.catalina.servlets.CGIServlet$CGIRunner.sendToLog stderr line: [    query = "select image_id from image where artist_id='"+artist_id+"'"]
27-Oct-2019 21:12:15.775 WARNING [Thread-174] org.apache.catalina.servlets.CGIServlet$CGIRunner.sendToLog stderr line: [TypeError: must be str, not tuple]
27-Oct-2019 21:12:15.793 WARNING [Thread-174] org.apache.catalina.servlets.CGIServlet$CGIRunner.sendToLog Received [4] lines on stderr
27-Oct-2019 22:38:38.797 WARNING [Thread-179] org.apache.catalina.servlets.CGIServlet$CGIRunner.sendToLog stderr line: [Traceback (most recent call last):]
27-Oct-2019 22:38:38.797 WARNING [Thread-179] org.apache.catalina.servlets.CGIServlet$CGIRunner.sendToLog stderr line: [  File "C:\Users\hayde\Desktop\UCI\Fall 2019\EECS 118\MP2\apache-tomcat-9.0.26\webapps\test\WEB-INF\cgi\project_3_search.py", line 143, in <module>]
27-Oct-2019 22:38:38.801 WARNING [Thread-179] org.apache.catalina.servlets.CGIServlet$CGIRunner.sendToLog stderr line: [    cur.execute(query)]
27-Oct-2019 22:38:38.801 WARNING [Thread-179] org.apache.catalina.servlets.CGIServlet$CGIRunner.sendToLog stderr line: [  File "C:\Users\hayde\AppData\Local\Programs\Python\Python36\lib\site-packages\pymysql\cursors.py", line 170, in execute]
27-Oct-2019 22:38:38.801 WARNING [Thread-179] org.apache.catalina.servlets.CGIServlet$CGIRunner.sendToLog stderr line: [    result = self._query(query)]
27-Oct-2019 22:38:38.801 WARNING [Thread-179] org.apache.catalina.servlets.CGIServlet$CGIRunner.sendToLog stderr line: [  File "C:\Users\hayde\AppData\Local\Programs\Python\Python36\lib\site-packages\pymysql\cursors.py", line 328, in _query]
27-Oct-2019 22:38:38.806 WARNING [Thread-179] org.apache.catalina.servlets.CGIServlet$CGIRunner.sendToLog stderr line: [    conn.query(q)]
27-Oct-2019 22:38:38.808 WARNING [Thread-179] org.apache.catalina.servlets.CGIServlet$CGIRunner.sendToLog stderr line: [  File "C:\Users\hayde\AppData\Local\Programs\Python\Python36\lib\site-packages\pymysql\connections.py", line 517, in query]
27-Oct-2019 22:38:38.810 WARNING [Thread-179] org.apache.catalina.servlets.CGIServlet$CGIRunner.sendToLog stderr line: [    self._affected_rows = self._read_query_result(unbuffered=unbuffered)]
27-Oct-2019 22:38:38.812 WARNING [Thread-179] org.apache.catalina.servlets.CGIServlet$CGIRunner.sendToLog stderr line: [  File "C:\Users\hayde\AppData\Local\Programs\Python\Python36\lib\site-packages\pymysql\connections.py", line 732, in _read_query_result]
27-Oct-2019 22:38:38.812 WARNING [Thread-179] org.apache.catalina.servlets.CGIServlet$CGIRunner.sendToLog stderr line: [    result.read()]
27-Oct-2019 22:38:38.814 WARNING [Thread-179] org.apache.catalina.servlets.CGIServlet$CGIRunner.sendToLog stderr line: [  File "C:\Users\hayde\AppData\Local\Programs\Python\Python36\lib\site-packages\pymysql\connections.py", line 1075, in read]
27-Oct-2019 22:38:38.816 WARNING [Thread-179] org.apache.catalina.servlets.CGIServlet$CGIRunner.sendToLog stderr line: [    first_packet = self.connection._read_packet()]
27-Oct-2019 22:38:38.816 WARNING [Thread-179] org.apache.catalina.servlets.CGIServlet$CGIRunner.sendToLog stderr line: [  File "C:\Users\hayde\AppData\Local\Programs\Python\Python36\lib\site-packages\pymysql\connections.py", line 684, in _read_packet]
27-Oct-2019 22:38:38.816 WARNING [Thread-179] org.apache.catalina.servlets.CGIServlet$CGIRunner.sendToLog stderr line: [    packet.check_error()]
27-Oct-2019 22:38:38.819 WARNING [Thread-179] org.apache.catalina.servlets.CGIServlet$CGIRunner.sendToLog stderr line: [  File "C:\Users\hayde\AppData\Local\Programs\Python\Python36\lib\site-packages\pymysql\protocol.py", line 220, in check_error]
27-Oct-2019 22:38:38.820 WARNING [Thread-179] org.apache.catalina.servlets.CGIServlet$CGIRunner.sendToLog stderr line: [    err.raise_mysql_exception(self._data)]
27-Oct-2019 22:38:38.820 WARNING [Thread-179] org.apache.catalina.servlets.CGIServlet$CGIRunner.sendToLog stderr line: [  File "C:\Users\hayde\AppData\Local\Programs\Python\Python36\lib\site-packages\pymysql\err.py", line 109, in raise_mysql_exception]
27-Oct-2019 22:38:38.820 WARNING [Thread-179] org.apache.catalina.servlets.CGIServlet$CGIRunner.sendToLog stderr line: [    raise errorclass(errno, errval)]
27-Oct-2019 22:38:38.820 WARNING [Thread-179] org.apache.catalina.servlets.CGIServlet$CGIRunner.sendToLog stderr line: [pymysql.err.InternalError: (1054, "Unknown column 'birth_year' in 'where clause'")]
27-Oct-2019 22:38:38.835 WARNING [Thread-179] org.apache.catalina.servlets.CGIServlet$CGIRunner.sendToLog Received [20] lines on stderr
27-Oct-2019 22:38:46.164 WARNING [Thread-180] org.apache.catalina.servlets.CGIServlet$CGIRunner.sendToLog stderr line: [Traceback (most recent call last):]
27-Oct-2019 22:38:46.164 WARNING [Thread-180] org.apache.catalina.servlets.CGIServlet$CGIRunner.sendToLog stderr line: [  File "C:\Users\hayde\Desktop\UCI\Fall 2019\EECS 118\MP2\apache-tomcat-9.0.26\webapps\test\WEB-INF\cgi\project_3_search.py", line 143, in <module>]
27-Oct-2019 22:38:46.168 WARNING [Thread-180] org.apache.catalina.servlets.CGIServlet$CGIRunner.sendToLog stderr line: [    cur.execute(query)]
27-Oct-2019 22:38:46.168 WARNING [Thread-180] org.apache.catalina.servlets.CGIServlet$CGIRunner.sendToLog stderr line: [  File "C:\Users\hayde\AppData\Local\Programs\Python\Python36\lib\site-packages\pymysql\cursors.py", line 170, in execute]
27-Oct-2019 22:38:46.169 WARNING [Thread-180] org.apache.catalina.servlets.CGIServlet$CGIRunner.sendToLog stderr line: [    result = self._query(query)]
27-Oct-2019 22:38:46.170 WARNING [Thread-180] org.apache.catalina.servlets.CGIServlet$CGIRunner.sendToLog stderr line: [  File "C:\Users\hayde\AppData\Local\Programs\Python\Python36\lib\site-packages\pymysql\cursors.py", line 328, in _query]
27-Oct-2019 22:38:46.171 WARNING [Thread-180] org.apache.catalina.servlets.CGIServlet$CGIRunner.sendToLog stderr line: [    conn.query(q)]
27-Oct-2019 22:38:46.172 WARNING [Thread-180] org.apache.catalina.servlets.CGIServlet$CGIRunner.sendToLog stderr line: [  File "C:\Users\hayde\AppData\Local\Programs\Python\Python36\lib\site-packages\pymysql\connections.py", line 517, in query]
27-Oct-2019 22:38:46.173 WARNING [Thread-180] org.apache.catalina.servlets.CGIServlet$CGIRunner.sendToLog stderr line: [    self._affected_rows = self._read_query_result(unbuffered=unbuffered)]
27-Oct-2019 22:38:46.173 WARNING [Thread-180] org.apache.catalina.servlets.CGIServlet$CGIRunner.sendToLog stderr line: [  File "C:\Users\hayde\AppData\Local\Programs\Python\Python36\lib\site-packages\pymysql\connections.py", line 732, in _read_query_result]
27-Oct-2019 22:38:46.175 WARNING [Thread-180] org.apache.catalina.servlets.CGIServlet$CGIRunner.sendToLog stderr line: [    result.read()]
27-Oct-2019 22:38:46.175 WARNING [Thread-180] org.apache.catalina.servlets.CGIServlet$CGIRunner.sendToLog stderr line: [  File "C:\Users\hayde\AppData\Local\Programs\Python\Python36\lib\site-packages\pymysql\connections.py", line 1075, in read]
27-Oct-2019 22:38:46.176 WARNING [Thread-180] org.apache.catalina.servlets.CGIServlet$CGIRunner.sendToLog stderr line: [    first_packet = self.connection._read_packet()]
27-Oct-2019 22:38:46.176 WARNING [Thread-180] org.apache.catalina.servlets.CGIServlet$CGIRunner.sendToLog stderr line: [  File "C:\Users\hayde\AppData\Local\Programs\Python\Python36\lib\site-packages\pymysql\connections.py", line 684, in _read_packet]
27-Oct-2019 22:38:46.177 WARNING [Thread-180] org.apache.catalina.servlets.CGIServlet$CGIRunner.sendToLog stderr line: [    packet.check_error()]
27-Oct-2019 22:38:46.178 WARNING [Thread-180] org.apache.catalina.servlets.CGIServlet$CGIRunner.sendToLog stderr line: [  File "C:\Users\hayde\AppData\Local\Programs\Python\Python36\lib\site-packages\pymysql\protocol.py", line 220, in check_error]
27-Oct-2019 22:38:46.179 WARNING [Thread-180] org.apache.catalina.servlets.CGIServlet$CGIRunner.sendToLog stderr line: [    err.raise_mysql_exception(self._data)]
27-Oct-2019 22:38:46.180 WARNING [Thread-180] org.apache.catalina.servlets.CGIServlet$CGIRunner.sendToLog stderr line: [  File "C:\Users\hayde\AppData\Local\Programs\Python\Python36\lib\site-packages\pymysql\err.py", line 109, in raise_mysql_exception]
27-Oct-2019 22:38:46.181 WARNING [Thread-180] org.apache.catalina.servlets.CGIServlet$CGIRunner.sendToLog stderr line: [    raise errorclass(errno, errval)]
27-Oct-2019 22:38:46.182 WARNING [Thread-180] org.apache.catalina.servlets.CGIServlet$CGIRunner.sendToLog stderr line: [pymysql.err.InternalError: (1054, "Unknown column 'birth_year' in 'where clause'")]
27-Oct-2019 22:38:46.187 WARNING [Thread-180] org.apache.catalina.servlets.CGIServlet$CGIRunner.sendToLog Received [20] lines on stderr
27-Oct-2019 22:39:55.240 WARNING [Thread-181] org.apache.catalina.servlets.CGIServlet$CGIRunner.sendToLog stderr line: [Traceback (most recent call last):]
27-Oct-2019 22:39:55.245 WARNING [Thread-181] org.apache.catalina.servlets.CGIServlet$CGIRunner.sendToLog stderr line: [  File "C:\Users\hayde\Desktop\UCI\Fall 2019\EECS 118\MP2\apache-tomcat-9.0.26\webapps\test\WEB-INF\cgi\project_3_search.py", line 143, in <module>]
27-Oct-2019 22:39:55.246 WARNING [Thread-181] org.apache.catalina.servlets.CGIServlet$CGIRunner.sendToLog stderr line: [    cur.execute(query)]
27-Oct-2019 22:39:55.246 WARNING [Thread-181] org.apache.catalina.servlets.CGIServlet$CGIRunner.sendToLog stderr line: [  File "C:\Users\hayde\AppData\Local\Programs\Python\Python36\lib\site-packages\pymysql\cursors.py", line 170, in execute]
27-Oct-2019 22:39:55.246 WARNING [Thread-181] org.apache.catalina.servlets.CGIServlet$CGIRunner.sendToLog stderr line: [    result = self._query(query)]
27-Oct-2019 22:39:55.248 WARNING [Thread-181] org.apache.catalina.servlets.CGIServlet$CGIRunner.sendToLog stderr line: [  File "C:\Users\hayde\AppData\Local\Programs\Python\Python36\lib\site-packages\pymysql\cursors.py", line 328, in _query]
27-Oct-2019 22:39:55.249 WARNING [Thread-181] org.apache.catalina.servlets.CGIServlet$CGIRunner.sendToLog stderr line: [    conn.query(q)]
27-Oct-2019 22:39:55.251 WARNING [Thread-181] org.apache.catalina.servlets.CGIServlet$CGIRunner.sendToLog stderr line: [  File "C:\Users\hayde\AppData\Local\Programs\Python\Python36\lib\site-packages\pymysql\connections.py", line 517, in query]
27-Oct-2019 22:39:55.251 WARNING [Thread-181] org.apache.catalina.servlets.CGIServlet$CGIRunner.sendToLog stderr line: [    self._affected_rows = self._read_query_result(unbuffered=unbuffered)]
27-Oct-2019 22:39:55.252 WARNING [Thread-181] org.apache.catalina.servlets.CGIServlet$CGIRunner.sendToLog stderr line: [  File "C:\Users\hayde\AppData\Local\Programs\Python\Python36\lib\site-packages\pymysql\connections.py", line 732, in _read_query_result]
27-Oct-2019 22:39:55.254 WARNING [Thread-181] org.apache.catalina.servlets.CGIServlet$CGIRunner.sendToLog stderr line: [    result.read()]
27-Oct-2019 22:39:55.254 WARNING [Thread-181] org.apache.catalina.servlets.CGIServlet$CGIRunner.sendToLog stderr line: [  File "C:\Users\hayde\AppData\Local\Programs\Python\Python36\lib\site-packages\pymysql\connections.py", line 1075, in read]
27-Oct-2019 22:39:55.255 WARNING [Thread-181] org.apache.catalina.servlets.CGIServlet$CGIRunner.sendToLog stderr line: [    first_packet = self.connection._read_packet()]
27-Oct-2019 22:39:55.255 WARNING [Thread-181] org.apache.catalina.servlets.CGIServlet$CGIRunner.sendToLog stderr line: [  File "C:\Users\hayde\AppData\Local\Programs\Python\Python36\lib\site-packages\pymysql\connections.py", line 684, in _read_packet]
27-Oct-2019 22:39:55.257 WARNING [Thread-181] org.apache.catalina.servlets.CGIServlet$CGIRunner.sendToLog stderr line: [    packet.check_error()]
27-Oct-2019 22:39:55.258 WARNING [Thread-181] org.apache.catalina.servlets.CGIServlet$CGIRunner.sendToLog stderr line: [  File "C:\Users\hayde\AppData\Local\Programs\Python\Python36\lib\site-packages\pymysql\protocol.py", line 220, in check_error]
27-Oct-2019 22:39:55.259 WARNING [Thread-181] org.apache.catalina.servlets.CGIServlet$CGIRunner.sendToLog stderr line: [    err.raise_mysql_exception(self._data)]
27-Oct-2019 22:39:55.259 WARNING [Thread-181] org.apache.catalina.servlets.CGIServlet$CGIRunner.sendToLog stderr line: [  File "C:\Users\hayde\AppData\Local\Programs\Python\Python36\lib\site-packages\pymysql\err.py", line 109, in raise_mysql_exception]
27-Oct-2019 22:39:55.260 WARNING [Thread-181] org.apache.catalina.servlets.CGIServlet$CGIRunner.sendToLog stderr line: [    raise errorclass(errno, errval)]
27-Oct-2019 22:39:55.261 WARNING [Thread-181] org.apache.catalina.servlets.CGIServlet$CGIRunner.sendToLog stderr line: [pymysql.err.InternalError: (1054, "Unknown column 'birth_year' in 'where clause'")]
27-Oct-2019 22:39:55.270 WARNING [Thread-181] org.apache.catalina.servlets.CGIServlet$CGIRunner.sendToLog Received [20] lines on stderr
27-Oct-2019 22:41:27.464 WARNING [Thread-182] org.apache.catalina.servlets.CGIServlet$CGIRunner.sendToLog stderr line: [  File "C:\Users\hayde\Desktop\UCI\Fall 2019\EECS 118\MP2\apache-tomcat-9.0.26\webapps\test\WEB-INF\cgi\project_3_search.py", line 167]
27-Oct-2019 22:41:27.466 WARNING [Thread-182] org.apache.catalina.servlets.CGIServlet$CGIRunner.sendToLog stderr line: [    else:]
27-Oct-2019 22:41:27.468 WARNING [Thread-182] org.apache.catalina.servlets.CGIServlet$CGIRunner.sendToLog stderr line: [       ^]
27-Oct-2019 22:41:27.470 WARNING [Thread-182] org.apache.catalina.servlets.CGIServlet$CGIRunner.sendToLog stderr line: [SyntaxError: invalid syntax]
27-Oct-2019 22:41:27.478 WARNING [Thread-182] org.apache.catalina.servlets.CGIServlet$CGIRunner.sendToLog Received [4] lines on stderr
27-Oct-2019 22:42:35.846 WARNING [Thread-183] org.apache.catalina.servlets.CGIServlet$CGIRunner.sendToLog stderr line: [Traceback (most recent call last):]
27-Oct-2019 22:42:35.846 WARNING [Thread-183] org.apache.catalina.servlets.CGIServlet$CGIRunner.sendToLog stderr line: [  File "C:\Users\hayde\Desktop\UCI\Fall 2019\EECS 118\MP2\apache-tomcat-9.0.26\webapps\test\WEB-INF\cgi\project_3.py", line 63, in <module>]
27-Oct-2019 22:42:35.846 WARNING [Thread-183] org.apache.catalina.servlets.CGIServlet$CGIRunner.sendToLog stderr line: [    print(js)]
27-Oct-2019 22:42:35.850 WARNING [Thread-183] org.apache.catalina.servlets.CGIServlet$CGIRunner.sendToLog stderr line: [NameError: name 'js' is not defined]
27-Oct-2019 22:42:35.866 WARNING [Thread-183] org.apache.catalina.servlets.CGIServlet$CGIRunner.sendToLog Received [4] lines on stderr
27-Oct-2019 22:42:38.151 WARNING [Thread-184] org.apache.catalina.servlets.CGIServlet$CGIRunner.sendToLog stderr line: [  File "C:\Users\hayde\Desktop\UCI\Fall 2019\EECS 118\MP2\apache-tomcat-9.0.26\webapps\test\WEB-INF\cgi\project_3_search.py", line 167]
27-Oct-2019 22:42:38.156 WARNING [Thread-184] org.apache.catalina.servlets.CGIServlet$CGIRunner.sendToLog stderr line: [    else:]
27-Oct-2019 22:42:38.158 WARNING [Thread-184] org.apache.catalina.servlets.CGIServlet$CGIRunner.sendToLog stderr line: [       ^]
27-Oct-2019 22:42:38.160 WARNING [Thread-184] org.apache.catalina.servlets.CGIServlet$CGIRunner.sendToLog stderr line: [SyntaxError: invalid syntax]
27-Oct-2019 22:42:38.167 WARNING [Thread-184] org.apache.catalina.servlets.CGIServlet$CGIRunner.sendToLog Received [4] lines on stderr
27-Oct-2019 22:42:51.672 WARNING [Thread-185] org.apache.catalina.servlets.CGIServlet$CGIRunner.sendToLog stderr line: [  File "C:\Users\hayde\Desktop\UCI\Fall 2019\EECS 118\MP2\apache-tomcat-9.0.26\webapps\test\WEB-INF\cgi\project_3_search.py", line 167]
27-Oct-2019 22:42:51.672 WARNING [Thread-185] org.apache.catalina.servlets.CGIServlet$CGIRunner.sendToLog stderr line: [    else:]
27-Oct-2019 22:42:51.676 WARNING [Thread-185] org.apache.catalina.servlets.CGIServlet$CGIRunner.sendToLog stderr line: [       ^]
27-Oct-2019 22:42:51.677 WARNING [Thread-185] org.apache.catalina.servlets.CGIServlet$CGIRunner.sendToLog stderr line: [SyntaxError: invalid syntax]
27-Oct-2019 22:42:51.684 WARNING [Thread-185] org.apache.catalina.servlets.CGIServlet$CGIRunner.sendToLog Received [4] lines on stderr
27-Oct-2019 22:44:21.543 WARNING [Thread-188] org.apache.catalina.servlets.CGIServlet$CGIRunner.sendToLog stderr line: [Traceback (most recent call last):]
27-Oct-2019 22:44:21.543 WARNING [Thread-188] org.apache.catalina.servlets.CGIServlet$CGIRunner.sendToLog stderr line: [  File "C:\Users\hayde\Desktop\UCI\Fall 2019\EECS 118\MP2\apache-tomcat-9.0.26\webapps\test\WEB-INF\cgi\project_3.py", line 63, in <module>]
27-Oct-2019 22:44:21.548 WARNING [Thread-188] org.apache.catalina.servlets.CGIServlet$CGIRunner.sendToLog stderr line: [    print(js)]
27-Oct-2019 22:44:21.548 WARNING [Thread-188] org.apache.catalina.servlets.CGIServlet$CGIRunner.sendToLog stderr line: [NameError: name 'js' is not defined]
27-Oct-2019 22:44:21.570 WARNING [Thread-188] org.apache.catalina.servlets.CGIServlet$CGIRunner.sendToLog Received [4] lines on stderr
27-Oct-2019 22:44:46.085 WARNING [Thread-189] org.apache.catalina.servlets.CGIServlet$CGIRunner.sendToLog stderr line: [Traceback (most recent call last):]
27-Oct-2019 22:44:46.085 WARNING [Thread-189] org.apache.catalina.servlets.CGIServlet$CGIRunner.sendToLog stderr line: [  File "C:\Users\hayde\Desktop\UCI\Fall 2019\EECS 118\MP2\apache-tomcat-9.0.26\webapps\test\WEB-INF\cgi\project_3_search.py", line 144, in <module>]
27-Oct-2019 22:44:46.089 WARNING [Thread-189] org.apache.catalina.servlets.CGIServlet$CGIRunner.sendToLog stderr line: [    cur.execute(query)]
27-Oct-2019 22:44:46.090 WARNING [Thread-189] org.apache.catalina.servlets.CGIServlet$CGIRunner.sendToLog stderr line: [  File "C:\Users\hayde\AppData\Local\Programs\Python\Python36\lib\site-packages\pymysql\cursors.py", line 170, in execute]
27-Oct-2019 22:44:46.091 WARNING [Thread-189] org.apache.catalina.servlets.CGIServlet$CGIRunner.sendToLog stderr line: [    result = self._query(query)]
27-Oct-2019 22:44:46.091 WARNING [Thread-189] org.apache.catalina.servlets.CGIServlet$CGIRunner.sendToLog stderr line: [  File "C:\Users\hayde\AppData\Local\Programs\Python\Python36\lib\site-packages\pymysql\cursors.py", line 328, in _query]
27-Oct-2019 22:44:46.092 WARNING [Thread-189] org.apache.catalina.servlets.CGIServlet$CGIRunner.sendToLog stderr line: [    conn.query(q)]
27-Oct-2019 22:44:46.092 WARNING [Thread-189] org.apache.catalina.servlets.CGIServlet$CGIRunner.sendToLog stderr line: [  File "C:\Users\hayde\AppData\Local\Programs\Python\Python36\lib\site-packages\pymysql\connections.py", line 517, in query]
27-Oct-2019 22:44:46.093 WARNING [Thread-189] org.apache.catalina.servlets.CGIServlet$CGIRunner.sendToLog stderr line: [    self._affected_rows = self._read_query_result(unbuffered=unbuffered)]
27-Oct-2019 22:44:46.094 WARNING [Thread-189] org.apache.catalina.servlets.CGIServlet$CGIRunner.sendToLog stderr line: [  File "C:\Users\hayde\AppData\Local\Programs\Python\Python36\lib\site-packages\pymysql\connections.py", line 732, in _read_query_result]
27-Oct-2019 22:44:46.095 WARNING [Thread-189] org.apache.catalina.servlets.CGIServlet$CGIRunner.sendToLog stderr line: [    result.read()]
27-Oct-2019 22:44:46.095 WARNING [Thread-189] org.apache.catalina.servlets.CGIServlet$CGIRunner.sendToLog stderr line: [  File "C:\Users\hayde\AppData\Local\Programs\Python\Python36\lib\site-packages\pymysql\connections.py", line 1075, in read]
27-Oct-2019 22:44:46.096 WARNING [Thread-189] org.apache.catalina.servlets.CGIServlet$CGIRunner.sendToLog stderr line: [    first_packet = self.connection._read_packet()]
27-Oct-2019 22:44:46.096 WARNING [Thread-189] org.apache.catalina.servlets.CGIServlet$CGIRunner.sendToLog stderr line: [  File "C:\Users\hayde\AppData\Local\Programs\Python\Python36\lib\site-packages\pymysql\connections.py", line 684, in _read_packet]
27-Oct-2019 22:44:46.097 WARNING [Thread-189] org.apache.catalina.servlets.CGIServlet$CGIRunner.sendToLog stderr line: [    packet.check_error()]
27-Oct-2019 22:44:46.098 WARNING [Thread-189] org.apache.catalina.servlets.CGIServlet$CGIRunner.sendToLog stderr line: [  File "C:\Users\hayde\AppData\Local\Programs\Python\Python36\lib\site-packages\pymysql\protocol.py", line 220, in check_error]
27-Oct-2019 22:44:46.099 WARNING [Thread-189] org.apache.catalina.servlets.CGIServlet$CGIRunner.sendToLog stderr line: [    err.raise_mysql_exception(self._data)]
27-Oct-2019 22:44:46.099 WARNING [Thread-189] org.apache.catalina.servlets.CGIServlet$CGIRunner.sendToLog stderr line: [  File "C:\Users\hayde\AppData\Local\Programs\Python\Python36\lib\site-packages\pymysql\err.py", line 109, in raise_mysql_exception]
27-Oct-2019 22:44:46.100 WARNING [Thread-189] org.apache.catalina.servlets.CGIServlet$CGIRunner.sendToLog stderr line: [    raise errorclass(errno, errval)]
27-Oct-2019 22:44:46.100 WARNING [Thread-189] org.apache.catalina.servlets.CGIServlet$CGIRunner.sendToLog stderr line: [pymysql.err.InternalError: (1054, "Unknown column 'birth_year' in 'where clause'")]
27-Oct-2019 22:44:46.105 WARNING [Thread-189] org.apache.catalina.servlets.CGIServlet$CGIRunner.sendToLog Received [20] lines on stderr
27-Oct-2019 22:51:31.880 WARNING [Thread-190] org.apache.catalina.servlets.CGIServlet$CGIRunner.sendToLog stderr line: [Traceback (most recent call last):]
27-Oct-2019 22:51:31.880 WARNING [Thread-190] org.apache.catalina.servlets.CGIServlet$CGIRunner.sendToLog stderr line: [  File "C:\Users\hayde\Desktop\UCI\Fall 2019\EECS 118\MP2\apache-tomcat-9.0.26\webapps\test\WEB-INF\cgi\project_3_search.py", line 144, in <module>]
27-Oct-2019 22:51:31.881 WARNING [Thread-190] org.apache.catalina.servlets.CGIServlet$CGIRunner.sendToLog stderr line: [    cur.execute(query)]
27-Oct-2019 22:51:31.881 WARNING [Thread-190] org.apache.catalina.servlets.CGIServlet$CGIRunner.sendToLog stderr line: [  File "C:\Users\hayde\AppData\Local\Programs\Python\Python36\lib\site-packages\pymysql\cursors.py", line 170, in execute]
27-Oct-2019 22:51:31.882 WARNING [Thread-190] org.apache.catalina.servlets.CGIServlet$CGIRunner.sendToLog stderr line: [    result = self._query(query)]
27-Oct-2019 22:51:31.882 WARNING [Thread-190] org.apache.catalina.servlets.CGIServlet$CGIRunner.sendToLog stderr line: [  File "C:\Users\hayde\AppData\Local\Programs\Python\Python36\lib\site-packages\pymysql\cursors.py", line 328, in _query]
27-Oct-2019 22:51:31.883 WARNING [Thread-190] org.apache.catalina.servlets.CGIServlet$CGIRunner.sendToLog stderr line: [    conn.query(q)]
27-Oct-2019 22:51:31.883 WARNING [Thread-190] org.apache.catalina.servlets.CGIServlet$CGIRunner.sendToLog stderr line: [  File "C:\Users\hayde\AppData\Local\Programs\Python\Python36\lib\site-packages\pymysql\connections.py", line 517, in query]
27-Oct-2019 22:51:31.884 WARNING [Thread-190] org.apache.catalina.servlets.CGIServlet$CGIRunner.sendToLog stderr line: [    self._affected_rows = self._read_query_result(unbuffered=unbuffered)]
27-Oct-2019 22:51:31.884 WARNING [Thread-190] org.apache.catalina.servlets.CGIServlet$CGIRunner.sendToLog stderr line: [  File "C:\Users\hayde\AppData\Local\Programs\Python\Python36\lib\site-packages\pymysql\connections.py", line 732, in _read_query_result]
27-Oct-2019 22:51:31.885 WARNING [Thread-190] org.apache.catalina.servlets.CGIServlet$CGIRunner.sendToLog stderr line: [    result.read()]
27-Oct-2019 22:51:31.886 WARNING [Thread-190] org.apache.catalina.servlets.CGIServlet$CGIRunner.sendToLog stderr line: [  File "C:\Users\hayde\AppData\Local\Programs\Python\Python36\lib\site-packages\pymysql\connections.py", line 1075, in read]
27-Oct-2019 22:51:31.887 WARNING [Thread-190] org.apache.catalina.servlets.CGIServlet$CGIRunner.sendToLog stderr line: [    first_packet = self.connection._read_packet()]
27-Oct-2019 22:51:31.887 WARNING [Thread-190] org.apache.catalina.servlets.CGIServlet$CGIRunner.sendToLog stderr line: [  File "C:\Users\hayde\AppData\Local\Programs\Python\Python36\lib\site-packages\pymysql\connections.py", line 684, in _read_packet]
27-Oct-2019 22:51:31.887 WARNING [Thread-190] org.apache.catalina.servlets.CGIServlet$CGIRunner.sendToLog stderr line: [    packet.check_error()]
27-Oct-2019 22:51:31.888 WARNING [Thread-190] org.apache.catalina.servlets.CGIServlet$CGIRunner.sendToLog stderr line: [  File "C:\Users\hayde\AppData\Local\Programs\Python\Python36\lib\site-packages\pymysql\protocol.py", line 220, in check_error]
27-Oct-2019 22:51:31.889 WARNING [Thread-190] org.apache.catalina.servlets.CGIServlet$CGIRunner.sendToLog stderr line: [    err.raise_mysql_exception(self._data)]
27-Oct-2019 22:51:31.890 WARNING [Thread-190] org.apache.catalina.servlets.CGIServlet$CGIRunner.sendToLog stderr line: [  File "C:\Users\hayde\AppData\Local\Programs\Python\Python36\lib\site-packages\pymysql\err.py", line 109, in raise_mysql_exception]
27-Oct-2019 22:51:31.890 WARNING [Thread-190] org.apache.catalina.servlets.CGIServlet$CGIRunner.sendToLog stderr line: [    raise errorclass(errno, errval)]
27-Oct-2019 22:51:31.890 WARNING [Thread-190] org.apache.catalina.servlets.CGIServlet$CGIRunner.sendToLog stderr line: [pymysql.err.InternalError: (1054, "Unknown column 'birth_year' in 'where clause'")]
27-Oct-2019 22:51:31.897 WARNING [Thread-190] org.apache.catalina.servlets.CGIServlet$CGIRunner.sendToLog Received [20] lines on stderr
27-Oct-2019 22:57:19.493 WARNING [Thread-198] org.apache.catalina.servlets.CGIServlet$CGIRunner.sendToLog stderr line: [Traceback (most recent call last):]
27-Oct-2019 22:57:19.493 WARNING [Thread-198] org.apache.catalina.servlets.CGIServlet$CGIRunner.sendToLog stderr line: [  File "C:\Users\hayde\Desktop\UCI\Fall 2019\EECS 118\MP2\apache-tomcat-9.0.26\webapps\test\WEB-INF\cgi\project_3.py", line 63, in <module>]
27-Oct-2019 22:57:19.494 WARNING [Thread-198] org.apache.catalina.servlets.CGIServlet$CGIRunner.sendToLog stderr line: [    print(js)]
27-Oct-2019 22:57:19.494 WARNING [Thread-198] org.apache.catalina.servlets.CGIServlet$CGIRunner.sendToLog stderr line: [NameError: name 'js' is not defined]
27-Oct-2019 22:57:19.518 WARNING [Thread-198] org.apache.catalina.servlets.CGIServlet$CGIRunner.sendToLog Received [4] lines on stderr
27-Oct-2019 23:05:38.877 WARNING [Thread-200] org.apache.catalina.servlets.CGIServlet$CGIRunner.sendToLog stderr line: [  File "C:\Users\hayde\Desktop\UCI\Fall 2019\EECS 118\MP2\apache-tomcat-9.0.26\webapps\test\WEB-INF\cgi\project_3.py", line 7]
27-Oct-2019 23:05:38.878 WARNING [Thread-200] org.apache.catalina.servlets.CGIServlet$CGIRunner.sendToLog stderr line: [    import cgi, cgitb, pymysql, ]
27-Oct-2019 23:05:38.878 WARNING [Thread-200] org.apache.catalina.servlets.CGIServlet$CGIRunner.sendToLog stderr line: [                               ^]
27-Oct-2019 23:05:38.883 WARNING [Thread-200] org.apache.catalina.servlets.CGIServlet$CGIRunner.sendToLog stderr line: [SyntaxError: invalid syntax]
27-Oct-2019 23:05:38.891 WARNING [Thread-200] org.apache.catalina.servlets.CGIServlet$CGIRunner.sendToLog Received [4] lines on stderr
27-Oct-2019 23:07:42.266 WARNING [Thread-201] org.apache.catalina.servlets.CGIServlet$CGIRunner.sendToLog stderr line: [  File "C:\Users\hayde\Desktop\UCI\Fall 2019\EECS 118\MP2\apache-tomcat-9.0.26\webapps\test\WEB-INF\cgi\project_3.py", line 7]
27-Oct-2019 23:07:42.266 WARNING [Thread-201] org.apache.catalina.servlets.CGIServlet$CGIRunner.sendToLog stderr line: [    import cgi, cgitb, pymysql, ]
27-Oct-2019 23:07:42.268 WARNING [Thread-201] org.apache.catalina.servlets.CGIServlet$CGIRunner.sendToLog stderr line: [                               ^]
27-Oct-2019 23:07:42.269 WARNING [Thread-201] org.apache.catalina.servlets.CGIServlet$CGIRunner.sendToLog stderr line: [SyntaxError: invalid syntax]
27-Oct-2019 23:07:42.272 WARNING [Thread-201] org.apache.catalina.servlets.CGIServlet$CGIRunner.sendToLog Received [4] lines on stderr
27-Oct-2019 23:08:49.412 WARNING [Thread-202] org.apache.catalina.servlets.CGIServlet$CGIRunner.sendToLog stderr line: [  File "C:\Users\hayde\Desktop\UCI\Fall 2019\EECS 118\MP2\apache-tomcat-9.0.26\webapps\test\WEB-INF\cgi\project_3.py", line 7]
27-Oct-2019 23:08:49.412 WARNING [Thread-202] org.apache.catalina.servlets.CGIServlet$CGIRunner.sendToLog stderr line: [    import cgi, cgitb, pymysql, ]
27-Oct-2019 23:08:49.416 WARNING [Thread-202] org.apache.catalina.servlets.CGIServlet$CGIRunner.sendToLog stderr line: [                               ^]
27-Oct-2019 23:08:49.417 WARNING [Thread-202] org.apache.catalina.servlets.CGIServlet$CGIRunner.sendToLog stderr line: [SyntaxError: invalid syntax]
27-Oct-2019 23:08:49.420 WARNING [Thread-202] org.apache.catalina.servlets.CGIServlet$CGIRunner.sendToLog Received [4] lines on stderr
27-Oct-2019 23:08:53.044 WARNING [Thread-203] org.apache.catalina.servlets.CGIServlet$CGIRunner.sendToLog stderr line: [  File "C:\Users\hayde\Desktop\UCI\Fall 2019\EECS 118\MP2\apache-tomcat-9.0.26\webapps\test\WEB-INF\cgi\project_3.py", line 7]
27-Oct-2019 23:08:53.044 WARNING [Thread-203] org.apache.catalina.servlets.CGIServlet$CGIRunner.sendToLog stderr line: [    import cgi, cgitb, pymysql, ]
27-Oct-2019 23:08:53.048 WARNING [Thread-203] org.apache.catalina.servlets.CGIServlet$CGIRunner.sendToLog stderr line: [                               ^]
27-Oct-2019 23:08:53.049 WARNING [Thread-203] org.apache.catalina.servlets.CGIServlet$CGIRunner.sendToLog stderr line: [SyntaxError: invalid syntax]
27-Oct-2019 23:08:53.053 WARNING [Thread-203] org.apache.catalina.servlets.CGIServlet$CGIRunner.sendToLog Received [4] lines on stderr
27-Oct-2019 23:09:25.826 WARNING [Thread-204] org.apache.catalina.servlets.CGIServlet$CGIRunner.sendToLog stderr line: [  File "C:\Users\hayde\Desktop\UCI\Fall 2019\EECS 118\MP2\apache-tomcat-9.0.26\webapps\test\WEB-INF\cgi\project_3.py", line 7]
27-Oct-2019 23:09:25.827 WARNING [Thread-204] org.apache.catalina.servlets.CGIServlet$CGIRunner.sendToLog stderr line: [    import cgi, cgitb, pymysql, ]
27-Oct-2019 23:09:25.830 WARNING [Thread-204] org.apache.catalina.servlets.CGIServlet$CGIRunner.sendToLog stderr line: [                               ^]
27-Oct-2019 23:09:25.832 WARNING [Thread-204] org.apache.catalina.servlets.CGIServlet$CGIRunner.sendToLog stderr line: [SyntaxError: invalid syntax]
27-Oct-2019 23:09:25.834 WARNING [Thread-204] org.apache.catalina.servlets.CGIServlet$CGIRunner.sendToLog Received [4] lines on stderr
27-Oct-2019 23:09:53.731 WARNING [Thread-205] org.apache.catalina.servlets.CGIServlet$CGIRunner.sendToLog stderr line: [  File "C:\Users\hayde\Desktop\UCI\Fall 2019\EECS 118\MP2\apache-tomcat-9.0.26\webapps\test\WEB-INF\cgi\project_3.py", line 7]
27-Oct-2019 23:09:53.731 WARNING [Thread-205] org.apache.catalina.servlets.CGIServlet$CGIRunner.sendToLog stderr line: [    import cgi, cgitb, pymysql, ]
27-Oct-2019 23:09:53.732 WARNING [Thread-205] org.apache.catalina.servlets.CGIServlet$CGIRunner.sendToLog stderr line: [                               ^]
27-Oct-2019 23:09:53.733 WARNING [Thread-205] org.apache.catalina.servlets.CGIServlet$CGIRunner.sendToLog stderr line: [SyntaxError: invalid syntax]
27-Oct-2019 23:09:53.738 WARNING [Thread-205] org.apache.catalina.servlets.CGIServlet$CGIRunner.sendToLog Received [4] lines on stderr
27-Oct-2019 23:10:11.090 WARNING [Thread-206] org.apache.catalina.servlets.CGIServlet$CGIRunner.sendToLog stderr line: [  File "C:\Users\hayde\Desktop\UCI\Fall 2019\EECS 118\MP2\apache-tomcat-9.0.26\webapps\test\WEB-INF\cgi\project_3.py", line 7]
27-Oct-2019 23:10:11.090 WARNING [Thread-206] org.apache.catalina.servlets.CGIServlet$CGIRunner.sendToLog stderr line: [    import cgi, cgitb, pymysql, ]
27-Oct-2019 23:10:11.094 WARNING [Thread-206] org.apache.catalina.servlets.CGIServlet$CGIRunner.sendToLog stderr line: [                               ^]
27-Oct-2019 23:10:11.094 WARNING [Thread-206] org.apache.catalina.servlets.CGIServlet$CGIRunner.sendToLog stderr line: [SyntaxError: invalid syntax]
27-Oct-2019 23:10:11.102 WARNING [Thread-206] org.apache.catalina.servlets.CGIServlet$CGIRunner.sendToLog Received [4] lines on stderr
27-Oct-2019 23:11:24.571 WARNING [Thread-207] org.apache.catalina.servlets.CGIServlet$CGIRunner.sendToLog stderr line: [  File "C:\Users\hayde\Desktop\UCI\Fall 2019\EECS 118\MP2\apache-tomcat-9.0.26\webapps\test\WEB-INF\cgi\project_3.py", line 7]
27-Oct-2019 23:11:24.571 WARNING [Thread-207] org.apache.catalina.servlets.CGIServlet$CGIRunner.sendToLog stderr line: [    import cgi, cgitb, pymysql, ]
27-Oct-2019 23:11:24.571 WARNING [Thread-207] org.apache.catalina.servlets.CGIServlet$CGIRunner.sendToLog stderr line: [                               ^]
27-Oct-2019 23:11:24.575 WARNING [Thread-207] org.apache.catalina.servlets.CGIServlet$CGIRunner.sendToLog stderr line: [SyntaxError: invalid syntax]
27-Oct-2019 23:11:24.578 WARNING [Thread-207] org.apache.catalina.servlets.CGIServlet$CGIRunner.sendToLog Received [4] lines on stderr
27-Oct-2019 23:12:00.158 WARNING [Thread-208] org.apache.catalina.servlets.CGIServlet$CGIRunner.sendToLog stderr line: [  File "C:\Users\hayde\Desktop\UCI\Fall 2019\EECS 118\MP2\apache-tomcat-9.0.26\webapps\test\WEB-INF\cgi\project_3.py", line 7]
27-Oct-2019 23:12:00.159 WARNING [Thread-208] org.apache.catalina.servlets.CGIServlet$CGIRunner.sendToLog stderr line: [    import cgi, cgitb, pymysql, ]
27-Oct-2019 23:12:00.161 WARNING [Thread-208] org.apache.catalina.servlets.CGIServlet$CGIRunner.sendToLog stderr line: [                               ^]
27-Oct-2019 23:12:00.162 WARNING [Thread-208] org.apache.catalina.servlets.CGIServlet$CGIRunner.sendToLog stderr line: [SyntaxError: invalid syntax]
27-Oct-2019 23:12:00.167 WARNING [Thread-208] org.apache.catalina.servlets.CGIServlet$CGIRunner.sendToLog Received [4] lines on stderr
27-Oct-2019 23:12:43.379 WARNING [Thread-210] org.apache.catalina.servlets.CGIServlet$CGIRunner.sendToLog stderr line: [Traceback (most recent call last):]
27-Oct-2019 23:12:43.379 WARNING [Thread-210] org.apache.catalina.servlets.CGIServlet$CGIRunner.sendToLog stderr line: [  File "C:\Users\hayde\Desktop\UCI\Fall 2019\EECS 118\MP2\apache-tomcat-9.0.26\webapps\test\WEB-INF\cgi\project_3.py", line 59, in <module>]
27-Oct-2019 23:12:43.382 WARNING [Thread-210] org.apache.catalina.servlets.CGIServlet$CGIRunner.sendToLog stderr line: [    if dt.datetime.now().hour >= 5 and dt.datetime.now().hour < 12:]
27-Oct-2019 23:12:43.382 WARNING [Thread-210] org.apache.catalina.servlets.CGIServlet$CGIRunner.sendToLog stderr line: [NameError: name 'dt' is not defined]
27-Oct-2019 23:12:43.401 WARNING [Thread-210] org.apache.catalina.servlets.CGIServlet$CGIRunner.sendToLog Received [4] lines on stderr
27-Oct-2019 23:18:46.835 WARNING [Thread-213] org.apache.catalina.servlets.CGIServlet$CGIRunner.sendToLog stderr line: [Traceback (most recent call last):]
27-Oct-2019 23:18:46.835 WARNING [Thread-213] org.apache.catalina.servlets.CGIServlet$CGIRunner.sendToLog stderr line: [  File "C:\Users\hayde\Desktop\UCI\Fall 2019\EECS 118\MP2\apache-tomcat-9.0.26\webapps\test\WEB-INF\cgi\project_3.py", line 69, in <module>]
27-Oct-2019 23:18:46.844 WARNING [Thread-213] org.apache.catalina.servlets.CGIServlet$CGIRunner.sendToLog stderr line: [    print("<H1>Galleries<br/>Good " + current_day+gal_upload++"</H1>")]
27-Oct-2019 23:18:46.844 WARNING [Thread-213] org.apache.catalina.servlets.CGIServlet$CGIRunner.sendToLog stderr line: [TypeError: bad operand type for unary +: 'str']
27-Oct-2019 23:18:46.856 WARNING [Thread-213] org.apache.catalina.servlets.CGIServlet$CGIRunner.sendToLog Received [4] lines on stderr
